Backup failed for Site task.local. Database or site_config.json may be corrupted
Traceback with variables (most recent call last):
  File "apps/frappe/frappe/commands/site.py", line 865, in backup
    odb = scheduled_backup(
      context = CliCtxObj(sites=['task.local'], force=False, profile=False, verbose=True)
      with_files = False
      backup_path = None
      backup_path_db = None
      backup_path_files = None
      backup_path_private_files = None
      backup_path_conf = None
      ignore_backup_conf = False
      verbose = True
      compress = False
      include = ''
      exclude = ''
      old_backup_metadata = False
      scheduled_backup = <function scheduled_backup at 0x10337cc20>
      exit_code = 0
      rollback_callback = None
      site = 'task.local'
  File "apps/frappe/frappe/utils/backups.py", line 589, in scheduled_backup
    return new_backup(
      older_than = 6
      ignore_files = True
      backup_path = None
      backup_path_db = None
      backup_path_files = None
      backup_path_private_files = None
      backup_path_conf = None
      ignore_conf = False
      include_doctypes = ''
      exclude_doctypes = ''
      compress = False
      force = True
      verbose = True
      old_backup_metadata = False
      rollback_callback = <frappe.utils.CallbackManager object at 0x103523c10>
  File "apps/frappe/frappe/utils/backups.py", line 647, in new_backup
    odb.get_backup(older_than, ignore_files, force=force)
      older_than = 6
      ignore_files = True
      backup_path = None
      backup_path_db = None
      backup_path_files = None
      backup_path_private_files = None
      backup_path_conf = None
      ignore_conf = False
      include_doctypes = ''
      exclude_doctypes = ''
      compress = False
      force = True
      verbose = True
      old_backup_metadata = False
      rollback_callback = <frappe.utils.CallbackManager object at 0x103523c10>
      odb = <frappe.utils.backups.BackupGenerator object at 0x103542850>
  File "apps/frappe/frappe/utils/backups.py", line 191, in get_backup
    self.delete_if_step_fails(self.take_dump, self.backup_path_db)
      self = <frappe.utils.backups.BackupGenerator object at 0x103542850>
      older_than = 6
      ignore_files = True
      force = True
      last_db = False
      last_file = False
      last_private_file = False
      site_config_backup_path = False
  File "apps/frappe/frappe/utils/backups.py", line 528, in delete_if_step_fails
    raise e
      self = <frappe.utils.backups.BackupGenerator object at 0x103542850>
      step = <bound method BackupGenerator.take_dump of <frappe.utils.backups.BackupGenerator object at 0x103542850>>
      paths = ('./task.local/private/backups/20250509_180001-task_local-database.sql.gz',)
      path = './task.local/private/backups/20250509_180001-task_local-database.sql.gz'
  File "apps/frappe/frappe/utils/backups.py", line 523, in delete_if_step_fails
    step()
      self = <frappe.utils.backups.BackupGenerator object at 0x103542850>
      step = <bound method BackupGenerator.take_dump of <frappe.utils.backups.BackupGenerator object at 0x103542850>>
      paths = ('./task.local/private/backups/20250509_180001-task_local-database.sql.gz',)
      path = './task.local/private/backups/20250509_180001-task_local-database.sql.gz'
  File "apps/frappe/frappe/utils/backups.py", line 465, in take_dump
    frappe.throw(
      self = <frappe.utils.backups.BackupGenerator object at 0x103542850>
      frappe = <module 'frappe' from 'apps/frappe/frappe/__init__.py'>
      shlex = <module 'shlex' from '/Users/upforcetech/.pyenv/versions/3.11.8/lib/python3.11/shlex.py'>
      get_app_branch = <function get_app_branch at 0x103562d40>
      gzip_exc = '/usr/bin/gzip'
      database_header_content = ['begin frappe metadata', '[frappe]', 'version = 16.0.0-dev', 'branch = develop', 'end frappe metadata', '']
      generated_header = '-- begin frappe metadata\n-- [frappe]\n-- version = 16.0.0-dev\n-- branch = develop\n-- end frappe metadata\n-- \n'
      f = <_io.TextIOWrapper name='./task.local/private/backups/20250509_180001-task_local-database.sql.gz' encoding='UTF-8'>
      cmd = []
      extra = []
      get_command = <function get_command at 0x1033aa5c0>
      bin = None
      args = ['--user=_cce20c0570d41558', '--host=127.0.0.1', '--port=3306', '--password=SOrrCnf2nEiGJvko', '--single-transaction', '--quick', '--lock-tables=false', '_cce20c0570d41558']
      bin_name = 'mariadb-dump'
  File "apps/frappe/frappe/utils/messages.py", line 145, in throw
    msgprint(
      msg = 'mariadb-dump not found in PATH! This is required to take a backup.'
      exc = <class 'frappe.exceptions.ExecutableNotFound'>
      title = None
      is_minimizable = False
      wide = False
      as_list = False
      primary_action = None
  File "apps/frappe/frappe/utils/messages.py", line 106, in msgprint
    _raise_exception()
      msg = 'mariadb-dump not found in PATH! This is required to take a backup.'
      title = None
      raise_exception = <class 'frappe.exceptions.ExecutableNotFound'>
      as_table = False
      as_list = False
      indicator = 'red'
      alert = False
      primary_action = None
      is_minimizable = False
      wide = False
      realtime = False
      _raise_exception = <function msgprint.<locals>._raise_exception at 0x103561bc0>
      inspect = <module 'inspect' from '/Users/upforcetech/.pyenv/versions/3.11.8/lib/python3.11/inspect.py'>
      out = {'message': 'mariadb-dump not found in PATH! This is required to take a backup.', 'title': 'Message', 'indicator': 'red', 'raise_exception': 1, '__frappe_exc_id': 'c5eddb894f6801161bc16130d41454bbbf1f5d9417f55b006e7a099c'}
  File "apps/frappe/frappe/utils/messages.py", line 57, in _raise_exception
    raise exc
      exc = ExecutableNotFound('mariadb-dump not found in PATH! This is required to take a backup.')
      inspect = <module 'inspect' from '/Users/upforcetech/.pyenv/versions/3.11.8/lib/python3.11/inspect.py'>
      msg = 'mariadb-dump not found in PATH! This is required to take a backup.'
      out = {'message': 'mariadb-dump not found in PATH! This is required to take a backup.', 'title': 'Message', 'indicator': 'red', 'raise_exception': 1, '__frappe_exc_id': 'c5eddb894f6801161bc16130d41454bbbf1f5d9417f55b006e7a099c'}
      raise_exception = <class 'frappe.exceptions.ExecutableNotFound'>
frappe.exceptions.ExecutableNotFound: mariadb-dump not found in PATH! This is required to take a backup.
Backup failed for Site task.local. Database or site_config.json may be corrupted
Traceback with variables (most recent call last):
  File "apps/frappe/frappe/commands/site.py", line 865, in backup
    odb = scheduled_backup(
      context = CliCtxObj(sites=['task.local'], force=False, profile=False, verbose=True)
      with_files = False
      backup_path = None
      backup_path_db = None
      backup_path_files = None
      backup_path_private_files = None
      backup_path_conf = None
      ignore_backup_conf = False
      verbose = True
      compress = False
      include = ''
      exclude = ''
      old_backup_metadata = False
      scheduled_backup = <function scheduled_backup at 0x10587cc20>
      exit_code = 0
      rollback_callback = None
      site = 'task.local'
  File "apps/frappe/frappe/utils/backups.py", line 589, in scheduled_backup
    return new_backup(
      older_than = 6
      ignore_files = True
      backup_path = None
      backup_path_db = None
      backup_path_files = None
      backup_path_private_files = None
      backup_path_conf = None
      ignore_conf = False
      include_doctypes = ''
      exclude_doctypes = ''
      compress = False
      force = True
      verbose = True
      old_backup_metadata = False
      rollback_callback = <frappe.utils.CallbackManager object at 0x105a57c10>
  File "apps/frappe/frappe/utils/backups.py", line 647, in new_backup
    odb.get_backup(older_than, ignore_files, force=force)
      older_than = 6
      ignore_files = True
      backup_path = None
      backup_path_db = None
      backup_path_files = None
      backup_path_private_files = None
      backup_path_conf = None
      ignore_conf = False
      include_doctypes = ''
      exclude_doctypes = ''
      compress = False
      force = True
      verbose = True
      old_backup_metadata = False
      rollback_callback = <frappe.utils.CallbackManager object at 0x105a57c10>
      odb = <frappe.utils.backups.BackupGenerator object at 0x105a76550>
  File "apps/frappe/frappe/utils/backups.py", line 191, in get_backup
    self.delete_if_step_fails(self.take_dump, self.backup_path_db)
      self = <frappe.utils.backups.BackupGenerator object at 0x105a76550>
      older_than = 6
      ignore_files = True
      force = True
      last_db = False
      last_file = False
      last_private_file = False
      site_config_backup_path = False
  File "apps/frappe/frappe/utils/backups.py", line 528, in delete_if_step_fails
    raise e
      self = <frappe.utils.backups.BackupGenerator object at 0x105a76550>
      step = <bound method BackupGenerator.take_dump of <frappe.utils.backups.BackupGenerator object at 0x105a76550>>
      paths = ('./task.local/private/backups/20250510_000001-task_local-database.sql.gz',)
      path = './task.local/private/backups/20250510_000001-task_local-database.sql.gz'
  File "apps/frappe/frappe/utils/backups.py", line 523, in delete_if_step_fails
    step()
      self = <frappe.utils.backups.BackupGenerator object at 0x105a76550>
      step = <bound method BackupGenerator.take_dump of <frappe.utils.backups.BackupGenerator object at 0x105a76550>>
      paths = ('./task.local/private/backups/20250510_000001-task_local-database.sql.gz',)
      path = './task.local/private/backups/20250510_000001-task_local-database.sql.gz'
  File "apps/frappe/frappe/utils/backups.py", line 465, in take_dump
    frappe.throw(
      self = <frappe.utils.backups.BackupGenerator object at 0x105a76550>
      frappe = <module 'frappe' from 'apps/frappe/frappe/__init__.py'>
      shlex = <module 'shlex' from '/Users/upforcetech/.pyenv/versions/3.11.8/lib/python3.11/shlex.py'>
      get_app_branch = <function get_app_branch at 0x105a96d40>
      gzip_exc = '/usr/bin/gzip'
      database_header_content = ['begin frappe metadata', '[frappe]', 'version = 16.0.0-dev', 'branch = develop', 'end frappe metadata', '']
      generated_header = '-- begin frappe metadata\n-- [frappe]\n-- version = 16.0.0-dev\n-- branch = develop\n-- end frappe metadata\n-- \n'
      f = <_io.TextIOWrapper name='./task.local/private/backups/20250510_000001-task_local-database.sql.gz' encoding='UTF-8'>
      cmd = []
      extra = []
      get_command = <function get_command at 0x1058aa5c0>
      bin = None
      args = ['--user=_cce20c0570d41558', '--host=127.0.0.1', '--port=3306', '--password=SOrrCnf2nEiGJvko', '--single-transaction', '--quick', '--lock-tables=false', '_cce20c0570d41558']
      bin_name = 'mariadb-dump'
  File "apps/frappe/frappe/utils/messages.py", line 145, in throw
    msgprint(
      msg = 'mariadb-dump not found in PATH! This is required to take a backup.'
      exc = <class 'frappe.exceptions.ExecutableNotFound'>
      title = None
      is_minimizable = False
      wide = False
      as_list = False
      primary_action = None
  File "apps/frappe/frappe/utils/messages.py", line 106, in msgprint
    _raise_exception()
      msg = 'mariadb-dump not found in PATH! This is required to take a backup.'
      title = None
      raise_exception = <class 'frappe.exceptions.ExecutableNotFound'>
      as_table = False
      as_list = False
      indicator = 'red'
      alert = False
      primary_action = None
      is_minimizable = False
      wide = False
      realtime = False
      _raise_exception = <function msgprint.<locals>._raise_exception at 0x105a95bc0>
      inspect = <module 'inspect' from '/Users/upforcetech/.pyenv/versions/3.11.8/lib/python3.11/inspect.py'>
      out = {'message': 'mariadb-dump not found in PATH! This is required to take a backup.', 'title': 'Message', 'indicator': 'red', 'raise_exception': 1, '__frappe_exc_id': 'b19ed839985ff5175656a087ef1a50140e89f1c944bb373e8e59bcea'}
  File "apps/frappe/frappe/utils/messages.py", line 57, in _raise_exception
    raise exc
      exc = ExecutableNotFound('mariadb-dump not found in PATH! This is required to take a backup.')
      inspect = <module 'inspect' from '/Users/upforcetech/.pyenv/versions/3.11.8/lib/python3.11/inspect.py'>
      msg = 'mariadb-dump not found in PATH! This is required to take a backup.'
      out = {'message': 'mariadb-dump not found in PATH! This is required to take a backup.', 'title': 'Message', 'indicator': 'red', 'raise_exception': 1, '__frappe_exc_id': 'b19ed839985ff5175656a087ef1a50140e89f1c944bb373e8e59bcea'}
      raise_exception = <class 'frappe.exceptions.ExecutableNotFound'>
frappe.exceptions.ExecutableNotFound: mariadb-dump not found in PATH! This is required to take a backup.
Backup failed for Site task.local. Database or site_config.json may be corrupted
Traceback with variables (most recent call last):
  File "apps/frappe/frappe/commands/site.py", line 865, in backup
    odb = scheduled_backup(
      context = CliCtxObj(sites=['task.local'], force=False, profile=False, verbose=True)
      with_files = False
      backup_path = None
      backup_path_db = None
      backup_path_files = None
      backup_path_private_files = None
      backup_path_conf = None
      ignore_backup_conf = False
      verbose = True
      compress = False
      include = ''
      exclude = ''
      old_backup_metadata = False
      scheduled_backup = <function scheduled_backup at 0x106abcc20>
      exit_code = 0
      rollback_callback = None
      site = 'task.local'
  File "apps/frappe/frappe/utils/backups.py", line 589, in scheduled_backup
    return new_backup(
      older_than = 6
      ignore_files = True
      backup_path = None
      backup_path_db = None
      backup_path_files = None
      backup_path_private_files = None
      backup_path_conf = None
      ignore_conf = False
      include_doctypes = ''
      exclude_doctypes = ''
      compress = False
      force = True
      verbose = True
      old_backup_metadata = False
      rollback_callback = <frappe.utils.CallbackManager object at 0x106c97c10>
  File "apps/frappe/frappe/utils/backups.py", line 647, in new_backup
    odb.get_backup(older_than, ignore_files, force=force)
      older_than = 6
      ignore_files = True
      backup_path = None
      backup_path_db = None
      backup_path_files = None
      backup_path_private_files = None
      backup_path_conf = None
      ignore_conf = False
      include_doctypes = ''
      exclude_doctypes = ''
      compress = False
      force = True
      verbose = True
      old_backup_metadata = False
      rollback_callback = <frappe.utils.CallbackManager object at 0x106c97c10>
      odb = <frappe.utils.backups.BackupGenerator object at 0x106cb6e10>
  File "apps/frappe/frappe/utils/backups.py", line 191, in get_backup
    self.delete_if_step_fails(self.take_dump, self.backup_path_db)
      self = <frappe.utils.backups.BackupGenerator object at 0x106cb6e10>
      older_than = 6
      ignore_files = True
      force = True
      last_db = False
      last_file = False
      last_private_file = False
      site_config_backup_path = False
  File "apps/frappe/frappe/utils/backups.py", line 528, in delete_if_step_fails
    raise e
      self = <frappe.utils.backups.BackupGenerator object at 0x106cb6e10>
      step = <bound method BackupGenerator.take_dump of <frappe.utils.backups.BackupGenerator object at 0x106cb6e10>>
      paths = ('./task.local/private/backups/20250510_120002-task_local-database.sql.gz',)
      path = './task.local/private/backups/20250510_120002-task_local-database.sql.gz'
  File "apps/frappe/frappe/utils/backups.py", line 523, in delete_if_step_fails
    step()
      self = <frappe.utils.backups.BackupGenerator object at 0x106cb6e10>
      step = <bound method BackupGenerator.take_dump of <frappe.utils.backups.BackupGenerator object at 0x106cb6e10>>
      paths = ('./task.local/private/backups/20250510_120002-task_local-database.sql.gz',)
      path = './task.local/private/backups/20250510_120002-task_local-database.sql.gz'
  File "apps/frappe/frappe/utils/backups.py", line 465, in take_dump
    frappe.throw(
      self = <frappe.utils.backups.BackupGenerator object at 0x106cb6e10>
      frappe = <module 'frappe' from 'apps/frappe/frappe/__init__.py'>
      shlex = <module 'shlex' from '/Users/upforcetech/.pyenv/versions/3.11.8/lib/python3.11/shlex.py'>
      get_app_branch = <function get_app_branch at 0x10765ce00>
      gzip_exc = '/usr/bin/gzip'
      database_header_content = ['begin frappe metadata', '[frappe]', 'version = 16.0.0-dev', 'branch = develop', 'end frappe metadata', '']
      generated_header = '-- begin frappe metadata\n-- [frappe]\n-- version = 16.0.0-dev\n-- branch = develop\n-- end frappe metadata\n-- \n'
      f = <_io.TextIOWrapper name='./task.local/private/backups/20250510_120002-task_local-database.sql.gz' encoding='UTF-8'>
      cmd = []
      extra = []
      get_command = <function get_command at 0x106aea5c0>
      bin = None
      args = ['--user=_cce20c0570d41558', '--host=127.0.0.1', '--port=3306', '--password=SOrrCnf2nEiGJvko', '--single-transaction', '--quick', '--lock-tables=false', '_cce20c0570d41558']
      bin_name = 'mariadb-dump'
  File "apps/frappe/frappe/utils/messages.py", line 145, in throw
    msgprint(
      msg = 'mariadb-dump not found in PATH! This is required to take a backup.'
      exc = <class 'frappe.exceptions.ExecutableNotFound'>
      title = None
      is_minimizable = False
      wide = False
      as_list = False
      primary_action = None
  File "apps/frappe/frappe/utils/messages.py", line 106, in msgprint
    _raise_exception()
      msg = 'mariadb-dump not found in PATH! This is required to take a backup.'
      title = None
      raise_exception = <class 'frappe.exceptions.ExecutableNotFound'>
      as_table = False
      as_list = False
      indicator = 'red'
      alert = False
      primary_action = None
      is_minimizable = False
      wide = False
      realtime = False
      _raise_exception = <function msgprint.<locals>._raise_exception at 0x106cd7380>
      inspect = <module 'inspect' from '/Users/upforcetech/.pyenv/versions/3.11.8/lib/python3.11/inspect.py'>
      out = {'message': 'mariadb-dump not found in PATH! This is required to take a backup.', 'title': 'Message', 'indicator': 'red', 'raise_exception': 1, '__frappe_exc_id': '9a8c77704b1594ad442fe17b7e939b6491926d37522108513f5889ad'}
  File "apps/frappe/frappe/utils/messages.py", line 57, in _raise_exception
    raise exc
      exc = ExecutableNotFound('mariadb-dump not found in PATH! This is required to take a backup.')
      inspect = <module 'inspect' from '/Users/upforcetech/.pyenv/versions/3.11.8/lib/python3.11/inspect.py'>
      msg = 'mariadb-dump not found in PATH! This is required to take a backup.'
      out = {'message': 'mariadb-dump not found in PATH! This is required to take a backup.', 'title': 'Message', 'indicator': 'red', 'raise_exception': 1, '__frappe_exc_id': '9a8c77704b1594ad442fe17b7e939b6491926d37522108513f5889ad'}
      raise_exception = <class 'frappe.exceptions.ExecutableNotFound'>
frappe.exceptions.ExecutableNotFound: mariadb-dump not found in PATH! This is required to take a backup.
Backup failed for Site task.local. Database or site_config.json may be corrupted
Traceback with variables (most recent call last):
  File "apps/frappe/frappe/commands/site.py", line 865, in backup
    odb = scheduled_backup(
      context = CliCtxObj(sites=['task.local'], force=False, profile=False, verbose=True)
      with_files = False
      backup_path = None
      backup_path_db = None
      backup_path_files = None
      backup_path_private_files = None
      backup_path_conf = None
      ignore_backup_conf = False
      verbose = True
      compress = False
      include = ''
      exclude = ''
      old_backup_metadata = False
      scheduled_backup = <function scheduled_backup at 0x105088c20>
      exit_code = 0
      rollback_callback = None
      site = 'task.local'
  File "apps/frappe/frappe/utils/backups.py", line 589, in scheduled_backup
    return new_backup(
      older_than = 6
      ignore_files = True
      backup_path = None
      backup_path_db = None
      backup_path_files = None
      backup_path_private_files = None
      backup_path_conf = None
      ignore_conf = False
      include_doctypes = ''
      exclude_doctypes = ''
      compress = False
      force = True
      verbose = True
      old_backup_metadata = False
      rollback_callback = <frappe.utils.CallbackManager object at 0x105263c10>
  File "apps/frappe/frappe/utils/backups.py", line 647, in new_backup
    odb.get_backup(older_than, ignore_files, force=force)
      older_than = 6
      ignore_files = True
      backup_path = None
      backup_path_db = None
      backup_path_files = None
      backup_path_private_files = None
      backup_path_conf = None
      ignore_conf = False
      include_doctypes = ''
      exclude_doctypes = ''
      compress = False
      force = True
      verbose = True
      old_backup_metadata = False
      rollback_callback = <frappe.utils.CallbackManager object at 0x105263c10>
      odb = <frappe.utils.backups.BackupGenerator object at 0x105282850>
  File "apps/frappe/frappe/utils/backups.py", line 191, in get_backup
    self.delete_if_step_fails(self.take_dump, self.backup_path_db)
      self = <frappe.utils.backups.BackupGenerator object at 0x105282850>
      older_than = 6
      ignore_files = True
      force = True
      last_db = False
      last_file = False
      last_private_file = False
      site_config_backup_path = False
  File "apps/frappe/frappe/utils/backups.py", line 528, in delete_if_step_fails
    raise e
      self = <frappe.utils.backups.BackupGenerator object at 0x105282850>
      step = <bound method BackupGenerator.take_dump of <frappe.utils.backups.BackupGenerator object at 0x105282850>>
      paths = ('./task.local/private/backups/20250510_180002-task_local-database.sql.gz',)
      path = './task.local/private/backups/20250510_180002-task_local-database.sql.gz'
  File "apps/frappe/frappe/utils/backups.py", line 523, in delete_if_step_fails
    step()
      self = <frappe.utils.backups.BackupGenerator object at 0x105282850>
      step = <bound method BackupGenerator.take_dump of <frappe.utils.backups.BackupGenerator object at 0x105282850>>
      paths = ('./task.local/private/backups/20250510_180002-task_local-database.sql.gz',)
      path = './task.local/private/backups/20250510_180002-task_local-database.sql.gz'
  File "apps/frappe/frappe/utils/backups.py", line 465, in take_dump
    frappe.throw(
      self = <frappe.utils.backups.BackupGenerator object at 0x105282850>
      frappe = <module 'frappe' from 'apps/frappe/frappe/__init__.py'>
      shlex = <module 'shlex' from '/Users/upforcetech/.pyenv/versions/3.11.8/lib/python3.11/shlex.py'>
      get_app_branch = <function get_app_branch at 0x105c28e00>
      gzip_exc = '/usr/bin/gzip'
      database_header_content = ['begin frappe metadata', '[frappe]', 'version = 16.0.0-dev', 'branch = develop', 'end frappe metadata', '']
      generated_header = '-- begin frappe metadata\n-- [frappe]\n-- version = 16.0.0-dev\n-- branch = develop\n-- end frappe metadata\n-- \n'
      f = <_io.TextIOWrapper name='./task.local/private/backups/20250510_180002-task_local-database.sql.gz' encoding='UTF-8'>
      cmd = []
      extra = []
      get_command = <function get_command at 0x1050b65c0>
      bin = None
      args = ['--user=_cce20c0570d41558', '--host=127.0.0.1', '--port=3306', '--password=SOrrCnf2nEiGJvko', '--single-transaction', '--quick', '--lock-tables=false', '_cce20c0570d41558']
      bin_name = 'mariadb-dump'
  File "apps/frappe/frappe/utils/messages.py", line 145, in throw
    msgprint(
      msg = 'mariadb-dump not found in PATH! This is required to take a backup.'
      exc = <class 'frappe.exceptions.ExecutableNotFound'>
      title = None
      is_minimizable = False
      wide = False
      as_list = False
      primary_action = None
  File "apps/frappe/frappe/utils/messages.py", line 106, in msgprint
    _raise_exception()
      msg = 'mariadb-dump not found in PATH! This is required to take a backup.'
      title = None
      raise_exception = <class 'frappe.exceptions.ExecutableNotFound'>
      as_table = False
      as_list = False
      indicator = 'red'
      alert = False
      primary_action = None
      is_minimizable = False
      wide = False
      realtime = False
      _raise_exception = <function msgprint.<locals>._raise_exception at 0x1052a3380>
      inspect = <module 'inspect' from '/Users/upforcetech/.pyenv/versions/3.11.8/lib/python3.11/inspect.py'>
      out = {'message': 'mariadb-dump not found in PATH! This is required to take a backup.', 'title': 'Message', 'indicator': 'red', 'raise_exception': 1, '__frappe_exc_id': '2f7ffe166d7d08ace3341090e61df0beab57c80453e30f8b0186d49e'}
  File "apps/frappe/frappe/utils/messages.py", line 57, in _raise_exception
    raise exc
      exc = ExecutableNotFound('mariadb-dump not found in PATH! This is required to take a backup.')
      inspect = <module 'inspect' from '/Users/upforcetech/.pyenv/versions/3.11.8/lib/python3.11/inspect.py'>
      msg = 'mariadb-dump not found in PATH! This is required to take a backup.'
      out = {'message': 'mariadb-dump not found in PATH! This is required to take a backup.', 'title': 'Message', 'indicator': 'red', 'raise_exception': 1, '__frappe_exc_id': '2f7ffe166d7d08ace3341090e61df0beab57c80453e30f8b0186d49e'}
      raise_exception = <class 'frappe.exceptions.ExecutableNotFound'>
frappe.exceptions.ExecutableNotFound: mariadb-dump not found in PATH! This is required to take a backup.
Backup failed for Site task.local. Database or site_config.json may be corrupted
Traceback with variables (most recent call last):
  File "apps/frappe/frappe/commands/site.py", line 865, in backup
    odb = scheduled_backup(
      context = CliCtxObj(sites=['task.local'], force=False, profile=False, verbose=True)
      with_files = False
      backup_path = None
      backup_path_db = None
      backup_path_files = None
      backup_path_private_files = None
      backup_path_conf = None
      ignore_backup_conf = False
      verbose = True
      compress = False
      include = ''
      exclude = ''
      old_backup_metadata = False
      scheduled_backup = <function scheduled_backup at 0x102da0c20>
      exit_code = 0
      rollback_callback = None
      site = 'task.local'
  File "apps/frappe/frappe/utils/backups.py", line 589, in scheduled_backup
    return new_backup(
      older_than = 6
      ignore_files = True
      backup_path = None
      backup_path_db = None
      backup_path_files = None
      backup_path_private_files = None
      backup_path_conf = None
      ignore_conf = False
      include_doctypes = ''
      exclude_doctypes = ''
      compress = False
      force = True
      verbose = True
      old_backup_metadata = False
      rollback_callback = <frappe.utils.CallbackManager object at 0x102f7bc10>
  File "apps/frappe/frappe/utils/backups.py", line 647, in new_backup
    odb.get_backup(older_than, ignore_files, force=force)
      older_than = 6
      ignore_files = True
      backup_path = None
      backup_path_db = None
      backup_path_files = None
      backup_path_private_files = None
      backup_path_conf = None
      ignore_conf = False
      include_doctypes = ''
      exclude_doctypes = ''
      compress = False
      force = True
      verbose = True
      old_backup_metadata = False
      rollback_callback = <frappe.utils.CallbackManager object at 0x102f7bc10>
      odb = <frappe.utils.backups.BackupGenerator object at 0x102f9a850>
  File "apps/frappe/frappe/utils/backups.py", line 191, in get_backup
    self.delete_if_step_fails(self.take_dump, self.backup_path_db)
      self = <frappe.utils.backups.BackupGenerator object at 0x102f9a850>
      older_than = 6
      ignore_files = True
      force = True
      last_db = False
      last_file = False
      last_private_file = False
      site_config_backup_path = False
  File "apps/frappe/frappe/utils/backups.py", line 528, in delete_if_step_fails
    raise e
      self = <frappe.utils.backups.BackupGenerator object at 0x102f9a850>
      step = <bound method BackupGenerator.take_dump of <frappe.utils.backups.BackupGenerator object at 0x102f9a850>>
      paths = ('./task.local/private/backups/20250511_120001-task_local-database.sql.gz',)
      path = './task.local/private/backups/20250511_120001-task_local-database.sql.gz'
  File "apps/frappe/frappe/utils/backups.py", line 523, in delete_if_step_fails
    step()
      self = <frappe.utils.backups.BackupGenerator object at 0x102f9a850>
      step = <bound method BackupGenerator.take_dump of <frappe.utils.backups.BackupGenerator object at 0x102f9a850>>
      paths = ('./task.local/private/backups/20250511_120001-task_local-database.sql.gz',)
      path = './task.local/private/backups/20250511_120001-task_local-database.sql.gz'
  File "apps/frappe/frappe/utils/backups.py", line 465, in take_dump
    frappe.throw(
      self = <frappe.utils.backups.BackupGenerator object at 0x102f9a850>
      frappe = <module 'frappe' from 'apps/frappe/frappe/__init__.py'>
      shlex = <module 'shlex' from '/Users/upforcetech/.pyenv/versions/3.11.8/lib/python3.11/shlex.py'>
      get_app_branch = <function get_app_branch at 0x102fbad40>
      gzip_exc = '/usr/bin/gzip'
      database_header_content = ['begin frappe metadata', '[frappe]', 'version = 16.0.0-dev', 'branch = develop', 'end frappe metadata', '']
      generated_header = '-- begin frappe metadata\n-- [frappe]\n-- version = 16.0.0-dev\n-- branch = develop\n-- end frappe metadata\n-- \n'
      f = <_io.TextIOWrapper name='./task.local/private/backups/20250511_120001-task_local-database.sql.gz' encoding='UTF-8'>
      cmd = []
      extra = []
      get_command = <function get_command at 0x102dce5c0>
      bin = None
      args = ['--user=_cce20c0570d41558', '--host=127.0.0.1', '--port=3306', '--password=SOrrCnf2nEiGJvko', '--single-transaction', '--quick', '--lock-tables=false', '_cce20c0570d41558']
      bin_name = 'mariadb-dump'
  File "apps/frappe/frappe/utils/messages.py", line 145, in throw
    msgprint(
      msg = 'mariadb-dump not found in PATH! This is required to take a backup.'
      exc = <class 'frappe.exceptions.ExecutableNotFound'>
      title = None
      is_minimizable = False
      wide = False
      as_list = False
      primary_action = None
  File "apps/frappe/frappe/utils/messages.py", line 106, in msgprint
    _raise_exception()
      msg = 'mariadb-dump not found in PATH! This is required to take a backup.'
      title = None
      raise_exception = <class 'frappe.exceptions.ExecutableNotFound'>
      as_table = False
      as_list = False
      indicator = 'red'
      alert = False
      primary_action = None
      is_minimizable = False
      wide = False
      realtime = False
      _raise_exception = <function msgprint.<locals>._raise_exception at 0x102fb9bc0>
      inspect = <module 'inspect' from '/Users/upforcetech/.pyenv/versions/3.11.8/lib/python3.11/inspect.py'>
      out = {'message': 'mariadb-dump not found in PATH! This is required to take a backup.', 'title': 'Message', 'indicator': 'red', 'raise_exception': 1, '__frappe_exc_id': 'eb12faf9ce1a02b2b350052234c714b16bf51e545735b305036bce61'}
  File "apps/frappe/frappe/utils/messages.py", line 57, in _raise_exception
    raise exc
      exc = ExecutableNotFound('mariadb-dump not found in PATH! This is required to take a backup.')
      inspect = <module 'inspect' from '/Users/upforcetech/.pyenv/versions/3.11.8/lib/python3.11/inspect.py'>
      msg = 'mariadb-dump not found in PATH! This is required to take a backup.'
      out = {'message': 'mariadb-dump not found in PATH! This is required to take a backup.', 'title': 'Message', 'indicator': 'red', 'raise_exception': 1, '__frappe_exc_id': 'eb12faf9ce1a02b2b350052234c714b16bf51e545735b305036bce61'}
      raise_exception = <class 'frappe.exceptions.ExecutableNotFound'>
frappe.exceptions.ExecutableNotFound: mariadb-dump not found in PATH! This is required to take a backup.
Backup failed for Site task.local. Database or site_config.json may be corrupted
Traceback with variables (most recent call last):
  File "apps/frappe/frappe/commands/site.py", line 865, in backup
    odb = scheduled_backup(
      context = CliCtxObj(sites=['task.local'], force=False, profile=False, verbose=True)
      with_files = False
      backup_path = None
      backup_path_db = None
      backup_path_files = None
      backup_path_private_files = None
      backup_path_conf = None
      ignore_backup_conf = False
      verbose = True
      compress = False
      include = ''
      exclude = ''
      old_backup_metadata = False
      scheduled_backup = <function scheduled_backup at 0x1077e0c20>
      exit_code = 0
      rollback_callback = None
      site = 'task.local'
  File "apps/frappe/frappe/utils/backups.py", line 589, in scheduled_backup
    return new_backup(
      older_than = 6
      ignore_files = True
      backup_path = None
      backup_path_db = None
      backup_path_files = None
      backup_path_private_files = None
      backup_path_conf = None
      ignore_conf = False
      include_doctypes = ''
      exclude_doctypes = ''
      compress = False
      force = True
      verbose = True
      old_backup_metadata = False
      rollback_callback = <frappe.utils.CallbackManager object at 0x1079bbc10>
  File "apps/frappe/frappe/utils/backups.py", line 647, in new_backup
    odb.get_backup(older_than, ignore_files, force=force)
      older_than = 6
      ignore_files = True
      backup_path = None
      backup_path_db = None
      backup_path_files = None
      backup_path_private_files = None
      backup_path_conf = None
      ignore_conf = False
      include_doctypes = ''
      exclude_doctypes = ''
      compress = False
      force = True
      verbose = True
      old_backup_metadata = False
      rollback_callback = <frappe.utils.CallbackManager object at 0x1079bbc10>
      odb = <frappe.utils.backups.BackupGenerator object at 0x1079da790>
  File "apps/frappe/frappe/utils/backups.py", line 191, in get_backup
    self.delete_if_step_fails(self.take_dump, self.backup_path_db)
      self = <frappe.utils.backups.BackupGenerator object at 0x1079da790>
      older_than = 6
      ignore_files = True
      force = True
      last_db = False
      last_file = False
      last_private_file = False
      site_config_backup_path = False
  File "apps/frappe/frappe/utils/backups.py", line 528, in delete_if_step_fails
    raise e
      self = <frappe.utils.backups.BackupGenerator object at 0x1079da790>
      step = <bound method BackupGenerator.take_dump of <frappe.utils.backups.BackupGenerator object at 0x1079da790>>
      paths = ('./task.local/private/backups/20250511_180008-task_local-database.sql.gz',)
      path = './task.local/private/backups/20250511_180008-task_local-database.sql.gz'
  File "apps/frappe/frappe/utils/backups.py", line 523, in delete_if_step_fails
    step()
      self = <frappe.utils.backups.BackupGenerator object at 0x1079da790>
      step = <bound method BackupGenerator.take_dump of <frappe.utils.backups.BackupGenerator object at 0x1079da790>>
      paths = ('./task.local/private/backups/20250511_180008-task_local-database.sql.gz',)
      path = './task.local/private/backups/20250511_180008-task_local-database.sql.gz'
  File "apps/frappe/frappe/utils/backups.py", line 465, in take_dump
    frappe.throw(
      self = <frappe.utils.backups.BackupGenerator object at 0x1079da790>
      frappe = <module 'frappe' from 'apps/frappe/frappe/__init__.py'>
      shlex = <module 'shlex' from '/Users/upforcetech/.pyenv/versions/3.11.8/lib/python3.11/shlex.py'>
      get_app_branch = <function get_app_branch at 0x1079fad40>
      gzip_exc = '/usr/bin/gzip'
      database_header_content = ['begin frappe metadata', '[frappe]', 'version = 16.0.0-dev', 'branch = develop', 'end frappe metadata', '']
      generated_header = '-- begin frappe metadata\n-- [frappe]\n-- version = 16.0.0-dev\n-- branch = develop\n-- end frappe metadata\n-- \n'
      f = <_io.TextIOWrapper name='./task.local/private/backups/20250511_180008-task_local-database.sql.gz' encoding='UTF-8'>
      cmd = []
      extra = []
      get_command = <function get_command at 0x10780e5c0>
      bin = None
      args = ['--user=_cce20c0570d41558', '--host=127.0.0.1', '--port=3306', '--password=SOrrCnf2nEiGJvko', '--single-transaction', '--quick', '--lock-tables=false', '_cce20c0570d41558']
      bin_name = 'mariadb-dump'
  File "apps/frappe/frappe/utils/messages.py", line 145, in throw
    msgprint(
      msg = 'mariadb-dump not found in PATH! This is required to take a backup.'
      exc = <class 'frappe.exceptions.ExecutableNotFound'>
      title = None
      is_minimizable = False
      wide = False
      as_list = False
      primary_action = None
  File "apps/frappe/frappe/utils/messages.py", line 106, in msgprint
    _raise_exception()
      msg = 'mariadb-dump not found in PATH! This is required to take a backup.'
      title = None
      raise_exception = <class 'frappe.exceptions.ExecutableNotFound'>
      as_table = False
      as_list = False
      indicator = 'red'
      alert = False
      primary_action = None
      is_minimizable = False
      wide = False
      realtime = False
      _raise_exception = <function msgprint.<locals>._raise_exception at 0x1079f9bc0>
      inspect = <module 'inspect' from '/Users/upforcetech/.pyenv/versions/3.11.8/lib/python3.11/inspect.py'>
      out = {'message': 'mariadb-dump not found in PATH! This is required to take a backup.', 'title': 'Message', 'indicator': 'red', 'raise_exception': 1, '__frappe_exc_id': 'f8fc6c82b03e4f516cbedee4b90ef8188a7d95a8b3055d52b2a42b7c'}
  File "apps/frappe/frappe/utils/messages.py", line 57, in _raise_exception
    raise exc
      exc = ExecutableNotFound('mariadb-dump not found in PATH! This is required to take a backup.')
      inspect = <module 'inspect' from '/Users/upforcetech/.pyenv/versions/3.11.8/lib/python3.11/inspect.py'>
      msg = 'mariadb-dump not found in PATH! This is required to take a backup.'
      out = {'message': 'mariadb-dump not found in PATH! This is required to take a backup.', 'title': 'Message', 'indicator': 'red', 'raise_exception': 1, '__frappe_exc_id': 'f8fc6c82b03e4f516cbedee4b90ef8188a7d95a8b3055d52b2a42b7c'}
      raise_exception = <class 'frappe.exceptions.ExecutableNotFound'>
frappe.exceptions.ExecutableNotFound: mariadb-dump not found in PATH! This is required to take a backup.
Backup failed for Site task.local. Database or site_config.json may be corrupted
Traceback with variables (most recent call last):
  File "apps/frappe/frappe/commands/site.py", line 865, in backup
    odb = scheduled_backup(
      context = CliCtxObj(sites=['task.local'], force=False, profile=False, verbose=True)
      with_files = False
      backup_path = None
      backup_path_db = None
      backup_path_files = None
      backup_path_private_files = None
      backup_path_conf = None
      ignore_backup_conf = False
      verbose = True
      compress = False
      include = ''
      exclude = ''
      old_backup_metadata = False
      scheduled_backup = <function scheduled_backup at 0x102f68c20>
      exit_code = 0
      rollback_callback = None
      site = 'task.local'
  File "apps/frappe/frappe/utils/backups.py", line 589, in scheduled_backup
    return new_backup(
      older_than = 6
      ignore_files = True
      backup_path = None
      backup_path_db = None
      backup_path_files = None
      backup_path_private_files = None
      backup_path_conf = None
      ignore_conf = False
      include_doctypes = ''
      exclude_doctypes = ''
      compress = False
      force = True
      verbose = True
      old_backup_metadata = False
      rollback_callback = <frappe.utils.CallbackManager object at 0x103147c10>
  File "apps/frappe/frappe/utils/backups.py", line 647, in new_backup
    odb.get_backup(older_than, ignore_files, force=force)
      older_than = 6
      ignore_files = True
      backup_path = None
      backup_path_db = None
      backup_path_files = None
      backup_path_private_files = None
      backup_path_conf = None
      ignore_conf = False
      include_doctypes = ''
      exclude_doctypes = ''
      compress = False
      force = True
      verbose = True
      old_backup_metadata = False
      rollback_callback = <frappe.utils.CallbackManager object at 0x103147c10>
      odb = <frappe.utils.backups.BackupGenerator object at 0x102ef9390>
  File "apps/frappe/frappe/utils/backups.py", line 191, in get_backup
    self.delete_if_step_fails(self.take_dump, self.backup_path_db)
      self = <frappe.utils.backups.BackupGenerator object at 0x102ef9390>
      older_than = 6
      ignore_files = True
      force = True
      last_db = False
      last_file = False
      last_private_file = False
      site_config_backup_path = False
  File "apps/frappe/frappe/utils/backups.py", line 528, in delete_if_step_fails
    raise e
      self = <frappe.utils.backups.BackupGenerator object at 0x102ef9390>
      step = <bound method BackupGenerator.take_dump of <frappe.utils.backups.BackupGenerator object at 0x102ef9390>>
      paths = ('./task.local/private/backups/20250512_000002-task_local-database.sql.gz',)
      path = './task.local/private/backups/20250512_000002-task_local-database.sql.gz'
  File "apps/frappe/frappe/utils/backups.py", line 523, in delete_if_step_fails
    step()
      self = <frappe.utils.backups.BackupGenerator object at 0x102ef9390>
      step = <bound method BackupGenerator.take_dump of <frappe.utils.backups.BackupGenerator object at 0x102ef9390>>
      paths = ('./task.local/private/backups/20250512_000002-task_local-database.sql.gz',)
      path = './task.local/private/backups/20250512_000002-task_local-database.sql.gz'
  File "apps/frappe/frappe/utils/backups.py", line 465, in take_dump
    frappe.throw(
      self = <frappe.utils.backups.BackupGenerator object at 0x102ef9390>
      frappe = <module 'frappe' from 'apps/frappe/frappe/__init__.py'>
      shlex = <module 'shlex' from '/Users/upforcetech/.pyenv/versions/3.11.8/lib/python3.11/shlex.py'>
      get_app_branch = <function get_app_branch at 0x103182d40>
      gzip_exc = '/usr/bin/gzip'
      database_header_content = ['begin frappe metadata', '[frappe]', 'version = 16.0.0-dev', 'branch = develop', 'end frappe metadata', '']
      generated_header = '-- begin frappe metadata\n-- [frappe]\n-- version = 16.0.0-dev\n-- branch = develop\n-- end frappe metadata\n-- \n'
      f = <_io.TextIOWrapper name='./task.local/private/backups/20250512_000002-task_local-database.sql.gz' encoding='UTF-8'>
      cmd = []
      extra = []
      get_command = <function get_command at 0x102f965c0>
      bin = None
      args = ['--user=_cce20c0570d41558', '--host=127.0.0.1', '--port=3306', '--password=SOrrCnf2nEiGJvko', '--single-transaction', '--quick', '--lock-tables=false', '_cce20c0570d41558']
      bin_name = 'mariadb-dump'
  File "apps/frappe/frappe/utils/messages.py", line 145, in throw
    msgprint(
      msg = 'mariadb-dump not found in PATH! This is required to take a backup.'
      exc = <class 'frappe.exceptions.ExecutableNotFound'>
      title = None
      is_minimizable = False
      wide = False
      as_list = False
      primary_action = None
  File "apps/frappe/frappe/utils/messages.py", line 106, in msgprint
    _raise_exception()
      msg = 'mariadb-dump not found in PATH! This is required to take a backup.'
      title = None
      raise_exception = <class 'frappe.exceptions.ExecutableNotFound'>
      as_table = False
      as_list = False
      indicator = 'red'
      alert = False
      primary_action = None
      is_minimizable = False
      wide = False
      realtime = False
      _raise_exception = <function msgprint.<locals>._raise_exception at 0x103181bc0>
      inspect = <module 'inspect' from '/Users/upforcetech/.pyenv/versions/3.11.8/lib/python3.11/inspect.py'>
      out = {'message': 'mariadb-dump not found in PATH! This is required to take a backup.', 'title': 'Message', 'indicator': 'red', 'raise_exception': 1, '__frappe_exc_id': 'bb47f49dde385d350ce013e92b58badd2fcad4bcdc982d165f2270e2'}
  File "apps/frappe/frappe/utils/messages.py", line 57, in _raise_exception
    raise exc
      exc = ExecutableNotFound('mariadb-dump not found in PATH! This is required to take a backup.')
      inspect = <module 'inspect' from '/Users/upforcetech/.pyenv/versions/3.11.8/lib/python3.11/inspect.py'>
      msg = 'mariadb-dump not found in PATH! This is required to take a backup.'
      out = {'message': 'mariadb-dump not found in PATH! This is required to take a backup.', 'title': 'Message', 'indicator': 'red', 'raise_exception': 1, '__frappe_exc_id': 'bb47f49dde385d350ce013e92b58badd2fcad4bcdc982d165f2270e2'}
      raise_exception = <class 'frappe.exceptions.ExecutableNotFound'>
frappe.exceptions.ExecutableNotFound: mariadb-dump not found in PATH! This is required to take a backup.
Backup failed for Site task.local. Database or site_config.json may be corrupted
Traceback with variables (most recent call last):
  File "apps/frappe/frappe/commands/site.py", line 865, in backup
    odb = scheduled_backup(
      context = CliCtxObj(sites=['task.local'], force=False, profile=False, verbose=True)
      with_files = False
      backup_path = None
      backup_path_db = None
      backup_path_files = None
      backup_path_private_files = None
      backup_path_conf = None
      ignore_backup_conf = False
      verbose = True
      compress = False
      include = ''
      exclude = ''
      old_backup_metadata = False
      scheduled_backup = <function scheduled_backup at 0x1050e0c20>
      exit_code = 0
      rollback_callback = None
      site = 'task.local'
  File "apps/frappe/frappe/utils/backups.py", line 589, in scheduled_backup
    return new_backup(
      older_than = 6
      ignore_files = True
      backup_path = None
      backup_path_db = None
      backup_path_files = None
      backup_path_private_files = None
      backup_path_conf = None
      ignore_conf = False
      include_doctypes = ''
      exclude_doctypes = ''
      compress = False
      force = True
      verbose = True
      old_backup_metadata = False
      rollback_callback = <frappe.utils.CallbackManager object at 0x1052bfc10>
  File "apps/frappe/frappe/utils/backups.py", line 647, in new_backup
    odb.get_backup(older_than, ignore_files, force=force)
      older_than = 6
      ignore_files = True
      backup_path = None
      backup_path_db = None
      backup_path_files = None
      backup_path_private_files = None
      backup_path_conf = None
      ignore_conf = False
      include_doctypes = ''
      exclude_doctypes = ''
      compress = False
      force = True
      verbose = True
      old_backup_metadata = False
      rollback_callback = <frappe.utils.CallbackManager object at 0x1052bfc10>
      odb = <frappe.utils.backups.BackupGenerator object at 0x1052da9d0>
  File "apps/frappe/frappe/utils/backups.py", line 191, in get_backup
    self.delete_if_step_fails(self.take_dump, self.backup_path_db)
      self = <frappe.utils.backups.BackupGenerator object at 0x1052da9d0>
      older_than = 6
      ignore_files = True
      force = True
      last_db = False
      last_file = False
      last_private_file = False
      site_config_backup_path = False
  File "apps/frappe/frappe/utils/backups.py", line 528, in delete_if_step_fails
    raise e
      self = <frappe.utils.backups.BackupGenerator object at 0x1052da9d0>
      step = <bound method BackupGenerator.take_dump of <frappe.utils.backups.BackupGenerator object at 0x1052da9d0>>
      paths = ('./task.local/private/backups/20250512_120001-task_local-database.sql.gz',)
      path = './task.local/private/backups/20250512_120001-task_local-database.sql.gz'
  File "apps/frappe/frappe/utils/backups.py", line 523, in delete_if_step_fails
    step()
      self = <frappe.utils.backups.BackupGenerator object at 0x1052da9d0>
      step = <bound method BackupGenerator.take_dump of <frappe.utils.backups.BackupGenerator object at 0x1052da9d0>>
      paths = ('./task.local/private/backups/20250512_120001-task_local-database.sql.gz',)
      path = './task.local/private/backups/20250512_120001-task_local-database.sql.gz'
  File "apps/frappe/frappe/utils/backups.py", line 465, in take_dump
    frappe.throw(
      self = <frappe.utils.backups.BackupGenerator object at 0x1052da9d0>
      frappe = <module 'frappe' from 'apps/frappe/frappe/__init__.py'>
      shlex = <module 'shlex' from '/Users/upforcetech/.pyenv/versions/3.11.8/lib/python3.11/shlex.py'>
      get_app_branch = <function get_app_branch at 0x1052fad40>
      gzip_exc = '/usr/bin/gzip'
      database_header_content = ['begin frappe metadata', '[frappe]', 'version = 16.0.0-dev', 'branch = develop', 'end frappe metadata', '']
      generated_header = '-- begin frappe metadata\n-- [frappe]\n-- version = 16.0.0-dev\n-- branch = develop\n-- end frappe metadata\n-- \n'
      f = <_io.TextIOWrapper name='./task.local/private/backups/20250512_120001-task_local-database.sql.gz' encoding='UTF-8'>
      cmd = []
      extra = []
      get_command = <function get_command at 0x10510e5c0>
      bin = None
      args = ['--user=_cce20c0570d41558', '--host=127.0.0.1', '--port=3306', '--password=SOrrCnf2nEiGJvko', '--single-transaction', '--quick', '--lock-tables=false', '_cce20c0570d41558']
      bin_name = 'mariadb-dump'
  File "apps/frappe/frappe/utils/messages.py", line 145, in throw
    msgprint(
      msg = 'mariadb-dump not found in PATH! This is required to take a backup.'
      exc = <class 'frappe.exceptions.ExecutableNotFound'>
      title = None
      is_minimizable = False
      wide = False
      as_list = False
      primary_action = None
  File "apps/frappe/frappe/utils/messages.py", line 106, in msgprint
    _raise_exception()
      msg = 'mariadb-dump not found in PATH! This is required to take a backup.'
      title = None
      raise_exception = <class 'frappe.exceptions.ExecutableNotFound'>
      as_table = False
      as_list = False
      indicator = 'red'
      alert = False
      primary_action = None
      is_minimizable = False
      wide = False
      realtime = False
      _raise_exception = <function msgprint.<locals>._raise_exception at 0x1052f9bc0>
      inspect = <module 'inspect' from '/Users/upforcetech/.pyenv/versions/3.11.8/lib/python3.11/inspect.py'>
      out = {'message': 'mariadb-dump not found in PATH! This is required to take a backup.', 'title': 'Message', 'indicator': 'red', 'raise_exception': 1, '__frappe_exc_id': 'c70d76e05199d08f13fe7735c80b23758b227915977e0ebb3631a49b'}
  File "apps/frappe/frappe/utils/messages.py", line 57, in _raise_exception
    raise exc
      exc = ExecutableNotFound('mariadb-dump not found in PATH! This is required to take a backup.')
      inspect = <module 'inspect' from '/Users/upforcetech/.pyenv/versions/3.11.8/lib/python3.11/inspect.py'>
      msg = 'mariadb-dump not found in PATH! This is required to take a backup.'
      out = {'message': 'mariadb-dump not found in PATH! This is required to take a backup.', 'title': 'Message', 'indicator': 'red', 'raise_exception': 1, '__frappe_exc_id': 'c70d76e05199d08f13fe7735c80b23758b227915977e0ebb3631a49b'}
      raise_exception = <class 'frappe.exceptions.ExecutableNotFound'>
frappe.exceptions.ExecutableNotFound: mariadb-dump not found in PATH! This is required to take a backup.
Backup failed for Site task.local. Database or site_config.json may be corrupted
Traceback with variables (most recent call last):
  File "apps/frappe/frappe/commands/site.py", line 865, in backup
    odb = scheduled_backup(
      context = CliCtxObj(sites=['task.local'], force=False, profile=False, verbose=True)
      with_files = False
      backup_path = None
      backup_path_db = None
      backup_path_files = None
      backup_path_private_files = None
      backup_path_conf = None
      ignore_backup_conf = False
      verbose = True
      compress = False
      include = ''
      exclude = ''
      old_backup_metadata = False
      scheduled_backup = <function scheduled_backup at 0x10557cc20>
      exit_code = 0
      rollback_callback = None
      site = 'task.local'
  File "apps/frappe/frappe/utils/backups.py", line 589, in scheduled_backup
    return new_backup(
      older_than = 6
      ignore_files = True
      backup_path = None
      backup_path_db = None
      backup_path_files = None
      backup_path_private_files = None
      backup_path_conf = None
      ignore_conf = False
      include_doctypes = ''
      exclude_doctypes = ''
      compress = False
      force = True
      verbose = True
      old_backup_metadata = False
      rollback_callback = <frappe.utils.CallbackManager object at 0x1056efdf0>
  File "apps/frappe/frappe/utils/backups.py", line 647, in new_backup
    odb.get_backup(older_than, ignore_files, force=force)
      older_than = 6
      ignore_files = True
      backup_path = None
      backup_path_db = None
      backup_path_files = None
      backup_path_private_files = None
      backup_path_conf = None
      ignore_conf = False
      include_doctypes = ''
      exclude_doctypes = ''
      compress = False
      force = True
      verbose = True
      old_backup_metadata = False
      rollback_callback = <frappe.utils.CallbackManager object at 0x1056efdf0>
      odb = <frappe.utils.backups.BackupGenerator object at 0x10546a010>
  File "apps/frappe/frappe/utils/backups.py", line 191, in get_backup
    self.delete_if_step_fails(self.take_dump, self.backup_path_db)
      self = <frappe.utils.backups.BackupGenerator object at 0x10546a010>
      older_than = 6
      ignore_files = True
      force = True
      last_db = False
      last_file = False
      last_private_file = False
      site_config_backup_path = False
  File "apps/frappe/frappe/utils/backups.py", line 528, in delete_if_step_fails
    raise e
      self = <frappe.utils.backups.BackupGenerator object at 0x10546a010>
      step = <bound method BackupGenerator.take_dump of <frappe.utils.backups.BackupGenerator object at 0x10546a010>>
      paths = ('./task.local/private/backups/20250512_180002-task_local-database.sql.gz',)
      path = './task.local/private/backups/20250512_180002-task_local-database.sql.gz'
  File "apps/frappe/frappe/utils/backups.py", line 523, in delete_if_step_fails
    step()
      self = <frappe.utils.backups.BackupGenerator object at 0x10546a010>
      step = <bound method BackupGenerator.take_dump of <frappe.utils.backups.BackupGenerator object at 0x10546a010>>
      paths = ('./task.local/private/backups/20250512_180002-task_local-database.sql.gz',)
      path = './task.local/private/backups/20250512_180002-task_local-database.sql.gz'
  File "apps/frappe/frappe/utils/backups.py", line 465, in take_dump
    frappe.throw(
      self = <frappe.utils.backups.BackupGenerator object at 0x10546a010>
      frappe = <module 'frappe' from 'apps/frappe/frappe/__init__.py'>
      shlex = <module 'shlex' from '/Users/upforcetech/.pyenv/versions/3.11.8/lib/python3.11/shlex.py'>
      get_app_branch = <function get_app_branch at 0x1066e09a0>
      gzip_exc = '/usr/bin/gzip'
      database_header_content = ['begin frappe metadata', '[frappe]', 'version = 16.0.0-dev', 'branch = develop', 'end frappe metadata', '']
      generated_header = '-- begin frappe metadata\n-- [frappe]\n-- version = 16.0.0-dev\n-- branch = develop\n-- end frappe metadata\n-- \n'
      f = <_io.TextIOWrapper name='./task.local/private/backups/20250512_180002-task_local-database.sql.gz' encoding='UTF-8'>
      cmd = []
      extra = []
      get_command = <function get_command at 0x1055aa5c0>
      bin = None
      args = ['--user=_cce20c0570d41558', '--host=127.0.0.1', '--port=3306', '--password=SOrrCnf2nEiGJvko', '--single-transaction', '--quick', '--lock-tables=false', '_cce20c0570d41558']
      bin_name = 'mariadb-dump'
  File "apps/frappe/frappe/utils/messages.py", line 145, in throw
    msgprint(
      msg = 'mariadb-dump not found in PATH! This is required to take a backup.'
      exc = <class 'frappe.exceptions.ExecutableNotFound'>
      title = None
      is_minimizable = False
      wide = False
      as_list = False
      primary_action = None
  File "apps/frappe/frappe/utils/messages.py", line 106, in msgprint
    _raise_exception()
      msg = 'mariadb-dump not found in PATH! This is required to take a backup.'
      title = None
      raise_exception = <class 'frappe.exceptions.ExecutableNotFound'>
      as_table = False
      as_list = False
      indicator = 'red'
      alert = False
      primary_action = None
      is_minimizable = False
      wide = False
      realtime = False
      _raise_exception = <function msgprint.<locals>._raise_exception at 0x10682a020>
      inspect = <module 'inspect' from '/Users/upforcetech/.pyenv/versions/3.11.8/lib/python3.11/inspect.py'>
      out = {'message': 'mariadb-dump not found in PATH! This is required to take a backup.', 'title': 'Message', 'indicator': 'red', 'raise_exception': 1, '__frappe_exc_id': '13c9adbd0fc29921f9de7685ad0b95dfc0fdbac3456e1a86ba01c715'}
  File "apps/frappe/frappe/utils/messages.py", line 57, in _raise_exception
    raise exc
      exc = ExecutableNotFound('mariadb-dump not found in PATH! This is required to take a backup.')
      inspect = <module 'inspect' from '/Users/upforcetech/.pyenv/versions/3.11.8/lib/python3.11/inspect.py'>
      msg = 'mariadb-dump not found in PATH! This is required to take a backup.'
      out = {'message': 'mariadb-dump not found in PATH! This is required to take a backup.', 'title': 'Message', 'indicator': 'red', 'raise_exception': 1, '__frappe_exc_id': '13c9adbd0fc29921f9de7685ad0b95dfc0fdbac3456e1a86ba01c715'}
      raise_exception = <class 'frappe.exceptions.ExecutableNotFound'>
frappe.exceptions.ExecutableNotFound: mariadb-dump not found in PATH! This is required to take a backup.
Backup failed for Site task.local. Database or site_config.json may be corrupted
Traceback with variables (most recent call last):
  File "apps/frappe/frappe/commands/site.py", line 865, in backup
    odb = scheduled_backup(
      context = CliCtxObj(sites=['task.local'], force=False, profile=False, verbose=True)
      with_files = False
      backup_path = None
      backup_path_db = None
      backup_path_files = None
      backup_path_private_files = None
      backup_path_conf = None
      ignore_backup_conf = False
      verbose = True
      compress = False
      include = ''
      exclude = ''
      old_backup_metadata = False
      scheduled_backup = <function scheduled_backup at 0x103944c20>
      exit_code = 0
      rollback_callback = None
      site = 'task.local'
  File "apps/frappe/frappe/utils/backups.py", line 589, in scheduled_backup
    return new_backup(
      older_than = 6
      ignore_files = True
      backup_path = None
      backup_path_db = None
      backup_path_files = None
      backup_path_private_files = None
      backup_path_conf = None
      ignore_conf = False
      include_doctypes = ''
      exclude_doctypes = ''
      compress = False
      force = True
      verbose = True
      old_backup_metadata = False
      rollback_callback = <frappe.utils.CallbackManager object at 0x10443fdf0>
  File "apps/frappe/frappe/utils/backups.py", line 647, in new_backup
    odb.get_backup(older_than, ignore_files, force=force)
      older_than = 6
      ignore_files = True
      backup_path = None
      backup_path_db = None
      backup_path_files = None
      backup_path_private_files = None
      backup_path_conf = None
      ignore_conf = False
      include_doctypes = ''
      exclude_doctypes = ''
      compress = False
      force = True
      verbose = True
      old_backup_metadata = False
      rollback_callback = <frappe.utils.CallbackManager object at 0x10443fdf0>
      odb = <frappe.utils.backups.BackupGenerator object at 0x104458ed0>
  File "apps/frappe/frappe/utils/backups.py", line 191, in get_backup
    self.delete_if_step_fails(self.take_dump, self.backup_path_db)
      self = <frappe.utils.backups.BackupGenerator object at 0x104458ed0>
      older_than = 6
      ignore_files = True
      force = True
      last_db = False
      last_file = False
      last_private_file = False
      site_config_backup_path = False
  File "apps/frappe/frappe/utils/backups.py", line 528, in delete_if_step_fails
    raise e
      self = <frappe.utils.backups.BackupGenerator object at 0x104458ed0>
      step = <bound method BackupGenerator.take_dump of <frappe.utils.backups.BackupGenerator object at 0x104458ed0>>
      paths = ('./task.local/private/backups/20250513_120002-task_local-database.sql.gz',)
      path = './task.local/private/backups/20250513_120002-task_local-database.sql.gz'
  File "apps/frappe/frappe/utils/backups.py", line 523, in delete_if_step_fails
    step()
      self = <frappe.utils.backups.BackupGenerator object at 0x104458ed0>
      step = <bound method BackupGenerator.take_dump of <frappe.utils.backups.BackupGenerator object at 0x104458ed0>>
      paths = ('./task.local/private/backups/20250513_120002-task_local-database.sql.gz',)
      path = './task.local/private/backups/20250513_120002-task_local-database.sql.gz'
  File "apps/frappe/frappe/utils/backups.py", line 465, in take_dump
    frappe.throw(
      self = <frappe.utils.backups.BackupGenerator object at 0x104458ed0>
      frappe = <module 'frappe' from 'apps/frappe/frappe/__init__.py'>
      shlex = <module 'shlex' from '/Users/upforcetech/.pyenv/versions/3.11.8/lib/python3.11/shlex.py'>
      get_app_branch = <function get_app_branch at 0x10548c9a0>
      gzip_exc = '/usr/bin/gzip'
      database_header_content = ['begin frappe metadata', '[frappe]', 'version = 16.0.0-dev', 'branch = develop', 'end frappe metadata', '']
      generated_header = '-- begin frappe metadata\n-- [frappe]\n-- version = 16.0.0-dev\n-- branch = develop\n-- end frappe metadata\n-- \n'
      f = <_io.TextIOWrapper name='./task.local/private/backups/20250513_120002-task_local-database.sql.gz' encoding='UTF-8'>
      cmd = []
      extra = []
      get_command = <function get_command at 0x1039725c0>
      bin = None
      args = ['--user=_cce20c0570d41558', '--host=127.0.0.1', '--port=3306', '--password=SOrrCnf2nEiGJvko', '--single-transaction', '--quick', '--lock-tables=false', '_cce20c0570d41558']
      bin_name = 'mariadb-dump'
  File "apps/frappe/frappe/utils/messages.py", line 145, in throw
    msgprint(
      msg = 'mariadb-dump not found in PATH! This is required to take a backup.'
      exc = <class 'frappe.exceptions.ExecutableNotFound'>
      title = None
      is_minimizable = False
      wide = False
      as_list = False
      primary_action = None
  File "apps/frappe/frappe/utils/messages.py", line 106, in msgprint
    _raise_exception()
      msg = 'mariadb-dump not found in PATH! This is required to take a backup.'
      title = None
      raise_exception = <class 'frappe.exceptions.ExecutableNotFound'>
      as_table = False
      as_list = False
      indicator = 'red'
      alert = False
      primary_action = None
      is_minimizable = False
      wide = False
      realtime = False
      _raise_exception = <function msgprint.<locals>._raise_exception at 0x1055d2020>
      inspect = <module 'inspect' from '/Users/upforcetech/.pyenv/versions/3.11.8/lib/python3.11/inspect.py'>
      out = {'message': 'mariadb-dump not found in PATH! This is required to take a backup.', 'title': 'Message', 'indicator': 'red', 'raise_exception': 1, '__frappe_exc_id': 'fab2dce91dcdbe64c0e32a48db0ec5978193a247df347859d819be4b'}
  File "apps/frappe/frappe/utils/messages.py", line 57, in _raise_exception
    raise exc
      exc = ExecutableNotFound('mariadb-dump not found in PATH! This is required to take a backup.')
      inspect = <module 'inspect' from '/Users/upforcetech/.pyenv/versions/3.11.8/lib/python3.11/inspect.py'>
      msg = 'mariadb-dump not found in PATH! This is required to take a backup.'
      out = {'message': 'mariadb-dump not found in PATH! This is required to take a backup.', 'title': 'Message', 'indicator': 'red', 'raise_exception': 1, '__frappe_exc_id': 'fab2dce91dcdbe64c0e32a48db0ec5978193a247df347859d819be4b'}
      raise_exception = <class 'frappe.exceptions.ExecutableNotFound'>
frappe.exceptions.ExecutableNotFound: mariadb-dump not found in PATH! This is required to take a backup.
Backup failed for Site task.local. Database or site_config.json may be corrupted
Traceback with variables (most recent call last):
  File "apps/frappe/frappe/commands/site.py", line 865, in backup
    odb = scheduled_backup(
      context = CliCtxObj(sites=['task.local'], force=False, profile=False, verbose=True)
      with_files = False
      backup_path = None
      backup_path_db = None
      backup_path_files = None
      backup_path_private_files = None
      backup_path_conf = None
      ignore_backup_conf = False
      verbose = True
      compress = False
      include = ''
      exclude = ''
      old_backup_metadata = False
      scheduled_backup = <function scheduled_backup at 0x106e90c20>
      exit_code = 0
      rollback_callback = None
      site = 'task.local'
  File "apps/frappe/frappe/utils/backups.py", line 589, in scheduled_backup
    return new_backup(
      older_than = 6
      ignore_files = True
      backup_path = None
      backup_path_db = None
      backup_path_files = None
      backup_path_private_files = None
      backup_path_conf = None
      ignore_conf = False
      include_doctypes = ''
      exclude_doctypes = ''
      compress = False
      force = True
      verbose = True
      old_backup_metadata = False
      rollback_callback = <frappe.utils.CallbackManager object at 0x10706fc10>
  File "apps/frappe/frappe/utils/backups.py", line 647, in new_backup
    odb.get_backup(older_than, ignore_files, force=force)
      older_than = 6
      ignore_files = True
      backup_path = None
      backup_path_db = None
      backup_path_files = None
      backup_path_private_files = None
      backup_path_conf = None
      ignore_conf = False
      include_doctypes = ''
      exclude_doctypes = ''
      compress = False
      force = True
      verbose = True
      old_backup_metadata = False
      rollback_callback = <frappe.utils.CallbackManager object at 0x10706fc10>
      odb = <frappe.utils.backups.BackupGenerator object at 0x10708aa90>
  File "apps/frappe/frappe/utils/backups.py", line 191, in get_backup
    self.delete_if_step_fails(self.take_dump, self.backup_path_db)
      self = <frappe.utils.backups.BackupGenerator object at 0x10708aa90>
      older_than = 6
      ignore_files = True
      force = True
      last_db = False
      last_file = False
      last_private_file = False
      site_config_backup_path = False
  File "apps/frappe/frappe/utils/backups.py", line 528, in delete_if_step_fails
    raise e
      self = <frappe.utils.backups.BackupGenerator object at 0x10708aa90>
      step = <bound method BackupGenerator.take_dump of <frappe.utils.backups.BackupGenerator object at 0x10708aa90>>
      paths = ('./task.local/private/backups/20250513_180002-task_local-database.sql.gz',)
      path = './task.local/private/backups/20250513_180002-task_local-database.sql.gz'
  File "apps/frappe/frappe/utils/backups.py", line 523, in delete_if_step_fails
    step()
      self = <frappe.utils.backups.BackupGenerator object at 0x10708aa90>
      step = <bound method BackupGenerator.take_dump of <frappe.utils.backups.BackupGenerator object at 0x10708aa90>>
      paths = ('./task.local/private/backups/20250513_180002-task_local-database.sql.gz',)
      path = './task.local/private/backups/20250513_180002-task_local-database.sql.gz'
  File "apps/frappe/frappe/utils/backups.py", line 465, in take_dump
    frappe.throw(
      self = <frappe.utils.backups.BackupGenerator object at 0x10708aa90>
      frappe = <module 'frappe' from 'apps/frappe/frappe/__init__.py'>
      shlex = <module 'shlex' from '/Users/upforcetech/.pyenv/versions/3.11.8/lib/python3.11/shlex.py'>
      get_app_branch = <function get_app_branch at 0x107a30e00>
      gzip_exc = '/usr/bin/gzip'
      database_header_content = ['begin frappe metadata', '[frappe]', 'version = 16.0.0-dev', 'branch = develop', 'end frappe metadata', '']
      generated_header = '-- begin frappe metadata\n-- [frappe]\n-- version = 16.0.0-dev\n-- branch = develop\n-- end frappe metadata\n-- \n'
      f = <_io.TextIOWrapper name='./task.local/private/backups/20250513_180002-task_local-database.sql.gz' encoding='UTF-8'>
      cmd = []
      extra = []
      get_command = <function get_command at 0x106ebe5c0>
      bin = None
      args = ['--user=_cce20c0570d41558', '--host=127.0.0.1', '--port=3306', '--password=SOrrCnf2nEiGJvko', '--single-transaction', '--quick', '--lock-tables=false', '_cce20c0570d41558']
      bin_name = 'mariadb-dump'
  File "apps/frappe/frappe/utils/messages.py", line 145, in throw
    msgprint(
      msg = 'mariadb-dump not found in PATH! This is required to take a backup.'
      exc = <class 'frappe.exceptions.ExecutableNotFound'>
      title = None
      is_minimizable = False
      wide = False
      as_list = False
      primary_action = None
  File "apps/frappe/frappe/utils/messages.py", line 106, in msgprint
    _raise_exception()
      msg = 'mariadb-dump not found in PATH! This is required to take a backup.'
      title = None
      raise_exception = <class 'frappe.exceptions.ExecutableNotFound'>
      as_table = False
      as_list = False
      indicator = 'red'
      alert = False
      primary_action = None
      is_minimizable = False
      wide = False
      realtime = False
      _raise_exception = <function msgprint.<locals>._raise_exception at 0x1070ab380>
      inspect = <module 'inspect' from '/Users/upforcetech/.pyenv/versions/3.11.8/lib/python3.11/inspect.py'>
      out = {'message': 'mariadb-dump not found in PATH! This is required to take a backup.', 'title': 'Message', 'indicator': 'red', 'raise_exception': 1, '__frappe_exc_id': '951f917e5593820c86a4940ef653e4f2a97685448298ef86cd6aad29'}
  File "apps/frappe/frappe/utils/messages.py", line 57, in _raise_exception
    raise exc
      exc = ExecutableNotFound('mariadb-dump not found in PATH! This is required to take a backup.')
      inspect = <module 'inspect' from '/Users/upforcetech/.pyenv/versions/3.11.8/lib/python3.11/inspect.py'>
      msg = 'mariadb-dump not found in PATH! This is required to take a backup.'
      out = {'message': 'mariadb-dump not found in PATH! This is required to take a backup.', 'title': 'Message', 'indicator': 'red', 'raise_exception': 1, '__frappe_exc_id': '951f917e5593820c86a4940ef653e4f2a97685448298ef86cd6aad29'}
      raise_exception = <class 'frappe.exceptions.ExecutableNotFound'>
frappe.exceptions.ExecutableNotFound: mariadb-dump not found in PATH! This is required to take a backup.
Backup failed for Site task.local. Database or site_config.json may be corrupted
Traceback with variables (most recent call last):
  File "apps/frappe/frappe/commands/site.py", line 865, in backup
    odb = scheduled_backup(
      context = CliCtxObj(sites=['task.local'], force=False, profile=False, verbose=True)
      with_files = False
      backup_path = None
      backup_path_db = None
      backup_path_files = None
      backup_path_private_files = None
      backup_path_conf = None
      ignore_backup_conf = False
      verbose = True
      compress = False
      include = ''
      exclude = ''
      old_backup_metadata = False
      scheduled_backup = <function scheduled_backup at 0x106b40c20>
      exit_code = 0
      rollback_callback = None
      site = 'task.local'
  File "apps/frappe/frappe/utils/backups.py", line 589, in scheduled_backup
    return new_backup(
      older_than = 6
      ignore_files = True
      backup_path = None
      backup_path_db = None
      backup_path_files = None
      backup_path_private_files = None
      backup_path_conf = None
      ignore_conf = False
      include_doctypes = ''
      exclude_doctypes = ''
      compress = False
      force = True
      verbose = True
      old_backup_metadata = False
      rollback_callback = <frappe.utils.CallbackManager object at 0x106d1fc10>
  File "apps/frappe/frappe/utils/backups.py", line 647, in new_backup
    odb.get_backup(older_than, ignore_files, force=force)
      older_than = 6
      ignore_files = True
      backup_path = None
      backup_path_db = None
      backup_path_files = None
      backup_path_private_files = None
      backup_path_conf = None
      ignore_conf = False
      include_doctypes = ''
      exclude_doctypes = ''
      compress = False
      force = True
      verbose = True
      old_backup_metadata = False
      rollback_callback = <frappe.utils.CallbackManager object at 0x106d1fc10>
      odb = <frappe.utils.backups.BackupGenerator object at 0x106d3a9d0>
  File "apps/frappe/frappe/utils/backups.py", line 191, in get_backup
    self.delete_if_step_fails(self.take_dump, self.backup_path_db)
      self = <frappe.utils.backups.BackupGenerator object at 0x106d3a9d0>
      older_than = 6
      ignore_files = True
      force = True
      last_db = False
      last_file = False
      last_private_file = False
      site_config_backup_path = False
  File "apps/frappe/frappe/utils/backups.py", line 528, in delete_if_step_fails
    raise e
      self = <frappe.utils.backups.BackupGenerator object at 0x106d3a9d0>
      step = <bound method BackupGenerator.take_dump of <frappe.utils.backups.BackupGenerator object at 0x106d3a9d0>>
      paths = ('./task.local/private/backups/20250514_000003-task_local-database.sql.gz',)
      path = './task.local/private/backups/20250514_000003-task_local-database.sql.gz'
  File "apps/frappe/frappe/utils/backups.py", line 523, in delete_if_step_fails
    step()
      self = <frappe.utils.backups.BackupGenerator object at 0x106d3a9d0>
      step = <bound method BackupGenerator.take_dump of <frappe.utils.backups.BackupGenerator object at 0x106d3a9d0>>
      paths = ('./task.local/private/backups/20250514_000003-task_local-database.sql.gz',)
      path = './task.local/private/backups/20250514_000003-task_local-database.sql.gz'
  File "apps/frappe/frappe/utils/backups.py", line 465, in take_dump
    frappe.throw(
      self = <frappe.utils.backups.BackupGenerator object at 0x106d3a9d0>
      frappe = <module 'frappe' from 'apps/frappe/frappe/__init__.py'>
      shlex = <module 'shlex' from '/Users/upforcetech/.pyenv/versions/3.11.8/lib/python3.11/shlex.py'>
      get_app_branch = <function get_app_branch at 0x106d5ad40>
      gzip_exc = '/usr/bin/gzip'
      database_header_content = ['begin frappe metadata', '[frappe]', 'version = 16.0.0-dev', 'branch = develop', 'end frappe metadata', '']
      generated_header = '-- begin frappe metadata\n-- [frappe]\n-- version = 16.0.0-dev\n-- branch = develop\n-- end frappe metadata\n-- \n'
      f = <_io.TextIOWrapper name='./task.local/private/backups/20250514_000003-task_local-database.sql.gz' encoding='UTF-8'>
      cmd = []
      extra = []
      get_command = <function get_command at 0x106b6e5c0>
      bin = None
      args = ['--user=_cce20c0570d41558', '--host=127.0.0.1', '--port=3306', '--password=SOrrCnf2nEiGJvko', '--single-transaction', '--quick', '--lock-tables=false', '_cce20c0570d41558']
      bin_name = 'mariadb-dump'
  File "apps/frappe/frappe/utils/messages.py", line 145, in throw
    msgprint(
      msg = 'mariadb-dump not found in PATH! This is required to take a backup.'
      exc = <class 'frappe.exceptions.ExecutableNotFound'>
      title = None
      is_minimizable = False
      wide = False
      as_list = False
      primary_action = None
  File "apps/frappe/frappe/utils/messages.py", line 106, in msgprint
    _raise_exception()
      msg = 'mariadb-dump not found in PATH! This is required to take a backup.'
      title = None
      raise_exception = <class 'frappe.exceptions.ExecutableNotFound'>
      as_table = False
      as_list = False
      indicator = 'red'
      alert = False
      primary_action = None
      is_minimizable = False
      wide = False
      realtime = False
      _raise_exception = <function msgprint.<locals>._raise_exception at 0x106d59bc0>
      inspect = <module 'inspect' from '/Users/upforcetech/.pyenv/versions/3.11.8/lib/python3.11/inspect.py'>
      out = {'message': 'mariadb-dump not found in PATH! This is required to take a backup.', 'title': 'Message', 'indicator': 'red', 'raise_exception': 1, '__frappe_exc_id': '629d10c61cfea1b1cd214a1f6695fdbbe3dcfc8e4f4d015076d246f4'}
  File "apps/frappe/frappe/utils/messages.py", line 57, in _raise_exception
    raise exc
      exc = ExecutableNotFound('mariadb-dump not found in PATH! This is required to take a backup.')
      inspect = <module 'inspect' from '/Users/upforcetech/.pyenv/versions/3.11.8/lib/python3.11/inspect.py'>
      msg = 'mariadb-dump not found in PATH! This is required to take a backup.'
      out = {'message': 'mariadb-dump not found in PATH! This is required to take a backup.', 'title': 'Message', 'indicator': 'red', 'raise_exception': 1, '__frappe_exc_id': '629d10c61cfea1b1cd214a1f6695fdbbe3dcfc8e4f4d015076d246f4'}
      raise_exception = <class 'frappe.exceptions.ExecutableNotFound'>
frappe.exceptions.ExecutableNotFound: mariadb-dump not found in PATH! This is required to take a backup.
Backup failed for Site task.local. Database or site_config.json may be corrupted
Traceback with variables (most recent call last):
  File "apps/frappe/frappe/commands/site.py", line 865, in backup
    odb = scheduled_backup(
      context = CliCtxObj(sites=['task.local'], force=False, profile=False, verbose=True)
      with_files = False
      backup_path = None
      backup_path_db = None
      backup_path_files = None
      backup_path_private_files = None
      backup_path_conf = None
      ignore_backup_conf = False
      verbose = True
      compress = False
      include = ''
      exclude = ''
      old_backup_metadata = False
      scheduled_backup = <function scheduled_backup at 0x10527cc20>
      exit_code = 0
      rollback_callback = None
      site = 'task.local'
  File "apps/frappe/frappe/utils/backups.py", line 589, in scheduled_backup
    return new_backup(
      older_than = 6
      ignore_files = True
      backup_path = None
      backup_path_db = None
      backup_path_files = None
      backup_path_private_files = None
      backup_path_conf = None
      ignore_conf = False
      include_doctypes = ''
      exclude_doctypes = ''
      compress = False
      force = True
      verbose = True
      old_backup_metadata = False
      rollback_callback = <frappe.utils.CallbackManager object at 0x1053ebc10>
  File "apps/frappe/frappe/utils/backups.py", line 647, in new_backup
    odb.get_backup(older_than, ignore_files, force=force)
      older_than = 6
      ignore_files = True
      backup_path = None
      backup_path_db = None
      backup_path_files = None
      backup_path_private_files = None
      backup_path_conf = None
      ignore_conf = False
      include_doctypes = ''
      exclude_doctypes = ''
      compress = False
      force = True
      verbose = True
      old_backup_metadata = False
      rollback_callback = <frappe.utils.CallbackManager object at 0x1053ebc10>
      odb = <frappe.utils.backups.BackupGenerator object at 0x10550a790>
  File "apps/frappe/frappe/utils/backups.py", line 191, in get_backup
    self.delete_if_step_fails(self.take_dump, self.backup_path_db)
      self = <frappe.utils.backups.BackupGenerator object at 0x10550a790>
      older_than = 6
      ignore_files = True
      force = True
      last_db = False
      last_file = False
      last_private_file = False
      site_config_backup_path = False
  File "apps/frappe/frappe/utils/backups.py", line 528, in delete_if_step_fails
    raise e
      self = <frappe.utils.backups.BackupGenerator object at 0x10550a790>
      step = <bound method BackupGenerator.take_dump of <frappe.utils.backups.BackupGenerator object at 0x10550a790>>
      paths = ('./task.local/private/backups/20250514_120001-task_local-database.sql.gz',)
      path = './task.local/private/backups/20250514_120001-task_local-database.sql.gz'
  File "apps/frappe/frappe/utils/backups.py", line 523, in delete_if_step_fails
    step()
      self = <frappe.utils.backups.BackupGenerator object at 0x10550a790>
      step = <bound method BackupGenerator.take_dump of <frappe.utils.backups.BackupGenerator object at 0x10550a790>>
      paths = ('./task.local/private/backups/20250514_120001-task_local-database.sql.gz',)
      path = './task.local/private/backups/20250514_120001-task_local-database.sql.gz'
  File "apps/frappe/frappe/utils/backups.py", line 465, in take_dump
    frappe.throw(
      self = <frappe.utils.backups.BackupGenerator object at 0x10550a790>
      frappe = <module 'frappe' from 'apps/frappe/frappe/__init__.py'>
      shlex = <module 'shlex' from '/Users/upforcetech/.pyenv/versions/3.11.8/lib/python3.11/shlex.py'>
      get_app_branch = <function get_app_branch at 0x10552ad40>
      gzip_exc = '/usr/bin/gzip'
      database_header_content = ['begin frappe metadata', '[frappe]', 'version = 16.0.0-dev', 'branch = develop', 'end frappe metadata', '']
      generated_header = '-- begin frappe metadata\n-- [frappe]\n-- version = 16.0.0-dev\n-- branch = develop\n-- end frappe metadata\n-- \n'
      f = <_io.TextIOWrapper name='./task.local/private/backups/20250514_120001-task_local-database.sql.gz' encoding='UTF-8'>
      cmd = []
      extra = []
      get_command = <function get_command at 0x1052aa5c0>
      bin = None
      args = ['--user=_cce20c0570d41558', '--host=127.0.0.1', '--port=3306', '--password=SOrrCnf2nEiGJvko', '--single-transaction', '--quick', '--lock-tables=false', '_cce20c0570d41558']
      bin_name = 'mariadb-dump'
  File "apps/frappe/frappe/utils/messages.py", line 145, in throw
    msgprint(
      msg = 'mariadb-dump not found in PATH! This is required to take a backup.'
      exc = <class 'frappe.exceptions.ExecutableNotFound'>
      title = None
      is_minimizable = False
      wide = False
      as_list = False
      primary_action = None
  File "apps/frappe/frappe/utils/messages.py", line 106, in msgprint
    _raise_exception()
      msg = 'mariadb-dump not found in PATH! This is required to take a backup.'
      title = None
      raise_exception = <class 'frappe.exceptions.ExecutableNotFound'>
      as_table = False
      as_list = False
      indicator = 'red'
      alert = False
      primary_action = None
      is_minimizable = False
      wide = False
      realtime = False
      _raise_exception = <function msgprint.<locals>._raise_exception at 0x105529bc0>
      inspect = <module 'inspect' from '/Users/upforcetech/.pyenv/versions/3.11.8/lib/python3.11/inspect.py'>
      out = {'message': 'mariadb-dump not found in PATH! This is required to take a backup.', 'title': 'Message', 'indicator': 'red', 'raise_exception': 1, '__frappe_exc_id': '81ea615b34682ab0643f270d934c0c006fa3dc7c5a656618300bd722'}
  File "apps/frappe/frappe/utils/messages.py", line 57, in _raise_exception
    raise exc
      exc = ExecutableNotFound('mariadb-dump not found in PATH! This is required to take a backup.')
      inspect = <module 'inspect' from '/Users/upforcetech/.pyenv/versions/3.11.8/lib/python3.11/inspect.py'>
      msg = 'mariadb-dump not found in PATH! This is required to take a backup.'
      out = {'message': 'mariadb-dump not found in PATH! This is required to take a backup.', 'title': 'Message', 'indicator': 'red', 'raise_exception': 1, '__frappe_exc_id': '81ea615b34682ab0643f270d934c0c006fa3dc7c5a656618300bd722'}
      raise_exception = <class 'frappe.exceptions.ExecutableNotFound'>
frappe.exceptions.ExecutableNotFound: mariadb-dump not found in PATH! This is required to take a backup.
Backup failed for Site task.local. Database or site_config.json may be corrupted
Traceback with variables (most recent call last):
  File "apps/frappe/frappe/commands/site.py", line 865, in backup
    odb = scheduled_backup(
      context = CliCtxObj(sites=['task.local'], force=False, profile=False, verbose=True)
      with_files = False
      backup_path = None
      backup_path_db = None
      backup_path_files = None
      backup_path_private_files = None
      backup_path_conf = None
      ignore_backup_conf = False
      verbose = True
      compress = False
      include = ''
      exclude = ''
      old_backup_metadata = False
      scheduled_backup = <function scheduled_backup at 0x106ae4c20>
      exit_code = 0
      rollback_callback = None
      site = 'task.local'
  File "apps/frappe/frappe/utils/backups.py", line 589, in scheduled_backup
    return new_backup(
      older_than = 6
      ignore_files = True
      backup_path = None
      backup_path_db = None
      backup_path_files = None
      backup_path_private_files = None
      backup_path_conf = None
      ignore_conf = False
      include_doctypes = ''
      exclude_doctypes = ''
      compress = False
      force = True
      verbose = True
      old_backup_metadata = False
      rollback_callback = <frappe.utils.CallbackManager object at 0x106cbfdf0>
  File "apps/frappe/frappe/utils/backups.py", line 647, in new_backup
    odb.get_backup(older_than, ignore_files, force=force)
      older_than = 6
      ignore_files = True
      backup_path = None
      backup_path_db = None
      backup_path_files = None
      backup_path_private_files = None
      backup_path_conf = None
      ignore_conf = False
      include_doctypes = ''
      exclude_doctypes = ''
      compress = False
      force = True
      verbose = True
      old_backup_metadata = False
      rollback_callback = <frappe.utils.CallbackManager object at 0x106cbfdf0>
      odb = <frappe.utils.backups.BackupGenerator object at 0x106ce0790>
  File "apps/frappe/frappe/utils/backups.py", line 191, in get_backup
    self.delete_if_step_fails(self.take_dump, self.backup_path_db)
      self = <frappe.utils.backups.BackupGenerator object at 0x106ce0790>
      older_than = 6
      ignore_files = True
      force = True
      last_db = False
      last_file = False
      last_private_file = False
      site_config_backup_path = False
  File "apps/frappe/frappe/utils/backups.py", line 528, in delete_if_step_fails
    raise e
      self = <frappe.utils.backups.BackupGenerator object at 0x106ce0790>
      step = <bound method BackupGenerator.take_dump of <frappe.utils.backups.BackupGenerator object at 0x106ce0790>>
      paths = ('./task.local/private/backups/20250514_180003-task_local-database.sql.gz',)
      path = './task.local/private/backups/20250514_180003-task_local-database.sql.gz'
  File "apps/frappe/frappe/utils/backups.py", line 523, in delete_if_step_fails
    step()
      self = <frappe.utils.backups.BackupGenerator object at 0x106ce0790>
      step = <bound method BackupGenerator.take_dump of <frappe.utils.backups.BackupGenerator object at 0x106ce0790>>
      paths = ('./task.local/private/backups/20250514_180003-task_local-database.sql.gz',)
      path = './task.local/private/backups/20250514_180003-task_local-database.sql.gz'
  File "apps/frappe/frappe/utils/backups.py", line 465, in take_dump
    frappe.throw(
      self = <frappe.utils.backups.BackupGenerator object at 0x106ce0790>
      frappe = <module 'frappe' from 'apps/frappe/frappe/__init__.py'>
      shlex = <module 'shlex' from '/Users/upforcetech/.pyenv/versions/3.11.8/lib/python3.11/shlex.py'>
      get_app_branch = <function get_app_branch at 0x107ad09a0>
      gzip_exc = '/usr/bin/gzip'
      database_header_content = ['begin frappe metadata', '[frappe]', 'version = 16.0.0-dev', 'branch = develop', 'end frappe metadata', '']
      generated_header = '-- begin frappe metadata\n-- [frappe]\n-- version = 16.0.0-dev\n-- branch = develop\n-- end frappe metadata\n-- \n'
      f = <_io.TextIOWrapper name='./task.local/private/backups/20250514_180003-task_local-database.sql.gz' encoding='UTF-8'>
      cmd = []
      extra = []
      get_command = <function get_command at 0x106b125c0>
      bin = None
      args = ['--user=_cce20c0570d41558', '--host=127.0.0.1', '--port=3306', '--password=SOrrCnf2nEiGJvko', '--single-transaction', '--quick', '--lock-tables=false', '_cce20c0570d41558']
      bin_name = 'mariadb-dump'
  File "apps/frappe/frappe/utils/messages.py", line 145, in throw
    msgprint(
      msg = 'mariadb-dump not found in PATH! This is required to take a backup.'
      exc = <class 'frappe.exceptions.ExecutableNotFound'>
      title = None
      is_minimizable = False
      wide = False
      as_list = False
      primary_action = None
  File "apps/frappe/frappe/utils/messages.py", line 106, in msgprint
    _raise_exception()
      msg = 'mariadb-dump not found in PATH! This is required to take a backup.'
      title = None
      raise_exception = <class 'frappe.exceptions.ExecutableNotFound'>
      as_table = False
      as_list = False
      indicator = 'red'
      alert = False
      primary_action = None
      is_minimizable = False
      wide = False
      realtime = False
      _raise_exception = <function msgprint.<locals>._raise_exception at 0x107c1a020>
      inspect = <module 'inspect' from '/Users/upforcetech/.pyenv/versions/3.11.8/lib/python3.11/inspect.py'>
      out = {'message': 'mariadb-dump not found in PATH! This is required to take a backup.', 'title': 'Message', 'indicator': 'red', 'raise_exception': 1, '__frappe_exc_id': 'd9aa1a1dfa236f3fb2b022736133d3f953edad499a4a784c853b3be9'}
  File "apps/frappe/frappe/utils/messages.py", line 57, in _raise_exception
    raise exc
      exc = ExecutableNotFound('mariadb-dump not found in PATH! This is required to take a backup.')
      inspect = <module 'inspect' from '/Users/upforcetech/.pyenv/versions/3.11.8/lib/python3.11/inspect.py'>
      msg = 'mariadb-dump not found in PATH! This is required to take a backup.'
      out = {'message': 'mariadb-dump not found in PATH! This is required to take a backup.', 'title': 'Message', 'indicator': 'red', 'raise_exception': 1, '__frappe_exc_id': 'd9aa1a1dfa236f3fb2b022736133d3f953edad499a4a784c853b3be9'}
      raise_exception = <class 'frappe.exceptions.ExecutableNotFound'>
frappe.exceptions.ExecutableNotFound: mariadb-dump not found in PATH! This is required to take a backup.
Backup failed for Site task.local. Database or site_config.json may be corrupted
Traceback with variables (most recent call last):
  File "apps/frappe/frappe/commands/site.py", line 865, in backup
    odb = scheduled_backup(
      context = CliCtxObj(sites=['task.local'], force=False, profile=False, verbose=True)
      with_files = False
      backup_path = None
      backup_path_db = None
      backup_path_files = None
      backup_path_private_files = None
      backup_path_conf = None
      ignore_backup_conf = False
      verbose = True
      compress = False
      include = ''
      exclude = ''
      old_backup_metadata = False
      scheduled_backup = <function scheduled_backup at 0x103b7cc20>
      exit_code = 0
      rollback_callback = None
      site = 'task.local'
  File "apps/frappe/frappe/utils/backups.py", line 589, in scheduled_backup
    return new_backup(
      older_than = 6
      ignore_files = True
      backup_path = None
      backup_path_db = None
      backup_path_files = None
      backup_path_private_files = None
      backup_path_conf = None
      ignore_conf = False
      include_doctypes = ''
      exclude_doctypes = ''
      compress = False
      force = True
      verbose = True
      old_backup_metadata = False
      rollback_callback = <frappe.utils.CallbackManager object at 0x103eefc10>
  File "apps/frappe/frappe/utils/backups.py", line 647, in new_backup
    odb.get_backup(older_than, ignore_files, force=force)
      older_than = 6
      ignore_files = True
      backup_path = None
      backup_path_db = None
      backup_path_files = None
      backup_path_private_files = None
      backup_path_conf = None
      ignore_conf = False
      include_doctypes = ''
      exclude_doctypes = ''
      compress = False
      force = True
      verbose = True
      old_backup_metadata = False
      rollback_callback = <frappe.utils.CallbackManager object at 0x103eefc10>
      odb = <frappe.utils.backups.BackupGenerator object at 0x103f0b1d0>
  File "apps/frappe/frappe/utils/backups.py", line 191, in get_backup
    self.delete_if_step_fails(self.take_dump, self.backup_path_db)
      self = <frappe.utils.backups.BackupGenerator object at 0x103f0b1d0>
      older_than = 6
      ignore_files = True
      force = True
      last_db = False
      last_file = False
      last_private_file = False
      site_config_backup_path = False
  File "apps/frappe/frappe/utils/backups.py", line 528, in delete_if_step_fails
    raise e
      self = <frappe.utils.backups.BackupGenerator object at 0x103f0b1d0>
      step = <bound method BackupGenerator.take_dump of <frappe.utils.backups.BackupGenerator object at 0x103f0b1d0>>
      paths = ('./task.local/private/backups/20250515_000011-task_local-database.sql.gz',)
      path = './task.local/private/backups/20250515_000011-task_local-database.sql.gz'
  File "apps/frappe/frappe/utils/backups.py", line 523, in delete_if_step_fails
    step()
      self = <frappe.utils.backups.BackupGenerator object at 0x103f0b1d0>
      step = <bound method BackupGenerator.take_dump of <frappe.utils.backups.BackupGenerator object at 0x103f0b1d0>>
      paths = ('./task.local/private/backups/20250515_000011-task_local-database.sql.gz',)
      path = './task.local/private/backups/20250515_000011-task_local-database.sql.gz'
  File "apps/frappe/frappe/utils/backups.py", line 465, in take_dump
    frappe.throw(
      self = <frappe.utils.backups.BackupGenerator object at 0x103f0b1d0>
      frappe = <module 'frappe' from 'apps/frappe/frappe/__init__.py'>
      shlex = <module 'shlex' from '/Users/upforcetech/.pyenv/versions/3.11.8/lib/python3.11/shlex.py'>
      get_app_branch = <function get_app_branch at 0x104870e00>
      gzip_exc = '/usr/bin/gzip'
      database_header_content = ['begin frappe metadata', '[frappe]', 'version = 16.0.0-dev', 'branch = develop', 'end frappe metadata', '']
      generated_header = '-- begin frappe metadata\n-- [frappe]\n-- version = 16.0.0-dev\n-- branch = develop\n-- end frappe metadata\n-- \n'
      f = <_io.TextIOWrapper name='./task.local/private/backups/20250515_000011-task_local-database.sql.gz' encoding='UTF-8'>
      cmd = []
      extra = []
      get_command = <function get_command at 0x103baa5c0>
      bin = None
      args = ['--user=_cce20c0570d41558', '--host=127.0.0.1', '--port=3306', '--password=SOrrCnf2nEiGJvko', '--single-transaction', '--quick', '--lock-tables=false', '_cce20c0570d41558']
      bin_name = 'mariadb-dump'
  File "apps/frappe/frappe/utils/messages.py", line 145, in throw
    msgprint(
      msg = 'mariadb-dump not found in PATH! This is required to take a backup.'
      exc = <class 'frappe.exceptions.ExecutableNotFound'>
      title = None
      is_minimizable = False
      wide = False
      as_list = False
      primary_action = None
  File "apps/frappe/frappe/utils/messages.py", line 106, in msgprint
    _raise_exception()
      msg = 'mariadb-dump not found in PATH! This is required to take a backup.'
      title = None
      raise_exception = <class 'frappe.exceptions.ExecutableNotFound'>
      as_table = False
      as_list = False
      indicator = 'red'
      alert = False
      primary_action = None
      is_minimizable = False
      wide = False
      realtime = False
      _raise_exception = <function msgprint.<locals>._raise_exception at 0x103f2b380>
      inspect = <module 'inspect' from '/Users/upforcetech/.pyenv/versions/3.11.8/lib/python3.11/inspect.py'>
      out = {'message': 'mariadb-dump not found in PATH! This is required to take a backup.', 'title': 'Message', 'indicator': 'red', 'raise_exception': 1, '__frappe_exc_id': '85a0e433a57f9baf145537a1ed3b1f2da328b4f21bbec0b99fbfb118'}
  File "apps/frappe/frappe/utils/messages.py", line 57, in _raise_exception
    raise exc
      exc = ExecutableNotFound('mariadb-dump not found in PATH! This is required to take a backup.')
      inspect = <module 'inspect' from '/Users/upforcetech/.pyenv/versions/3.11.8/lib/python3.11/inspect.py'>
      msg = 'mariadb-dump not found in PATH! This is required to take a backup.'
      out = {'message': 'mariadb-dump not found in PATH! This is required to take a backup.', 'title': 'Message', 'indicator': 'red', 'raise_exception': 1, '__frappe_exc_id': '85a0e433a57f9baf145537a1ed3b1f2da328b4f21bbec0b99fbfb118'}
      raise_exception = <class 'frappe.exceptions.ExecutableNotFound'>
frappe.exceptions.ExecutableNotFound: mariadb-dump not found in PATH! This is required to take a backup.
