/bin/sh: /Users/upforcetech/Desktop/Frappe/venv/bin/bench: No such file or directory
/bin/sh: /Users/upforcetech/Desktop/Frappe/venv/bin/bench: No such file or directory
Backup failed for Site site1.local. Database or site_config.json may be corrupted
Traceback with variables (most recent call last):
  File "apps/frappe/frappe/commands/site.py", line 843, in backup
    odb = scheduled_backup(
      context = {'sites': ['site1.local'], 'force': False, 'verbose': True, 'profile': False}
      with_files = False
      backup_path = None
      backup_path_db = None
      backup_path_files = None
      backup_path_private_files = None
      backup_path_conf = None
      ignore_backup_conf = False
      verbose = True
      compress = False
      include = ''
      exclude = ''
      old_backup_metadata = False
      scheduled_backup = <function scheduled_backup at 0x103740cc0>
      exit_code = 0
      rollback_callback = None
      site = 'site1.local'
  File "apps/frappe/frappe/utils/backups.py", line 568, in scheduled_backup
    return new_backup(
      older_than = 6
      ignore_files = True
      backup_path = None
      backup_path_db = None
      backup_path_files = None
      backup_path_private_files = None
      backup_path_conf = None
      ignore_conf = False
      include_doctypes = ''
      exclude_doctypes = ''
      compress = False
      force = True
      verbose = True
      old_backup_metadata = False
      rollback_callback = <frappe.utils.CallbackManager object at 0x103967cd0>
  File "apps/frappe/frappe/utils/backups.py", line 626, in new_backup
    odb.get_backup(older_than, ignore_files, force=force)
      older_than = 6
      ignore_files = True
      backup_path = None
      backup_path_db = None
      backup_path_files = None
      backup_path_private_files = None
      backup_path_conf = None
      ignore_conf = False
      include_doctypes = ''
      exclude_doctypes = ''
      compress = False
      force = True
      verbose = True
      old_backup_metadata = False
      rollback_callback = <frappe.utils.CallbackManager object at 0x103967cd0>
      odb = <frappe.utils.backups.BackupGenerator object at 0x1038ded10>
  File "apps/frappe/frappe/utils/backups.py", line 195, in get_backup
    self.delete_if_step_fails(self.take_dump, self.backup_path_db)
      self = <frappe.utils.backups.BackupGenerator object at 0x1038ded10>
      older_than = 6
      ignore_files = True
      force = True
      last_db = False
      last_file = False
      last_private_file = False
      site_config_backup_path = False
  File "apps/frappe/frappe/utils/backups.py", line 520, in delete_if_step_fails
    raise e
      self = <frappe.utils.backups.BackupGenerator object at 0x1038ded10>
      step = <bound method BackupGenerator.take_dump of <frappe.utils.backups.BackupGenerator object at 0x1038ded10>>
      paths = ('./site1.local/private/backups/20250430_120011-site1_local-database.sql.gz',)
      path = './site1.local/private/backups/20250430_120011-site1_local-database.sql.gz'
  File "apps/frappe/frappe/utils/backups.py", line 515, in delete_if_step_fails
    step()
      self = <frappe.utils.backups.BackupGenerator object at 0x1038ded10>
      step = <bound method BackupGenerator.take_dump of <frappe.utils.backups.BackupGenerator object at 0x1038ded10>>
      paths = ('./site1.local/private/backups/20250430_120011-site1_local-database.sql.gz',)
      path = './site1.local/private/backups/20250430_120011-site1_local-database.sql.gz'
  File "apps/frappe/frappe/utils/backups.py", line 457, in take_dump
    frappe.throw(
      self = <frappe.utils.backups.BackupGenerator object at 0x1038ded10>
      shlex = <module 'shlex' from '/Users/upforcetech/.pyenv/versions/3.11.8/lib/python3.11/shlex.py'>
      frappe = <module 'frappe' from 'apps/frappe/frappe/__init__.py'>
      get_app_branch = <function get_app_branch at 0x103614360>
      gzip_exc = '/usr/bin/gzip'
      database_header_content = ['begin frappe metadata', '[frappe]', 'version = 15.67.0', 'branch = version-15', 'end frappe metadata', '']
      generated_header = '-- begin frappe metadata\n-- [frappe]\n-- version = 15.67.0\n-- branch = version-15\n-- end frappe metadata\n-- \n'
      f = <_io.TextIOWrapper name='./site1.local/private/backups/20250430_120011-site1_local-database.sql.gz' encoding='UTF-8'>
      cmd = []
      extra = []
      get_command = <function get_command at 0x103412520>
      bin = None
      args = ['--user=_229972456c5e818c', '--host=127.0.0.1', '--port=3306', '--password=LZkj4nvLsCF0qQK4', '--single-transaction', '--quick', '--lock-tables=false', '_229972456c5e818c']
      bin_name = 'mariadb-dump'
  File "apps/frappe/frappe/__init__.py", line 609, in throw
    msgprint(
      msg = 'mariadb-dump not found in PATH! This is required to take a backup.'
      exc = <class 'frappe.exceptions.ExecutableNotFound'>
      title = None
      is_minimizable = False
      wide = False
      as_list = False
      primary_action = None
  File "apps/frappe/frappe/__init__.py", line 574, in msgprint
    _raise_exception()
      msg = 'mariadb-dump not found in PATH! This is required to take a backup.'
      title = None
      raise_exception = <class 'frappe.exceptions.ExecutableNotFound'>
      as_table = False
      as_list = False
      indicator = 'red'
      alert = False
      primary_action = None
      is_minimizable = False
      wide = False
      realtime = False
      sys = <module 'sys' (built-in)>
      _raise_exception = <function msgprint.<locals>._raise_exception at 0x103ce85e0>
      inspect = <module 'inspect' from '/Users/upforcetech/.pyenv/versions/3.11.8/lib/python3.11/inspect.py'>
      out = {'message': 'mariadb-dump not found in PATH! This is required to take a backup.', 'title': 'Message', 'indicator': 'red', 'raise_exception': 1, '__frappe_exc_id': '75836f4087f619908052a3ce674e17bbd8ced7d7926b6793c4c34682'}
  File "apps/frappe/frappe/__init__.py", line 525, in _raise_exception
    raise exc
      exc = ExecutableNotFound('mariadb-dump not found in PATH! This is required to take a backup.')
      inspect = <module 'inspect' from '/Users/upforcetech/.pyenv/versions/3.11.8/lib/python3.11/inspect.py'>
      msg = 'mariadb-dump not found in PATH! This is required to take a backup.'
      out = {'message': 'mariadb-dump not found in PATH! This is required to take a backup.', 'title': 'Message', 'indicator': 'red', 'raise_exception': 1, '__frappe_exc_id': '75836f4087f619908052a3ce674e17bbd8ced7d7926b6793c4c34682'}
      raise_exception = <class 'frappe.exceptions.ExecutableNotFound'>
frappe.exceptions.ExecutableNotFound: mariadb-dump not found in PATH! This is required to take a backup.
/bin/sh: /Users/upforcetech/Desktop/Frappe/venv/bin/bench: No such file or directory
Backup failed for Site site1.local. Database or site_config.json may be corrupted
Traceback with variables (most recent call last):
  File "apps/frappe/frappe/commands/site.py", line 843, in backup
    odb = scheduled_backup(
      context = {'sites': ['site1.local'], 'force': False, 'verbose': True, 'profile': False}
      with_files = False
      backup_path = None
      backup_path_db = None
      backup_path_files = None
      backup_path_private_files = None
      backup_path_conf = None
      ignore_backup_conf = False
      verbose = True
      compress = False
      include = ''
      exclude = ''
      old_backup_metadata = False
      scheduled_backup = <function scheduled_backup at 0x103984cc0>
      exit_code = 0
      rollback_callback = None
      site = 'site1.local'
  File "apps/frappe/frappe/utils/backups.py", line 568, in scheduled_backup
    return new_backup(
      older_than = 6
      ignore_files = True
      backup_path = None
      backup_path_db = None
      backup_path_files = None
      backup_path_private_files = None
      backup_path_conf = None
      ignore_conf = False
      include_doctypes = ''
      exclude_doctypes = ''
      compress = False
      force = True
      verbose = True
      old_backup_metadata = False
      rollback_callback = <frappe.utils.CallbackManager object at 0x103bf0040>
  File "apps/frappe/frappe/utils/backups.py", line 626, in new_backup
    odb.get_backup(older_than, ignore_files, force=force)
      older_than = 6
      ignore_files = True
      backup_path = None
      backup_path_db = None
      backup_path_files = None
      backup_path_private_files = None
      backup_path_conf = None
      ignore_conf = False
      include_doctypes = ''
      exclude_doctypes = ''
      compress = False
      force = True
      verbose = True
      old_backup_metadata = False
      rollback_callback = <frappe.utils.CallbackManager object at 0x103bf0040>
      odb = <frappe.utils.backups.BackupGenerator object at 0x1039f8dd0>
  File "apps/frappe/frappe/utils/backups.py", line 195, in get_backup
    self.delete_if_step_fails(self.take_dump, self.backup_path_db)
      self = <frappe.utils.backups.BackupGenerator object at 0x1039f8dd0>
      older_than = 6
      ignore_files = True
      force = True
      last_db = False
      last_file = False
      last_private_file = False
      site_config_backup_path = False
  File "apps/frappe/frappe/utils/backups.py", line 520, in delete_if_step_fails
    raise e
      self = <frappe.utils.backups.BackupGenerator object at 0x1039f8dd0>
      step = <bound method BackupGenerator.take_dump of <frappe.utils.backups.BackupGenerator object at 0x1039f8dd0>>
      paths = ('./site1.local/private/backups/20250430_180002-site1_local-database.sql.gz',)
      path = './site1.local/private/backups/20250430_180002-site1_local-database.sql.gz'
  File "apps/frappe/frappe/utils/backups.py", line 515, in delete_if_step_fails
    step()
      self = <frappe.utils.backups.BackupGenerator object at 0x1039f8dd0>
      step = <bound method BackupGenerator.take_dump of <frappe.utils.backups.BackupGenerator object at 0x1039f8dd0>>
      paths = ('./site1.local/private/backups/20250430_180002-site1_local-database.sql.gz',)
      path = './site1.local/private/backups/20250430_180002-site1_local-database.sql.gz'
  File "apps/frappe/frappe/utils/backups.py", line 457, in take_dump
    frappe.throw(
      self = <frappe.utils.backups.BackupGenerator object at 0x1039f8dd0>
      shlex = <module 'shlex' from '/Users/upforcetech/.pyenv/versions/3.11.8/lib/python3.11/shlex.py'>
      frappe = <module 'frappe' from 'apps/frappe/frappe/__init__.py'>
      get_app_branch = <function get_app_branch at 0x10381c360>
      gzip_exc = '/usr/bin/gzip'
      database_header_content = ['begin frappe metadata', '[frappe]', 'version = 15.67.0', 'branch = version-15', 'end frappe metadata', '']
      generated_header = '-- begin frappe metadata\n-- [frappe]\n-- version = 15.67.0\n-- branch = version-15\n-- end frappe metadata\n-- \n'
      f = <_io.TextIOWrapper name='./site1.local/private/backups/20250430_180002-site1_local-database.sql.gz' encoding='UTF-8'>
      cmd = []
      extra = []
      get_command = <function get_command at 0x103616520>
      bin = None
      args = ['--user=_229972456c5e818c', '--host=127.0.0.1', '--port=3306', '--password=LZkj4nvLsCF0qQK4', '--single-transaction', '--quick', '--lock-tables=false', '_229972456c5e818c']
      bin_name = 'mariadb-dump'
  File "apps/frappe/frappe/__init__.py", line 609, in throw
    msgprint(
      msg = 'mariadb-dump not found in PATH! This is required to take a backup.'
      exc = <class 'frappe.exceptions.ExecutableNotFound'>
      title = None
      is_minimizable = False
      wide = False
      as_list = False
      primary_action = None
  File "apps/frappe/frappe/__init__.py", line 574, in msgprint
    _raise_exception()
      msg = 'mariadb-dump not found in PATH! This is required to take a backup.'
      title = None
      raise_exception = <class 'frappe.exceptions.ExecutableNotFound'>
      as_table = False
      as_list = False
      indicator = 'red'
      alert = False
      primary_action = None
      is_minimizable = False
      wide = False
      realtime = False
      sys = <module 'sys' (built-in)>
      _raise_exception = <function msgprint.<locals>._raise_exception at 0x101a591c0>
      inspect = <module 'inspect' from '/Users/upforcetech/.pyenv/versions/3.11.8/lib/python3.11/inspect.py'>
      out = {'message': 'mariadb-dump not found in PATH! This is required to take a backup.', 'title': 'Message', 'indicator': 'red', 'raise_exception': 1, '__frappe_exc_id': '2ffa400b317441edf766f3d064c259c81b19e1bbb561ac95656aa7c6'}
  File "apps/frappe/frappe/__init__.py", line 525, in _raise_exception
    raise exc
      exc = ExecutableNotFound('mariadb-dump not found in PATH! This is required to take a backup.')
      inspect = <module 'inspect' from '/Users/upforcetech/.pyenv/versions/3.11.8/lib/python3.11/inspect.py'>
      msg = 'mariadb-dump not found in PATH! This is required to take a backup.'
      out = {'message': 'mariadb-dump not found in PATH! This is required to take a backup.', 'title': 'Message', 'indicator': 'red', 'raise_exception': 1, '__frappe_exc_id': '2ffa400b317441edf766f3d064c259c81b19e1bbb561ac95656aa7c6'}
      raise_exception = <class 'frappe.exceptions.ExecutableNotFound'>
frappe.exceptions.ExecutableNotFound: mariadb-dump not found in PATH! This is required to take a backup.
/bin/sh: /Users/upforcetech/Desktop/Frappe/venv/bin/bench: No such file or directory
Backup failed for Site site1.local. Database or site_config.json may be corrupted
Traceback with variables (most recent call last):
  File "apps/frappe/frappe/commands/site.py", line 843, in backup
    odb = scheduled_backup(
      context = {'sites': ['site1.local'], 'force': False, 'verbose': True, 'profile': False}
      with_files = False
      backup_path = None
      backup_path_db = None
      backup_path_files = None
      backup_path_private_files = None
      backup_path_conf = None
      ignore_backup_conf = False
      verbose = True
      compress = False
      include = ''
      exclude = ''
      old_backup_metadata = False
      scheduled_backup = <function scheduled_backup at 0x10417ccc0>
      exit_code = 0
      rollback_callback = None
      site = 'site1.local'
  File "apps/frappe/frappe/utils/backups.py", line 568, in scheduled_backup
    return new_backup(
      older_than = 6
      ignore_files = True
      backup_path = None
      backup_path_db = None
      backup_path_files = None
      backup_path_private_files = None
      backup_path_conf = None
      ignore_conf = False
      include_doctypes = ''
      exclude_doctypes = ''
      compress = False
      force = True
      verbose = True
      old_backup_metadata = False
      rollback_callback = <frappe.utils.CallbackManager object at 0x1044b00a0>
  File "apps/frappe/frappe/utils/backups.py", line 626, in new_backup
    odb.get_backup(older_than, ignore_files, force=force)
      older_than = 6
      ignore_files = True
      backup_path = None
      backup_path_db = None
      backup_path_files = None
      backup_path_private_files = None
      backup_path_conf = None
      ignore_conf = False
      include_doctypes = ''
      exclude_doctypes = ''
      compress = False
      force = True
      verbose = True
      old_backup_metadata = False
      rollback_callback = <frappe.utils.CallbackManager object at 0x1044b00a0>
      odb = <frappe.utils.backups.BackupGenerator object at 0x1041f0c50>
  File "apps/frappe/frappe/utils/backups.py", line 195, in get_backup
    self.delete_if_step_fails(self.take_dump, self.backup_path_db)
      self = <frappe.utils.backups.BackupGenerator object at 0x1041f0c50>
      older_than = 6
      ignore_files = True
      force = True
      last_db = False
      last_file = False
      last_private_file = False
      site_config_backup_path = False
  File "apps/frappe/frappe/utils/backups.py", line 520, in delete_if_step_fails
    raise e
      self = <frappe.utils.backups.BackupGenerator object at 0x1041f0c50>
      step = <bound method BackupGenerator.take_dump of <frappe.utils.backups.BackupGenerator object at 0x1041f0c50>>
      paths = ('./site1.local/private/backups/20250501_120002-site1_local-database.sql.gz',)
      path = './site1.local/private/backups/20250501_120002-site1_local-database.sql.gz'
  File "apps/frappe/frappe/utils/backups.py", line 515, in delete_if_step_fails
    step()
      self = <frappe.utils.backups.BackupGenerator object at 0x1041f0c50>
      step = <bound method BackupGenerator.take_dump of <frappe.utils.backups.BackupGenerator object at 0x1041f0c50>>
      paths = ('./site1.local/private/backups/20250501_120002-site1_local-database.sql.gz',)
      path = './site1.local/private/backups/20250501_120002-site1_local-database.sql.gz'
  File "apps/frappe/frappe/utils/backups.py", line 457, in take_dump
    frappe.throw(
      self = <frappe.utils.backups.BackupGenerator object at 0x1041f0c50>
      shlex = <module 'shlex' from '/Users/upforcetech/.pyenv/versions/3.11.8/lib/python3.11/shlex.py'>
      frappe = <module 'frappe' from 'apps/frappe/frappe/__init__.py'>
      get_app_branch = <function get_app_branch at 0x104054360>
      gzip_exc = '/usr/bin/gzip'
      database_header_content = ['begin frappe metadata', '[frappe]', 'version = 15.67.0', 'branch = version-15', 'end frappe metadata', '']
      generated_header = '-- begin frappe metadata\n-- [frappe]\n-- version = 15.67.0\n-- branch = version-15\n-- end frappe metadata\n-- \n'
      f = <_io.TextIOWrapper name='./site1.local/private/backups/20250501_120002-site1_local-database.sql.gz' encoding='UTF-8'>
      cmd = []
      extra = []
      get_command = <function get_command at 0x103e4e520>
      bin = None
      args = ['--user=_229972456c5e818c', '--host=127.0.0.1', '--port=3306', '--password=LZkj4nvLsCF0qQK4', '--single-transaction', '--quick', '--lock-tables=false', '_229972456c5e818c']
      bin_name = 'mariadb-dump'
  File "apps/frappe/frappe/__init__.py", line 609, in throw
    msgprint(
      msg = 'mariadb-dump not found in PATH! This is required to take a backup.'
      exc = <class 'frappe.exceptions.ExecutableNotFound'>
      title = None
      is_minimizable = False
      wide = False
      as_list = False
      primary_action = None
  File "apps/frappe/frappe/__init__.py", line 574, in msgprint
    _raise_exception()
      msg = 'mariadb-dump not found in PATH! This is required to take a backup.'
      title = None
      raise_exception = <class 'frappe.exceptions.ExecutableNotFound'>
      as_table = False
      as_list = False
      indicator = 'red'
      alert = False
      primary_action = None
      is_minimizable = False
      wide = False
      realtime = False
      sys = <module 'sys' (built-in)>
      _raise_exception = <function msgprint.<locals>._raise_exception at 0x101c891c0>
      inspect = <module 'inspect' from '/Users/upforcetech/.pyenv/versions/3.11.8/lib/python3.11/inspect.py'>
      out = {'message': 'mariadb-dump not found in PATH! This is required to take a backup.', 'title': 'Message', 'indicator': 'red', 'raise_exception': 1, '__frappe_exc_id': '822b4a0fb9c9edc98b2f855d7c038d472e9ac3a933df1699af6b4086'}
  File "apps/frappe/frappe/__init__.py", line 525, in _raise_exception
    raise exc
      exc = ExecutableNotFound('mariadb-dump not found in PATH! This is required to take a backup.')
      inspect = <module 'inspect' from '/Users/upforcetech/.pyenv/versions/3.11.8/lib/python3.11/inspect.py'>
      msg = 'mariadb-dump not found in PATH! This is required to take a backup.'
      out = {'message': 'mariadb-dump not found in PATH! This is required to take a backup.', 'title': 'Message', 'indicator': 'red', 'raise_exception': 1, '__frappe_exc_id': '822b4a0fb9c9edc98b2f855d7c038d472e9ac3a933df1699af6b4086'}
      raise_exception = <class 'frappe.exceptions.ExecutableNotFound'>
frappe.exceptions.ExecutableNotFound: mariadb-dump not found in PATH! This is required to take a backup.
/bin/sh: /Users/upforcetech/Desktop/Frappe/venv/bin/bench: No such file or directory
Backup failed for Site site1.local. Database or site_config.json may be corrupted
Traceback with variables (most recent call last):
  File "apps/frappe/frappe/commands/site.py", line 843, in backup
    odb = scheduled_backup(
      context = {'sites': ['site1.local'], 'force': False, 'verbose': True, 'profile': False}
      with_files = False
      backup_path = None
      backup_path_db = None
      backup_path_files = None
      backup_path_private_files = None
      backup_path_conf = None
      ignore_backup_conf = False
      verbose = True
      compress = False
      include = ''
      exclude = ''
      old_backup_metadata = False
      scheduled_backup = <function scheduled_backup at 0x105d7ccc0>
      exit_code = 0
      rollback_callback = None
      site = 'site1.local'
  File "apps/frappe/frappe/utils/backups.py", line 568, in scheduled_backup
    return new_backup(
      older_than = 6
      ignore_files = True
      backup_path = None
      backup_path_db = None
      backup_path_files = None
      backup_path_private_files = None
      backup_path_conf = None
      ignore_conf = False
      include_doctypes = ''
      exclude_doctypes = ''
      compress = False
      force = True
      verbose = True
      old_backup_metadata = False
      rollback_callback = <frappe.utils.CallbackManager object at 0x105fa3d30>
  File "apps/frappe/frappe/utils/backups.py", line 626, in new_backup
    odb.get_backup(older_than, ignore_files, force=force)
      older_than = 6
      ignore_files = True
      backup_path = None
      backup_path_db = None
      backup_path_files = None
      backup_path_private_files = None
      backup_path_conf = None
      ignore_conf = False
      include_doctypes = ''
      exclude_doctypes = ''
      compress = False
      force = True
      verbose = True
      old_backup_metadata = False
      rollback_callback = <frappe.utils.CallbackManager object at 0x105fa3d30>
      odb = <frappe.utils.backups.BackupGenerator object at 0x105df0a50>
  File "apps/frappe/frappe/utils/backups.py", line 195, in get_backup
    self.delete_if_step_fails(self.take_dump, self.backup_path_db)
      self = <frappe.utils.backups.BackupGenerator object at 0x105df0a50>
      older_than = 6
      ignore_files = True
      force = True
      last_db = False
      last_file = False
      last_private_file = False
      site_config_backup_path = False
  File "apps/frappe/frappe/utils/backups.py", line 520, in delete_if_step_fails
    raise e
      self = <frappe.utils.backups.BackupGenerator object at 0x105df0a50>
      step = <bound method BackupGenerator.take_dump of <frappe.utils.backups.BackupGenerator object at 0x105df0a50>>
      paths = ('./site1.local/private/backups/20250501_180002-site1_local-database.sql.gz',)
      path = './site1.local/private/backups/20250501_180002-site1_local-database.sql.gz'
  File "apps/frappe/frappe/utils/backups.py", line 515, in delete_if_step_fails
    step()
      self = <frappe.utils.backups.BackupGenerator object at 0x105df0a50>
      step = <bound method BackupGenerator.take_dump of <frappe.utils.backups.BackupGenerator object at 0x105df0a50>>
      paths = ('./site1.local/private/backups/20250501_180002-site1_local-database.sql.gz',)
      path = './site1.local/private/backups/20250501_180002-site1_local-database.sql.gz'
  File "apps/frappe/frappe/utils/backups.py", line 457, in take_dump
    frappe.throw(
      self = <frappe.utils.backups.BackupGenerator object at 0x105df0a50>
      shlex = <module 'shlex' from '/Users/upforcetech/.pyenv/versions/3.11.8/lib/python3.11/shlex.py'>
      frappe = <module 'frappe' from 'apps/frappe/frappe/__init__.py'>
      get_app_branch = <function get_app_branch at 0x105b54360>
      gzip_exc = '/usr/bin/gzip'
      database_header_content = ['begin frappe metadata', '[frappe]', 'version = 15.67.0', 'branch = version-15', 'end frappe metadata', '']
      generated_header = '-- begin frappe metadata\n-- [frappe]\n-- version = 15.67.0\n-- branch = version-15\n-- end frappe metadata\n-- \n'
      f = <_io.TextIOWrapper name='./site1.local/private/backups/20250501_180002-site1_local-database.sql.gz' encoding='UTF-8'>
      cmd = []
      extra = []
      get_command = <function get_command at 0x10584e520>
      bin = None
      args = ['--user=_229972456c5e818c', '--host=127.0.0.1', '--port=3306', '--password=LZkj4nvLsCF0qQK4', '--single-transaction', '--quick', '--lock-tables=false', '_229972456c5e818c']
      bin_name = 'mariadb-dump'
  File "apps/frappe/frappe/__init__.py", line 609, in throw
    msgprint(
      msg = 'mariadb-dump not found in PATH! This is required to take a backup.'
      exc = <class 'frappe.exceptions.ExecutableNotFound'>
      title = None
      is_minimizable = False
      wide = False
      as_list = False
      primary_action = None
  File "apps/frappe/frappe/__init__.py", line 574, in msgprint
    _raise_exception()
      msg = 'mariadb-dump not found in PATH! This is required to take a backup.'
      title = None
      raise_exception = <class 'frappe.exceptions.ExecutableNotFound'>
      as_table = False
      as_list = False
      indicator = 'red'
      alert = False
      primary_action = None
      is_minimizable = False
      wide = False
      realtime = False
      sys = <module 'sys' (built-in)>
      _raise_exception = <function msgprint.<locals>._raise_exception at 0x103e551c0>
      inspect = <module 'inspect' from '/Users/upforcetech/.pyenv/versions/3.11.8/lib/python3.11/inspect.py'>
      out = {'message': 'mariadb-dump not found in PATH! This is required to take a backup.', 'title': 'Message', 'indicator': 'red', 'raise_exception': 1, '__frappe_exc_id': '7950328aaf7925f86cb95eb6c10b9d741a05f3f61d7340931b7edb4f'}
  File "apps/frappe/frappe/__init__.py", line 525, in _raise_exception
    raise exc
      exc = ExecutableNotFound('mariadb-dump not found in PATH! This is required to take a backup.')
      inspect = <module 'inspect' from '/Users/upforcetech/.pyenv/versions/3.11.8/lib/python3.11/inspect.py'>
      msg = 'mariadb-dump not found in PATH! This is required to take a backup.'
      out = {'message': 'mariadb-dump not found in PATH! This is required to take a backup.', 'title': 'Message', 'indicator': 'red', 'raise_exception': 1, '__frappe_exc_id': '7950328aaf7925f86cb95eb6c10b9d741a05f3f61d7340931b7edb4f'}
      raise_exception = <class 'frappe.exceptions.ExecutableNotFound'>
frappe.exceptions.ExecutableNotFound: mariadb-dump not found in PATH! This is required to take a backup.
/bin/sh: /Users/upforcetech/Desktop/Frappe/venv/bin/bench: No such file or directory
Backup failed for Site site1.local. Database or site_config.json may be corrupted
Traceback with variables (most recent call last):
  File "apps/frappe/frappe/commands/site.py", line 843, in backup
    odb = scheduled_backup(
      context = {'sites': ['site1.local'], 'force': False, 'verbose': True, 'profile': False}
      with_files = False
      backup_path = None
      backup_path_db = None
      backup_path_files = None
      backup_path_private_files = None
      backup_path_conf = None
      ignore_backup_conf = False
      verbose = True
      compress = False
      include = ''
      exclude = ''
      old_backup_metadata = False
      scheduled_backup = <function scheduled_backup at 0x103d98cc0>
      exit_code = 0
      rollback_callback = None
      site = 'site1.local'
  File "apps/frappe/frappe/utils/backups.py", line 568, in scheduled_backup
    return new_backup(
      older_than = 6
      ignore_files = True
      backup_path = None
      backup_path_db = None
      backup_path_files = None
      backup_path_private_files = None
      backup_path_conf = None
      ignore_conf = False
      include_doctypes = ''
      exclude_doctypes = ''
      compress = False
      force = True
      verbose = True
      old_backup_metadata = False
      rollback_callback = <frappe.utils.CallbackManager object at 0x103fd6530>
  File "apps/frappe/frappe/utils/backups.py", line 626, in new_backup
    odb.get_backup(older_than, ignore_files, force=force)
      older_than = 6
      ignore_files = True
      backup_path = None
      backup_path_db = None
      backup_path_files = None
      backup_path_private_files = None
      backup_path_conf = None
      ignore_conf = False
      include_doctypes = ''
      exclude_doctypes = ''
      compress = False
      force = True
      verbose = True
      old_backup_metadata = False
      rollback_callback = <frappe.utils.CallbackManager object at 0x103fd6530>
      odb = <frappe.utils.backups.BackupGenerator object at 0x103e0ced0>
  File "apps/frappe/frappe/utils/backups.py", line 195, in get_backup
    self.delete_if_step_fails(self.take_dump, self.backup_path_db)
      self = <frappe.utils.backups.BackupGenerator object at 0x103e0ced0>
      older_than = 6
      ignore_files = True
      force = True
      last_db = False
      last_file = False
      last_private_file = False
      site_config_backup_path = False
  File "apps/frappe/frappe/utils/backups.py", line 520, in delete_if_step_fails
    raise e
      self = <frappe.utils.backups.BackupGenerator object at 0x103e0ced0>
      step = <bound method BackupGenerator.take_dump of <frappe.utils.backups.BackupGenerator object at 0x103e0ced0>>
      paths = ('./site1.local/private/backups/20250502_120001-site1_local-database.sql.gz',)
      path = './site1.local/private/backups/20250502_120001-site1_local-database.sql.gz'
  File "apps/frappe/frappe/utils/backups.py", line 515, in delete_if_step_fails
    step()
      self = <frappe.utils.backups.BackupGenerator object at 0x103e0ced0>
      step = <bound method BackupGenerator.take_dump of <frappe.utils.backups.BackupGenerator object at 0x103e0ced0>>
      paths = ('./site1.local/private/backups/20250502_120001-site1_local-database.sql.gz',)
      path = './site1.local/private/backups/20250502_120001-site1_local-database.sql.gz'
  File "apps/frappe/frappe/utils/backups.py", line 457, in take_dump
    frappe.throw(
      self = <frappe.utils.backups.BackupGenerator object at 0x103e0ced0>
      shlex = <module 'shlex' from '/Users/upforcetech/.pyenv/versions/3.11.8/lib/python3.11/shlex.py'>
      frappe = <module 'frappe' from 'apps/frappe/frappe/__init__.py'>
      get_app_branch = <function get_app_branch at 0x103c30360>
      gzip_exc = '/usr/bin/gzip'
      database_header_content = ['begin frappe metadata', '[frappe]', 'version = 15.67.0', 'branch = version-15', 'end frappe metadata', '']
      generated_header = '-- begin frappe metadata\n-- [frappe]\n-- version = 15.67.0\n-- branch = version-15\n-- end frappe metadata\n-- \n'
      f = <_io.TextIOWrapper name='./site1.local/private/backups/20250502_120001-site1_local-database.sql.gz' encoding='UTF-8'>
      cmd = []
      extra = []
      get_command = <function get_command at 0x103a2a520>
      bin = None
      args = ['--user=_229972456c5e818c', '--host=127.0.0.1', '--port=3306', '--password=LZkj4nvLsCF0qQK4', '--single-transaction', '--quick', '--lock-tables=false', '_229972456c5e818c']
      bin_name = 'mariadb-dump'
  File "apps/frappe/frappe/__init__.py", line 609, in throw
    msgprint(
      msg = 'mariadb-dump not found in PATH! This is required to take a backup.'
      exc = <class 'frappe.exceptions.ExecutableNotFound'>
      title = None
      is_minimizable = False
      wide = False
      as_list = False
      primary_action = None
  File "apps/frappe/frappe/__init__.py", line 574, in msgprint
    _raise_exception()
      msg = 'mariadb-dump not found in PATH! This is required to take a backup.'
      title = None
      raise_exception = <class 'frappe.exceptions.ExecutableNotFound'>
      as_table = False
      as_list = False
      indicator = 'red'
      alert = False
      primary_action = None
      is_minimizable = False
      wide = False
      realtime = False
      sys = <module 'sys' (built-in)>
      _raise_exception = <function msgprint.<locals>._raise_exception at 0x101e891c0>
      inspect = <module 'inspect' from '/Users/upforcetech/.pyenv/versions/3.11.8/lib/python3.11/inspect.py'>
      out = {'message': 'mariadb-dump not found in PATH! This is required to take a backup.', 'title': 'Message', 'indicator': 'red', 'raise_exception': 1, '__frappe_exc_id': 'e97dc17500d5b4e91edcb938a574ee55d37c3b51bf425606c5c28014'}
  File "apps/frappe/frappe/__init__.py", line 525, in _raise_exception
    raise exc
      exc = ExecutableNotFound('mariadb-dump not found in PATH! This is required to take a backup.')
      inspect = <module 'inspect' from '/Users/upforcetech/.pyenv/versions/3.11.8/lib/python3.11/inspect.py'>
      msg = 'mariadb-dump not found in PATH! This is required to take a backup.'
      out = {'message': 'mariadb-dump not found in PATH! This is required to take a backup.', 'title': 'Message', 'indicator': 'red', 'raise_exception': 1, '__frappe_exc_id': 'e97dc17500d5b4e91edcb938a574ee55d37c3b51bf425606c5c28014'}
      raise_exception = <class 'frappe.exceptions.ExecutableNotFound'>
frappe.exceptions.ExecutableNotFound: mariadb-dump not found in PATH! This is required to take a backup.
/bin/sh: /Users/upforcetech/Desktop/Frappe/venv/bin/bench: No such file or directory
Backup failed for Site site1.local. Database or site_config.json may be corrupted
Traceback with variables (most recent call last):
  File "apps/frappe/frappe/commands/site.py", line 843, in backup
    odb = scheduled_backup(
      context = {'sites': ['site1.local'], 'force': False, 'verbose': True, 'profile': False}
      with_files = False
      backup_path = None
      backup_path_db = None
      backup_path_files = None
      backup_path_private_files = None
      backup_path_conf = None
      ignore_backup_conf = False
      verbose = True
      compress = False
      include = ''
      exclude = ''
      old_backup_metadata = False
      scheduled_backup = <function scheduled_backup at 0x108398cc0>
      exit_code = 0
      rollback_callback = None
      site = 'site1.local'
  File "apps/frappe/frappe/utils/backups.py", line 568, in scheduled_backup
    return new_backup(
      older_than = 6
      ignore_files = True
      backup_path = None
      backup_path_db = None
      backup_path_files = None
      backup_path_private_files = None
      backup_path_conf = None
      ignore_conf = False
      include_doctypes = ''
      exclude_doctypes = ''
      compress = False
      force = True
      verbose = True
      old_backup_metadata = False
      rollback_callback = <frappe.utils.CallbackManager object at 0x108638160>
  File "apps/frappe/frappe/utils/backups.py", line 626, in new_backup
    odb.get_backup(older_than, ignore_files, force=force)
      older_than = 6
      ignore_files = True
      backup_path = None
      backup_path_db = None
      backup_path_files = None
      backup_path_private_files = None
      backup_path_conf = None
      ignore_conf = False
      include_doctypes = ''
      exclude_doctypes = ''
      compress = False
      force = True
      verbose = True
      old_backup_metadata = False
      rollback_callback = <frappe.utils.CallbackManager object at 0x108638160>
      odb = <frappe.utils.backups.BackupGenerator object at 0x10840ce90>
  File "apps/frappe/frappe/utils/backups.py", line 195, in get_backup
    self.delete_if_step_fails(self.take_dump, self.backup_path_db)
      self = <frappe.utils.backups.BackupGenerator object at 0x10840ce90>
      older_than = 6
      ignore_files = True
      force = True
      last_db = False
      last_file = False
      last_private_file = False
      site_config_backup_path = False
  File "apps/frappe/frappe/utils/backups.py", line 520, in delete_if_step_fails
    raise e
      self = <frappe.utils.backups.BackupGenerator object at 0x10840ce90>
      step = <bound method BackupGenerator.take_dump of <frappe.utils.backups.BackupGenerator object at 0x10840ce90>>
      paths = ('./site1.local/private/backups/20250502_180001-site1_local-database.sql.gz',)
      path = './site1.local/private/backups/20250502_180001-site1_local-database.sql.gz'
  File "apps/frappe/frappe/utils/backups.py", line 515, in delete_if_step_fails
    step()
      self = <frappe.utils.backups.BackupGenerator object at 0x10840ce90>
      step = <bound method BackupGenerator.take_dump of <frappe.utils.backups.BackupGenerator object at 0x10840ce90>>
      paths = ('./site1.local/private/backups/20250502_180001-site1_local-database.sql.gz',)
      path = './site1.local/private/backups/20250502_180001-site1_local-database.sql.gz'
  File "apps/frappe/frappe/utils/backups.py", line 457, in take_dump
    frappe.throw(
      self = <frappe.utils.backups.BackupGenerator object at 0x10840ce90>
      shlex = <module 'shlex' from '/Users/upforcetech/.pyenv/versions/3.11.8/lib/python3.11/shlex.py'>
      frappe = <module 'frappe' from 'apps/frappe/frappe/__init__.py'>
      get_app_branch = <function get_app_branch at 0x108270360>
      gzip_exc = '/usr/bin/gzip'
      database_header_content = ['begin frappe metadata', '[frappe]', 'version = 15.67.0', 'branch = version-15', 'end frappe metadata', '']
      generated_header = '-- begin frappe metadata\n-- [frappe]\n-- version = 15.67.0\n-- branch = version-15\n-- end frappe metadata\n-- \n'
      f = <_io.TextIOWrapper name='./site1.local/private/backups/20250502_180001-site1_local-database.sql.gz' encoding='UTF-8'>
      cmd = []
      extra = []
      get_command = <function get_command at 0x10806a520>
      bin = None
      args = ['--user=_229972456c5e818c', '--host=127.0.0.1', '--port=3306', '--password=LZkj4nvLsCF0qQK4', '--single-transaction', '--quick', '--lock-tables=false', '_229972456c5e818c']
      bin_name = 'mariadb-dump'
  File "apps/frappe/frappe/__init__.py", line 609, in throw
    msgprint(
      msg = 'mariadb-dump not found in PATH! This is required to take a backup.'
      exc = <class 'frappe.exceptions.ExecutableNotFound'>
      title = None
      is_minimizable = False
      wide = False
      as_list = False
      primary_action = None
  File "apps/frappe/frappe/__init__.py", line 574, in msgprint
    _raise_exception()
      msg = 'mariadb-dump not found in PATH! This is required to take a backup.'
      title = None
      raise_exception = <class 'frappe.exceptions.ExecutableNotFound'>
      as_table = False
      as_list = False
      indicator = 'red'
      alert = False
      primary_action = None
      is_minimizable = False
      wide = False
      realtime = False
      sys = <module 'sys' (built-in)>
      _raise_exception = <function msgprint.<locals>._raise_exception at 0x1064a11c0>
      inspect = <module 'inspect' from '/Users/upforcetech/.pyenv/versions/3.11.8/lib/python3.11/inspect.py'>
      out = {'message': 'mariadb-dump not found in PATH! This is required to take a backup.', 'title': 'Message', 'indicator': 'red', 'raise_exception': 1, '__frappe_exc_id': '15e13a069e64f347fed348bf7029ad2997bc0584e2f50eaf64268e1e'}
  File "apps/frappe/frappe/__init__.py", line 525, in _raise_exception
    raise exc
      exc = ExecutableNotFound('mariadb-dump not found in PATH! This is required to take a backup.')
      inspect = <module 'inspect' from '/Users/upforcetech/.pyenv/versions/3.11.8/lib/python3.11/inspect.py'>
      msg = 'mariadb-dump not found in PATH! This is required to take a backup.'
      out = {'message': 'mariadb-dump not found in PATH! This is required to take a backup.', 'title': 'Message', 'indicator': 'red', 'raise_exception': 1, '__frappe_exc_id': '15e13a069e64f347fed348bf7029ad2997bc0584e2f50eaf64268e1e'}
      raise_exception = <class 'frappe.exceptions.ExecutableNotFound'>
frappe.exceptions.ExecutableNotFound: mariadb-dump not found in PATH! This is required to take a backup.
/bin/sh: /Users/upforcetech/Desktop/Frappe/venv/bin/bench: No such file or directory
Backup failed for Site site1.local. Database or site_config.json may be corrupted
Traceback with variables (most recent call last):
  File "apps/frappe/frappe/commands/site.py", line 843, in backup
    odb = scheduled_backup(
      context = {'sites': ['site1.local'], 'force': False, 'verbose': True, 'profile': False}
      with_files = False
      backup_path = None
      backup_path_db = None
      backup_path_files = None
      backup_path_private_files = None
      backup_path_conf = None
      ignore_backup_conf = False
      verbose = True
      compress = False
      include = ''
      exclude = ''
      old_backup_metadata = False
      scheduled_backup = <function scheduled_backup at 0x106398cc0>
      exit_code = 0
      rollback_callback = None
      site = 'site1.local'
  File "apps/frappe/frappe/utils/backups.py", line 568, in scheduled_backup
    return new_backup(
      older_than = 6
      ignore_files = True
      backup_path = None
      backup_path_db = None
      backup_path_files = None
      backup_path_private_files = None
      backup_path_conf = None
      ignore_conf = False
      include_doctypes = ''
      exclude_doctypes = ''
      compress = False
      force = True
      verbose = True
      old_backup_metadata = False
      rollback_callback = <frappe.utils.CallbackManager object at 0x1065bfd60>
  File "apps/frappe/frappe/utils/backups.py", line 626, in new_backup
    odb.get_backup(older_than, ignore_files, force=force)
      older_than = 6
      ignore_files = True
      backup_path = None
      backup_path_db = None
      backup_path_files = None
      backup_path_private_files = None
      backup_path_conf = None
      ignore_conf = False
      include_doctypes = ''
      exclude_doctypes = ''
      compress = False
      force = True
      verbose = True
      old_backup_metadata = False
      rollback_callback = <frappe.utils.CallbackManager object at 0x1065bfd60>
      odb = <frappe.utils.backups.BackupGenerator object at 0x10640cd90>
  File "apps/frappe/frappe/utils/backups.py", line 195, in get_backup
    self.delete_if_step_fails(self.take_dump, self.backup_path_db)
      self = <frappe.utils.backups.BackupGenerator object at 0x10640cd90>
      older_than = 6
      ignore_files = True
      force = True
      last_db = False
      last_file = False
      last_private_file = False
      site_config_backup_path = False
  File "apps/frappe/frappe/utils/backups.py", line 520, in delete_if_step_fails
    raise e
      self = <frappe.utils.backups.BackupGenerator object at 0x10640cd90>
      step = <bound method BackupGenerator.take_dump of <frappe.utils.backups.BackupGenerator object at 0x10640cd90>>
      paths = ('./site1.local/private/backups/20250503_120001-site1_local-database.sql.gz',)
      path = './site1.local/private/backups/20250503_120001-site1_local-database.sql.gz'
  File "apps/frappe/frappe/utils/backups.py", line 515, in delete_if_step_fails
    step()
      self = <frappe.utils.backups.BackupGenerator object at 0x10640cd90>
      step = <bound method BackupGenerator.take_dump of <frappe.utils.backups.BackupGenerator object at 0x10640cd90>>
      paths = ('./site1.local/private/backups/20250503_120001-site1_local-database.sql.gz',)
      path = './site1.local/private/backups/20250503_120001-site1_local-database.sql.gz'
  File "apps/frappe/frappe/utils/backups.py", line 457, in take_dump
    frappe.throw(
      self = <frappe.utils.backups.BackupGenerator object at 0x10640cd90>
      shlex = <module 'shlex' from '/Users/upforcetech/.pyenv/versions/3.11.8/lib/python3.11/shlex.py'>
      frappe = <module 'frappe' from 'apps/frappe/frappe/__init__.py'>
      get_app_branch = <function get_app_branch at 0x106270360>
      gzip_exc = '/usr/bin/gzip'
      database_header_content = ['begin frappe metadata', '[frappe]', 'version = 15.67.0', 'branch = version-15', 'end frappe metadata', '']
      generated_header = '-- begin frappe metadata\n-- [frappe]\n-- version = 15.67.0\n-- branch = version-15\n-- end frappe metadata\n-- \n'
      f = <_io.TextIOWrapper name='./site1.local/private/backups/20250503_120001-site1_local-database.sql.gz' encoding='UTF-8'>
      cmd = []
      extra = []
      get_command = <function get_command at 0x10606a520>
      bin = None
      args = ['--user=_229972456c5e818c', '--host=127.0.0.1', '--port=3306', '--password=LZkj4nvLsCF0qQK4', '--single-transaction', '--quick', '--lock-tables=false', '_229972456c5e818c']
      bin_name = 'mariadb-dump'
  File "apps/frappe/frappe/__init__.py", line 609, in throw
    msgprint(
      msg = 'mariadb-dump not found in PATH! This is required to take a backup.'
      exc = <class 'frappe.exceptions.ExecutableNotFound'>
      title = None
      is_minimizable = False
      wide = False
      as_list = False
      primary_action = None
  File "apps/frappe/frappe/__init__.py", line 574, in msgprint
    _raise_exception()
      msg = 'mariadb-dump not found in PATH! This is required to take a backup.'
      title = None
      raise_exception = <class 'frappe.exceptions.ExecutableNotFound'>
      as_table = False
      as_list = False
      indicator = 'red'
      alert = False
      primary_action = None
      is_minimizable = False
      wide = False
      realtime = False
      sys = <module 'sys' (built-in)>
      _raise_exception = <function msgprint.<locals>._raise_exception at 0x1044811c0>
      inspect = <module 'inspect' from '/Users/upforcetech/.pyenv/versions/3.11.8/lib/python3.11/inspect.py'>
      out = {'message': 'mariadb-dump not found in PATH! This is required to take a backup.', 'title': 'Message', 'indicator': 'red', 'raise_exception': 1, '__frappe_exc_id': '57418ad9467c876740b6f25fe9593f85d9c3ab747c490b6b6edbaa83'}
  File "apps/frappe/frappe/__init__.py", line 525, in _raise_exception
    raise exc
      exc = ExecutableNotFound('mariadb-dump not found in PATH! This is required to take a backup.')
      inspect = <module 'inspect' from '/Users/upforcetech/.pyenv/versions/3.11.8/lib/python3.11/inspect.py'>
      msg = 'mariadb-dump not found in PATH! This is required to take a backup.'
      out = {'message': 'mariadb-dump not found in PATH! This is required to take a backup.', 'title': 'Message', 'indicator': 'red', 'raise_exception': 1, '__frappe_exc_id': '57418ad9467c876740b6f25fe9593f85d9c3ab747c490b6b6edbaa83'}
      raise_exception = <class 'frappe.exceptions.ExecutableNotFound'>
frappe.exceptions.ExecutableNotFound: mariadb-dump not found in PATH! This is required to take a backup.
/bin/sh: /Users/upforcetech/Desktop/Frappe/venv/bin/bench: No such file or directory
Backup failed for Site site1.local. Database or site_config.json may be corrupted
Traceback with variables (most recent call last):
  File "apps/frappe/frappe/commands/site.py", line 843, in backup
    odb = scheduled_backup(
      context = {'sites': ['site1.local'], 'force': False, 'verbose': True, 'profile': False}
      with_files = False
      backup_path = None
      backup_path_db = None
      backup_path_files = None
      backup_path_private_files = None
      backup_path_conf = None
      ignore_backup_conf = False
      verbose = True
      compress = False
      include = ''
      exclude = ''
      old_backup_metadata = False
      scheduled_backup = <function scheduled_backup at 0x12067ccc0>
      exit_code = 0
      rollback_callback = None
      site = 'site1.local'
  File "apps/frappe/frappe/utils/backups.py", line 568, in scheduled_backup
    return new_backup(
      older_than = 6
      ignore_files = True
      backup_path = None
      backup_path_db = None
      backup_path_files = None
      backup_path_private_files = None
      backup_path_conf = None
      ignore_conf = False
      include_doctypes = ''
      exclude_doctypes = ''
      compress = False
      force = True
      verbose = True
      old_backup_metadata = False
      rollback_callback = <frappe.utils.CallbackManager object at 0x120ab0040>
  File "apps/frappe/frappe/utils/backups.py", line 626, in new_backup
    odb.get_backup(older_than, ignore_files, force=force)
      older_than = 6
      ignore_files = True
      backup_path = None
      backup_path_db = None
      backup_path_files = None
      backup_path_private_files = None
      backup_path_conf = None
      ignore_conf = False
      include_doctypes = ''
      exclude_doctypes = ''
      compress = False
      force = True
      verbose = True
      old_backup_metadata = False
      rollback_callback = <frappe.utils.CallbackManager object at 0x120ab0040>
      odb = <frappe.utils.backups.BackupGenerator object at 0x1206ed0d0>
  File "apps/frappe/frappe/utils/backups.py", line 195, in get_backup
    self.delete_if_step_fails(self.take_dump, self.backup_path_db)
      self = <frappe.utils.backups.BackupGenerator object at 0x1206ed0d0>
      older_than = 6
      ignore_files = True
      force = True
      last_db = False
      last_file = False
      last_private_file = False
      site_config_backup_path = False
  File "apps/frappe/frappe/utils/backups.py", line 520, in delete_if_step_fails
    raise e
      self = <frappe.utils.backups.BackupGenerator object at 0x1206ed0d0>
      step = <bound method BackupGenerator.take_dump of <frappe.utils.backups.BackupGenerator object at 0x1206ed0d0>>
      paths = ('./site1.local/private/backups/20250503_180002-site1_local-database.sql.gz',)
      path = './site1.local/private/backups/20250503_180002-site1_local-database.sql.gz'
  File "apps/frappe/frappe/utils/backups.py", line 515, in delete_if_step_fails
    step()
      self = <frappe.utils.backups.BackupGenerator object at 0x1206ed0d0>
      step = <bound method BackupGenerator.take_dump of <frappe.utils.backups.BackupGenerator object at 0x1206ed0d0>>
      paths = ('./site1.local/private/backups/20250503_180002-site1_local-database.sql.gz',)
      path = './site1.local/private/backups/20250503_180002-site1_local-database.sql.gz'
  File "apps/frappe/frappe/utils/backups.py", line 457, in take_dump
    frappe.throw(
      self = <frappe.utils.backups.BackupGenerator object at 0x1206ed0d0>
      shlex = <module 'shlex' from '/Users/upforcetech/.pyenv/versions/3.11.8/lib/python3.11/shlex.py'>
      frappe = <module 'frappe' from 'apps/frappe/frappe/__init__.py'>
      get_app_branch = <function get_app_branch at 0x120554360>
      gzip_exc = '/usr/bin/gzip'
      database_header_content = ['begin frappe metadata', '[frappe]', 'version = 15.67.0', 'branch = version-15', 'end frappe metadata', '']
      generated_header = '-- begin frappe metadata\n-- [frappe]\n-- version = 15.67.0\n-- branch = version-15\n-- end frappe metadata\n-- \n'
      f = <_io.TextIOWrapper name='./site1.local/private/backups/20250503_180002-site1_local-database.sql.gz' encoding='UTF-8'>
      cmd = []
      extra = []
      get_command = <function get_command at 0x12034e520>
      bin = None
      args = ['--user=_229972456c5e818c', '--host=127.0.0.1', '--port=3306', '--password=LZkj4nvLsCF0qQK4', '--single-transaction', '--quick', '--lock-tables=false', '_229972456c5e818c']
      bin_name = 'mariadb-dump'
  File "apps/frappe/frappe/__init__.py", line 609, in throw
    msgprint(
      msg = 'mariadb-dump not found in PATH! This is required to take a backup.'
      exc = <class 'frappe.exceptions.ExecutableNotFound'>
      title = None
      is_minimizable = False
      wide = False
      as_list = False
      primary_action = None
  File "apps/frappe/frappe/__init__.py", line 574, in msgprint
    _raise_exception()
      msg = 'mariadb-dump not found in PATH! This is required to take a backup.'
      title = None
      raise_exception = <class 'frappe.exceptions.ExecutableNotFound'>
      as_table = False
      as_list = False
      indicator = 'red'
      alert = False
      primary_action = None
      is_minimizable = False
      wide = False
      realtime = False
      sys = <module 'sys' (built-in)>
      _raise_exception = <function msgprint.<locals>._raise_exception at 0x1063711c0>
      inspect = <module 'inspect' from '/Users/upforcetech/.pyenv/versions/3.11.8/lib/python3.11/inspect.py'>
      out = {'message': 'mariadb-dump not found in PATH! This is required to take a backup.', 'title': 'Message', 'indicator': 'red', 'raise_exception': 1, '__frappe_exc_id': '100d507ceef7959cee3f067114476efe193b45f7943d3a98b031e290'}
  File "apps/frappe/frappe/__init__.py", line 525, in _raise_exception
    raise exc
      exc = ExecutableNotFound('mariadb-dump not found in PATH! This is required to take a backup.')
      inspect = <module 'inspect' from '/Users/upforcetech/.pyenv/versions/3.11.8/lib/python3.11/inspect.py'>
      msg = 'mariadb-dump not found in PATH! This is required to take a backup.'
      out = {'message': 'mariadb-dump not found in PATH! This is required to take a backup.', 'title': 'Message', 'indicator': 'red', 'raise_exception': 1, '__frappe_exc_id': '100d507ceef7959cee3f067114476efe193b45f7943d3a98b031e290'}
      raise_exception = <class 'frappe.exceptions.ExecutableNotFound'>
frappe.exceptions.ExecutableNotFound: mariadb-dump not found in PATH! This is required to take a backup.
/bin/sh: /Users/upforcetech/Desktop/Frappe/venv/bin/bench: No such file or directory
Backup failed for Site site1.local. Database or site_config.json may be corrupted
Traceback with variables (most recent call last):
  File "apps/frappe/frappe/commands/site.py", line 843, in backup
    odb = scheduled_backup(
      context = {'sites': ['site1.local'], 'force': False, 'verbose': True, 'profile': False}
      with_files = False
      backup_path = None
      backup_path_db = None
      backup_path_files = None
      backup_path_private_files = None
      backup_path_conf = None
      ignore_backup_conf = False
      verbose = True
      compress = False
      include = ''
      exclude = ''
      old_backup_metadata = False
      scheduled_backup = <function scheduled_backup at 0x107cd0cc0>
      exit_code = 0
      rollback_callback = None
      site = 'site1.local'
  File "apps/frappe/frappe/utils/backups.py", line 568, in scheduled_backup
    return new_backup(
      older_than = 6
      ignore_files = True
      backup_path = None
      backup_path_db = None
      backup_path_files = None
      backup_path_private_files = None
      backup_path_conf = None
      ignore_conf = False
      include_doctypes = ''
      exclude_doctypes = ''
      compress = False
      force = True
      verbose = True
      old_backup_metadata = False
      rollback_callback = <frappe.utils.CallbackManager object at 0x107f2bd90>
  File "apps/frappe/frappe/utils/backups.py", line 626, in new_backup
    odb.get_backup(older_than, ignore_files, force=force)
      older_than = 6
      ignore_files = True
      backup_path = None
      backup_path_db = None
      backup_path_files = None
      backup_path_private_files = None
      backup_path_conf = None
      ignore_conf = False
      include_doctypes = ''
      exclude_doctypes = ''
      compress = False
      force = True
      verbose = True
      old_backup_metadata = False
      rollback_callback = <frappe.utils.CallbackManager object at 0x107f2bd90>
      odb = <frappe.utils.backups.BackupGenerator object at 0x107f45ad0>
  File "apps/frappe/frappe/utils/backups.py", line 195, in get_backup
    self.delete_if_step_fails(self.take_dump, self.backup_path_db)
      self = <frappe.utils.backups.BackupGenerator object at 0x107f45ad0>
      older_than = 6
      ignore_files = True
      force = True
      last_db = False
      last_file = False
      last_private_file = False
      site_config_backup_path = False
  File "apps/frappe/frappe/utils/backups.py", line 520, in delete_if_step_fails
    raise e
      self = <frappe.utils.backups.BackupGenerator object at 0x107f45ad0>
      step = <bound method BackupGenerator.take_dump of <frappe.utils.backups.BackupGenerator object at 0x107f45ad0>>
      paths = ('./site1.local/private/backups/20250504_120001-site1_local-database.sql.gz',)
      path = './site1.local/private/backups/20250504_120001-site1_local-database.sql.gz'
  File "apps/frappe/frappe/utils/backups.py", line 515, in delete_if_step_fails
    step()
      self = <frappe.utils.backups.BackupGenerator object at 0x107f45ad0>
      step = <bound method BackupGenerator.take_dump of <frappe.utils.backups.BackupGenerator object at 0x107f45ad0>>
      paths = ('./site1.local/private/backups/20250504_120001-site1_local-database.sql.gz',)
      path = './site1.local/private/backups/20250504_120001-site1_local-database.sql.gz'
  File "apps/frappe/frappe/utils/backups.py", line 457, in take_dump
    frappe.throw(
      self = <frappe.utils.backups.BackupGenerator object at 0x107f45ad0>
      shlex = <module 'shlex' from '/Users/upforcetech/.pyenv/versions/3.11.8/lib/python3.11/shlex.py'>
      frappe = <module 'frappe' from 'apps/frappe/frappe/__init__.py'>
      get_app_branch = <function get_app_branch at 0x107ba8360>
      gzip_exc = '/usr/bin/gzip'
      database_header_content = ['begin frappe metadata', '[frappe]', 'version = 15.67.0', 'branch = version-15', 'end frappe metadata', '']
      generated_header = '-- begin frappe metadata\n-- [frappe]\n-- version = 15.67.0\n-- branch = version-15\n-- end frappe metadata\n-- \n'
      f = <_io.TextIOWrapper name='./site1.local/private/backups/20250504_120001-site1_local-database.sql.gz' encoding='UTF-8'>
      cmd = []
      extra = []
      get_command = <function get_command at 0x1079a2520>
      bin = None
      args = ['--user=_229972456c5e818c', '--host=127.0.0.1', '--port=3306', '--password=LZkj4nvLsCF0qQK4', '--single-transaction', '--quick', '--lock-tables=false', '_229972456c5e818c']
      bin_name = 'mariadb-dump'
  File "apps/frappe/frappe/__init__.py", line 609, in throw
    msgprint(
      msg = 'mariadb-dump not found in PATH! This is required to take a backup.'
      exc = <class 'frappe.exceptions.ExecutableNotFound'>
      title = None
      is_minimizable = False
      wide = False
      as_list = False
      primary_action = None
  File "apps/frappe/frappe/__init__.py", line 574, in msgprint
    _raise_exception()
      msg = 'mariadb-dump not found in PATH! This is required to take a backup.'
      title = None
      raise_exception = <class 'frappe.exceptions.ExecutableNotFound'>
      as_table = False
      as_list = False
      indicator = 'red'
      alert = False
      primary_action = None
      is_minimizable = False
      wide = False
      realtime = False
      sys = <module 'sys' (built-in)>
      _raise_exception = <function msgprint.<locals>._raise_exception at 0x105dbd1c0>
      inspect = <module 'inspect' from '/Users/upforcetech/.pyenv/versions/3.11.8/lib/python3.11/inspect.py'>
      out = {'message': 'mariadb-dump not found in PATH! This is required to take a backup.', 'title': 'Message', 'indicator': 'red', 'raise_exception': 1, '__frappe_exc_id': '4c5403952ab5e3a984f6df6fad74fa8dd52749f04f9e7e7c27668556'}
  File "apps/frappe/frappe/__init__.py", line 525, in _raise_exception
    raise exc
      exc = ExecutableNotFound('mariadb-dump not found in PATH! This is required to take a backup.')
      inspect = <module 'inspect' from '/Users/upforcetech/.pyenv/versions/3.11.8/lib/python3.11/inspect.py'>
      msg = 'mariadb-dump not found in PATH! This is required to take a backup.'
      out = {'message': 'mariadb-dump not found in PATH! This is required to take a backup.', 'title': 'Message', 'indicator': 'red', 'raise_exception': 1, '__frappe_exc_id': '4c5403952ab5e3a984f6df6fad74fa8dd52749f04f9e7e7c27668556'}
      raise_exception = <class 'frappe.exceptions.ExecutableNotFound'>
frappe.exceptions.ExecutableNotFound: mariadb-dump not found in PATH! This is required to take a backup.
/bin/sh: /Users/upforcetech/Desktop/Frappe/venv/bin/bench: No such file or directory
Backup failed for Site site1.local. Database or site_config.json may be corrupted
Traceback with variables (most recent call last):
  File "apps/frappe/frappe/commands/site.py", line 843, in backup
    odb = scheduled_backup(
      context = {'sites': ['site1.local'], 'force': False, 'verbose': True, 'profile': False}
      with_files = False
      backup_path = None
      backup_path_db = None
      backup_path_files = None
      backup_path_private_files = None
      backup_path_conf = None
      ignore_backup_conf = False
      verbose = True
      compress = False
      include = ''
      exclude = ''
      old_backup_metadata = False
      scheduled_backup = <function scheduled_backup at 0x108080cc0>
      exit_code = 0
      rollback_callback = None
      site = 'site1.local'
  File "apps/frappe/frappe/utils/backups.py", line 568, in scheduled_backup
    return new_backup(
      older_than = 6
      ignore_files = True
      backup_path = None
      backup_path_db = None
      backup_path_files = None
      backup_path_private_files = None
      backup_path_conf = None
      ignore_conf = False
      include_doctypes = ''
      exclude_doctypes = ''
      compress = False
      force = True
      verbose = True
      old_backup_metadata = False
      rollback_callback = <frappe.utils.CallbackManager object at 0x1082dbee0>
  File "apps/frappe/frappe/utils/backups.py", line 626, in new_backup
    odb.get_backup(older_than, ignore_files, force=force)
      older_than = 6
      ignore_files = True
      backup_path = None
      backup_path_db = None
      backup_path_files = None
      backup_path_private_files = None
      backup_path_conf = None
      ignore_conf = False
      include_doctypes = ''
      exclude_doctypes = ''
      compress = False
      force = True
      verbose = True
      old_backup_metadata = False
      rollback_callback = <frappe.utils.CallbackManager object at 0x1082dbee0>
      odb = <frappe.utils.backups.BackupGenerator object at 0x1080f1050>
  File "apps/frappe/frappe/utils/backups.py", line 195, in get_backup
    self.delete_if_step_fails(self.take_dump, self.backup_path_db)
      self = <frappe.utils.backups.BackupGenerator object at 0x1080f1050>
      older_than = 6
      ignore_files = True
      force = True
      last_db = False
      last_file = False
      last_private_file = False
      site_config_backup_path = False
  File "apps/frappe/frappe/utils/backups.py", line 520, in delete_if_step_fails
    raise e
      self = <frappe.utils.backups.BackupGenerator object at 0x1080f1050>
      step = <bound method BackupGenerator.take_dump of <frappe.utils.backups.BackupGenerator object at 0x1080f1050>>
      paths = ('./site1.local/private/backups/20250505_120002-site1_local-database.sql.gz',)
      path = './site1.local/private/backups/20250505_120002-site1_local-database.sql.gz'
  File "apps/frappe/frappe/utils/backups.py", line 515, in delete_if_step_fails
    step()
      self = <frappe.utils.backups.BackupGenerator object at 0x1080f1050>
      step = <bound method BackupGenerator.take_dump of <frappe.utils.backups.BackupGenerator object at 0x1080f1050>>
      paths = ('./site1.local/private/backups/20250505_120002-site1_local-database.sql.gz',)
      path = './site1.local/private/backups/20250505_120002-site1_local-database.sql.gz'
  File "apps/frappe/frappe/utils/backups.py", line 457, in take_dump
    frappe.throw(
      self = <frappe.utils.backups.BackupGenerator object at 0x1080f1050>
      shlex = <module 'shlex' from '/Users/upforcetech/.pyenv/versions/3.11.8/lib/python3.11/shlex.py'>
      frappe = <module 'frappe' from 'apps/frappe/frappe/__init__.py'>
      get_app_branch = <function get_app_branch at 0x107f58360>
      gzip_exc = '/usr/bin/gzip'
      database_header_content = ['begin frappe metadata', '[frappe]', 'version = 15.67.0', 'branch = version-15', 'end frappe metadata', '']
      generated_header = '-- begin frappe metadata\n-- [frappe]\n-- version = 15.67.0\n-- branch = version-15\n-- end frappe metadata\n-- \n'
      f = <_io.TextIOWrapper name='./site1.local/private/backups/20250505_120002-site1_local-database.sql.gz' encoding='UTF-8'>
      cmd = []
      extra = []
      get_command = <function get_command at 0x107d52520>
      bin = None
      args = ['--user=_229972456c5e818c', '--host=127.0.0.1', '--port=3306', '--password=LZkj4nvLsCF0qQK4', '--single-transaction', '--quick', '--lock-tables=false', '_229972456c5e818c']
      bin_name = 'mariadb-dump'
  File "apps/frappe/frappe/__init__.py", line 609, in throw
    msgprint(
      msg = 'mariadb-dump not found in PATH! This is required to take a backup.'
      exc = <class 'frappe.exceptions.ExecutableNotFound'>
      title = None
      is_minimizable = False
      wide = False
      as_list = False
      primary_action = None
  File "apps/frappe/frappe/__init__.py", line 574, in msgprint
    _raise_exception()
      msg = 'mariadb-dump not found in PATH! This is required to take a backup.'
      title = None
      raise_exception = <class 'frappe.exceptions.ExecutableNotFound'>
      as_table = False
      as_list = False
      indicator = 'red'
      alert = False
      primary_action = None
      is_minimizable = False
      wide = False
      realtime = False
      sys = <module 'sys' (built-in)>
      _raise_exception = <function msgprint.<locals>._raise_exception at 0x10616d1c0>
      inspect = <module 'inspect' from '/Users/upforcetech/.pyenv/versions/3.11.8/lib/python3.11/inspect.py'>
      out = {'message': 'mariadb-dump not found in PATH! This is required to take a backup.', 'title': 'Message', 'indicator': 'red', 'raise_exception': 1, '__frappe_exc_id': '8967aca285fcc838a836b6743db5096637bba55d6b8c5f96e81fae79'}
  File "apps/frappe/frappe/__init__.py", line 525, in _raise_exception
    raise exc
      exc = ExecutableNotFound('mariadb-dump not found in PATH! This is required to take a backup.')
      inspect = <module 'inspect' from '/Users/upforcetech/.pyenv/versions/3.11.8/lib/python3.11/inspect.py'>
      msg = 'mariadb-dump not found in PATH! This is required to take a backup.'
      out = {'message': 'mariadb-dump not found in PATH! This is required to take a backup.', 'title': 'Message', 'indicator': 'red', 'raise_exception': 1, '__frappe_exc_id': '8967aca285fcc838a836b6743db5096637bba55d6b8c5f96e81fae79'}
      raise_exception = <class 'frappe.exceptions.ExecutableNotFound'>
frappe.exceptions.ExecutableNotFound: mariadb-dump not found in PATH! This is required to take a backup.
/bin/sh: /Users/upforcetech/Desktop/Frappe/venv/bin/bench: No such file or directory
Backup failed for Site site1.local. Database or site_config.json may be corrupted
Traceback with variables (most recent call last):
  File "apps/frappe/frappe/commands/site.py", line 843, in backup
    odb = scheduled_backup(
      context = {'sites': ['site1.local'], 'force': False, 'verbose': True, 'profile': False}
      with_files = False
      backup_path = None
      backup_path_db = None
      backup_path_files = None
      backup_path_private_files = None
      backup_path_conf = None
      ignore_backup_conf = False
      verbose = True
      compress = False
      include = ''
      exclude = ''
      old_backup_metadata = False
      scheduled_backup = <function scheduled_backup at 0x105d7ccc0>
      exit_code = 0
      rollback_callback = None
      site = 'site1.local'
  File "apps/frappe/frappe/utils/backups.py", line 568, in scheduled_backup
    return new_backup(
      older_than = 6
      ignore_files = True
      backup_path = None
      backup_path_db = None
      backup_path_files = None
      backup_path_private_files = None
      backup_path_conf = None
      ignore_conf = False
      include_doctypes = ''
      exclude_doctypes = ''
      compress = False
      force = True
      verbose = True
      old_backup_metadata = False
      rollback_callback = <frappe.utils.CallbackManager object at 0x105f82710>
  File "apps/frappe/frappe/utils/backups.py", line 626, in new_backup
    odb.get_backup(older_than, ignore_files, force=force)
      older_than = 6
      ignore_files = True
      backup_path = None
      backup_path_db = None
      backup_path_files = None
      backup_path_private_files = None
      backup_path_conf = None
      ignore_conf = False
      include_doctypes = ''
      exclude_doctypes = ''
      compress = False
      force = True
      verbose = True
      old_backup_metadata = False
      rollback_callback = <frappe.utils.CallbackManager object at 0x105f82710>
      odb = <frappe.utils.backups.BackupGenerator object at 0x105db74d0>
  File "apps/frappe/frappe/utils/backups.py", line 195, in get_backup
    self.delete_if_step_fails(self.take_dump, self.backup_path_db)
      self = <frappe.utils.backups.BackupGenerator object at 0x105db74d0>
      older_than = 6
      ignore_files = True
      force = True
      last_db = False
      last_file = False
      last_private_file = False
      site_config_backup_path = False
  File "apps/frappe/frappe/utils/backups.py", line 520, in delete_if_step_fails
    raise e
      self = <frappe.utils.backups.BackupGenerator object at 0x105db74d0>
      step = <bound method BackupGenerator.take_dump of <frappe.utils.backups.BackupGenerator object at 0x105db74d0>>
      paths = ('./site1.local/private/backups/20250505_180002-site1_local-database.sql.gz',)
      path = './site1.local/private/backups/20250505_180002-site1_local-database.sql.gz'
  File "apps/frappe/frappe/utils/backups.py", line 515, in delete_if_step_fails
    step()
      self = <frappe.utils.backups.BackupGenerator object at 0x105db74d0>
      step = <bound method BackupGenerator.take_dump of <frappe.utils.backups.BackupGenerator object at 0x105db74d0>>
      paths = ('./site1.local/private/backups/20250505_180002-site1_local-database.sql.gz',)
      path = './site1.local/private/backups/20250505_180002-site1_local-database.sql.gz'
  File "apps/frappe/frappe/utils/backups.py", line 457, in take_dump
    frappe.throw(
      self = <frappe.utils.backups.BackupGenerator object at 0x105db74d0>
      shlex = <module 'shlex' from '/Users/upforcetech/.pyenv/versions/3.11.8/lib/python3.11/shlex.py'>
      frappe = <module 'frappe' from 'apps/frappe/frappe/__init__.py'>
      get_app_branch = <function get_app_branch at 0x105b54360>
      gzip_exc = '/usr/bin/gzip'
      database_header_content = ['begin frappe metadata', '[frappe]', 'version = 15.67.0', 'branch = version-15', 'end frappe metadata', '']
      generated_header = '-- begin frappe metadata\n-- [frappe]\n-- version = 15.67.0\n-- branch = version-15\n-- end frappe metadata\n-- \n'
      f = <_io.TextIOWrapper name='./site1.local/private/backups/20250505_180002-site1_local-database.sql.gz' encoding='UTF-8'>
      cmd = []
      extra = []
      get_command = <function get_command at 0x10594e520>
      bin = None
      args = ['--user=_229972456c5e818c', '--host=127.0.0.1', '--port=3306', '--password=LZkj4nvLsCF0qQK4', '--single-transaction', '--quick', '--lock-tables=false', '_229972456c5e818c']
      bin_name = 'mariadb-dump'
  File "apps/frappe/frappe/__init__.py", line 609, in throw
    msgprint(
      msg = 'mariadb-dump not found in PATH! This is required to take a backup.'
      exc = <class 'frappe.exceptions.ExecutableNotFound'>
      title = None
      is_minimizable = False
      wide = False
      as_list = False
      primary_action = None
  File "apps/frappe/frappe/__init__.py", line 574, in msgprint
    _raise_exception()
      msg = 'mariadb-dump not found in PATH! This is required to take a backup.'
      title = None
      raise_exception = <class 'frappe.exceptions.ExecutableNotFound'>
      as_table = False
      as_list = False
      indicator = 'red'
      alert = False
      primary_action = None
      is_minimizable = False
      wide = False
      realtime = False
      sys = <module 'sys' (built-in)>
      _raise_exception = <function msgprint.<locals>._raise_exception at 0x10630ccc0>
      inspect = <module 'inspect' from '/Users/upforcetech/.pyenv/versions/3.11.8/lib/python3.11/inspect.py'>
      out = {'message': 'mariadb-dump not found in PATH! This is required to take a backup.', 'title': 'Message', 'indicator': 'red', 'raise_exception': 1, '__frappe_exc_id': 'cc511b6eb2fd64811e62774e22dfb132d3d1792d6ed8aa46b43ad4d4'}
  File "apps/frappe/frappe/__init__.py", line 525, in _raise_exception
    raise exc
      exc = ExecutableNotFound('mariadb-dump not found in PATH! This is required to take a backup.')
      inspect = <module 'inspect' from '/Users/upforcetech/.pyenv/versions/3.11.8/lib/python3.11/inspect.py'>
      msg = 'mariadb-dump not found in PATH! This is required to take a backup.'
      out = {'message': 'mariadb-dump not found in PATH! This is required to take a backup.', 'title': 'Message', 'indicator': 'red', 'raise_exception': 1, '__frappe_exc_id': 'cc511b6eb2fd64811e62774e22dfb132d3d1792d6ed8aa46b43ad4d4'}
      raise_exception = <class 'frappe.exceptions.ExecutableNotFound'>
frappe.exceptions.ExecutableNotFound: mariadb-dump not found in PATH! This is required to take a backup.
/bin/sh: /Users/upforcetech/Desktop/Frappe/venv/bin/bench: No such file or directory
Backup failed for Site site1.local. Database or site_config.json may be corrupted
Traceback with variables (most recent call last):
  File "apps/frappe/frappe/commands/site.py", line 843, in backup
    odb = scheduled_backup(
      context = {'sites': ['site1.local'], 'force': False, 'verbose': True, 'profile': False}
      with_files = False
      backup_path = None
      backup_path_db = None
      backup_path_files = None
      backup_path_private_files = None
      backup_path_conf = None
      ignore_backup_conf = False
      verbose = True
      compress = False
      include = ''
      exclude = ''
      old_backup_metadata = False
      scheduled_backup = <function scheduled_backup at 0x105cd8cc0>
      exit_code = 0
      rollback_callback = None
      site = 'site1.local'
  File "apps/frappe/frappe/utils/backups.py", line 568, in scheduled_backup
    return new_backup(
      older_than = 6
      ignore_files = True
      backup_path = None
      backup_path_db = None
      backup_path_files = None
      backup_path_private_files = None
      backup_path_conf = None
      ignore_conf = False
      include_doctypes = ''
      exclude_doctypes = ''
      compress = False
      force = True
      verbose = True
      old_backup_metadata = False
      rollback_callback = <frappe.utils.CallbackManager object at 0x105f74340>
  File "apps/frappe/frappe/utils/backups.py", line 626, in new_backup
    odb.get_backup(older_than, ignore_files, force=force)
      older_than = 6
      ignore_files = True
      backup_path = None
      backup_path_db = None
      backup_path_files = None
      backup_path_private_files = None
      backup_path_conf = None
      ignore_conf = False
      include_doctypes = ''
      exclude_doctypes = ''
      compress = False
      force = True
      verbose = True
      old_backup_metadata = False
      rollback_callback = <frappe.utils.CallbackManager object at 0x105f74340>
      odb = <frappe.utils.backups.BackupGenerator object at 0x105f4d7d0>
  File "apps/frappe/frappe/utils/backups.py", line 195, in get_backup
    self.delete_if_step_fails(self.take_dump, self.backup_path_db)
      self = <frappe.utils.backups.BackupGenerator object at 0x105f4d7d0>
      older_than = 6
      ignore_files = True
      force = True
      last_db = False
      last_file = False
      last_private_file = False
      site_config_backup_path = False
  File "apps/frappe/frappe/utils/backups.py", line 520, in delete_if_step_fails
    raise e
      self = <frappe.utils.backups.BackupGenerator object at 0x105f4d7d0>
      step = <bound method BackupGenerator.take_dump of <frappe.utils.backups.BackupGenerator object at 0x105f4d7d0>>
      paths = ('./site1.local/private/backups/20250506_120002-site1_local-database.sql.gz',)
      path = './site1.local/private/backups/20250506_120002-site1_local-database.sql.gz'
  File "apps/frappe/frappe/utils/backups.py", line 515, in delete_if_step_fails
    step()
      self = <frappe.utils.backups.BackupGenerator object at 0x105f4d7d0>
      step = <bound method BackupGenerator.take_dump of <frappe.utils.backups.BackupGenerator object at 0x105f4d7d0>>
      paths = ('./site1.local/private/backups/20250506_120002-site1_local-database.sql.gz',)
      path = './site1.local/private/backups/20250506_120002-site1_local-database.sql.gz'
  File "apps/frappe/frappe/utils/backups.py", line 457, in take_dump
    frappe.throw(
      self = <frappe.utils.backups.BackupGenerator object at 0x105f4d7d0>
      shlex = <module 'shlex' from '/Users/upforcetech/.pyenv/versions/3.11.8/lib/python3.11/shlex.py'>
      frappe = <module 'frappe' from 'apps/frappe/frappe/__init__.py'>
      get_app_branch = <function get_app_branch at 0x105bb0360>
      gzip_exc = '/usr/bin/gzip'
      database_header_content = ['begin frappe metadata', '[frappe]', 'version = 15.67.0', 'branch = version-15', 'end frappe metadata', '']
      generated_header = '-- begin frappe metadata\n-- [frappe]\n-- version = 15.67.0\n-- branch = version-15\n-- end frappe metadata\n-- \n'
      f = <_io.TextIOWrapper name='./site1.local/private/backups/20250506_120002-site1_local-database.sql.gz' encoding='UTF-8'>
      cmd = []
      extra = []
      get_command = <function get_command at 0x1059aa520>
      bin = None
      args = ['--user=_229972456c5e818c', '--host=127.0.0.1', '--port=3306', '--password=LZkj4nvLsCF0qQK4', '--single-transaction', '--quick', '--lock-tables=false', '_229972456c5e818c']
      bin_name = 'mariadb-dump'
  File "apps/frappe/frappe/__init__.py", line 609, in throw
    msgprint(
      msg = 'mariadb-dump not found in PATH! This is required to take a backup.'
      exc = <class 'frappe.exceptions.ExecutableNotFound'>
      title = None
      is_minimizable = False
      wide = False
      as_list = False
      primary_action = None
  File "apps/frappe/frappe/__init__.py", line 574, in msgprint
    _raise_exception()
      msg = 'mariadb-dump not found in PATH! This is required to take a backup.'
      title = None
      raise_exception = <class 'frappe.exceptions.ExecutableNotFound'>
      as_table = False
      as_list = False
      indicator = 'red'
      alert = False
      primary_action = None
      is_minimizable = False
      wide = False
      realtime = False
      sys = <module 'sys' (built-in)>
      _raise_exception = <function msgprint.<locals>._raise_exception at 0x1062d4cc0>
      inspect = <module 'inspect' from '/Users/upforcetech/.pyenv/versions/3.11.8/lib/python3.11/inspect.py'>
      out = {'message': 'mariadb-dump not found in PATH! This is required to take a backup.', 'title': 'Message', 'indicator': 'red', 'raise_exception': 1, '__frappe_exc_id': '0af97f86d70f068a94d4db19c5899060fb11c2c5a16128f2c0589d00'}
  File "apps/frappe/frappe/__init__.py", line 525, in _raise_exception
    raise exc
      exc = ExecutableNotFound('mariadb-dump not found in PATH! This is required to take a backup.')
      inspect = <module 'inspect' from '/Users/upforcetech/.pyenv/versions/3.11.8/lib/python3.11/inspect.py'>
      msg = 'mariadb-dump not found in PATH! This is required to take a backup.'
      out = {'message': 'mariadb-dump not found in PATH! This is required to take a backup.', 'title': 'Message', 'indicator': 'red', 'raise_exception': 1, '__frappe_exc_id': '0af97f86d70f068a94d4db19c5899060fb11c2c5a16128f2c0589d00'}
      raise_exception = <class 'frappe.exceptions.ExecutableNotFound'>
frappe.exceptions.ExecutableNotFound: mariadb-dump not found in PATH! This is required to take a backup.
/bin/sh: /Users/upforcetech/Desktop/Frappe/venv/bin/bench: No such file or directory
Backup failed for Site site1.local. Database or site_config.json may be corrupted
Traceback with variables (most recent call last):
  File "apps/frappe/frappe/commands/site.py", line 843, in backup
    odb = scheduled_backup(
      context = {'sites': ['site1.local'], 'force': False, 'verbose': True, 'profile': False}
      with_files = False
      backup_path = None
      backup_path_db = None
      backup_path_files = None
      backup_path_private_files = None
      backup_path_conf = None
      ignore_backup_conf = False
      verbose = True
      compress = False
      include = ''
      exclude = ''
      old_backup_metadata = False
      scheduled_backup = <function scheduled_backup at 0x105990cc0>
      exit_code = 0
      rollback_callback = None
      site = 'site1.local'
  File "apps/frappe/frappe/utils/backups.py", line 568, in scheduled_backup
    return new_backup(
      older_than = 6
      ignore_files = True
      backup_path = None
      backup_path_db = None
      backup_path_files = None
      backup_path_private_files = None
      backup_path_conf = None
      ignore_conf = False
      include_doctypes = ''
      exclude_doctypes = ''
      compress = False
      force = True
      verbose = True
      old_backup_metadata = False
      rollback_callback = <frappe.utils.CallbackManager object at 0x105c30280>
  File "apps/frappe/frappe/utils/backups.py", line 626, in new_backup
    odb.get_backup(older_than, ignore_files, force=force)
      older_than = 6
      ignore_files = True
      backup_path = None
      backup_path_db = None
      backup_path_files = None
      backup_path_private_files = None
      backup_path_conf = None
      ignore_conf = False
      include_doctypes = ''
      exclude_doctypes = ''
      compress = False
      force = True
      verbose = True
      old_backup_metadata = False
      rollback_callback = <frappe.utils.CallbackManager object at 0x105c30280>
      odb = <frappe.utils.backups.BackupGenerator object at 0x105c05dd0>
  File "apps/frappe/frappe/utils/backups.py", line 195, in get_backup
    self.delete_if_step_fails(self.take_dump, self.backup_path_db)
      self = <frappe.utils.backups.BackupGenerator object at 0x105c05dd0>
      older_than = 6
      ignore_files = True
      force = True
      last_db = False
      last_file = False
      last_private_file = False
      site_config_backup_path = False
  File "apps/frappe/frappe/utils/backups.py", line 520, in delete_if_step_fails
    raise e
      self = <frappe.utils.backups.BackupGenerator object at 0x105c05dd0>
      step = <bound method BackupGenerator.take_dump of <frappe.utils.backups.BackupGenerator object at 0x105c05dd0>>
      paths = ('./site1.local/private/backups/20250506_180002-site1_local-database.sql.gz',)
      path = './site1.local/private/backups/20250506_180002-site1_local-database.sql.gz'
  File "apps/frappe/frappe/utils/backups.py", line 515, in delete_if_step_fails
    step()
      self = <frappe.utils.backups.BackupGenerator object at 0x105c05dd0>
      step = <bound method BackupGenerator.take_dump of <frappe.utils.backups.BackupGenerator object at 0x105c05dd0>>
      paths = ('./site1.local/private/backups/20250506_180002-site1_local-database.sql.gz',)
      path = './site1.local/private/backups/20250506_180002-site1_local-database.sql.gz'
  File "apps/frappe/frappe/utils/backups.py", line 457, in take_dump
    frappe.throw(
      self = <frappe.utils.backups.BackupGenerator object at 0x105c05dd0>
      shlex = <module 'shlex' from '/Users/upforcetech/.pyenv/versions/3.11.8/lib/python3.11/shlex.py'>
      frappe = <module 'frappe' from 'apps/frappe/frappe/__init__.py'>
      get_app_branch = <function get_app_branch at 0x105868360>
      gzip_exc = '/usr/bin/gzip'
      database_header_content = ['begin frappe metadata', '[frappe]', 'version = 15.67.0', 'branch = version-15', 'end frappe metadata', '']
      generated_header = '-- begin frappe metadata\n-- [frappe]\n-- version = 15.67.0\n-- branch = version-15\n-- end frappe metadata\n-- \n'
      f = <_io.TextIOWrapper name='./site1.local/private/backups/20250506_180002-site1_local-database.sql.gz' encoding='UTF-8'>
      cmd = []
      extra = []
      get_command = <function get_command at 0x105662520>
      bin = None
      args = ['--user=_229972456c5e818c', '--host=127.0.0.1', '--port=3306', '--password=LZkj4nvLsCF0qQK4', '--single-transaction', '--quick', '--lock-tables=false', '_229972456c5e818c']
      bin_name = 'mariadb-dump'
  File "apps/frappe/frappe/__init__.py", line 609, in throw
    msgprint(
      msg = 'mariadb-dump not found in PATH! This is required to take a backup.'
      exc = <class 'frappe.exceptions.ExecutableNotFound'>
      title = None
      is_minimizable = False
      wide = False
      as_list = False
      primary_action = None
  File "apps/frappe/frappe/__init__.py", line 574, in msgprint
    _raise_exception()
      msg = 'mariadb-dump not found in PATH! This is required to take a backup.'
      title = None
      raise_exception = <class 'frappe.exceptions.ExecutableNotFound'>
      as_table = False
      as_list = False
      indicator = 'red'
      alert = False
      primary_action = None
      is_minimizable = False
      wide = False
      realtime = False
      sys = <module 'sys' (built-in)>
      _raise_exception = <function msgprint.<locals>._raise_exception at 0x105f8ccc0>
      inspect = <module 'inspect' from '/Users/upforcetech/.pyenv/versions/3.11.8/lib/python3.11/inspect.py'>
      out = {'message': 'mariadb-dump not found in PATH! This is required to take a backup.', 'title': 'Message', 'indicator': 'red', 'raise_exception': 1, '__frappe_exc_id': '4d7c187707bb77f3faa5593e8ff80a7878538c49e886549e3c533e4b'}
  File "apps/frappe/frappe/__init__.py", line 525, in _raise_exception
    raise exc
      exc = ExecutableNotFound('mariadb-dump not found in PATH! This is required to take a backup.')
      inspect = <module 'inspect' from '/Users/upforcetech/.pyenv/versions/3.11.8/lib/python3.11/inspect.py'>
      msg = 'mariadb-dump not found in PATH! This is required to take a backup.'
      out = {'message': 'mariadb-dump not found in PATH! This is required to take a backup.', 'title': 'Message', 'indicator': 'red', 'raise_exception': 1, '__frappe_exc_id': '4d7c187707bb77f3faa5593e8ff80a7878538c49e886549e3c533e4b'}
      raise_exception = <class 'frappe.exceptions.ExecutableNotFound'>
frappe.exceptions.ExecutableNotFound: mariadb-dump not found in PATH! This is required to take a backup.
/bin/sh: /Users/upforcetech/Desktop/Frappe/venv/bin/bench: No such file or directory
Backup failed for Site site1.local. Database or site_config.json may be corrupted
Traceback with variables (most recent call last):
  File "apps/frappe/frappe/commands/site.py", line 843, in backup
    odb = scheduled_backup(
      context = {'sites': ['site1.local'], 'force': False, 'verbose': True, 'profile': False}
      with_files = False
      backup_path = None
      backup_path_db = None
      backup_path_files = None
      backup_path_private_files = None
      backup_path_conf = None
      ignore_backup_conf = False
      verbose = True
      compress = False
      include = ''
      exclude = ''
      old_backup_metadata = False
      scheduled_backup = <function scheduled_backup at 0x107c7ccc0>
      exit_code = 0
      rollback_callback = None
      site = 'site1.local'
  File "apps/frappe/frappe/utils/backups.py", line 568, in scheduled_backup
    return new_backup(
      older_than = 6
      ignore_files = True
      backup_path = None
      backup_path_db = None
      backup_path_files = None
      backup_path_private_files = None
      backup_path_conf = None
      ignore_conf = False
      include_doctypes = ''
      exclude_doctypes = ''
      compress = False
      force = True
      verbose = True
      old_backup_metadata = False
      rollback_callback = <frappe.utils.CallbackManager object at 0x107ea85e0>
  File "apps/frappe/frappe/utils/backups.py", line 626, in new_backup
    odb.get_backup(older_than, ignore_files, force=force)
      older_than = 6
      ignore_files = True
      backup_path = None
      backup_path_db = None
      backup_path_files = None
      backup_path_private_files = None
      backup_path_conf = None
      ignore_conf = False
      include_doctypes = ''
      exclude_doctypes = ''
      compress = False
      force = True
      verbose = True
      old_backup_metadata = False
      rollback_callback = <frappe.utils.CallbackManager object at 0x107ea85e0>
      odb = <frappe.utils.backups.BackupGenerator object at 0x107e85090>
  File "apps/frappe/frappe/utils/backups.py", line 195, in get_backup
    self.delete_if_step_fails(self.take_dump, self.backup_path_db)
      self = <frappe.utils.backups.BackupGenerator object at 0x107e85090>
      older_than = 6
      ignore_files = True
      force = True
      last_db = False
      last_file = False
      last_private_file = False
      site_config_backup_path = False
  File "apps/frappe/frappe/utils/backups.py", line 520, in delete_if_step_fails
    raise e
      self = <frappe.utils.backups.BackupGenerator object at 0x107e85090>
      step = <bound method BackupGenerator.take_dump of <frappe.utils.backups.BackupGenerator object at 0x107e85090>>
      paths = ('./site1.local/private/backups/20250507_120002-site1_local-database.sql.gz',)
      path = './site1.local/private/backups/20250507_120002-site1_local-database.sql.gz'
  File "apps/frappe/frappe/utils/backups.py", line 515, in delete_if_step_fails
    step()
      self = <frappe.utils.backups.BackupGenerator object at 0x107e85090>
      step = <bound method BackupGenerator.take_dump of <frappe.utils.backups.BackupGenerator object at 0x107e85090>>
      paths = ('./site1.local/private/backups/20250507_120002-site1_local-database.sql.gz',)
      path = './site1.local/private/backups/20250507_120002-site1_local-database.sql.gz'
  File "apps/frappe/frappe/utils/backups.py", line 457, in take_dump
    frappe.throw(
      self = <frappe.utils.backups.BackupGenerator object at 0x107e85090>
      shlex = <module 'shlex' from '/Users/upforcetech/.pyenv/versions/3.11.8/lib/python3.11/shlex.py'>
      frappe = <module 'frappe' from 'apps/frappe/frappe/__init__.py'>
      get_app_branch = <function get_app_branch at 0x107a54360>
      gzip_exc = '/usr/bin/gzip'
      database_header_content = ['begin frappe metadata', '[frappe]', 'version = 15.67.0', 'branch = version-15', 'end frappe metadata', '']
      generated_header = '-- begin frappe metadata\n-- [frappe]\n-- version = 15.67.0\n-- branch = version-15\n-- end frappe metadata\n-- \n'
      f = <_io.TextIOWrapper name='./site1.local/private/backups/20250507_120002-site1_local-database.sql.gz' encoding='UTF-8'>
      cmd = []
      extra = []
      get_command = <function get_command at 0x10784e520>
      bin = None
      args = ['--user=_229972456c5e818c', '--host=127.0.0.1', '--port=3306', '--password=LZkj4nvLsCF0qQK4', '--single-transaction', '--quick', '--lock-tables=false', '_229972456c5e818c']
      bin_name = 'mariadb-dump'
  File "apps/frappe/frappe/__init__.py", line 609, in throw
    msgprint(
      msg = 'mariadb-dump not found in PATH! This is required to take a backup.'
      exc = <class 'frappe.exceptions.ExecutableNotFound'>
      title = None
      is_minimizable = False
      wide = False
      as_list = False
      primary_action = None
  File "apps/frappe/frappe/__init__.py", line 574, in msgprint
    _raise_exception()
      msg = 'mariadb-dump not found in PATH! This is required to take a backup.'
      title = None
      raise_exception = <class 'frappe.exceptions.ExecutableNotFound'>
      as_table = False
      as_list = False
      indicator = 'red'
      alert = False
      primary_action = None
      is_minimizable = False
      wide = False
      realtime = False
      sys = <module 'sys' (built-in)>
      _raise_exception = <function msgprint.<locals>._raise_exception at 0x11030ccc0>
      inspect = <module 'inspect' from '/Users/upforcetech/.pyenv/versions/3.11.8/lib/python3.11/inspect.py'>
      out = {'message': 'mariadb-dump not found in PATH! This is required to take a backup.', 'title': 'Message', 'indicator': 'red', 'raise_exception': 1, '__frappe_exc_id': '74c4884ad59e96b69a80643b0ed420a97b7f15f29547642e38af0e81'}
  File "apps/frappe/frappe/__init__.py", line 525, in _raise_exception
    raise exc
      exc = ExecutableNotFound('mariadb-dump not found in PATH! This is required to take a backup.')
      inspect = <module 'inspect' from '/Users/upforcetech/.pyenv/versions/3.11.8/lib/python3.11/inspect.py'>
      msg = 'mariadb-dump not found in PATH! This is required to take a backup.'
      out = {'message': 'mariadb-dump not found in PATH! This is required to take a backup.', 'title': 'Message', 'indicator': 'red', 'raise_exception': 1, '__frappe_exc_id': '74c4884ad59e96b69a80643b0ed420a97b7f15f29547642e38af0e81'}
      raise_exception = <class 'frappe.exceptions.ExecutableNotFound'>
frappe.exceptions.ExecutableNotFound: mariadb-dump not found in PATH! This is required to take a backup.
