/Users/upforcetech/Desktop/Frappe/frappe-bench/env/lib/python3.11/site-packages/passlib/utils/__init__.py:854: DeprecationWarning: 'crypt' is deprecated and slated for removal in Python 3.13
  from crypt import crypt as _crypt
2025-04-29 19:04:47,433 Could not connect to Redis instance: Connection closed by server. Retrying in 2 seconds...
/Users/upforcetech/Desktop/Frappe/frappe-bench/env/lib/python3.11/site-packages/passlib/utils/__init__.py:854: DeprecationWarning: 'crypt' is deprecated and slated for removal in Python 3.13
  from crypt import crypt as _crypt
/Users/upforcetech/Desktop/Frappe/frappe-bench/env/lib/python3.11/site-packages/passlib/utils/__init__.py:854: DeprecationWarning: 'crypt' is deprecated and slated for removal in Python 3.13
  from crypt import crypt as _crypt
Exception in thread Thread-1:
Traceback (most recent call last):
  File "/Users/upforcetech/.pyenv/versions/3.11.8/lib/python3.11/threading.py", line 1045, in _bootstrap_inner
    self.run()
  File "/Users/upforcetech/Desktop/Frappe/frappe-bench/env/lib/python3.11/site-packages/redis/client.py", line 1799, in run
    pubsub.get_message(ignore_subscribe_messages=True, timeout=sleep_time)
  File "/Users/upforcetech/Desktop/Frappe/frappe-bench/env/lib/python3.11/site-packages/redis/client.py", line 1690, in get_message
    response = self.parse_response(block=(timeout is None), timeout=timeout)
               ^^^^^^^^^^^^^^^^^^^^^^^^^^^^^^^^^^^^^^^^^^^^^^^^^^^^^^^^^^^^^
  File "/Users/upforcetech/Desktop/Frappe/frappe-bench/env/lib/python3.11/site-packages/redis/client.py", line 1542, in parse_response
    response = self._execute(conn, try_read)
               ^^^^^^^^^^^^^^^^^^^^^^^^^^^^^
  File "/Users/upforcetech/Desktop/Frappe/frappe-bench/env/lib/python3.11/site-packages/redis/client.py", line 1518, in _execute
    return conn.retry.call_with_retry(
           ^^^^^^^^^^^^^^^^^^^^^^^^^^^
  File "/Users/upforcetech/Desktop/Frappe/frappe-bench/env/lib/python3.11/site-packages/redis/retry.py", line 49, in call_with_retry
    fail(error)
  File "/Users/upforcetech/Desktop/Frappe/frappe-bench/env/lib/python3.11/site-packages/redis/client.py", line 1520, in <lambda>
    lambda error: self._disconnect_raise_connect(conn, error),
                  ^^^^^^^^^^^^^^^^^^^^^^^^^^^^^^^^^^^^^^^^^^^
  File "/Users/upforcetech/Desktop/Frappe/frappe-bench/env/lib/python3.11/site-packages/redis/client.py", line 1507, in _disconnect_raise_connect
    raise error
  File "/Users/upforcetech/Desktop/Frappe/frappe-bench/env/lib/python3.11/site-packages/redis/retry.py", line 46, in call_with_retry
    return do()
           ^^^^
  File "/Users/upforcetech/Desktop/Frappe/frappe-bench/env/lib/python3.11/site-packages/redis/client.py", line 1519, in <lambda>
    lambda: command(*args, **kwargs),
            ^^^^^^^^^^^^^^^^^^^^^^^^
  File "/Users/upforcetech/Desktop/Frappe/frappe-bench/env/lib/python3.11/site-packages/redis/client.py", line 1536, in try_read
    if not conn.can_read(timeout=timeout):
           ^^^^^^^^^^^^^^^^^^^^^^^^^^^^^^
  File "/Users/upforcetech/Desktop/Frappe/frappe-bench/env/lib/python3.11/site-packages/redis/connection.py", line 861, in can_read
    return self._parser.can_read(timeout)
           ^^^^^^^^^^^^^^^^^^^^^^^^^^^^^^
  File "/Users/upforcetech/Desktop/Frappe/frappe-bench/env/lib/python3.11/site-packages/redis/connection.py", line 444, in can_read
    return self.read_from_socket(timeout=timeout, raise_on_timeout=False)
           ^^^^^^^^^^^^^^^^^^^^^^^^^^^^^^^^^^^^^^^^^^^^^^^^^^^^^^^^^^^^^^
  File "/Users/upforcetech/Desktop/Frappe/frappe-bench/env/lib/python3.11/site-packages/redis/connection.py", line 455, in read_from_socket
    raise ConnectionError(SERVER_CLOSED_CONNECTION_ERROR)
redis.exceptions.ConnectionError: Connection closed by server.
Traceback (most recent call last):
  File "/Users/upforcetech/Desktop/Frappe/frappe-bench/env/lib/python3.11/site-packages/redis/connection.py", line 699, in connect
    sock = self.retry.call_with_retry(
           ^^^^^^^^^^^^^^^^^^^^^^^^^^^
  File "/Users/upforcetech/Desktop/Frappe/frappe-bench/env/lib/python3.11/site-packages/redis/retry.py", line 46, in call_with_retry
    return do()
           ^^^^
  File "/Users/upforcetech/Desktop/Frappe/frappe-bench/env/lib/python3.11/site-packages/redis/connection.py", line 700, in <lambda>
    lambda: self._connect(), lambda error: self.disconnect(error)
            ^^^^^^^^^^^^^^^
  File "/Users/upforcetech/Desktop/Frappe/frappe-bench/env/lib/python3.11/site-packages/redis/connection.py", line 1002, in _connect
    raise err
  File "/Users/upforcetech/Desktop/Frappe/frappe-bench/env/lib/python3.11/site-packages/redis/connection.py", line 990, in _connect
    sock.connect(socket_address)
ConnectionRefusedError: [Errno 61] Connection refused

During handling of the above exception, another exception occurred:

Traceback (most recent call last):
  File "<frozen runpy>", line 198, in _run_module_as_main
  File "<frozen runpy>", line 88, in _run_code
  File "/Users/upforcetech/Desktop/Frappe/frappe-bench/apps/frappe/frappe/utils/bench_helper.py", line 114, in <module>
    main()
  File "/Users/upforcetech/Desktop/Frappe/frappe-bench/apps/frappe/frappe/utils/bench_helper.py", line 20, in main
    click.Group(commands=commands)(prog_name="bench")
  File "/Users/upforcetech/Desktop/Frappe/frappe-bench/env/lib/python3.11/site-packages/click/core.py", line 1161, in __call__
    return self.main(*args, **kwargs)
           ^^^^^^^^^^^^^^^^^^^^^^^^^^
  File "/Users/upforcetech/Desktop/Frappe/frappe-bench/env/lib/python3.11/site-packages/click/core.py", line 1082, in main
    rv = self.invoke(ctx)
         ^^^^^^^^^^^^^^^^
  File "/Users/upforcetech/Desktop/Frappe/frappe-bench/env/lib/python3.11/site-packages/click/core.py", line 1697, in invoke
    return _process_result(sub_ctx.command.invoke(sub_ctx))
                           ^^^^^^^^^^^^^^^^^^^^^^^^^^^^^^^
  File "/Users/upforcetech/Desktop/Frappe/frappe-bench/env/lib/python3.11/site-packages/click/core.py", line 1697, in invoke
    return _process_result(sub_ctx.command.invoke(sub_ctx))
                           ^^^^^^^^^^^^^^^^^^^^^^^^^^^^^^^
  File "/Users/upforcetech/Desktop/Frappe/frappe-bench/env/lib/python3.11/site-packages/click/core.py", line 1443, in invoke
    return ctx.invoke(self.callback, **ctx.params)
           ^^^^^^^^^^^^^^^^^^^^^^^^^^^^^^^^^^^^^^^
  File "/Users/upforcetech/Desktop/Frappe/frappe-bench/env/lib/python3.11/site-packages/click/core.py", line 788, in invoke
    return __callback(*args, **kwargs)
           ^^^^^^^^^^^^^^^^^^^^^^^^^^^
  File "/Users/upforcetech/Desktop/Frappe/frappe-bench/apps/frappe/frappe/commands/scheduler.py", line 205, in start_worker
    start_worker(
  File "/Users/upforcetech/Desktop/Frappe/frappe-bench/apps/frappe/frappe/utils/background_jobs.py", line 318, in start_worker
    worker.work(
  File "/Users/upforcetech/Desktop/Frappe/frappe-bench/env/lib/python3.11/site-packages/rq/worker.py", line 456, in work
    self.teardown()
  File "/Users/upforcetech/Desktop/Frappe/frappe-bench/env/lib/python3.11/site-packages/rq/worker.py", line 1047, in teardown
    self.unsubscribe()
  File "/Users/upforcetech/Desktop/Frappe/frappe-bench/env/lib/python3.11/site-packages/rq/worker.py", line 624, in unsubscribe
    self.pubsub.unsubscribe()
  File "/Users/upforcetech/Desktop/Frappe/frappe-bench/env/lib/python3.11/site-packages/redis/client.py", line 1659, in unsubscribe
    return self.execute_command("UNSUBSCRIBE", *args)
           ^^^^^^^^^^^^^^^^^^^^^^^^^^^^^^^^^^^^^^^^^^
  File "/Users/upforcetech/Desktop/Frappe/frappe-bench/env/lib/python3.11/site-packages/redis/client.py", line 1479, in execute_command
    self._execute(connection, connection.send_command, *args, **kwargs)
  File "/Users/upforcetech/Desktop/Frappe/frappe-bench/env/lib/python3.11/site-packages/redis/client.py", line 1518, in _execute
    return conn.retry.call_with_retry(
           ^^^^^^^^^^^^^^^^^^^^^^^^^^^
  File "/Users/upforcetech/Desktop/Frappe/frappe-bench/env/lib/python3.11/site-packages/redis/retry.py", line 49, in call_with_retry
    fail(error)
  File "/Users/upforcetech/Desktop/Frappe/frappe-bench/env/lib/python3.11/site-packages/redis/client.py", line 1520, in <lambda>
    lambda error: self._disconnect_raise_connect(conn, error),
                  ^^^^^^^^^^^^^^^^^^^^^^^^^^^^^^^^^^^^^^^^^^^
  File "/Users/upforcetech/Desktop/Frappe/frappe-bench/env/lib/python3.11/site-packages/redis/client.py", line 1507, in _disconnect_raise_connect
    raise error
  File "/Users/upforcetech/Desktop/Frappe/frappe-bench/env/lib/python3.11/site-packages/redis/retry.py", line 46, in call_with_retry
    return do()
           ^^^^
  File "/Users/upforcetech/Desktop/Frappe/frappe-bench/env/lib/python3.11/site-packages/redis/client.py", line 1519, in <lambda>
    lambda: command(*args, **kwargs),
            ^^^^^^^^^^^^^^^^^^^^^^^^
  File "/Users/upforcetech/Desktop/Frappe/frappe-bench/env/lib/python3.11/site-packages/redis/connection.py", line 847, in send_command
    self.send_packed_command(
  File "/Users/upforcetech/Desktop/Frappe/frappe-bench/env/lib/python3.11/site-packages/redis/connection.py", line 817, in send_packed_command
    self.connect()
  File "/Users/upforcetech/Desktop/Frappe/frappe-bench/env/lib/python3.11/site-packages/redis/connection.py", line 705, in connect
    raise ConnectionError(self._error_message(e))
redis.exceptions.ConnectionError: Error 61 connecting to 127.0.0.1:11010. Connection refused.
Exception in thread Thread-1:
Traceback (most recent call last):
  File "/Users/upforcetech/.pyenv/versions/3.11.8/lib/python3.11/threading.py", line 1045, in _bootstrap_inner
    self.run()
  File "/Users/upforcetech/Desktop/Frappe/frappe-bench/env/lib/python3.11/site-packages/redis/client.py", line 1799, in run
    pubsub.get_message(ignore_subscribe_messages=True, timeout=sleep_time)
  File "/Users/upforcetech/Desktop/Frappe/frappe-bench/env/lib/python3.11/site-packages/redis/client.py", line 1690, in get_message
    response = self.parse_response(block=(timeout is None), timeout=timeout)
               ^^^^^^^^^^^^^^^^^^^^^^^^^^^^^^^^^^^^^^^^^^^^^^^^^^^^^^^^^^^^^
  File "/Users/upforcetech/Desktop/Frappe/frappe-bench/env/lib/python3.11/site-packages/redis/client.py", line 1542, in parse_response
    response = self._execute(conn, try_read)
               ^^^^^^^^^^^^^^^^^^^^^^^^^^^^^
  File "/Users/upforcetech/Desktop/Frappe/frappe-bench/env/lib/python3.11/site-packages/redis/client.py", line 1518, in _execute
    return conn.retry.call_with_retry(
           ^^^^^^^^^^^^^^^^^^^^^^^^^^^
  File "/Users/upforcetech/Desktop/Frappe/frappe-bench/env/lib/python3.11/site-packages/redis/retry.py", line 49, in call_with_retry
    fail(error)
  File "/Users/upforcetech/Desktop/Frappe/frappe-bench/env/lib/python3.11/site-packages/redis/client.py", line 1520, in <lambda>
    lambda error: self._disconnect_raise_connect(conn, error),
                  ^^^^^^^^^^^^^^^^^^^^^^^^^^^^^^^^^^^^^^^^^^^
  File "/Users/upforcetech/Desktop/Frappe/frappe-bench/env/lib/python3.11/site-packages/redis/client.py", line 1507, in _disconnect_raise_connect
    raise error
  File "/Users/upforcetech/Desktop/Frappe/frappe-bench/env/lib/python3.11/site-packages/redis/retry.py", line 46, in call_with_retry
    return do()
           ^^^^
  File "/Users/upforcetech/Desktop/Frappe/frappe-bench/env/lib/python3.11/site-packages/redis/client.py", line 1519, in <lambda>
    lambda: command(*args, **kwargs),
            ^^^^^^^^^^^^^^^^^^^^^^^^
  File "/Users/upforcetech/Desktop/Frappe/frappe-bench/env/lib/python3.11/site-packages/redis/client.py", line 1536, in try_read
    if not conn.can_read(timeout=timeout):
           ^^^^^^^^^^^^^^^^^^^^^^^^^^^^^^
  File "/Users/upforcetech/Desktop/Frappe/frappe-bench/env/lib/python3.11/site-packages/redis/connection.py", line 861, in can_read
    return self._parser.can_read(timeout)
           ^^^^^^^^^^^^^^^^^^^^^^^^^^^^^^
  File "/Users/upforcetech/Desktop/Frappe/frappe-bench/env/lib/python3.11/site-packages/redis/connection.py", line 444, in can_read
    return self.read_from_socket(timeout=timeout, raise_on_timeout=False)
           ^^^^^^^^^^^^^^^^^^^^^^^^^^^^^^^^^^^^^^^^^^^^^^^^^^^^^^^^^^^^^^
  File "/Users/upforcetech/Desktop/Frappe/frappe-bench/env/lib/python3.11/site-packages/redis/connection.py", line 455, in read_from_socket
    raise ConnectionError(SERVER_CLOSED_CONNECTION_ERROR)
redis.exceptions.ConnectionError: Connection closed by server.
Traceback (most recent call last):
  File "/Users/upforcetech/Desktop/Frappe/frappe-bench/env/lib/python3.11/site-packages/redis/connection.py", line 699, in connect
    sock = self.retry.call_with_retry(
           ^^^^^^^^^^^^^^^^^^^^^^^^^^^
  File "/Users/upforcetech/Desktop/Frappe/frappe-bench/env/lib/python3.11/site-packages/redis/retry.py", line 46, in call_with_retry
    return do()
           ^^^^
  File "/Users/upforcetech/Desktop/Frappe/frappe-bench/env/lib/python3.11/site-packages/redis/connection.py", line 700, in <lambda>
    lambda: self._connect(), lambda error: self.disconnect(error)
            ^^^^^^^^^^^^^^^
  File "/Users/upforcetech/Desktop/Frappe/frappe-bench/env/lib/python3.11/site-packages/redis/connection.py", line 1002, in _connect
    raise err
  File "/Users/upforcetech/Desktop/Frappe/frappe-bench/env/lib/python3.11/site-packages/redis/connection.py", line 990, in _connect
    sock.connect(socket_address)
ConnectionRefusedError: [Errno 61] Connection refused

During handling of the above exception, another exception occurred:

Traceback (most recent call last):
  File "<frozen runpy>", line 198, in _run_module_as_main
  File "<frozen runpy>", line 88, in _run_code
  File "/Users/upforcetech/Desktop/Frappe/frappe-bench/apps/frappe/frappe/utils/bench_helper.py", line 114, in <module>
    main()
  File "/Users/upforcetech/Desktop/Frappe/frappe-bench/apps/frappe/frappe/utils/bench_helper.py", line 20, in main
    click.Group(commands=commands)(prog_name="bench")
  File "/Users/upforcetech/Desktop/Frappe/frappe-bench/env/lib/python3.11/site-packages/click/core.py", line 1161, in __call__
    return self.main(*args, **kwargs)
           ^^^^^^^^^^^^^^^^^^^^^^^^^^
  File "/Users/upforcetech/Desktop/Frappe/frappe-bench/env/lib/python3.11/site-packages/click/core.py", line 1082, in main
    rv = self.invoke(ctx)
         ^^^^^^^^^^^^^^^^
  File "/Users/upforcetech/Desktop/Frappe/frappe-bench/env/lib/python3.11/site-packages/click/core.py", line 1697, in invoke
    return _process_result(sub_ctx.command.invoke(sub_ctx))
                           ^^^^^^^^^^^^^^^^^^^^^^^^^^^^^^^
  File "/Users/upforcetech/Desktop/Frappe/frappe-bench/env/lib/python3.11/site-packages/click/core.py", line 1697, in invoke
    return _process_result(sub_ctx.command.invoke(sub_ctx))
                           ^^^^^^^^^^^^^^^^^^^^^^^^^^^^^^^
  File "/Users/upforcetech/Desktop/Frappe/frappe-bench/env/lib/python3.11/site-packages/click/core.py", line 1443, in invoke
    return ctx.invoke(self.callback, **ctx.params)
           ^^^^^^^^^^^^^^^^^^^^^^^^^^^^^^^^^^^^^^^
  File "/Users/upforcetech/Desktop/Frappe/frappe-bench/env/lib/python3.11/site-packages/click/core.py", line 788, in invoke
    return __callback(*args, **kwargs)
           ^^^^^^^^^^^^^^^^^^^^^^^^^^^
  File "/Users/upforcetech/Desktop/Frappe/frappe-bench/apps/frappe/frappe/commands/scheduler.py", line 205, in start_worker
    start_worker(
  File "/Users/upforcetech/Desktop/Frappe/frappe-bench/apps/frappe/frappe/utils/background_jobs.py", line 318, in start_worker
    worker.work(
  File "/Users/upforcetech/Desktop/Frappe/frappe-bench/env/lib/python3.11/site-packages/rq/worker.py", line 456, in work
    self.teardown()
  File "/Users/upforcetech/Desktop/Frappe/frappe-bench/env/lib/python3.11/site-packages/rq/worker.py", line 1047, in teardown
    self.unsubscribe()
  File "/Users/upforcetech/Desktop/Frappe/frappe-bench/env/lib/python3.11/site-packages/rq/worker.py", line 624, in unsubscribe
    self.pubsub.unsubscribe()
  File "/Users/upforcetech/Desktop/Frappe/frappe-bench/env/lib/python3.11/site-packages/redis/client.py", line 1659, in unsubscribe
    return self.execute_command("UNSUBSCRIBE", *args)
           ^^^^^^^^^^^^^^^^^^^^^^^^^^^^^^^^^^^^^^^^^^
  File "/Users/upforcetech/Desktop/Frappe/frappe-bench/env/lib/python3.11/site-packages/redis/client.py", line 1479, in execute_command
    self._execute(connection, connection.send_command, *args, **kwargs)
  File "/Users/upforcetech/Desktop/Frappe/frappe-bench/env/lib/python3.11/site-packages/redis/client.py", line 1518, in _execute
    return conn.retry.call_with_retry(
           ^^^^^^^^^^^^^^^^^^^^^^^^^^^
  File "/Users/upforcetech/Desktop/Frappe/frappe-bench/env/lib/python3.11/site-packages/redis/retry.py", line 49, in call_with_retry
    fail(error)
  File "/Users/upforcetech/Desktop/Frappe/frappe-bench/env/lib/python3.11/site-packages/redis/client.py", line 1520, in <lambda>
    lambda error: self._disconnect_raise_connect(conn, error),
                  ^^^^^^^^^^^^^^^^^^^^^^^^^^^^^^^^^^^^^^^^^^^
  File "/Users/upforcetech/Desktop/Frappe/frappe-bench/env/lib/python3.11/site-packages/redis/client.py", line 1507, in _disconnect_raise_connect
    raise error
  File "/Users/upforcetech/Desktop/Frappe/frappe-bench/env/lib/python3.11/site-packages/redis/retry.py", line 46, in call_with_retry
    return do()
           ^^^^
  File "/Users/upforcetech/Desktop/Frappe/frappe-bench/env/lib/python3.11/site-packages/redis/client.py", line 1519, in <lambda>
    lambda: command(*args, **kwargs),
            ^^^^^^^^^^^^^^^^^^^^^^^^
  File "/Users/upforcetech/Desktop/Frappe/frappe-bench/env/lib/python3.11/site-packages/redis/connection.py", line 847, in send_command
    self.send_packed_command(
  File "/Users/upforcetech/Desktop/Frappe/frappe-bench/env/lib/python3.11/site-packages/redis/connection.py", line 817, in send_packed_command
    self.connect()
  File "/Users/upforcetech/Desktop/Frappe/frappe-bench/env/lib/python3.11/site-packages/redis/connection.py", line 705, in connect
    raise ConnectionError(self._error_message(e))
redis.exceptions.ConnectionError: Error 61 connecting to 127.0.0.1:11010. Connection refused.
/Users/upforcetech/Desktop/Frappe/frappe-bench/env/lib/python3.11/site-packages/rq/connections.py:58: DeprecationWarning: The `push_connection` function is deprecated. Pass the `connection` explicitly instead.
  warnings.warn(
/Users/upforcetech/Desktop/Frappe/frappe-bench/env/lib/python3.11/site-packages/rq/connections.py:72: DeprecationWarning: The `pop_connection` function is deprecated. Pass the `connection` explicitly instead.
  warnings.warn(
Exception in thread Thread-1:
Traceback (most recent call last):
  File "/Users/upforcetech/.pyenv/versions/3.11.8/lib/python3.11/threading.py", line 1045, in _bootstrap_inner
Traceback (most recent call last):
    self.run()
  File "/Users/upforcetech/Desktop/Frappe/frappe-bench/env/lib/python3.11/site-packages/redis/client.py", line 1799, in run
    pubsub.get_message(ignore_subscribe_messages=True, timeout=sleep_time)
  File "/Users/upforcetech/Desktop/Frappe/frappe-bench/env/lib/python3.11/site-packages/redis/client.py", line 1690, in get_message
  File "/Users/upforcetech/Desktop/Frappe/frappe-bench/env/lib/python3.11/site-packages/redis/connection.py", line 699, in connect
    response = self.parse_response(block=(timeout is None), timeout=timeout)
               ^^^^^^^^^^^^^^^^^^^^^^^^^^^^^^^^^^^^^^^^^^^^^^^^^^^^^^^^^^^^^
  File "/Users/upforcetech/Desktop/Frappe/frappe-bench/env/lib/python3.11/site-packages/redis/client.py", line 1542, in parse_response
    response = self._execute(conn, try_read)
               ^^^^^^^^^^^^^^^^^^^^^^^^^^^^^
  File "/Users/upforcetech/Desktop/Frappe/frappe-bench/env/lib/python3.11/site-packages/redis/client.py", line 1518, in _execute
    return conn.retry.call_with_retry(
           ^^^^^^^^^^^^^^^^^^^^^^^^^^^
  File "/Users/upforcetech/Desktop/Frappe/frappe-bench/env/lib/python3.11/site-packages/redis/retry.py", line 49, in call_with_retry
    fail(error)
  File "/Users/upforcetech/Desktop/Frappe/frappe-bench/env/lib/python3.11/site-packages/redis/client.py", line 1520, in <lambda>
    lambda error: self._disconnect_raise_connect(conn, error),
                  ^^^^^^^^^^^^^^^^^^^^^^^^^^^^^^^^^^^^^^^^^^^
  File "/Users/upforcetech/Desktop/Frappe/frappe-bench/env/lib/python3.11/site-packages/redis/client.py", line 1507, in _disconnect_raise_connect
    raise error
  File "/Users/upforcetech/Desktop/Frappe/frappe-bench/env/lib/python3.11/site-packages/redis/retry.py", line 46, in call_with_retry
    return do()
           ^^^^
  File "/Users/upforcetech/Desktop/Frappe/frappe-bench/env/lib/python3.11/site-packages/redis/client.py", line 1519, in <lambda>
    lambda: command(*args, **kwargs),
            ^^^^^^^^^^^^^^^^^^^^^^^^
  File "/Users/upforcetech/Desktop/Frappe/frappe-bench/env/lib/python3.11/site-packages/redis/client.py", line 1536, in try_read
    if not conn.can_read(timeout=timeout):
           ^^^^^^^^^^^^^^^^^^^^^^^^^^^^^^
  File "/Users/upforcetech/Desktop/Frappe/frappe-bench/env/lib/python3.11/site-packages/redis/connection.py", line 861, in can_read
    return self._parser.can_read(timeout)
           ^^^^^^^^^^^^^^^^^^^^^^^^^^^^^^
  File "/Users/upforcetech/Desktop/Frappe/frappe-bench/env/lib/python3.11/site-packages/redis/connection.py", line 444, in can_read
        return self.read_from_socket(timeout=timeout, raise_on_timeout=False)
           ^^^^^^^^^^^^^^^^^^^^^^^^^^^^^^^^^^^^^^^^^^^^^^^^^^^^^^^^^^^^^^
  File "/Users/upforcetech/Desktop/Frappe/frappe-bench/env/lib/python3.11/site-packages/redis/connection.py", line 455, in read_from_socket
    raise ConnectionError(SERVER_CLOSED_CONNECTION_ERROR)
redis.exceptions.ConnectionError: Connection closed by server.
sock = self.retry.call_with_retry(
           ^^^^^^^^^^^^^^^^^^^^^^^^^^^
  File "/Users/upforcetech/Desktop/Frappe/frappe-bench/env/lib/python3.11/site-packages/redis/retry.py", line 46, in call_with_retry
    return do()
           ^^^^
  File "/Users/upforcetech/Desktop/Frappe/frappe-bench/env/lib/python3.11/site-packages/redis/connection.py", line 700, in <lambda>
    lambda: self._connect(), lambda error: self.disconnect(error)
            ^^^^^^^^^^^^^^^
  File "/Users/upforcetech/Desktop/Frappe/frappe-bench/env/lib/python3.11/site-packages/redis/connection.py", line 1002, in _connect
    raise err
  File "/Users/upforcetech/Desktop/Frappe/frappe-bench/env/lib/python3.11/site-packages/redis/connection.py", line 990, in _connect
    sock.connect(socket_address)
ConnectionRefusedError: [Errno 61] Connection refused

During handling of the above exception, another exception occurred:

Traceback (most recent call last):
  File "<frozen runpy>", line 198, in _run_module_as_main
  File "<frozen runpy>", line 88, in _run_code
  File "/Users/upforcetech/Desktop/Frappe/frappe-bench/apps/frappe/frappe/utils/bench_helper.py", line 114, in <module>
    main()
  File "/Users/upforcetech/Desktop/Frappe/frappe-bench/apps/frappe/frappe/utils/bench_helper.py", line 20, in main
    click.Group(commands=commands)(prog_name="bench")
  File "/Users/upforcetech/Desktop/Frappe/frappe-bench/env/lib/python3.11/site-packages/click/core.py", line 1161, in __call__
    return self.main(*args, **kwargs)
           ^^^^^^^^^^^^^^^^^^^^^^^^^^
  File "/Users/upforcetech/Desktop/Frappe/frappe-bench/env/lib/python3.11/site-packages/click/core.py", line 1082, in main
    rv = self.invoke(ctx)
         ^^^^^^^^^^^^^^^^
  File "/Users/upforcetech/Desktop/Frappe/frappe-bench/env/lib/python3.11/site-packages/click/core.py", line 1697, in invoke
    return _process_result(sub_ctx.command.invoke(sub_ctx))
                           ^^^^^^^^^^^^^^^^^^^^^^^^^^^^^^^
  File "/Users/upforcetech/Desktop/Frappe/frappe-bench/env/lib/python3.11/site-packages/click/core.py", line 1697, in invoke
    return _process_result(sub_ctx.command.invoke(sub_ctx))
                           ^^^^^^^^^^^^^^^^^^^^^^^^^^^^^^^
  File "/Users/upforcetech/Desktop/Frappe/frappe-bench/env/lib/python3.11/site-packages/click/core.py", line 1443, in invoke
    return ctx.invoke(self.callback, **ctx.params)
           ^^^^^^^^^^^^^^^^^^^^^^^^^^^^^^^^^^^^^^^
  File "/Users/upforcetech/Desktop/Frappe/frappe-bench/env/lib/python3.11/site-packages/click/core.py", line 788, in invoke
    return __callback(*args, **kwargs)
           ^^^^^^^^^^^^^^^^^^^^^^^^^^^
  File "/Users/upforcetech/Desktop/Frappe/frappe-bench/apps/frappe/frappe/commands/scheduler.py", line 205, in start_worker
    start_worker(
  File "/Users/upforcetech/Desktop/Frappe/frappe-bench/apps/frappe/frappe/utils/background_jobs.py", line 318, in start_worker
    worker.work(
  File "/Users/upforcetech/Desktop/Frappe/frappe-bench/env/lib/python3.11/site-packages/rq/worker.py", line 456, in work
    self.teardown()
  File "/Users/upforcetech/Desktop/Frappe/frappe-bench/env/lib/python3.11/site-packages/rq/worker.py", line 1046, in teardown
    self.register_death()
  File "/Users/upforcetech/Desktop/Frappe/frappe-bench/env/lib/python3.11/site-packages/rq/worker.py", line 832, in register_death
    p.execute()
  File "/Users/upforcetech/Desktop/Frappe/frappe-bench/env/lib/python3.11/site-packages/redis/client.py", line 2114, in execute
    conn = self.connection_pool.get_connection("MULTI", self.shard_hint)
           ^^^^^^^^^^^^^^^^^^^^^^^^^^^^^^^^^^^^^^^^^^^^^^^^^^^^^^^^^^^^^
  File "/Users/upforcetech/Desktop/Frappe/frappe-bench/env/lib/python3.11/site-packages/redis/connection.py", line 1457, in get_connection
    connection.connect()
  File "/Users/upforcetech/Desktop/Frappe/frappe-bench/env/lib/python3.11/site-packages/redis/connection.py", line 705, in connect
    raise ConnectionError(self._error_message(e))
redis.exceptions.ConnectionError: Error 61 connecting to 127.0.0.1:11010. Connection refused.
Traceback (most recent call last):
Exception in thread   File "/Users/upforcetech/Desktop/Frappe/frappe-bench/env/lib/python3.11/site-packages/redis/connection.py", line 874, in read_response
Thread-1:
Traceback (most recent call last):
  File "/Users/upforcetech/.pyenv/versions/3.11.8/lib/python3.11/threading.py", line 1045, in _bootstrap_inner
    response = self._parser.read_response(disable_decoding=disable_decoding)    self.run()
  File "/Users/upforcetech/Desktop/Frappe/frappe-bench/env/lib/python3.11/site-packages/redis/client.py", line 1799, in run
    pubsub.get_message(ignore_subscribe_messages=True, timeout=sleep_time)
  File "/Users/upforcetech/Desktop/Frappe/frappe-bench/env/lib/python3.11/site-packages/redis/client.py", line 1690, in get_message
    response = self.parse_response(block=(timeout is None), timeout=timeout)
        
                ^^^^^^^^^      ^^^^^^^^^^^^^^^^^^^^^^^^^^^^^^^^^^^^^^^^^^^^^^^^^^^^^^^^^^^^^
  File "/Users/upforcetech/Desktop/Frappe/frappe-bench/env/lib/python3.11/site-packages/redis/client.py", line 1542, in parse_response
^^^^^^^^^^^^^^^^^^^^^^^^^^^^^^^^^^^^^^^^^^^^^^^^    response = self._execute(conn, try_read)
               ^^^^^^^^^^^^^^^^^^^^^^^^^^^^^
  File "/Users/upforcetech/Desktop/Frappe/frappe-bench/env/lib/python3.11/site-packages/redis/client.py", line 1518, in _execute
    return conn.retry.call_with_retry(
           ^^^^^^^^^^^^^^^^^^^^^^^^^^^
  File "/Users/upforcetech/Desktop/Frappe/frappe-bench/env/lib/python3.11/site-packages/redis/retry.py", line 49, in call_with_retry
    fail(error)
^  File "/Users/upforcetech/Desktop/Frappe/frappe-bench/env/lib/python3.11/site-packages/redis/client.py", line 1520, in <lambda>
    lambda error: self._disconnect_raise_connect(conn, error),
    ^^^
  File "/Users/upforcetech/Desktop/Frappe/frappe-bench/env/lib/python3.11/site-packages/redis/connection.py", line 493, in read_response
    self.read_from_socket()
  File "/Users/upforcetech/Desktop/Frappe/frappe-bench/env/lib/python3.11/site-packages/redis/connection.py", line 453, in read_from_socket
    bufflen = self._sock.recv_into(self._buffer)
              ^^^^^^^^^^^^^^^^^^^^^^^^^^^^^^^^^^
ConnectionResetError: [Errno 54] Connection reset by peer

During handling of the above exception, another exception occurred:

Traceback (most recent call last):
  File "<frozen runpy>", line 198, in _run_module_as_main
  File "<frozen runpy>", line 88, in _run_code
  File "/Users/upforcetech/Desktop/Frappe/frappe-bench/apps/frappe/frappe/utils/bench_helper.py", line 114, in <module>
     main()
  File "/Users/upforcetech/Desktop/Frappe/frappe-bench/apps/frappe/frappe/utils/bench_helper.py", line 20, in main
    click.Group(commands=commands)(prog_name="bench")
  File "/Users/upforcetech/Desktop/Frappe/frappe-bench/env/lib/python3.11/site-packages/click/core.py", line 1161, in __call__
    return self.main(*args, **kwargs)
           ^^^^^^^^^^^^^^^^^^^^^^^^^^
  File "/Users/upforcetech/Desktop/Frappe/frappe-bench/env/lib/python3.11/site-packages/click/core.py", line 1082, in main
    rv = self.invoke(ctx)
         ^^^^^^^^^^^^^^^^
  File "/Users/upforcetech/Desktop/Frappe/frappe-bench/env/lib/python3.11/site-packages/click/core.py", line 1697, in invoke
             ^^^^    return _process_result(sub_ctx.command.invoke(sub_ctx))
                           ^^^^^^^^^^^^^^^^^^^^^^^^^^^^^^^
  File "/Users/upforcetech/Desktop/Frappe/frappe-bench/env/lib/python3.11/site-packages/click/core.py", line 1697, in invoke
    return _process_result(sub_ctx.command.invoke(sub_ctx))
                           ^^^^^^^^^^^^^^^^^^^^^^^^^^^^^^^
  File "/Users/upforcetech/Desktop/Frappe/frappe-bench/env/lib/python3.11/site-packages/click/core.py", line 1443, in invoke
    return ctx.invoke(self.callback, **ctx.params)
           ^^^^^^^^^^^^^^^^^^^^^^^^^^^^^^^^^^^^^^^
  File "/Users/upforcetech/Desktop/Frappe/frappe-bench/env/lib/python3.11/site-packages/click/core.py", line 788, in invoke
    return __callback(*args, **kwargs)
           ^^^^^^^^^^^^^^^^^^^^^^^^^^^
  File "/Users/upforcetech/Desktop/Frappe/frappe-bench/apps/frappe/frappe/commands/scheduler.py", line 205, in start_worker
    start_worker(
  File "/Users/upforcetech/Desktop/Frappe/frappe-bench/apps/frappe/frappe/utils/background_jobs.py", line 318, in start_worker
    worker.work(
  File "/Users/upforcetech/Desktop/Frappe/frappe-bench/env/lib/python3.11/site-packages/rq/worker.py", line 456, in work
    self.teardown()
  File "/Users/upforcetech/Desktop/Frappe/frappe-bench/env/lib/python3.11/site-packages/rq/worker.py", line 1046, in teardown
^^^^^^^^^^^^^^^^^^^    self.register_death()
  File "/Users/upforcetech/Desktop/Frappe/frappe-bench/env/lib/python3.11/site-packages/rq/worker.py", line 832, in register_death
    p.execute()
  File "/Users/upforcetech/Desktop/Frappe/frappe-bench/env/lib/python3.11/site-packages/redis/client.py", line 2120, in execute
^^^    return conn.retry.call_with_retry(
^^^^^^^^^^^^^^^^^
  File "/Users/upforcetech/Desktop/Frappe/frappe-bench/env/lib/python3.11/site-packages/redis/client.py", line 1507, in _disconnect_raise_connect
    raise error
  File "/Users/upforcetech/Desktop/Frappe/frappe-bench/env/lib/python3.11/site-packages/redis/retry.py", line 46, in call_with_retry
        return do()
           ^^^^
  File "/Users/upforcetech/Desktop/Frappe/frappe-bench/env/lib/python3.11/site-packages/redis/client.py", line 1519, in <lambda>
    lambda: command(*args, **kwargs),
            ^^^^^^^^^^^^^^^^^^^^       ^^^^^^^^^^^^^^^^^^^^^^^^^^^
  File "/Users/upforcetech/Desktop/Frappe/frappe-bench/env/lib/python3.11/site-packages/redis/retry.py", line 49, in call_with_retry
^^^^
  File "/Users/upforcetech/Desktop/Frappe/frappe-bench/env/lib/python3.11/site-packages/redis/client.py", line 1536, in try_read
    fail(error)
  File "/Users/upforcetech/Desktop/Frappe/frappe-bench/env/lib/python3.11/site-packages/redis/client.py", line 2122, in <lambda>
    lambda error: self._disconnect_raise_reset(conn, error),
                  ^^^^^^^^^^^^^^^^^^^^^^^^^^^^^^    if not conn.can_read(timeout=timeout):
           ^^^^^^^^^^^^^^^^^^^^^^^^^^^^^^
  File "/Users/upforcetech/Desktop/Frappe/frappe-bench/env/lib/python3.11/site-packages/redis/connection.py", line 861, in can_read
    return self._parser.can_read(timeout)
           ^^^^^^^^^^^^^^^^^^^^^^^^^^^^^^
^^^^^^^^^^  File "/Users/upforcetech/Desktop/Frappe/frappe-bench/env/lib/python3.11/site-packages/redis/connection.py", line 444, in can_read
^
  File "/Users/upforcetech/Desktop/Frappe/frappe-bench/env/lib/python3.11/site-packages/redis/retry.py", line 46, in call_with_retry
    return self.read_from_socket(timeout=timeout, raise_on_timeout=False)
           ^^^^^^^^    return do()
^^^^^^^^^^^^^^^^^^^^^^^^^^^^^^^^^^^^^^^^^^^^^^^^^^^^^^
           ^^^^  File "/Users/upforcetech/Desktop/Frappe/frappe-bench/env/lib/python3.11/site-packages/redis/connection.py", line 455, in read_from_socket

  File "/Users/upforcetech/Desktop/Frappe/frappe-bench/env/lib/python3.11/site-packages/redis/client.py", line 2121, in <lambda>
    raise ConnectionError(SERVER_CLOSED_CONNECTION_ERROR)
redis.exceptions.    lambda: execute(conn, stack, raise_on_error),
            ^^^^^^^^^^^^^^^^^^^^^^^^^^^^^^^^^^^^
  File "/Users/upforcetech/Desktop/Frappe/frappe-bench/env/lib/python3.11/site-packages/redis/client.py", line 1975, in _execute_transaction
    self.parse_response(connection, "_")
  File "/Users/upforcetech/Desktop/Frappe/frappe-bench/env/lib/python3.11/site-packages/redis/client.py", line 2060, in parse_response
ConnectionError: Connection closed by server.
    result = Redis.parse_response(self, connection, command_name, **options)
             ^^^^^^^^^^^^^^^^^^^^^^^^^^^^^^^^^^^^^^^^^^^^^^^^^^^^^^^^^^^^^^^
  File "/Users/upforcetech/Desktop/Frappe/frappe-bench/env/lib/python3.11/site-packages/redis/client.py", line 1286, in parse_response
    response = connection.read_response()
               ^^^^^^^^^^^^^^^^^^^^^^^^^^
  File "/Users/upforcetech/Desktop/Frappe/frappe-bench/env/lib/python3.11/site-packages/redis/connection.py", line 882, in read_response
    raise ConnectionError(
redis.exceptions.ConnectionError: Error while reading from 127.0.0.1:11010 : (54, 'Connection reset by peer')
Exception in thread Thread-1:
Traceback (most recent call last):
  File "/Users/upforcetech/.pyenv/versions/3.11.8/lib/python3.11/threading.py", line 1045, in _bootstrap_inner
    self.run()
  File "/Users/upforcetech/Desktop/Frappe/frappe-bench/env/lib/python3.11/site-packages/redis/client.py", line 1799, in run
    pubsub.get_message(ignore_subscribe_messages=True, timeout=sleep_time)
  File "/Users/upforcetech/Desktop/Frappe/frappe-bench/env/lib/python3.11/site-packages/redis/client.py", line 1690, in get_message
    response = self.parse_response(block=(timeout is None), timeout=timeout)
               ^^^^^^^^^^^^^^^^^^^^^^^^^^^^^^^^^^^^^^^^^^^^^^^^^^^^^^^^^^^^^
  File "/Users/upforcetech/Desktop/Frappe/frappe-bench/env/lib/python3.11/site-packages/redis/client.py", line 1542, in parse_response
    response = self._execute(conn, try_read)
               ^^^^^^^^^^^^^^^^^^^^^^^^^^^^^
  File "/Users/upforcetech/Desktop/Frappe/frappe-bench/env/lib/python3.11/site-packages/redis/client.py", line 1518, in _execute
    return conn.retry.call_with_retry(
           ^^^^^^^^^^^^^^^^^^^^^^^^^^^
  File "/Users/upforcetech/Desktop/Frappe/frappe-bench/env/lib/python3.11/site-packages/redis/retry.py", line 49, in call_with_retry
    fail(error)
  File "/Users/upforcetech/Desktop/Frappe/frappe-bench/env/lib/python3.11/site-packages/redis/client.py", line 1520, in <lambda>
    lambda error: self._disconnect_raise_connect(conn, error),
                  ^^^^^^^^^^^^^^^^^^^^^^^^^^^^^^^^^^^^^^^^^^^
  File "/Users/upforcetech/Desktop/Frappe/frappe-bench/env/lib/python3.11/site-packages/redis/client.py", line 1507, in _disconnect_raise_connect
    raise error
  File "/Users/upforcetech/Desktop/Frappe/frappe-bench/env/lib/python3.11/site-packages/redis/retry.py", line 46, in call_with_retry
    return do()
           ^^^^
  File "/Users/upforcetech/Desktop/Frappe/frappe-bench/env/lib/python3.11/site-packages/redis/client.py", line 1519, in <lambda>
    lambda: command(*args, **kwargs),
            ^^^^^^^^^^^^^^^^^^^^^^^^
  File "/Users/upforcetech/Desktop/Frappe/frappe-bench/env/lib/python3.11/site-packages/redis/client.py", line 1536, in try_read
    if not conn.can_read(timeout=timeout):
           ^^^^^^^^^^^^^^^^^^^^^^^^^^^^^^
  File "/Users/upforcetech/Desktop/Frappe/frappe-bench/env/lib/python3.11/site-packages/redis/connection.py", line 861, in can_read
    return self._parser.can_read(timeout)
           ^^^^^^^^^^^^^^^^^^^^^^^^^^^^^^
  File "/Users/upforcetech/Desktop/Frappe/frappe-bench/env/lib/python3.11/site-packages/redis/connection.py", line 444, in can_read
    return self.read_from_socket(timeout=timeout, raise_on_timeout=False)
           ^^^^^^^^^^^^^^^^^^^^^^^^^^^^^^^^^^^^^^^^^^^^^^^^^^^^^^^^^^^^^^
  File "/Users/upforcetech/Desktop/Frappe/frappe-bench/env/lib/python3.11/site-packages/redis/connection.py", line 455, in read_from_socket
    raise ConnectionError(SERVER_CLOSED_CONNECTION_ERROR)
redis.exceptions.ConnectionError: Connection closed by server.
Traceback (most recent call last):
  File "/Users/upforcetech/Desktop/Frappe/frappe-bench/env/lib/python3.11/site-packages/redis/connection.py", line 699, in connect
    sock = self.retry.call_with_retry(
           ^^^^^^^^^^^^^^^^^^^^^^^^^^^
  File "/Users/upforcetech/Desktop/Frappe/frappe-bench/env/lib/python3.11/site-packages/redis/retry.py", line 46, in call_with_retry
    return do()
           ^^^^
  File "/Users/upforcetech/Desktop/Frappe/frappe-bench/env/lib/python3.11/site-packages/redis/connection.py", line 700, in <lambda>
    lambda: self._connect(), lambda error: self.disconnect(error)
            ^^^^^^^^^^^^^^^
  File "/Users/upforcetech/Desktop/Frappe/frappe-bench/env/lib/python3.11/site-packages/redis/connection.py", line 1002, in _connect
    raise err
  File "/Users/upforcetech/Desktop/Frappe/frappe-bench/env/lib/python3.11/site-packages/redis/connection.py", line 990, in _connect
    sock.connect(socket_address)
ConnectionRefusedError: [Errno 61] Connection refused

During handling of the above exception, another exception occurred:

Traceback (most recent call last):
  File "<frozen runpy>", line 198, in _run_module_as_main
  File "<frozen runpy>", line 88, in _run_code
  File "/Users/upforcetech/Desktop/Frappe/frappe-bench/apps/frappe/frappe/utils/bench_helper.py", line 114, in <module>
    main()
  File "/Users/upforcetech/Desktop/Frappe/frappe-bench/apps/frappe/frappe/utils/bench_helper.py", line 20, in main
    click.Group(commands=commands)(prog_name="bench")
  File "/Users/upforcetech/Desktop/Frappe/frappe-bench/env/lib/python3.11/site-packages/click/core.py", line 1161, in __call__
    return self.main(*args, **kwargs)
           ^^^^^^^^^^^^^^^^^^^^^^^^^^
  File "/Users/upforcetech/Desktop/Frappe/frappe-bench/env/lib/python3.11/site-packages/click/core.py", line 1082, in main
    rv = self.invoke(ctx)
         ^^^^^^^^^^^^^^^^
  File "/Users/upforcetech/Desktop/Frappe/frappe-bench/env/lib/python3.11/site-packages/click/core.py", line 1697, in invoke
    return _process_result(sub_ctx.command.invoke(sub_ctx))
                           ^^^^^^^^^^^^^^^^^^^^^^^^^^^^^^^
  File "/Users/upforcetech/Desktop/Frappe/frappe-bench/env/lib/python3.11/site-packages/click/core.py", line 1697, in invoke
    return _process_result(sub_ctx.command.invoke(sub_ctx))
                           ^^^^^^^^^^^^^^^^^^^^^^^^^^^^^^^
  File "/Users/upforcetech/Desktop/Frappe/frappe-bench/env/lib/python3.11/site-packages/click/core.py", line 1443, in invoke
    return ctx.invoke(self.callback, **ctx.params)
           ^^^^^^^^^^^^^^^^^^^^^^^^^^^^^^^^^^^^^^^
  File "/Users/upforcetech/Desktop/Frappe/frappe-bench/env/lib/python3.11/site-packages/click/core.py", line 788, in invoke
    return __callback(*args, **kwargs)
           ^^^^^^^^^^^^^^^^^^^^^^^^^^^
  File "/Users/upforcetech/Desktop/Frappe/frappe-bench/apps/frappe/frappe/commands/scheduler.py", line 205, in start_worker
    start_worker(
  File "/Users/upforcetech/Desktop/Frappe/frappe-bench/apps/frappe/frappe/utils/background_jobs.py", line 318, in start_worker
    worker.work(
  File "/Users/upforcetech/Desktop/Frappe/frappe-bench/env/lib/python3.11/site-packages/rq/worker.py", line 456, in work
    self.teardown()
  File "/Users/upforcetech/Desktop/Frappe/frappe-bench/env/lib/python3.11/site-packages/rq/worker.py", line 1047, in teardown
    self.unsubscribe()
  File "/Users/upforcetech/Desktop/Frappe/frappe-bench/env/lib/python3.11/site-packages/rq/worker.py", line 624, in unsubscribe
    self.pubsub.unsubscribe()
  File "/Users/upforcetech/Desktop/Frappe/frappe-bench/env/lib/python3.11/site-packages/redis/client.py", line 1659, in unsubscribe
    return self.execute_command("UNSUBSCRIBE", *args)
           ^^^^^^^^^^^^^^^^^^^^^^^^^^^^^^^^^^^^^^^^^^
  File "/Users/upforcetech/Desktop/Frappe/frappe-bench/env/lib/python3.11/site-packages/redis/client.py", line 1479, in execute_command
    self._execute(connection, connection.send_command, *args, **kwargs)
  File "/Users/upforcetech/Desktop/Frappe/frappe-bench/env/lib/python3.11/site-packages/redis/client.py", line 1518, in _execute
    return conn.retry.call_with_retry(
           ^^^^^^^^^^^^^^^^^^^^^^^^^^^
  File "/Users/upforcetech/Desktop/Frappe/frappe-bench/env/lib/python3.11/site-packages/redis/retry.py", line 49, in call_with_retry
    fail(error)
  File "/Users/upforcetech/Desktop/Frappe/frappe-bench/env/lib/python3.11/site-packages/redis/client.py", line 1520, in <lambda>
    lambda error: self._disconnect_raise_connect(conn, error),
                  ^^^^^^^^^^^^^^^^^^^^^^^^^^^^^^^^^^^^^^^^^^^
  File "/Users/upforcetech/Desktop/Frappe/frappe-bench/env/lib/python3.11/site-packages/redis/client.py", line 1507, in _disconnect_raise_connect
    raise error
  File "/Users/upforcetech/Desktop/Frappe/frappe-bench/env/lib/python3.11/site-packages/redis/retry.py", line 46, in call_with_retry
    return do()
           ^^^^
  File "/Users/upforcetech/Desktop/Frappe/frappe-bench/env/lib/python3.11/site-packages/redis/client.py", line 1519, in <lambda>
    lambda: command(*args, **kwargs),
            ^^^^^^^^^^^^^^^^^^^^^^^^
  File "/Users/upforcetech/Desktop/Frappe/frappe-bench/env/lib/python3.11/site-packages/redis/connection.py", line 847, in send_command
    self.send_packed_command(
  File "/Users/upforcetech/Desktop/Frappe/frappe-bench/env/lib/python3.11/site-packages/redis/connection.py", line 817, in send_packed_command
    self.connect()
  File "/Users/upforcetech/Desktop/Frappe/frappe-bench/env/lib/python3.11/site-packages/redis/connection.py", line 705, in connect
    raise ConnectionError(self._error_message(e))
redis.exceptions.ConnectionError: Error 61 connecting to 127.0.0.1:11010. Connection refused.
/Users/upforcetech/Desktop/Frappe/frappe-bench/env/lib/python3.11/site-packages/rq/connections.py:58: DeprecationWarning: The `push_connection` function is deprecated. Pass the `connection` explicitly instead.
  warnings.warn(
/Users/upforcetech/Desktop/Frappe/frappe-bench/env/lib/python3.11/site-packages/rq/connections.py:72: DeprecationWarning: The `pop_connection` function is deprecated. Pass the `connection` explicitly instead.
  warnings.warn(
/Users/upforcetech/Desktop/Frappe/frappe-bench/env/lib/python3.11/site-packages/rq/connections.py:58: DeprecationWarning: The `push_connection` function is deprecated. Pass the `connection` explicitly instead.
  warnings.warn(
/Users/upforcetech/Desktop/Frappe/frappe-bench/env/lib/python3.11/site-packages/rq/connections.py:72: DeprecationWarning: The `pop_connection` function is deprecated. Pass the `connection` explicitly instead.
  warnings.warn(
/Users/upforcetech/Desktop/Frappe/frappe-bench/env/lib/python3.11/site-packages/rq/connections.py:58: DeprecationWarning: The `push_connection` function is deprecated. Pass the `connection` explicitly instead.
  warnings.warn(
/Users/upforcetech/Desktop/Frappe/frappe-bench/env/lib/python3.11/site-packages/rq/connections.py:72: DeprecationWarning: The `pop_connection` function is deprecated. Pass the `connection` explicitly instead.
  warnings.warn(
/Users/upforcetech/Desktop/Frappe/frappe-bench/env/lib/python3.11/site-packages/rq/connections.py:58: DeprecationWarning: The `push_connection` function is deprecated. Pass the `connection` explicitly instead.
  warnings.warn(
/Users/upforcetech/Desktop/Frappe/frappe-bench/env/lib/python3.11/site-packages/passlib/utils/__init__.py:854: DeprecationWarning: 'crypt' is deprecated and slated for removal in Python 3.13
  from crypt import crypt as _crypt
/Users/upforcetech/Desktop/Frappe/frappe-bench/env/lib/python3.11/site-packages/rq/connections.py:72: DeprecationWarning: The `pop_connection` function is deprecated. Pass the `connection` explicitly instead.
  warnings.warn(
Traceback (most recent call last):
  File "/Users/upforcetech/Desktop/Frappe/frappe-bench/env/lib/python3.11/site-packages/redis/connection.py", line 699, in connect
    sock = self.retry.call_with_retry(Exception in thread Thread-1:
Traceback (most recent call last):
  File "/Users/upforcetech/.pyenv/versions/3.11.8/lib/python3.11/threading.py", line 1045, in _bootstrap_inner

           ^^^^^^^^^^^^^^^^^^^^^^^^^^^
  File "/Users/upforcetech/Desktop/Frappe/frappe-bench/env/lib/python3.11/site-packages/redis/retry.py", line 46, in call_with_retry
    return do()
           ^^^^
  File "/Users/upforcetech/Desktop/Frappe/frappe-bench/env/lib/python3.11/site-packages/redis/connection.py", line 700, in <lambda>
    lambda: self._connect(), lambda error: self.disconnect(error)
            ^^^^^^^^^^^^^^^
  File "/Users/upforcetech/Desktop/Frappe/frappe-bench/env/lib/python3.11/site-packages/redis/connection.py", line 1002, in _connect
    raise err
  File "/Users/upforcetech/Desktop/Frappe/frappe-bench/env/lib/python3.11/site-packages/redis/connection.py", line 990, in _connect
    self.run()
  File "/Users/upforcetech/Desktop/Frappe/frappe-bench/env/lib/python3.11/site-packages/redis/client.py", line 1799, in run
    sock.connect(socket_address)
ConnectionRefusedError: [Errno 61] Connection refused

During handling of the above exception, another exception occurred:

Traceback (most recent call last):
  File "<frozen runpy>", line 198, in _run_module_as_main
  File "<frozen runpy>", line 88, in _run_code
  File "/Users/upforcetech/Desktop/Frappe/frappe-bench/apps/frappe/frappe/utils/bench_helper.py", line 114, in <module>
    main()
  File "/Users/upforcetech/Desktop/Frappe/frappe-bench/apps/frappe/frappe/utils/bench_helper.py", line 20, in main
    click.Group(commands=commands)(prog_name="bench")
  File "/Users/upforcetech/Desktop/Frappe/frappe-bench/env/lib/python3.11/site-packages/click/core.py", line 1161, in __call__
    return self.main(*args, **kwargs)
           ^^^^^^^^^^^^^^^^^^^^^^^^^^
  File "/Users/upforcetech/Desktop/Frappe/frappe-bench/env/lib/python3.11/site-packages/click/core.py", line 1082, in main
    rv = self.invoke(ctx)
         ^^^^^^^^^^^^^^^^
  File "/Users/upforcetech/Desktop/Frappe/frappe-bench/env/lib/python3.11/site-packages/click/core.py", line 1697, in invoke
        pubsub.get_message(ignore_subscribe_messages=True, timeout=sleep_time)
  File "/Users/upforcetech/Desktop/Frappe/frappe-bench/env/lib/python3.11/site-packages/redis/client.py", line 1690, in get_message
    response = self.parse_response(block=(timeout is None), timeout=timeout)
               ^^^^^^^^^^^^^^^^^^^^^^^^^^^^^^^^^^^^^^^^^^^^^^^^^^^^^^^^^^^^^
  File "/Users/upforcetech/Desktop/Frappe/frappe-bench/env/lib/python3.11/site-packages/redis/client.py", line 1542, in parse_response
    response = self._execute(conn, try_read)
               ^^^^^^^^^^^^^^^^^^^^^^^^^^^^^
  File "/Users/upforcetech/Desktop/Frappe/frappe-bench/env/lib/python3.11/site-packages/redis/client.py", line 1518, in _execute
    return conn.retry.call_with_retry(
           ^^^^^^^^^^^^^^^^^^^^^^^^^^^
  File "/Users/upforcetech/Desktop/Frappe/frappe-bench/env/lib/python3.11/site-packages/redis/retry.py", line 49, in call_with_retry
    fail(error)
  File "/Users/upforcetech/Desktop/Frappe/frappe-bench/env/lib/python3.11/site-packages/redis/client.py", line 1520, in <lambda>
    lambda error: self._disconnect_raise_connect(conn, error),
                  ^^^^^^^^^^^^^^^^^^^^^^^^^^^^^^^^^^^^^^^^^^^
  File "/Users/upforcetech/Desktop/Frappe/frappe-bench/env/lib/python3.11/site-packages/redis/client.py", line 1507, in _disconnect_raise_connect
    raise error
  File "/Users/upforcetech/Desktop/Frappe/frappe-bench/env/lib/python3.11/site-packages/redis/retry.py", line 46, in call_with_retry
    return do()
           ^^^^
  File "/Users/upforcetech/Desktop/Frappe/frappe-bench/env/lib/python3.11/site-packages/redis/client.py", line 1519, in <lambda>
    lambda: command(*args, **kwargs),
            ^^^^^^^^^^^^^^^^^^^^^^^^
  File "/Users/upforcetech/Desktop/Frappe/frappe-bench/env/lib/python3.11/site-packages/redis/client.py", line 1536, in try_read
    if not conn.can_read(timeout=timeout):
           ^^^^^^^^^^^^^^^^^^^^^^^^^^^^^^
  File "/Users/upforcetech/Desktop/Frappe/frappe-bench/env/lib/python3.11/site-packages/redis/connection.py", line 861, in can_read
    return self._parser.can_read(timeout)
           ^^^^^^^^^^^^^^^^^^^^^^^^^^^^^^
  File "/Users/upforcetech/Desktop/Frappe/frappe-bench/env/lib/python3.11/site-packages/redis/connection.py", line 444, in can_read
    return self.read_from_socket(timeout=timeout, raise_on_timeout=False)
           ^^^^^^^^^^^^^^^^^^^^^^^^^^^^^^^^^^^^^^^^^^^^^^^^^^^^^^^^^^^^^^
  File "/Users/upforcetech/Desktop/Frappe/frappe-bench/env/lib/python3.11/site-packages/redis/connection.py", line 455, in read_from_socket
    raise ConnectionError(SERVER_CLOSED_CONNECTION_ERROR)
redis.exceptions.ConnectionError: Connection closed by server.
return _process_result(sub_ctx.command.invoke(sub_ctx))
                           ^^^^^^^^^^^^^^^^^^^^^^^^^^^^^^^
  File "/Users/upforcetech/Desktop/Frappe/frappe-bench/env/lib/python3.11/site-packages/click/core.py", line 1697, in invoke
    return _process_result(sub_ctx.command.invoke(sub_ctx))
                           ^^^^^^^^^^^^^^^^^^^^^^^^^^^^^^^
  File "/Users/upforcetech/Desktop/Frappe/frappe-bench/env/lib/python3.11/site-packages/click/core.py", line 1443, in invoke
    return ctx.invoke(self.callback, **ctx.params)
           ^^^^^^^^^^^^^^^^^^^^^^^^^^^^^^^^^^^^^^^
  File "/Users/upforcetech/Desktop/Frappe/frappe-bench/env/lib/python3.11/site-packages/click/core.py", line 788, in invoke
    return __callback(*args, **kwargs)
           ^^^^^^^^^^^^^^^^^^^^^^^^^^^
  File "/Users/upforcetech/Desktop/Frappe/frappe-bench/apps/frappe/frappe/commands/scheduler.py", line 205, in start_worker
    start_worker(
  File "/Users/upforcetech/Desktop/Frappe/frappe-bench/apps/frappe/frappe/utils/background_jobs.py", line 318, in start_worker
    worker.work(
  File "/Users/upforcetech/Desktop/Frappe/frappe-bench/env/lib/python3.11/site-packages/rq/worker.py", line 456, in work
    self.teardown()
  File "/Users/upforcetech/Desktop/Frappe/frappe-bench/env/lib/python3.11/site-packages/rq/worker.py", line 1046, in teardown
    self.register_death()
  File "/Users/upforcetech/Desktop/Frappe/frappe-bench/env/lib/python3.11/site-packages/rq/worker.py", line 832, in register_death
    p.execute()
  File "/Users/upforcetech/Desktop/Frappe/frappe-bench/env/lib/python3.11/site-packages/redis/client.py", line 2114, in execute
    conn = self.connection_pool.get_connection("MULTI", self.shard_hint)
           ^^^^^^^^^^^^^^^^^^^^^^^^^^^^^^^^^^^^^^^^^^^^^^^^^^^^^^^^^^^^^
  File "/Users/upforcetech/Desktop/Frappe/frappe-bench/env/lib/python3.11/site-packages/redis/connection.py", line 1457, in get_connection
    connection.connect()
  File "/Users/upforcetech/Desktop/Frappe/frappe-bench/env/lib/python3.11/site-packages/redis/connection.py", line 705, in connect
    raise ConnectionError(self._error_message(e))
redis.exceptions.ConnectionError: Error 61 connecting to 127.0.0.1:11010. Connection refused.
Exception in thread Thread-1:
Traceback (most recent call last):
  File "/Users/upforcetech/.pyenv/versions/3.11.8/lib/python3.11/threading.py", line 1045, in _bootstrap_inner
    self.run()
  File "/Users/upforcetech/Desktop/Frappe/frappe-bench/env/lib/python3.11/site-packages/redis/client.py", line 1799, in run
    pubsub.get_message(ignore_subscribe_messages=True, timeout=sleep_time)
  File "/Users/upforcetech/Desktop/Frappe/frappe-bench/env/lib/python3.11/site-packages/redis/client.py", line 1690, in get_message
    response = self.parse_response(block=(timeout is None), timeout=timeout)
               ^^^^^^^^^^^^^^^^^^^^^^^^^^^^^^^^^^^^^^^^^^^^^^^^^^^^^^^^^^^^^
  File "/Users/upforcetech/Desktop/Frappe/frappe-bench/env/lib/python3.11/site-packages/redis/client.py", line 1542, in parse_response
    response = self._execute(conn, try_read)
               ^^^^^^^^^^^^^^^^^^^^^^^^^^^^^
  File "/Users/upforcetech/Desktop/Frappe/frappe-bench/env/lib/python3.11/site-packages/redis/client.py", line 1518, in _execute
    return conn.retry.call_with_retry(
           ^^^^^^^^^^^^^^^^^^^^^^^^^^^
  File "/Users/upforcetech/Desktop/Frappe/frappe-bench/env/lib/python3.11/site-packages/redis/retry.py", line 49, in call_with_retry
    fail(error)
  File "/Users/upforcetech/Desktop/Frappe/frappe-bench/env/lib/python3.11/site-packages/redis/client.py", line 1520, in <lambda>
    lambda error: self._disconnect_raise_connect(conn, error),
                  ^^^^^^^^^^^^^^^^^^^^^^^^^^^^^^^^^^^^^^^^^^^
  File "/Users/upforcetech/Desktop/Frappe/frappe-bench/env/lib/python3.11/site-packages/redis/client.py", line 1507, in _disconnect_raise_connect
    raise error
  File "/Users/upforcetech/Desktop/Frappe/frappe-bench/env/lib/python3.11/site-packages/redis/retry.py", line 46, in call_with_retry
    return do()
           ^^^^
  File "/Users/upforcetech/Desktop/Frappe/frappe-bench/env/lib/python3.11/site-packages/redis/client.py", line 1519, in <lambda>
    lambda: command(*args, **kwargs),
            ^^^^^^^^^^^^^^^^^^^^^^^^
  File "/Users/upforcetech/Desktop/Frappe/frappe-bench/env/lib/python3.11/site-packages/redis/client.py", line 1536, in try_read
    if not conn.can_read(timeout=timeout):
           ^^^^^^^^^^^^^^^^^^^^^^^^^^^^^^
  File "/Users/upforcetech/Desktop/Frappe/frappe-bench/env/lib/python3.11/site-packages/redis/connection.py", line 861, in can_read
    return self._parser.can_read(timeout)
           ^^^^^^^^^^^^^^^^^^^^^^^^^^^^^^
  File "/Users/upforcetech/Desktop/Frappe/frappe-bench/env/lib/python3.11/site-packages/redis/connection.py", line 444, in can_read
    return self.read_from_socket(timeout=timeout, raise_on_timeout=False)
           ^^^^^^^^^^^^^^^^^^^^^^^^^^^^^^^^^^^^^^^^^^^^^^^^^^^^^^^^^^^^^^
  File "/Users/upforcetech/Desktop/Frappe/frappe-bench/env/lib/python3.11/site-packages/redis/connection.py", line 455, in read_from_socket
    raise ConnectionError(SERVER_CLOSED_CONNECTION_ERROR)
redis.exceptions.ConnectionError: Connection closed by server.
Traceback (most recent call last):
  File "/Users/upforcetech/Desktop/Frappe/frappe-bench/env/lib/python3.11/site-packages/redis/connection.py", line 699, in connect
    sock = self.retry.call_with_retry(
           ^^^^^^^^^^^^^^^^^^^^^^^^^^^
  File "/Users/upforcetech/Desktop/Frappe/frappe-bench/env/lib/python3.11/site-packages/redis/retry.py", line 46, in call_with_retry
    return do()
           ^^^^
  File "/Users/upforcetech/Desktop/Frappe/frappe-bench/env/lib/python3.11/site-packages/redis/connection.py", line 700, in <lambda>
    lambda: self._connect(), lambda error: self.disconnect(error)
            ^^^^^^^^^^^^^^^
  File "/Users/upforcetech/Desktop/Frappe/frappe-bench/env/lib/python3.11/site-packages/redis/connection.py", line 1002, in _connect
    raise err
  File "/Users/upforcetech/Desktop/Frappe/frappe-bench/env/lib/python3.11/site-packages/redis/connection.py", line 990, in _connect
    sock.connect(socket_address)
ConnectionRefusedError: [Errno 61] Connection refused

During handling of the above exception, another exception occurred:

Traceback (most recent call last):
  File "<frozen runpy>", line 198, in _run_module_as_main
  File "<frozen runpy>", line 88, in _run_code
  File "/Users/upforcetech/Desktop/Frappe/frappe-bench/apps/frappe/frappe/utils/bench_helper.py", line 114, in <module>
    main()
  File "/Users/upforcetech/Desktop/Frappe/frappe-bench/apps/frappe/frappe/utils/bench_helper.py", line 20, in main
    click.Group(commands=commands)(prog_name="bench")
  File "/Users/upforcetech/Desktop/Frappe/frappe-bench/env/lib/python3.11/site-packages/click/core.py", line 1161, in __call__
    return self.main(*args, **kwargs)
           ^^^^^^^^^^^^^^^^^^^^^^^^^^
  File "/Users/upforcetech/Desktop/Frappe/frappe-bench/env/lib/python3.11/site-packages/click/core.py", line 1082, in main
    rv = self.invoke(ctx)
         ^^^^^^^^^^^^^^^^
  File "/Users/upforcetech/Desktop/Frappe/frappe-bench/env/lib/python3.11/site-packages/click/core.py", line 1697, in invoke
    return _process_result(sub_ctx.command.invoke(sub_ctx))
                           ^^^^^^^^^^^^^^^^^^^^^^^^^^^^^^^
  File "/Users/upforcetech/Desktop/Frappe/frappe-bench/env/lib/python3.11/site-packages/click/core.py", line 1697, in invoke
    return _process_result(sub_ctx.command.invoke(sub_ctx))
                           ^^^^^^^^^^^^^^^^^^^^^^^^^^^^^^^
  File "/Users/upforcetech/Desktop/Frappe/frappe-bench/env/lib/python3.11/site-packages/click/core.py", line 1443, in invoke
    return ctx.invoke(self.callback, **ctx.params)
           ^^^^^^^^^^^^^^^^^^^^^^^^^^^^^^^^^^^^^^^
  File "/Users/upforcetech/Desktop/Frappe/frappe-bench/env/lib/python3.11/site-packages/click/core.py", line 788, in invoke
    return __callback(*args, **kwargs)
           ^^^^^^^^^^^^^^^^^^^^^^^^^^^
  File "/Users/upforcetech/Desktop/Frappe/frappe-bench/apps/frappe/frappe/commands/scheduler.py", line 205, in start_worker
    start_worker(
  File "/Users/upforcetech/Desktop/Frappe/frappe-bench/apps/frappe/frappe/utils/background_jobs.py", line 318, in start_worker
    worker.work(
  File "/Users/upforcetech/Desktop/Frappe/frappe-bench/env/lib/python3.11/site-packages/rq/worker.py", line 456, in work
    self.teardown()
  File "/Users/upforcetech/Desktop/Frappe/frappe-bench/env/lib/python3.11/site-packages/rq/worker.py", line 1047, in teardown
    self.unsubscribe()
  File "/Users/upforcetech/Desktop/Frappe/frappe-bench/env/lib/python3.11/site-packages/rq/worker.py", line 624, in unsubscribe
    self.pubsub.unsubscribe()
  File "/Users/upforcetech/Desktop/Frappe/frappe-bench/env/lib/python3.11/site-packages/redis/client.py", line 1659, in unsubscribe
    return self.execute_command("UNSUBSCRIBE", *args)
           ^^^^^^^^^^^^^^^^^^^^^^^^^^^^^^^^^^^^^^^^^^
  File "/Users/upforcetech/Desktop/Frappe/frappe-bench/env/lib/python3.11/site-packages/redis/client.py", line 1479, in execute_command
    self._execute(connection, connection.send_command, *args, **kwargs)
  File "/Users/upforcetech/Desktop/Frappe/frappe-bench/env/lib/python3.11/site-packages/redis/client.py", line 1518, in _execute
    return conn.retry.call_with_retry(
           ^^^^^^^^^^^^^^^^^^^^^^^^^^^
  File "/Users/upforcetech/Desktop/Frappe/frappe-bench/env/lib/python3.11/site-packages/redis/retry.py", line 49, in call_with_retry
    fail(error)
  File "/Users/upforcetech/Desktop/Frappe/frappe-bench/env/lib/python3.11/site-packages/redis/client.py", line 1520, in <lambda>
    lambda error: self._disconnect_raise_connect(conn, error),
                  ^^^^^^^^^^^^^^^^^^^^^^^^^^^^^^^^^^^^^^^^^^^
  File "/Users/upforcetech/Desktop/Frappe/frappe-bench/env/lib/python3.11/site-packages/redis/client.py", line 1507, in _disconnect_raise_connect
    raise error
  File "/Users/upforcetech/Desktop/Frappe/frappe-bench/env/lib/python3.11/site-packages/redis/retry.py", line 46, in call_with_retry
    return do()
           ^^^^
  File "/Users/upforcetech/Desktop/Frappe/frappe-bench/env/lib/python3.11/site-packages/redis/client.py", line 1519, in <lambda>
    lambda: command(*args, **kwargs),
            ^^^^^^^^^^^^^^^^^^^^^^^^
  File "/Users/upforcetech/Desktop/Frappe/frappe-bench/env/lib/python3.11/site-packages/redis/connection.py", line 847, in send_command
    self.send_packed_command(
  File "/Users/upforcetech/Desktop/Frappe/frappe-bench/env/lib/python3.11/site-packages/redis/connection.py", line 817, in send_packed_command
    self.connect()
  File "/Users/upforcetech/Desktop/Frappe/frappe-bench/env/lib/python3.11/site-packages/redis/connection.py", line 705, in connect
    raise ConnectionError(self._error_message(e))
redis.exceptions.ConnectionError: Error 61 connecting to 127.0.0.1:11010. Connection refused.
Exception in thread Thread-1:
Traceback (most recent call last):
  File "/Users/upforcetech/.pyenv/versions/3.11.8/lib/python3.11/threading.py", line 1045, in _bootstrap_inner
    self.run()
  File "/Users/upforcetech/Desktop/Frappe/frappe-bench/env/lib/python3.11/site-packages/redis/client.py", line 1799, in run
    pubsub.get_message(ignore_subscribe_messages=True, timeout=sleep_time)
  File "/Users/upforcetech/Desktop/Frappe/frappe-bench/env/lib/python3.11/site-packages/redis/client.py", line 1690, in get_message
    response = self.parse_response(block=(timeout is None), timeout=timeout)
               ^^^^^^^^^^^^^^^^^^^^^^^^^^^^^^^^^^^^^^^^^^^^^^^^^^^^^^^^^^^^^
  File "/Users/upforcetech/Desktop/Frappe/frappe-bench/env/lib/python3.11/site-packages/redis/client.py", line 1542, in parse_response
    response = self._execute(conn, try_read)
               ^^^^^^^^^^^^^^^^^^^^^^^^^^^^^
  File "/Users/upforcetech/Desktop/Frappe/frappe-bench/env/lib/python3.11/site-packages/redis/client.py", line 1518, in _execute
    return conn.retry.call_with_retry(
           ^^^^^^^^^^^^^^^^^^^^^^^^^^^
  File "/Users/upforcetech/Desktop/Frappe/frappe-bench/env/lib/python3.11/site-packages/redis/retry.py", line 49, in call_with_retry
    fail(error)
  File "/Users/upforcetech/Desktop/Frappe/frappe-bench/env/lib/python3.11/site-packages/redis/client.py", line 1520, in <lambda>
    lambda error: self._disconnect_raise_connect(conn, error),
                  ^^^^^^^^^^^^^^^^^^^^^^^^^^^^^^^^^^^^^^^^^^^
  File "/Users/upforcetech/Desktop/Frappe/frappe-bench/env/lib/python3.11/site-packages/redis/client.py", line 1507, in _disconnect_raise_connect
    raise error
  File "/Users/upforcetech/Desktop/Frappe/frappe-bench/env/lib/python3.11/site-packages/redis/retry.py", line 46, in call_with_retry
    return do()
           ^^^^
  File "/Users/upforcetech/Desktop/Frappe/frappe-bench/env/lib/python3.11/site-packages/redis/client.py", line 1519, in <lambda>
    lambda: command(*args, **kwargs),
            ^^^^^^^^^^^^^^^^^^^^^^^^
  File "/Users/upforcetech/Desktop/Frappe/frappe-bench/env/lib/python3.11/site-packages/redis/client.py", line 1536, in try_read
    if not conn.can_read(timeout=timeout):
           ^^^^^^^^^^^^^^^^^^^^^^^^^^^^^^
  File "/Users/upforcetech/Desktop/Frappe/frappe-bench/env/lib/python3.11/site-packages/redis/connection.py", line 861, in can_read
    return self._parser.can_read(timeout)
           ^^^^^^^^^^^^^^^^^^^^^^^^^^^^^^
  File "/Users/upforcetech/Desktop/Frappe/frappe-bench/env/lib/python3.11/site-packages/redis/connection.py", line 444, in can_read
    return self.read_from_socket(timeout=timeout, raise_on_timeout=False)
           ^^^^^^^^^^^^^^^^^^^^^^^^^^^^^^^^^^^^^^^^^^^^^^^^^^^^^^^^^^^^^^
  File "/Users/upforcetech/Desktop/Frappe/frappe-bench/env/lib/python3.11/site-packages/redis/connection.py", line 455, in read_from_socket
    raise ConnectionError(SERVER_CLOSED_CONNECTION_ERROR)
redis.exceptions.ConnectionError: Connection closed by server.
Traceback (most recent call last):
  File "/Users/upforcetech/Desktop/Frappe/frappe-bench/env/lib/python3.11/site-packages/redis/connection.py", line 699, in connect
    sock = self.retry.call_with_retry(
           ^^^^^^^^^^^^^^^^^^^^^^^^^^^
  File "/Users/upforcetech/Desktop/Frappe/frappe-bench/env/lib/python3.11/site-packages/redis/retry.py", line 46, in call_with_retry
    return do()
           ^^^^
  File "/Users/upforcetech/Desktop/Frappe/frappe-bench/env/lib/python3.11/site-packages/redis/connection.py", line 700, in <lambda>
    lambda: self._connect(), lambda error: self.disconnect(error)
            ^^^^^^^^^^^^^^^
  File "/Users/upforcetech/Desktop/Frappe/frappe-bench/env/lib/python3.11/site-packages/redis/connection.py", line 1002, in _connect
    raise err
  File "/Users/upforcetech/Desktop/Frappe/frappe-bench/env/lib/python3.11/site-packages/redis/connection.py", line 990, in _connect
    sock.connect(socket_address)
ConnectionRefusedError: [Errno 61] Connection refused

During handling of the above exception, another exception occurred:

Traceback (most recent call last):
  File "<frozen runpy>", line 198, in _run_module_as_main
  File "<frozen runpy>", line 88, in _run_code
  File "/Users/upforcetech/Desktop/Frappe/frappe-bench/apps/frappe/frappe/utils/bench_helper.py", line 114, in <module>
    main()
  File "/Users/upforcetech/Desktop/Frappe/frappe-bench/apps/frappe/frappe/utils/bench_helper.py", line 20, in main
    click.Group(commands=commands)(prog_name="bench")
  File "/Users/upforcetech/Desktop/Frappe/frappe-bench/env/lib/python3.11/site-packages/click/core.py", line 1161, in __call__
    return self.main(*args, **kwargs)
           ^^^^^^^^^^^^^^^^^^^^^^^^^^
  File "/Users/upforcetech/Desktop/Frappe/frappe-bench/env/lib/python3.11/site-packages/click/core.py", line 1082, in main
    rv = self.invoke(ctx)
         ^^^^^^^^^^^^^^^^
  File "/Users/upforcetech/Desktop/Frappe/frappe-bench/env/lib/python3.11/site-packages/click/core.py", line 1697, in invoke
    return _process_result(sub_ctx.command.invoke(sub_ctx))
                           ^^^^^^^^^^^^^^^^^^^^^^^^^^^^^^^
  File "/Users/upforcetech/Desktop/Frappe/frappe-bench/env/lib/python3.11/site-packages/click/core.py", line 1697, in invoke
    return _process_result(sub_ctx.command.invoke(sub_ctx))
                           ^^^^^^^^^^^^^^^^^^^^^^^^^^^^^^^
  File "/Users/upforcetech/Desktop/Frappe/frappe-bench/env/lib/python3.11/site-packages/click/core.py", line 1443, in invoke
    return ctx.invoke(self.callback, **ctx.params)
           ^^^^^^^^^^^^^^^^^^^^^^^^^^^^^^^^^^^^^^^
  File "/Users/upforcetech/Desktop/Frappe/frappe-bench/env/lib/python3.11/site-packages/click/core.py", line 788, in invoke
    return __callback(*args, **kwargs)
           ^^^^^^^^^^^^^^^^^^^^^^^^^^^
  File "/Users/upforcetech/Desktop/Frappe/frappe-bench/apps/frappe/frappe/commands/scheduler.py", line 205, in start_worker
    start_worker(
  File "/Users/upforcetech/Desktop/Frappe/frappe-bench/apps/frappe/frappe/utils/background_jobs.py", line 318, in start_worker
    worker.work(
  File "/Users/upforcetech/Desktop/Frappe/frappe-bench/env/lib/python3.11/site-packages/rq/worker.py", line 456, in work
    self.teardown()
  File "/Users/upforcetech/Desktop/Frappe/frappe-bench/env/lib/python3.11/site-packages/rq/worker.py", line 1047, in teardown
    self.unsubscribe()
  File "/Users/upforcetech/Desktop/Frappe/frappe-bench/env/lib/python3.11/site-packages/rq/worker.py", line 624, in unsubscribe
    self.pubsub.unsubscribe()
  File "/Users/upforcetech/Desktop/Frappe/frappe-bench/env/lib/python3.11/site-packages/redis/client.py", line 1659, in unsubscribe
    return self.execute_command("UNSUBSCRIBE", *args)
           ^^^^^^^^^^^^^^^^^^^^^^^^^^^^^^^^^^^^^^^^^^
  File "/Users/upforcetech/Desktop/Frappe/frappe-bench/env/lib/python3.11/site-packages/redis/client.py", line 1479, in execute_command
    self._execute(connection, connection.send_command, *args, **kwargs)
  File "/Users/upforcetech/Desktop/Frappe/frappe-bench/env/lib/python3.11/site-packages/redis/client.py", line 1518, in _execute
    return conn.retry.call_with_retry(
           ^^^^^^^^^^^^^^^^^^^^^^^^^^^
  File "/Users/upforcetech/Desktop/Frappe/frappe-bench/env/lib/python3.11/site-packages/redis/retry.py", line 49, in call_with_retry
    fail(error)
  File "/Users/upforcetech/Desktop/Frappe/frappe-bench/env/lib/python3.11/site-packages/redis/client.py", line 1520, in <lambda>
    lambda error: self._disconnect_raise_connect(conn, error),
                  ^^^^^^^^^^^^^^^^^^^^^^^^^^^^^^^^^^^^^^^^^^^
  File "/Users/upforcetech/Desktop/Frappe/frappe-bench/env/lib/python3.11/site-packages/redis/client.py", line 1507, in _disconnect_raise_connect
    raise error
  File "/Users/upforcetech/Desktop/Frappe/frappe-bench/env/lib/python3.11/site-packages/redis/retry.py", line 46, in call_with_retry
    return do()
           ^^^^
  File "/Users/upforcetech/Desktop/Frappe/frappe-bench/env/lib/python3.11/site-packages/redis/client.py", line 1519, in <lambda>
    lambda: command(*args, **kwargs),
            ^^^^^^^^^^^^^^^^^^^^^^^^
  File "/Users/upforcetech/Desktop/Frappe/frappe-bench/env/lib/python3.11/site-packages/redis/connection.py", line 847, in send_command
    self.send_packed_command(
  File "/Users/upforcetech/Desktop/Frappe/frappe-bench/env/lib/python3.11/site-packages/redis/connection.py", line 817, in send_packed_command
    self.connect()
  File "/Users/upforcetech/Desktop/Frappe/frappe-bench/env/lib/python3.11/site-packages/redis/connection.py", line 705, in connect
    raise ConnectionError(self._error_message(e))
redis.exceptions.ConnectionError: Error 61 connecting to 127.0.0.1:11010. Connection refused.
Exception in thread Thread-1:
Traceback (most recent call last):
  File "/Users/upforcetech/.pyenv/versions/3.11.8/lib/python3.11/threading.py", line 1045, in _bootstrap_inner
    self.run()
  File "/Users/upforcetech/Desktop/Frappe/frappe-bench/env/lib/python3.11/site-packages/redis/client.py", line 1799, in run
    pubsub.get_message(ignore_subscribe_messages=True, timeout=sleep_time)
  File "/Users/upforcetech/Desktop/Frappe/frappe-bench/env/lib/python3.11/site-packages/redis/client.py", line 1690, in get_message
    response = self.parse_response(block=(timeout is None), timeout=timeout)
               ^^^^^^^^^^^^^^^^^^^^^^^^^^^^^^^^^^^^^^^^^^^^^^^^^^^^^^^^^^^^^
  File "/Users/upforcetech/Desktop/Frappe/frappe-bench/env/lib/python3.11/site-packages/redis/client.py", line 1542, in parse_response
    response = self._execute(conn, try_read)
               ^^^^^^^^^^^^^^^^^^^^^^^^^^^^^
  File "/Users/upforcetech/Desktop/Frappe/frappe-bench/env/lib/python3.11/site-packages/redis/client.py", line 1518, in _execute
    return conn.retry.call_with_retry(
           ^^^^^^^^^^^^^^^^^^^^^^^^^^^
  File "/Users/upforcetech/Desktop/Frappe/frappe-bench/env/lib/python3.11/site-packages/redis/retry.py", line 49, in call_with_retry
    fail(error)
  File "/Users/upforcetech/Desktop/Frappe/frappe-bench/env/lib/python3.11/site-packages/redis/client.py", line 1520, in <lambda>
    lambda error: self._disconnect_raise_connect(conn, error),
                  ^^^^^^^^^^^^^^^^^^^^^^^^^^^^^^^^^^^^^^^^^^^
  File "/Users/upforcetech/Desktop/Frappe/frappe-bench/env/lib/python3.11/site-packages/redis/client.py", line 1507, in _disconnect_raise_connect
    raise error
  File "/Users/upforcetech/Desktop/Frappe/frappe-bench/env/lib/python3.11/site-packages/redis/retry.py", line 46, in call_with_retry
    return do()
           ^^^^
  File "/Users/upforcetech/Desktop/Frappe/frappe-bench/env/lib/python3.11/site-packages/redis/client.py", line 1519, in <lambda>
    lambda: command(*args, **kwargs),
            ^^^^^^^^^^^^^^^^^^^^^^^^
  File "/Users/upforcetech/Desktop/Frappe/frappe-bench/env/lib/python3.11/site-packages/redis/client.py", line 1536, in try_read
    if not conn.can_read(timeout=timeout):
           ^^^^^^^^^^^^^^^^^^^^^^^^^^^^^^
  File "/Users/upforcetech/Desktop/Frappe/frappe-bench/env/lib/python3.11/site-packages/redis/connection.py", line 861, in can_read
    return self._parser.can_read(timeout)
           ^^^^^^^^^^^^^^^^^^^^^^^^^^^^^^
  File "/Users/upforcetech/Desktop/Frappe/frappe-bench/env/lib/python3.11/site-packages/redis/connection.py", line 444, in can_read
    return self.read_from_socket(timeout=timeout, raise_on_timeout=False)
           ^^^^^^^^^^^^^^^^^^^^^^^^^^^^^^^^^^^^^^^^^^^^^^^^^^^^^^^^^^^^^^
  File "/Users/upforcetech/Desktop/Frappe/frappe-bench/env/lib/python3.11/site-packages/redis/connection.py", line 455, in read_from_socket
    raise ConnectionError(SERVER_CLOSED_CONNECTION_ERROR)
redis.exceptions.ConnectionError: Connection closed by server.
Traceback (most recent call last):
  File "/Users/upforcetech/Desktop/Frappe/frappe-bench/env/lib/python3.11/site-packages/redis/connection.py", line 699, in connect
    sock = self.retry.call_with_retry(
           ^^^^^^^^^^^^^^^^^^^^^^^^^^^
  File "/Users/upforcetech/Desktop/Frappe/frappe-bench/env/lib/python3.11/site-packages/redis/retry.py", line 46, in call_with_retry
    return do()
           ^^^^
  File "/Users/upforcetech/Desktop/Frappe/frappe-bench/env/lib/python3.11/site-packages/redis/connection.py", line 700, in <lambda>
    lambda: self._connect(), lambda error: self.disconnect(error)
            ^^^^^^^^^^^^^^^
  File "/Users/upforcetech/Desktop/Frappe/frappe-bench/env/lib/python3.11/site-packages/redis/connection.py", line 1002, in _connect
    raise err
  File "/Users/upforcetech/Desktop/Frappe/frappe-bench/env/lib/python3.11/site-packages/redis/connection.py", line 990, in _connect
    sock.connect(socket_address)
ConnectionRefusedError: [Errno 61] Connection refused

During handling of the above exception, another exception occurred:

Traceback (most recent call last):
  File "<frozen runpy>", line 198, in _run_module_as_main
  File "<frozen runpy>", line 88, in _run_code
  File "/Users/upforcetech/Desktop/Frappe/frappe-bench/apps/frappe/frappe/utils/bench_helper.py", line 114, in <module>
    main()
  File "/Users/upforcetech/Desktop/Frappe/frappe-bench/apps/frappe/frappe/utils/bench_helper.py", line 20, in main
    click.Group(commands=commands)(prog_name="bench")
  File "/Users/upforcetech/Desktop/Frappe/frappe-bench/env/lib/python3.11/site-packages/click/core.py", line 1161, in __call__
    return self.main(*args, **kwargs)
           ^^^^^^^^^^^^^^^^^^^^^^^^^^
  File "/Users/upforcetech/Desktop/Frappe/frappe-bench/env/lib/python3.11/site-packages/click/core.py", line 1082, in main
    rv = self.invoke(ctx)
         ^^^^^^^^^^^^^^^^
  File "/Users/upforcetech/Desktop/Frappe/frappe-bench/env/lib/python3.11/site-packages/click/core.py", line 1697, in invoke
    return _process_result(sub_ctx.command.invoke(sub_ctx))
                           ^^^^^^^^^^^^^^^^^^^^^^^^^^^^^^^
  File "/Users/upforcetech/Desktop/Frappe/frappe-bench/env/lib/python3.11/site-packages/click/core.py", line 1697, in invoke
    return _process_result(sub_ctx.command.invoke(sub_ctx))
                           ^^^^^^^^^^^^^^^^^^^^^^^^^^^^^^^
  File "/Users/upforcetech/Desktop/Frappe/frappe-bench/env/lib/python3.11/site-packages/click/core.py", line 1443, in invoke
    return ctx.invoke(self.callback, **ctx.params)
           ^^^^^^^^^^^^^^^^^^^^^^^^^^^^^^^^^^^^^^^
  File "/Users/upforcetech/Desktop/Frappe/frappe-bench/env/lib/python3.11/site-packages/click/core.py", line 788, in invoke
    return __callback(*args, **kwargs)
           ^^^^^^^^^^^^^^^^^^^^^^^^^^^
  File "/Users/upforcetech/Desktop/Frappe/frappe-bench/apps/frappe/frappe/commands/scheduler.py", line 205, in start_worker
    start_worker(
  File "/Users/upforcetech/Desktop/Frappe/frappe-bench/apps/frappe/frappe/utils/background_jobs.py", line 318, in start_worker
    worker.work(
  File "/Users/upforcetech/Desktop/Frappe/frappe-bench/env/lib/python3.11/site-packages/rq/worker.py", line 456, in work
    self.teardown()
  File "/Users/upforcetech/Desktop/Frappe/frappe-bench/env/lib/python3.11/site-packages/rq/worker.py", line 1047, in teardown
    self.unsubscribe()
  File "/Users/upforcetech/Desktop/Frappe/frappe-bench/env/lib/python3.11/site-packages/rq/worker.py", line 624, in unsubscribe
    self.pubsub.unsubscribe()
  File "/Users/upforcetech/Desktop/Frappe/frappe-bench/env/lib/python3.11/site-packages/redis/client.py", line 1659, in unsubscribe
    return self.execute_command("UNSUBSCRIBE", *args)
           ^^^^^^^^^^^^^^^^^^^^^^^^^^^^^^^^^^^^^^^^^^
  File "/Users/upforcetech/Desktop/Frappe/frappe-bench/env/lib/python3.11/site-packages/redis/client.py", line 1479, in execute_command
    self._execute(connection, connection.send_command, *args, **kwargs)
  File "/Users/upforcetech/Desktop/Frappe/frappe-bench/env/lib/python3.11/site-packages/redis/client.py", line 1518, in _execute
    return conn.retry.call_with_retry(
           ^^^^^^^^^^^^^^^^^^^^^^^^^^^
  File "/Users/upforcetech/Desktop/Frappe/frappe-bench/env/lib/python3.11/site-packages/redis/retry.py", line 49, in call_with_retry
    fail(error)
  File "/Users/upforcetech/Desktop/Frappe/frappe-bench/env/lib/python3.11/site-packages/redis/client.py", line 1520, in <lambda>
    lambda error: self._disconnect_raise_connect(conn, error),
                  ^^^^^^^^^^^^^^^^^^^^^^^^^^^^^^^^^^^^^^^^^^^
  File "/Users/upforcetech/Desktop/Frappe/frappe-bench/env/lib/python3.11/site-packages/redis/client.py", line 1507, in _disconnect_raise_connect
    raise error
  File "/Users/upforcetech/Desktop/Frappe/frappe-bench/env/lib/python3.11/site-packages/redis/retry.py", line 46, in call_with_retry
    return do()
           ^^^^
  File "/Users/upforcetech/Desktop/Frappe/frappe-bench/env/lib/python3.11/site-packages/redis/client.py", line 1519, in <lambda>
    lambda: command(*args, **kwargs),
            ^^^^^^^^^^^^^^^^^^^^^^^^
  File "/Users/upforcetech/Desktop/Frappe/frappe-bench/env/lib/python3.11/site-packages/redis/connection.py", line 847, in send_command
    self.send_packed_command(
  File "/Users/upforcetech/Desktop/Frappe/frappe-bench/env/lib/python3.11/site-packages/redis/connection.py", line 817, in send_packed_command
    self.connect()
  File "/Users/upforcetech/Desktop/Frappe/frappe-bench/env/lib/python3.11/site-packages/redis/connection.py", line 705, in connect
    raise ConnectionError(self._error_message(e))
redis.exceptions.ConnectionError: Error 61 connecting to 127.0.0.1:11010. Connection refused.
Exception in thread Thread-1:
Traceback (most recent call last):
  File "/Users/upforcetech/.pyenv/versions/3.11.8/lib/python3.11/threading.py", line 1045, in _bootstrap_inner
    self.run()
  File "/Users/upforcetech/Desktop/Frappe/frappe-bench/env/lib/python3.11/site-packages/redis/client.py", line 1799, in run
    pubsub.get_message(ignore_subscribe_messages=True, timeout=sleep_time)
  File "/Users/upforcetech/Desktop/Frappe/frappe-bench/env/lib/python3.11/site-packages/redis/client.py", line 1690, in get_message
    response = self.parse_response(block=(timeout is None), timeout=timeout)
               ^^^^^^^^^^^^^^^^^^^^^^^^^^^^^^^^^^^^^^^^^^^^^^^^^^^^^^^^^^^^^
  File "/Users/upforcetech/Desktop/Frappe/frappe-bench/env/lib/python3.11/site-packages/redis/client.py", line 1542, in parse_response
    response = self._execute(conn, try_read)
               ^^^^^^^^^^^^^^^^^^^^^^^^^^^^^
  File "/Users/upforcetech/Desktop/Frappe/frappe-bench/env/lib/python3.11/site-packages/redis/client.py", line 1518, in _execute
    return conn.retry.call_with_retry(
           ^^^^^^^^^^^^^^^^^^^^^^^^^^^
  File "/Users/upforcetech/Desktop/Frappe/frappe-bench/env/lib/python3.11/site-packages/redis/retry.py", line 49, in call_with_retry
    fail(error)
  File "/Users/upforcetech/Desktop/Frappe/frappe-bench/env/lib/python3.11/site-packages/redis/client.py", line 1520, in <lambda>
    lambda error: self._disconnect_raise_connect(conn, error),
                  ^^^^^^^^^^^^^^^^^^^^^^^^^^^^^^^^^^^^^^^^^^^
  File "/Users/upforcetech/Desktop/Frappe/frappe-bench/env/lib/python3.11/site-packages/redis/client.py", line 1507, in _disconnect_raise_connect
    raise error
  File "/Users/upforcetech/Desktop/Frappe/frappe-bench/env/lib/python3.11/site-packages/redis/retry.py", line 46, in call_with_retry
    return do()
           ^^^^
  File "/Users/upforcetech/Desktop/Frappe/frappe-bench/env/lib/python3.11/site-packages/redis/client.py", line 1519, in <lambda>
    lambda: command(*args, **kwargs),
            ^^^^^^^^^^^^^^^^^^^^^^^^
  File "/Users/upforcetech/Desktop/Frappe/frappe-bench/env/lib/python3.11/site-packages/redis/client.py", line 1536, in try_read
    if not conn.can_read(timeout=timeout):
           ^^^^^^^^^^^^^^^^^^^^^^^^^^^^^^
  File "/Users/upforcetech/Desktop/Frappe/frappe-bench/env/lib/python3.11/site-packages/redis/connection.py", line 861, in can_read
    return self._parser.can_read(timeout)
           ^^^^^^^^^^^^^^^^^^^^^^^^^^^^^^
  File "/Users/upforcetech/Desktop/Frappe/frappe-bench/env/lib/python3.11/site-packages/redis/connection.py", line 444, in can_read
    return self.read_from_socket(timeout=timeout, raise_on_timeout=False)
           ^^^^^^^^^^^^^^^^^^^^^^^^^^^^^^^^^^^^^^^^^^^^^^^^^^^^^^^^^^^^^^
  File "/Users/upforcetech/Desktop/Frappe/frappe-bench/env/lib/python3.11/site-packages/redis/connection.py", line 455, in read_from_socket
    raise ConnectionError(SERVER_CLOSED_CONNECTION_ERROR)
redis.exceptions.ConnectionError: Connection closed by server.
Traceback (most recent call last):
  File "/Users/upforcetech/Desktop/Frappe/frappe-bench/env/lib/python3.11/site-packages/redis/connection.py", line 699, in connect
    sock = self.retry.call_with_retry(
           ^^^^^^^^^^^^^^^^^^^^^^^^^^^
  File "/Users/upforcetech/Desktop/Frappe/frappe-bench/env/lib/python3.11/site-packages/redis/retry.py", line 46, in call_with_retry
    return do()
           ^^^^
  File "/Users/upforcetech/Desktop/Frappe/frappe-bench/env/lib/python3.11/site-packages/redis/connection.py", line 700, in <lambda>
    lambda: self._connect(), lambda error: self.disconnect(error)
            ^^^^^^^^^^^^^^^
  File "/Users/upforcetech/Desktop/Frappe/frappe-bench/env/lib/python3.11/site-packages/redis/connection.py", line 1002, in _connect
    raise err
  File "/Users/upforcetech/Desktop/Frappe/frappe-bench/env/lib/python3.11/site-packages/redis/connection.py", line 990, in _connect
    sock.connect(socket_address)
ConnectionRefusedError: [Errno 61] Connection refused

During handling of the above exception, another exception occurred:

Traceback (most recent call last):
  File "<frozen runpy>", line 198, in _run_module_as_main
  File "<frozen runpy>", line 88, in _run_code
  File "/Users/upforcetech/Desktop/Frappe/frappe-bench/apps/frappe/frappe/utils/bench_helper.py", line 114, in <module>
    main()
  File "/Users/upforcetech/Desktop/Frappe/frappe-bench/apps/frappe/frappe/utils/bench_helper.py", line 20, in main
    click.Group(commands=commands)(prog_name="bench")
  File "/Users/upforcetech/Desktop/Frappe/frappe-bench/env/lib/python3.11/site-packages/click/core.py", line 1161, in __call__
    return self.main(*args, **kwargs)
           ^^^^^^^^^^^^^^^^^^^^^^^^^^
  File "/Users/upforcetech/Desktop/Frappe/frappe-bench/env/lib/python3.11/site-packages/click/core.py", line 1082, in main
    rv = self.invoke(ctx)
         ^^^^^^^^^^^^^^^^
  File "/Users/upforcetech/Desktop/Frappe/frappe-bench/env/lib/python3.11/site-packages/click/core.py", line 1697, in invoke
    return _process_result(sub_ctx.command.invoke(sub_ctx))
                           ^^^^^^^^^^^^^^^^^^^^^^^^^^^^^^^
  File "/Users/upforcetech/Desktop/Frappe/frappe-bench/env/lib/python3.11/site-packages/click/core.py", line 1697, in invoke
    return _process_result(sub_ctx.command.invoke(sub_ctx))
                           ^^^^^^^^^^^^^^^^^^^^^^^^^^^^^^^
  File "/Users/upforcetech/Desktop/Frappe/frappe-bench/env/lib/python3.11/site-packages/click/core.py", line 1443, in invoke
    return ctx.invoke(self.callback, **ctx.params)
           ^^^^^^^^^^^^^^^^^^^^^^^^^^^^^^^^^^^^^^^
  File "/Users/upforcetech/Desktop/Frappe/frappe-bench/env/lib/python3.11/site-packages/click/core.py", line 788, in invoke
    return __callback(*args, **kwargs)
           ^^^^^^^^^^^^^^^^^^^^^^^^^^^
  File "/Users/upforcetech/Desktop/Frappe/frappe-bench/apps/frappe/frappe/commands/scheduler.py", line 205, in start_worker
    start_worker(
  File "/Users/upforcetech/Desktop/Frappe/frappe-bench/apps/frappe/frappe/utils/background_jobs.py", line 318, in start_worker
    worker.work(
  File "/Users/upforcetech/Desktop/Frappe/frappe-bench/env/lib/python3.11/site-packages/rq/worker.py", line 456, in work
    self.teardown()
  File "/Users/upforcetech/Desktop/Frappe/frappe-bench/env/lib/python3.11/site-packages/rq/worker.py", line 1047, in teardown
    self.unsubscribe()
  File "/Users/upforcetech/Desktop/Frappe/frappe-bench/env/lib/python3.11/site-packages/rq/worker.py", line 624, in unsubscribe
    self.pubsub.unsubscribe()
  File "/Users/upforcetech/Desktop/Frappe/frappe-bench/env/lib/python3.11/site-packages/redis/client.py", line 1659, in unsubscribe
    return self.execute_command("UNSUBSCRIBE", *args)
           ^^^^^^^^^^^^^^^^^^^^^^^^^^^^^^^^^^^^^^^^^^
  File "/Users/upforcetech/Desktop/Frappe/frappe-bench/env/lib/python3.11/site-packages/redis/client.py", line 1479, in execute_command
    self._execute(connection, connection.send_command, *args, **kwargs)
  File "/Users/upforcetech/Desktop/Frappe/frappe-bench/env/lib/python3.11/site-packages/redis/client.py", line 1518, in _execute
    return conn.retry.call_with_retry(
           ^^^^^^^^^^^^^^^^^^^^^^^^^^^
  File "/Users/upforcetech/Desktop/Frappe/frappe-bench/env/lib/python3.11/site-packages/redis/retry.py", line 49, in call_with_retry
    fail(error)
  File "/Users/upforcetech/Desktop/Frappe/frappe-bench/env/lib/python3.11/site-packages/redis/client.py", line 1520, in <lambda>
    lambda error: self._disconnect_raise_connect(conn, error),
                  ^^^^^^^^^^^^^^^^^^^^^^^^^^^^^^^^^^^^^^^^^^^
  File "/Users/upforcetech/Desktop/Frappe/frappe-bench/env/lib/python3.11/site-packages/redis/client.py", line 1507, in _disconnect_raise_connect
    raise error
  File "/Users/upforcetech/Desktop/Frappe/frappe-bench/env/lib/python3.11/site-packages/redis/retry.py", line 46, in call_with_retry
    return do()
           ^^^^
  File "/Users/upforcetech/Desktop/Frappe/frappe-bench/env/lib/python3.11/site-packages/redis/client.py", line 1519, in <lambda>
    lambda: command(*args, **kwargs),
            ^^^^^^^^^^^^^^^^^^^^^^^^
  File "/Users/upforcetech/Desktop/Frappe/frappe-bench/env/lib/python3.11/site-packages/redis/connection.py", line 847, in send_command
    self.send_packed_command(
  File "/Users/upforcetech/Desktop/Frappe/frappe-bench/env/lib/python3.11/site-packages/redis/connection.py", line 817, in send_packed_command
    self.connect()
  File "/Users/upforcetech/Desktop/Frappe/frappe-bench/env/lib/python3.11/site-packages/redis/connection.py", line 705, in connect
    raise ConnectionError(self._error_message(e))
redis.exceptions.ConnectionError: Error 61 connecting to 127.0.0.1:11010. Connection refused.
Traceback (most recent call last):
  File "/Users/upforcetech/Desktop/Frappe/frappe-bench/env/lib/python3.11/site-packages/redis/connection.py", line 699, in connect
    sock = self.retry.call_with_retry(
           ^^^^^^^^^^^^^^^^^^^^^^^^^^^
  File "/Users/upforcetech/Desktop/Frappe/frappe-bench/env/lib/python3.11/site-packages/redis/retry.py", line 46, in call_with_retry
    return do()
           ^^^^
  File "/Users/upforcetech/Desktop/Frappe/frappe-bench/env/lib/python3.11/site-packages/redis/connection.py", line 700, in <lambda>
    Exception in thread Thread-1:
Traceback (most recent call last):
  File "/Users/upforcetech/.pyenv/versions/3.11.8/lib/python3.11/threading.py", line 1045, in _bootstrap_inner
lambda: self._connect(), lambda error: self.disconnect(error)
            ^^^    self.run()
  File "/Users/upforcetech/Desktop/Frappe/frappe-bench/env/lib/python3.11/site-packages/redis/client.py", line 1799, in run
^^^^^^^^^^^^
  File "/Users/upforcetech/Desktop/Frappe/frappe-bench/env/lib/python3.11/site-packages/redis/connection.py", line 1002, in _connect
    pubsub.get_message(ignore_subscribe_messages=True, timeout=sleep_time)
  File "/Users/upforcetech/Desktop/Frappe/frappe-bench/env/lib/python3.11/site-packages/redis/client.py", line 1690, in get_message
    response = self.parse_response(block=(timeout is None), timeout=timeout)
          raise err
  File "/Users/upforcetech/Desktop/Frappe/frappe-bench/env/lib/python3.11/site-packages/redis/connection.py", line 990, in _connect
    sock.connect(socket_address)
ConnectionRefusedError: [Errno 61] Connection refused

During handling of the above exception, another exception occurred:

Traceback (most recent call last):
  File "<frozen runpy>", line 198, in _run_module_as_main
  File "<frozen runpy>", line 88, in _run_code
  File "/Users/upforcetech/Desktop/Frappe/frappe-bench/apps/frappe/frappe/utils/bench_helper.py", line 114, in <module>
         ^^^^^^^^^^^^^^^^^^^    main()
  File "/Users/upforcetech/Desktop/Frappe/frappe-bench/apps/frappe/frappe/utils/bench_helper.py", line 20, in main
    click.Group(commands=commands)(prog_name="bench")
  File "/Users/upforcetech/Desktop/Frappe/frappe-bench/env/lib/python3.11/site-packages/click/core.py", line 1161, in __call__
    return self.main(*args, **kwargs)
           ^^^^^^^^^^^^^^^^^^^^^^^^^^
  File "/Users/upforcetech/Desktop/Frappe/frappe-bench/env/lib/python3.11/site-packages/click/core.py", line 1082, in main
    rv = self.invoke(ctx)
         ^^^^^^^^^^^^^^^^
  File "/Users/upforcetech/Desktop/Frappe/frappe-bench/env/lib/python3.11/site-packages/click/core.py", line 1697, in invoke
^^^^^^^^^^^^^^^^^^^^^^^^^^^^^^^^^^^^^^^^^^
  File "/Users/upforcetech/Desktop/Frappe/frappe-bench/env/lib/python3.11/site-packages/redis/client.py", line 1542, in parse_response
    response = self._execute(conn, try_read)
               ^^^^^^^^^^^^^^^^^^^^^^^^^^^^^
  File "/Users/upforcetech/Desktop/Frappe/frappe-bench/env/lib/python3.11/site-packages/redis/client.py", line 1518, in _execute
    return conn.retry.call_with_retry(
           ^^^^^^^^^^^^^^^^^^^^^^^^^^^
  File "/Users/upforcetech/Desktop/Frappe/frappe-bench/env/lib/python3.11/site-packages/redis/retry.py", line 49, in call_with_retry
    fail(error)
  File "/Users/upforcetech/Desktop/Frappe/frappe-bench/env/lib/python3.11/site-packages/redis/client.py", line 1520, in <lambda>
    lambda error: self._disconnect_raise_connect(conn, error),
      return _process_result(sub_ctx.command.invoke(sub_ctx))
                           ^^^^^^^^^^^^^^^^^^^^^^^^^^^^^^^
  File "/Users/upforcetech/Desktop/Frappe/frappe-bench/env/lib/python3.11/site-packages/click/core.py", line 1697, in invoke
    return _process_result(sub_ctx.command.invoke(sub_ctx))
                           ^^^^^^^^^^^^^^^^^^^^^^^^^^^^^^^
  File "/Users/upforcetech/Desktop/Frappe/frappe-bench/env/lib/python3.11/site-packages/click/core.py", line 1443, in invoke
    return ctx.invoke(self.callback, **ctx.params)
           ^^^^^^^^^^^^^^^^^^^^^^^^^^^^^^^^^^^^^^^
  File "/Users/upforcetech/Desktop/Frappe/frappe-bench/env/lib/python3.11/site-packages/click/core.py", line 788, in invoke
     return __callback(*args, **kwargs)
           ^^^^^^^^^^^^^^^^^^^^^^^^^^^
  File "/Users/upforcetech/Desktop/Frappe/frappe-bench/apps/frappe/frappe/commands/scheduler.py", line 205, in start_worker
    start_worker(
  File "/Users/upforcetech/Desktop/Frappe/frappe-bench/apps/frappe/frappe/utils/background_jobs.py", line 318, in start_worker
    worker.work(
  File "/Users/upforcetech/Desktop/Frappe/frappe-bench/env/lib/python3.11/site-packages/rq/worker.py", line 456, in work
    self.teardown()
  File "/Users/upforcetech/Desktop/Frappe/frappe-bench/env/lib/python3.11/site-packages/rq/worker.py", line 1046, in teardown
    self.register_death()
  File "/Users/upforcetech/Desktop/Frappe/frappe-bench/env/lib/python3.11/site-packages/rq/worker.py", line 832, in register_death
    p.execute()
  File "/Users/upforcetech/Desktop/Frappe/frappe-bench/env/lib/python3.11/site-packages/redis/client.py", line 2114, in execute
    conn = self.connection_pool.get_connection("MULTI", self.shard_hint)
           ^^^^^^^^^^^^^^^^^^^^^^^^^^^^^^^^^^^^^^^^^^^^^^^^^^^^^^^^^^^^^
  File "/Users/upforcetech/Desktop/Frappe/frappe-bench/env/lib/python3.11/site-packages/redis/connection.py", line 1457, in get_connection
    connection.connect()
  File "/Users/upforcetech/Desktop/Frappe/frappe-bench/env/lib/python3.11/site-packages/redis/connection.py", line 705, in connect
    raise ConnectionError(self._error_message(e))
redis.exceptions.ConnectionError: Error 61 connecting to 127.0.0.1:11010. Connection refused.
Exception in thread Thread-1:
Traceback (most recent call last):
  File "/Users/upforcetech/.pyenv/versions/3.11.8/lib/python3.11/threading.py", line 1045, in _bootstrap_inner
    self.run()
  File "/Users/upforcetech/Desktop/Frappe/frappe-bench/env/lib/python3.11/site-packages/redis/client.py", line 1799, in run
    pubsub.get_message(ignore_subscribe_messages=True, timeout=sleep_time)
  File "/Users/upforcetech/Desktop/Frappe/frappe-bench/env/lib/python3.11/site-packages/redis/client.py", line 1690, in get_message
    response = self.parse_response(block=(timeout is None), timeout=timeout)
               ^^^^^^^^^^^^^^^^^^^^^^^^^^^^^^^^^^^^^^^^^^^^^^^^^^^^^^^^^^^^^
  File "/Users/upforcetech/Desktop/Frappe/frappe-bench/env/lib/python3.11/site-packages/redis/client.py", line 1542, in parse_response
    response = self._execute(conn, try_read)
               ^^^^^^^^^^^^^^^^^^^^^^^^^^^^^
  File "/Users/upforcetech/Desktop/Frappe/frappe-bench/env/lib/python3.11/site-packages/redis/client.py", line 1518, in _execute
    return conn.retry.call_with_retry(
           ^^^^^^^^^^^^^^^^^^^^^^^^^^^
  File "/Users/upforcetech/Desktop/Frappe/frappe-bench/env/lib/python3.11/site-packages/redis/retry.py", line 49, in call_with_retry
    fail(error)
  File "/Users/upforcetech/Desktop/Frappe/frappe-bench/env/lib/python3.11/site-packages/redis/client.py", line 1520, in <lambda>
    lambda error: self._disconnect_raise_connect(conn, error),
                  ^^^^^^^^^^^^^^^^^^^^^^^^^^^^^^^^^^^^^^^^^^^
  File "/Users/upforcetech/Desktop/Frappe/frappe-bench/env/lib/python3.11/site-packages/redis/client.py", line 1507, in _disconnect_raise_connect
    raise error
  File "/Users/upforcetech/Desktop/Frappe/frappe-bench/env/lib/python3.11/site-packages/redis/retry.py", line 46, in call_with_retry
    return do()
           ^^^^
  File "/Users/upforcetech/Desktop/Frappe/frappe-bench/env/lib/python3.11/site-packages/redis/client.py", line 1519, in <lambda>
    lambda: command(*args, **kwargs),
            ^^^^^^^^^^^^^^^^^^^^^^^^
  File "/Users/upforcetech/Desktop/Frappe/frappe-bench/env/lib/python3.11/site-packages/redis/client.py", line 1536, in try_read
    if not conn.can_read(timeout=timeout):
           ^^^^^^^^^^^^^^^^^^^^^^^^^^^^^^
  File "/Users/upforcetech/Desktop/Frappe/frappe-bench/env/lib/python3.11/site-packages/redis/connection.py", line 861, in can_read
    return self._parser.can_read(timeout)
           ^^^^^^^^^^^^^^^^^^^^^^^^^^^^^^
  File "/Users/upforcetech/Desktop/Frappe/frappe-bench/env/lib/python3.11/site-packages/redis/connection.py", line 444, in can_read
    return self.read_from_socket(timeout=timeout, raise_on_timeout=False)
           ^^^^^^^^^^^^^^^^^^^^^^^^^^^^^^^^^^^^^^^^^^^^^^^^^^^^^^^^^^^^^^
  File "/Users/upforcetech/Desktop/Frappe/frappe-bench/env/lib/python3.11/site-packages/redis/connection.py", line 455, in read_from_socket
    raise ConnectionError(SERVER_CLOSED_CONNECTION_ERROR)
redis.exceptions.ConnectionError: Connection closed by server.
Traceback (most recent call last):
  File "/Users/upforcetech/Desktop/Frappe/frappe-bench/env/lib/python3.11/site-packages/redis/connection.py", line 699, in connect
    sock = self.retry.call_with_retry(
           ^^^^^^^^^^^^^^^^^^^^^^^^^^^
  File "/Users/upforcetech/Desktop/Frappe/frappe-bench/env/lib/python3.11/site-packages/redis/retry.py", line 46, in call_with_retry
    return do()
           ^^^^
  File "/Users/upforcetech/Desktop/Frappe/frappe-bench/env/lib/python3.11/site-packages/redis/connection.py", line 700, in <lambda>
    lambda: self._connect(), lambda error: self.disconnect(error)
            ^^^^^^^^^^^^^^^
  File "/Users/upforcetech/Desktop/Frappe/frappe-bench/env/lib/python3.11/site-packages/redis/connection.py", line 1002, in _connect
    raise err
  File "/Users/upforcetech/Desktop/Frappe/frappe-bench/env/lib/python3.11/site-packages/redis/connection.py", line 990, in _connect
    sock.connect(socket_address)
ConnectionRefusedError: [Errno 61] Connection refused

During handling of the above exception, another exception occurred:

Traceback (most recent call last):
  File "<frozen runpy>", line 198, in _run_module_as_main
  File "<frozen runpy>", line 88, in _run_code
  File "/Users/upforcetech/Desktop/Frappe/frappe-bench/apps/frappe/frappe/utils/bench_helper.py", line 114, in <module>
    main()
  File "/Users/upforcetech/Desktop/Frappe/frappe-bench/apps/frappe/frappe/utils/bench_helper.py", line 20, in main
    click.Group(commands=commands)(prog_name="bench")
  File "/Users/upforcetech/Desktop/Frappe/frappe-bench/env/lib/python3.11/site-packages/click/core.py", line 1161, in __call__
    return self.main(*args, **kwargs)
           ^^^^^^^^^^^^^^^^^^^^^^^^^^
  File "/Users/upforcetech/Desktop/Frappe/frappe-bench/env/lib/python3.11/site-packages/click/core.py", line 1082, in main
    rv = self.invoke(ctx)
         ^^^^^^^^^^^^^^^^
  File "/Users/upforcetech/Desktop/Frappe/frappe-bench/env/lib/python3.11/site-packages/click/core.py", line 1697, in invoke
    return _process_result(sub_ctx.command.invoke(sub_ctx))
                           ^^^^^^^^^^^^^^^^^^^^^^^^^^^^^^^
  File "/Users/upforcetech/Desktop/Frappe/frappe-bench/env/lib/python3.11/site-packages/click/core.py", line 1697, in invoke
    return _process_result(sub_ctx.command.invoke(sub_ctx))
                           ^^^^^^^^^^^^^^^^^^^^^^^^^^^^^^^
  File "/Users/upforcetech/Desktop/Frappe/frappe-bench/env/lib/python3.11/site-packages/click/core.py", line 1443, in invoke
    return ctx.invoke(self.callback, **ctx.params)
           ^^^^^^^^^^^^^^^^^^^^^^^^^^^^^^^^^^^^^^^
  File "/Users/upforcetech/Desktop/Frappe/frappe-bench/env/lib/python3.11/site-packages/click/core.py", line 788, in invoke
    return __callback(*args, **kwargs)
           ^^^^^^^^^^^^^^^^^^^^^^^^^^^
  File "/Users/upforcetech/Desktop/Frappe/frappe-bench/apps/frappe/frappe/commands/scheduler.py", line 205, in start_worker
    start_worker(
  File "/Users/upforcetech/Desktop/Frappe/frappe-bench/apps/frappe/frappe/utils/background_jobs.py", line 318, in start_worker
    worker.work(
  File "/Users/upforcetech/Desktop/Frappe/frappe-bench/env/lib/python3.11/site-packages/rq/worker.py", line 456, in work
    self.teardown()
  File "/Users/upforcetech/Desktop/Frappe/frappe-bench/env/lib/python3.11/site-packages/rq/worker.py", line 1047, in teardown
    self.unsubscribe()
  File "/Users/upforcetech/Desktop/Frappe/frappe-bench/env/lib/python3.11/site-packages/rq/worker.py", line 624, in unsubscribe
    self.pubsub.unsubscribe()
  File "/Users/upforcetech/Desktop/Frappe/frappe-bench/env/lib/python3.11/site-packages/redis/client.py", line 1659, in unsubscribe
    return self.execute_command("UNSUBSCRIBE", *args)
           ^^^^^^^^^^^^^^^^^^^^^^^^^^^^^^^^^^^^^^^^^^
  File "/Users/upforcetech/Desktop/Frappe/frappe-bench/env/lib/python3.11/site-packages/redis/client.py", line 1479, in execute_command
    self._execute(connection, connection.send_command, *args, **kwargs)
  File "/Users/upforcetech/Desktop/Frappe/frappe-bench/env/lib/python3.11/site-packages/redis/client.py", line 1518, in _execute
    return conn.retry.call_with_retry(
           ^^^^^^^^^^^^^^^^^^^^^^^^^^^
  File "/Users/upforcetech/Desktop/Frappe/frappe-bench/env/lib/python3.11/site-packages/redis/retry.py", line 49, in call_with_retry
    fail(error)
  File "/Users/upforcetech/Desktop/Frappe/frappe-bench/env/lib/python3.11/site-packages/redis/client.py", line 1520, in <lambda>
    lambda error: self._disconnect_raise_connect(conn, error),
                  ^^^^^^^^^^^^^^^^^^^^^^^^^^^^^^^^^^^^^^^^^^^
  File "/Users/upforcetech/Desktop/Frappe/frappe-bench/env/lib/python3.11/site-packages/redis/client.py", line 1507, in _disconnect_raise_connect
    raise error
  File "/Users/upforcetech/Desktop/Frappe/frappe-bench/env/lib/python3.11/site-packages/redis/retry.py", line 46, in call_with_retry
    return do()
           ^^^^
  File "/Users/upforcetech/Desktop/Frappe/frappe-bench/env/lib/python3.11/site-packages/redis/client.py", line 1519, in <lambda>
    lambda: command(*args, **kwargs),
            ^^^^^^^^^^^^^^^^^^^^^^^^
  File "/Users/upforcetech/Desktop/Frappe/frappe-bench/env/lib/python3.11/site-packages/redis/connection.py", line 847, in send_command
    self.send_packed_command(
  File "/Users/upforcetech/Desktop/Frappe/frappe-bench/env/lib/python3.11/site-packages/redis/connection.py", line 817, in send_packed_command
    self.connect()
  File "/Users/upforcetech/Desktop/Frappe/frappe-bench/env/lib/python3.11/site-packages/redis/connection.py", line 705, in connect
    raise ConnectionError(self._error_message(e))
redis.exceptions.ConnectionError: Error 61 connecting to 127.0.0.1:11010. Connection refused.
Exception in thread Traceback (most recent call last):
  File "/Users/upforcetech/Desktop/Frappe/frappe-bench/env/lib/python3.11/site-packages/redis/connection.py", line 699, in connect
    sock = self.retry.call_with_retry(
           ^^^^^^^^^^^^^^^^^^^^^^^^^^^
  File "/Users/upforcetech/Desktop/Frappe/frappe-bench/env/lib/python3.11/site-packages/redis/retry.py", line 46, in call_with_retry
Thread-1    return do()
           ^^^^
  File "/Users/upforcetech/Desktop/Frappe/frappe-bench/env/lib/python3.11/site-packages/redis/connection.py", line 700, in <lambda>
    lambda: self._connect(), lambda error: self.disconnect(error)
            ^^^^^^^^^^^^^^^
  File "/Users/upforcetech/Desktop/Frappe/frappe-bench/env/lib/python3.11/site-packages/redis/connection.py", line 1002, in _connect
    raise err
  File "/Users/upforcetech/Desktop/Frappe/frappe-bench/env/lib/python3.11/site-packages/redis/connection.py", line 990, in _connect
    sock.connect(socket_address)
ConnectionRefusedError: [Errno 61] Connection refused

During handling of the above exception, another exception occurred:

:
Traceback (most recent call last):
  File "/Users/upforcetech/.pyenv/versions/3.11.8/lib/python3.11/threading.py", line 1045, in _bootstrap_inner
    self.run()
  File "/Users/upforcetech/Desktop/Frappe/frappe-bench/env/lib/python3.11/site-packages/redis/client.py", line 1799, in run
    pubsub.get_message(ignore_subscribe_messages=True, timeout=sleep_time)
  File "/Users/upforcetech/Desktop/Frappe/frappe-bench/env/lib/python3.11/site-packages/redis/client.py", line 1690, in get_message
    response = self.parse_response(block=(timeout is None), timeout=timeout)
Traceback (most recent call last):
  File "<frozen runpy>", line 198, in _run_module_as_main
  File "<frozen runpy>", line 88, in _run_code
  File "/Users/upforcetech/Desktop/Frappe/frappe-bench/apps/frappe/frappe/utils/bench_helper.py", line 114, in <module>
    main()
  File "/Users/upforcetech/Desktop/Frappe/frappe-bench/apps/frappe/frappe/utils/bench_helper.py", line 20, in main
               ^^^^^^^^^^^^^^^^^^^^^^^^^^^^^^^^^^^^^^^^^^^^^^^^^^^^^^^^^^^^^
  File "/Users/upforcetech/Desktop/Frappe/frappe-bench/env/lib/python3.11/site-packages/redis/client.py", line 1542, in parse_response
    response = self._execute(conn, try_read)
               ^^^^^^^^^^^^^^^^^^^^^^^^^^^^^
  File "/Users/upforcetech/Desktop/Frappe/frappe-bench/env/lib/python3.11/site-packages/redis/client.py", line 1518, in _execute
    return conn.retry.call_with_retry(
           ^^^^^^^^^^^^^^^^^^^^^^^^^^^
  File "/Users/upforcetech/Desktop/Frappe/frappe-bench/env/lib/python3.11/site-packages/redis/retry.py", line 49, in call_with_retry
    fail(error)
  File "/Users/upforcetech/Desktop/Frappe/frappe-bench/env/lib/python3.11/site-packages/redis/client.py", line 1520, in <lambda>
    lambda error: self._disconnect_raise_connect(conn, error),
       click.Group(commands=commands)(prog_name="bench")
  File "/Users/upforcetech/Desktop/Frappe/frappe-bench/env/lib/python3.11/site-packages/click/core.py", line 1161, in __call__
    return self.main(*args, **kwargs)
           ^^^^^^^^^^^^^^^^^^^^^^^^^^
  File "/Users/upforcetech/Desktop/Frappe/frappe-bench/env/lib/python3.11/site-packages/click/core.py", line 1082, in main
    rv = self.invoke(ctx)
         ^^^^^^^^^^^^^^^^
  File "/Users/upforcetech/Desktop/Frappe/frappe-bench/env/lib/python3.11/site-packages/click/core.py", line 1697, in invoke
        return _process_result(sub_ctx.command.invoke(sub_ctx))
                           ^^^^^^^^^^^^^^^^^^^^^^^^^^^^^^^
  File "/Users/upforcetech/Desktop/Frappe/frappe-bench/env/lib/python3.11/site-packages/click/core.py", line 1697, in invoke
    return _process_result(sub_ctx.command.invoke(sub_ctx))
                           ^^^^^^^^^^^^^^^^^^^^^^^^^^^^^^^
  File "/Users/upforcetech/Desktop/Frappe/frappe-bench/env/lib/python3.11/site-packages/click/core.py", line 1443, in invoke
           ^^^    return ctx.invoke(self.callback, **ctx.params)
           ^^^^^^^^^^^^^^^^^^^^^^^^^^^^^^^^^^^^^^^
  File "/Users/upforcetech/Desktop/Frappe/frappe-bench/env/lib/python3.11/site-packages/click/core.py", line 788, in invoke
^^^^    return __callback(*args, **kwargs)
           ^^^^^^^^^^^^^^^^^^^^^^^^^^^
  File "/Users/upforcetech/Desktop/Frappe/frappe-bench/apps/frappe/frappe/commands/scheduler.py", line 205, in start_worker
    start_worker(
  File "/Users/upforcetech/Desktop/Frappe/frappe-bench/apps/frappe/frappe/utils/background_jobs.py", line 318, in start_worker
    worker.work(
  File "/Users/upforcetech/Desktop/Frappe/frappe-bench/env/lib/python3.11/site-packages/rq/worker.py", line 456, in work
    self.teardown()
  File "/Users/upforcetech/Desktop/Frappe/frappe-bench/env/lib/python3.11/site-packages/rq/worker.py", line 1046, in teardown
    self.register_death()
  File "/Users/upforcetech/Desktop/Frappe/frappe-bench/env/lib/python3.11/site-packages/rq/worker.py", line 832, in register_death
    p.execute()
  File "/Users/upforcetech/Desktop/Frappe/frappe-bench/env/lib/python3.11/site-packages/redis/client.py", line 2114, in execute
    conn = self.connection_pool.get_connection("MULTI", self.shard_hint)
           ^^^^^^^^^^^^^^^^^^^^^^^^^^^^^^^^^^^^^^^^^^^^^^^^^^^^^^^^^^^^^
  File "/Users/upforcetech/Desktop/Frappe/frappe-bench/env/lib/python3.11/site-packages/redis/connection.py", line 1457, in get_connection
    connection.connect()
  File "/Users/upforcetech/Desktop/Frappe/frappe-bench/env/lib/python3.11/site-packages/redis/connection.py", line 705, in connect
    raise ConnectionError(self._error_message(e))
redis.exceptions.ConnectionError: Error 61 connecting to 127.0.0.1:11010. Connection refused.
^Traceback (most recent call last):
  File "<frozen runpy>", line 198, in _run_module_as_main
  File "<frozen runpy>", line 88, in _run_code
  File "/Users/upforcetech/Desktop/Frappe/frappe-bench/apps/frappe/frappe/utils/bench_helper.py", line 114, in <module>
    main()
  File "/Users/upforcetech/Desktop/Frappe/frappe-bench/apps/frappe/frappe/utils/bench_helper.py", line 20, in main
    click.Group(commands=commands)(prog_name="bench")
  File "/Users/upforcetech/Desktop/Frappe/frappe-bench/env/lib/python3.11/site-packages/click/core.py", line 1161, in __call__
Exception in thread Thread-1:
Traceback (most recent call last):
  File "/Users/upforcetech/.pyenv/versions/3.11.8/lib/python3.11/threading.py", line 1045, in _bootstrap_inner
    self.run()
  File "/Users/upforcetech/Desktop/Frappe/frappe-bench/env/lib/python3.11/site-packages/redis/client.py", line 1799, in run
    pubsub.get_message(ignore_subscribe_messages=True, timeout=sleep_time)
  File "/Users/upforcetech/Desktop/Frappe/frappe-bench/env/lib/python3.11/site-packages/redis/client.py", line 1690, in get_message
    response = self.parse_response(block=(timeout is None), timeout=timeout)
               ^^^^^^^^^^^^^^^^^^^^^^^^^^^^^^^^^^^^^^^^^^^^^^^^^^^^^^^^^^^^^
  File "/Users/upforcetech/Desktop/Frappe/frappe-bench/env/lib/python3.11/site-packages/redis/client.py", line 1542, in parse_response
    response = self._execute(conn, try_read)
               ^^^^^^^^^^^^^^^^^^^^^^^^^^^^^
  File "/Users/upforcetech/Desktop/Frappe/frappe-bench/env/lib/python3.11/site-packages/redis/client.py", line 1518, in _execute
    return conn.retry.call_with_retry(
           ^^^^^^^^^^^^^^^^^^^^^^^^^^^
  File "/Users/upforcetech/Desktop/Frappe/frappe-bench/env/lib/python3.11/site-packages/redis/retry.py", line 49, in call_with_retry
    fail(error)
  File "/Users/upforcetech/Desktop/Frappe/frappe-bench/env/lib/python3.11/site-packages/redis/client.py", line 1520, in <lambda>
    lambda error: self._disconnect_raise_connect(conn, error),
                  ^^^^^^^^^^^^^^^^^^^^^^^^^^^^^^^^^^^^^^^^^^^
  File "/Users/upforcetech/Desktop/Frappe/frappe-bench/env/lib/python3.11/site-packages/redis/client.py", line 1507, in _disconnect_raise_connect
    raise error
  File "/Users/upforcetech/Desktop/Frappe/frappe-bench/env/lib/python3.11/site-packages/redis/retry.py", line 46, in call_with_retry
    return do()
           ^^^^
  File "/Users/upforcetech/Desktop/Frappe/frappe-bench/env/lib/python3.11/site-packages/redis/client.py", line 1519, in <lambda>
    lambda: command(*args, **kwargs),
            ^^^^^^^^^^^^^^^^^^^^^^^^
  File "/Users/upforcetech/Desktop/Frappe/frappe-bench/env/lib/python3.11/site-packages/redis/client.py", line 1536, in try_read
    if not conn.can_read(timeout=timeout):
           ^^^^^^^^^^^^^^^^^^^^^^^^^^^^^^
  File "/Users/upforcetech/Desktop/Frappe/frappe-bench/env/lib/python3.11/site-packages/redis/connection.py", line 861, in can_read
    return self._parser.can_read(timeout)
           ^^^^^^^^^^^^^^^^^^^^^^^^^^^^^^
  File "/Users/upforcetech/Desktop/Frappe/frappe-bench/env/lib/python3.11/site-packages/redis/connection.py", line 444, in can_read
    return self.read_from_socket(timeout=timeout, raise_on_timeout=False)
           ^^^^^^^^    return self.main(*args, **kwargs)
           ^^^^^^^^^^^^^^^^^^^^^^^^^^
  File "/Users/upforcetech/Desktop/Frappe/frappe-bench/env/lib/python3.11/site-packages/click/core.py", line 1082, in main
    rv = self.invoke(ctx)
         ^^^^^^^^^^^^^^^^
  File "/Users/upforcetech/Desktop/Frappe/frappe-bench/env/lib/python3.11/site-packages/click/core.py", line 1697, in invoke
    return _process_result(sub_ctx.command.invoke(sub_ctx))
                           ^^^^^^^^^^^^^^^^^^^^^^^^^^^^^^^
  File "/Users/upforcetech/Desktop/Frappe/frappe-bench/env/lib/python3.11/site-packages/click/core.py", line 1697, in invoke
    return _process_result(sub_ctx.command.invoke(sub_ctx))
                           ^^^^^^^^^^^^^^^^^^^^^^^^^^^^^^^
  File "/Users/upforcetech/Desktop/Frappe/frappe-bench/env/lib/python3.11/site-packages/click/core.py", line 1443, in invoke
    return ctx.invoke(self.callback, **ctx.params)
           ^^^^^^^^^^^^^^^^^^^^^^^^^^^^^^^^^^^^^^^
  File "/Users/upforcetech/Desktop/Frappe/frappe-bench/env/lib/python3.11/site-packages/click/core.py", line 788, in invoke
    return __callback(*args, **kwargs)
           ^^^^^^^^^^^^^^^^^^^^^^^^^^^^^^^^^^^^^^^^^^^^^^
  File "/Users/upforcetech/Desktop/Frappe/frappe-bench/apps/frappe/frappe/commands/scheduler.py", line 205, in start_worker
    start_worker(
  File "/Users/upforcetech/Desktop/Frappe/frappe-bench/apps/frappe/frappe/utils/background_jobs.py", line 318, in start_worker
^^    ^^^^^^^^^^^^^^^^^^^^^^^^^^^^worker.work(^^^^^

  File "/Users/upforcetech/Desktop/Frappe/frappe-bench/env/lib/python3.11/site-packages/redis/connection.py", line 455, in read_from_socket
  File "/Users/upforcetech/Desktop/Frappe/frappe-bench/env/lib/python3.11/site-packages/rq/worker.py", line 456, in work
    raise ConnectionError(SERVER_CLOSED_CONNECTION_ERROR)
redis.exceptions.ConnectionError:     self.teardown()
  File "/Users/upforcetech/Desktop/Frappe/frappe-bench/env/lib/python3.11/site-packages/rq/worker.py", line 1046, in teardown
Connection closed by server.
    self.register_death()
  File "/Users/upforcetech/Desktop/Frappe/frappe-bench/env/lib/python3.11/site-packages/rq/worker.py", line 832, in register_death
    p.execute()
  File "/Users/upforcetech/Desktop/Frappe/frappe-bench/env/lib/python3.11/site-packages/redis/client.py", line 2120, in execute
    return conn.retry.call_with_retry(
           ^^^^^^^^^^^^^^^^^^^^^^^^^^^
  File "/Users/upforcetech/Desktop/Frappe/frappe-bench/env/lib/python3.11/site-packages/redis/retry.py", line 49, in call_with_retry
    fail(error)
  File "/Users/upforcetech/Desktop/Frappe/frappe-bench/env/lib/python3.11/site-packages/redis/client.py", line 2122, in <lambda>
    lambda error: self._disconnect_raise_reset(conn, error),
                  ^^^^^^^^^^^^^^^^^^^^^^^^^^^^^^^^^^^^^^^^^
  File "/Users/upforcetech/Desktop/Frappe/frappe-bench/env/lib/python3.11/site-packages/redis/retry.py", line 46, in call_with_retry
    return do()
           ^^^^
  File "/Users/upforcetech/Desktop/Frappe/frappe-bench/env/lib/python3.11/site-packages/redis/client.py", line 2121, in <lambda>
    lambda: execute(conn, stack, raise_on_error),
            ^^^^^^^^^^^^^^^^^^^^^^^^^^^^^^^^^^^^
  File "/Users/upforcetech/Desktop/Frappe/frappe-bench/env/lib/python3.11/site-packages/redis/client.py", line 1975, in _execute_transaction
    self.parse_response(connection, "_")
  File "/Users/upforcetech/Desktop/Frappe/frappe-bench/env/lib/python3.11/site-packages/redis/client.py", line 2060, in parse_response
    result = Redis.parse_response(self, connection, command_name, **options)
             ^^^^^^^^^^^^^^^^^^^^^^^^^^^^^^^^^^^^^^^^^^^^^^^^^^^^^^^^^^^^^^^
  File "/Users/upforcetech/Desktop/Frappe/frappe-bench/env/lib/python3.11/site-packages/redis/client.py", line 1286, in parse_response
    response = connection.read_response()
               ^^^^^^^^^^^^^^^^^^^^^^^^^^
  File "/Users/upforcetech/Desktop/Frappe/frappe-bench/env/lib/python3.11/site-packages/redis/connection.py", line 874, in read_response
    response = self._parser.read_response(disable_decoding=disable_decoding)
               ^^^^^^^^^^^^^^^^^^^^^^^^^^^^^^^^^^^^^^^^^^^^^^^^^^^^^^^^^^^^^
  File "/Users/upforcetech/Desktop/Frappe/frappe-bench/env/lib/python3.11/site-packages/redis/connection.py", line 493, in read_response
    self.read_from_socket()
  File "/Users/upforcetech/Desktop/Frappe/frappe-bench/env/lib/python3.11/site-packages/redis/connection.py", line 455, in read_from_socket
    raise ConnectionError(SERVER_CLOSED_CONNECTION_ERROR)
redis.exceptions.ConnectionError: Connection closed by server.
/Users/upforcetech/Desktop/Frappe/frappe-bench/env/lib/python3.11/site-packages/rq/connections.py:58: DeprecationWarning: The `push_connection` function is deprecated. Pass the `connection` explicitly instead.
  warnings.warn(
/Users/upforcetech/Desktop/Frappe/frappe-bench/env/lib/python3.11/site-packages/passlib/utils/__init__.py:854: DeprecationWarning: 'crypt' is deprecated and slated for removal in Python 3.13
  from crypt import crypt as _crypt
/Users/upforcetech/Desktop/Frappe/frappe-bench/env/lib/python3.11/site-packages/rq/connections.py:72: DeprecationWarning: The `pop_connection` function is deprecated. Pass the `connection` explicitly instead.
  warnings.warn(
/Users/upforcetech/Desktop/Frappe/frappe-bench/env/lib/python3.11/site-packages/rq/connections.py:58: DeprecationWarning: The `push_connection` function is deprecated. Pass the `connection` explicitly instead.
  warnings.warn(
/Users/upforcetech/Desktop/Frappe/frappe-bench/env/lib/python3.11/site-packages/passlib/utils/__init__.py:854: DeprecationWarning: 'crypt' is deprecated and slated for removal in Python 3.13
  from crypt import crypt as _crypt
/Users/upforcetech/Desktop/Frappe/frappe-bench/env/lib/python3.11/site-packages/rq/connections.py:72: DeprecationWarning: The `pop_connection` function is deprecated. Pass the `connection` explicitly instead.
  warnings.warn(
Traceback (most recent call last):
  File "/Users/upforcetech/Desktop/Frappe/frappe-bench/env/lib/python3.11/site-packages/redis/connection.py", line 874, in read_response
Exception in thread Thread-1:
Traceback (most recent call last):
  File "/Users/upforcetech/.pyenv/versions/3.11.8/lib/python3.11/threading.py", line 1045, in _bootstrap_inner
    response = self._parser.read_response(disable_decoding=disable_decoding)
               ^^^^^^^^^^^^^^^^^^^^^^^^^^^^^^^^^^^^^^^^^^^^^^^^^^^^^^^^^^^^^
  File "/Users/upforcetech/Desktop/Frappe/frappe-bench/env/lib/python3.11/site-packages/redis/connection.py", line 493, in read_response
    self.read_from_socket()
  File "/Users/upforcetech/Desktop/Frappe/frappe-bench/env/lib/python3.11/site-packages/redis/connection.py", line 453, in read_from_socket
    bufflen = self._sock.recv_into(self._buffer)
              ^    self.run()
  File "/Users/upforcetech/Desktop/Frappe/frappe-bench/env/lib/python3.11/site-packages/redis/client.py", line 1799, in run
    pubsub.get_message(ignore_subscribe_messages=True, timeout=sleep_time)
  File "/Users/upforcetech/Desktop/Frappe/frappe-bench/env/lib/python3.11/site-packages/redis/client.py", line 1690, in get_message
    response = self.parse_response(block=(timeout is None), timeout=timeout)
               ^^^^^^^^^^^^^^^^^^^^^^^^^^^^^^^^^^^^^^^^^^^^^^^^^^^^^^^^^^^^^
  File "/Users/upforcetech/Desktop/Frappe/frappe-bench/env/lib/python3.11/site-packages/redis/client.py", line 1542, in parse_response
    response = self._execute(conn, try_read)
               ^^^^^^^^^^^^^^^^^^^^^^^^^^^^^
  File "/Users/upforcetech/Desktop/Frappe/frappe-bench/env/lib/python3.11/site-packages/redis/client.py", line 1518, in _execute
    return conn.retry.call_with_retry(
           ^^^^^^^^^^^^^^^^^^^^^^^^^^^^^^^^^^^^^^^
ConnectionResetError: [Errno 54] Connection reset by peer

During handling of the above exception, another exception occurred:

Traceback (most recent call last):
  File "<frozen runpy>", line 198, in _run_module_as_main
  File "<frozen runpy>", line 88, in _run_code
  File "/Users/upforcetech/Desktop/Frappe/frappe-bench/apps/frappe/frappe/utils/bench_helper.py", line 114, in <module>
    main()
  File "/Users/upforcetech/Desktop/Frappe/frappe-bench/apps/frappe/frappe/utils/bench_helper.py", line 20, in main
    click.Group(commands=commands)(prog_name="bench")
  File "/Users/upforcetech/Desktop/Frappe/frappe-bench/env/lib/python3.11/site-packages/click/core.py", line 1161, in __call__
    return self.main(*args, **kwargs)
           ^^^^^^^^^^^^^^^^^^^^^^^^^^
  File "/Users/upforcetech/Desktop/Frappe/frappe-bench/env/lib/python3.11/site-packages/click/core.py", line 1082, in main
    rv = self.invoke(ctx)
         ^^^^^^^^^^^^^^^^
  File "/Users/upforcetech/Desktop/Frappe/frappe-bench/env/lib/python3.11/site-packages/click/core.py", line 1697, in invoke
^^^^^^^^^    return _process_result(sub_ctx.command.invoke(sub_ctx))
                           ^^^^^^^^^^^^^^^^^^^^^^^^^^^^^^^
  File "/Users/upforcetech/Desktop/Frappe/frappe-bench/env/lib/python3.11/site-packages/click/core.py", line 1697, in invoke
    return _process_result(sub_ctx.command.invoke(sub_ctx))
                           ^^^^^^^^^^^^^^^^^^^^^^^^^^^^^^^
  File "/Users/upforcetech/Desktop/Frappe/frappe-bench/env/lib/python3.11/site-packages/click/core.py", line 1443, in invoke
    return ctx.invoke(self.callback, **ctx.params)
           ^^^^^^^^^^^^^^^^^^^^^^^^^^^^^^^^^^^^^^^
  File "/Users/upforcetech/Desktop/Frappe/frappe-bench/env/lib/python3.11/site-packages/click/core.py", line 788, in invoke
    return __callback(*args, **kwargs)
           ^^^^^^^^^^^^^^^^^^^^^^^^^^^
  File "/Users/upforcetech/Desktop/Frappe/frappe-bench/apps/frappe/frappe/commands/scheduler.py", line 205, in start_worker
    start_worker(
  File "/Users/upforcetech/Desktop/Frappe/frappe-bench/apps/frappe/frappe/utils/background_jobs.py", line 318, in start_worker
    worker.work(
  File "/Users/upforcetech/Desktop/Frappe/frappe-bench/env/lib/python3.11/site-packages/rq/worker.py", line 456, in work
    self.teardown()
  File "/Users/upforcetech/Desktop/Frappe/frappe-bench/env/lib/python3.11/site-packages/rq/worker.py", line 1046, in teardown
    self.register_death()
  File "/Users/upforcetech/Desktop/Frappe/frappe-bench/env/lib/python3.11/site-packages/rq/worker.py", line 832, in register_death
    p.execute()
  File "/Users/upforcetech/Desktop/Frappe/frappe-bench/env/lib/python3.11/site-packages/redis/client.py", line 2120, in execute
    return conn.retry.call_with_retry(
^           ^^^^^^^^^^^^^^^^^^^^^^^^^^^
  File "/Users/upforcetech/Desktop/Frappe/frappe-bench/env/lib/python3.11/site-packages/redis/retry.py", line 49, in call_with_retry
    fail(error)
  File "/Users/upforcetech/Desktop/Frappe/frappe-bench/env/lib/python3.11/site-packages/redis/client.py", line 2122, in <lambda>
^^^^^^^^^^^
    lambda error: self._disconnect_raise_reset(conn, error),
                  ^^^^^^^^^^^^^^^^^^^^^^^^^^^^^^^^^^^^^^^^^
  File "/Users/upforcetech/Desktop/Frappe/frappe-bench/env/lib/python3.11/site-packages/redis/retry.py", line 46, in call_with_retry
    return do()
           ^^^^
  File "/Users/upforcetech/Desktop/Frappe/frappe-bench/env/lib/python3.11/site-packages/redis/client.py", line 2121, in <lambda>
  File "/Users/upforcetech/Desktop/Frappe/frappe-bench/env/lib/python3.11/site-packages/redis/retry.py", line 49, in call_with_retry
    lambda: execute(conn, stack, raise_on_error),
            ^^^^^^^^^^^^^^^^^^^^^^^^^^^^^^^^^^^^
  File "/Users/upforcetech/Desktop/Frappe/frappe-bench/env/lib/python3.11/site-packages/redis/client.py", line 1975, in _execute_transaction
    self.parse_response(connection, "_")
  File "/Users/upforcetech/Desktop/Frappe/frappe-bench/env/lib/python3.11/site-packages/redis/client.py", line 2060, in parse_response
    result = Redis.parse_response(self, connection, command_name, **options)
             ^^^^^^^^^^^^^^^^^^^^^^^^^^^^^^^^^^^^^^^^^^^^^^^^^^^^^^^^^^^^^^^
  File "/Users/upforcetech/Desktop/Frappe/frappe-bench/env/lib/python3.11/site-packages/redis/client.py", line 1286, in parse_response
    fail(error)
  File "/Users/upforcetech/Desktop/Frappe/frappe-bench/env/lib/python3.11/site-packages/redis/client.py", line 1520, in <lambda>
    lambda error: self._disconnect_raise_connect(conn, error),
                  ^^^^^^^^^^^^^^^^^^^^^^^^^^^^^^^^^^^^^^^^^^^
  File "/Users/upforcetech/Desktop/Frappe/frappe-bench/env/lib/python3.11/site-packages/redis/client.py", line 1507, in _disconnect_raise_connect
    raise error
  File "/Users/upforcetech/Desktop/Frappe/frappe-bench/env/lib/python3.11/site-packages/redis/retry.py", line 46, in call_with_retry
    return do()
           ^^^^
  File "/Users/upforcetech/Desktop/Frappe/frappe-bench/env/lib/python3.11/site-packages/redis/client.py", line 1519, in <lambda>
    lambda: command(*args, **kwargs),
            ^^^^^^^^^^^^^^^^^^^^^^^^
  File "/Users/upforcetech/Desktop/Frappe/frappe-bench/env/lib/python3.11/site-packages/redis/client.py", line 1536, in try_read
    if not conn.can_read(timeout=timeout):
           ^^^^^^^^^^^^^^^^^^^^^^^^^^^^^^
  File "/Users/upforcetech/Desktop/Frappe/frappe-bench/env/lib/python3.11/site-packages/redis/connection.py", line 861, in can_read
    return self._parser.can_read(timeout)
           ^^^^^^^^^^^^^^^^^^^^^^^^^^^^^^
  File "/Users/upforcetech/Desktop/Frappe/frappe-bench/env/lib/python3.11/site-packages/redis/connection.py", line 444, in can_read
    return self.read_from_socket(timeout=timeout, raise_on_timeout=False)
           ^^^^^^^^^^^^^^^^    response = connection.read_response()
               ^^^^^^^^^^^^^^^^^^^^^^^^^^
  File "/Users/upforcetech/Desktop/Frappe/frappe-bench/env/lib/python3.11/site-packages/redis/connection.py", line 882, in read_response
^    raise ConnectionError(
redis.exceptions.ConnectionError: Error while reading from 127.0.0.1:11010 : (54, 'Connection reset by peer')
/Users/upforcetech/Desktop/Frappe/frappe-bench/env/lib/python3.11/site-packages/rq/connections.py:58: DeprecationWarning: The `push_connection` function is deprecated. Pass the `connection` explicitly instead.
  warnings.warn(
/Users/upforcetech/Desktop/Frappe/frappe-bench/env/lib/python3.11/site-packages/passlib/utils/__init__.py:854: DeprecationWarning: 'crypt' is deprecated and slated for removal in Python 3.13
  from crypt import crypt as _crypt
/Users/upforcetech/Desktop/Frappe/frappe-bench/env/lib/python3.11/site-packages/rq/connections.py:72: DeprecationWarning: The `pop_connection` function is deprecated. Pass the `connection` explicitly instead.
  warnings.warn(
/Users/upforcetech/Desktop/Frappe/frappe-bench/env/lib/python3.11/site-packages/rq/connections.py:58: DeprecationWarning: The `push_connection` function is deprecated. Pass the `connection` explicitly instead.
  warnings.warn(
/Users/upforcetech/Desktop/Frappe/frappe-bench/env/lib/python3.11/site-packages/passlib/utils/__init__.py:854: DeprecationWarning: 'crypt' is deprecated and slated for removal in Python 3.13
  from crypt import crypt as _crypt
/Users/upforcetech/Desktop/Frappe/frappe-bench/env/lib/python3.11/site-packages/rq/connections.py:72: DeprecationWarning: The `pop_connection` function is deprecated. Pass the `connection` explicitly instead.
  warnings.warn(
Exception in thread Thread-1:
Traceback (most recent call last):
  File "/Users/upforcetech/.pyenv/versions/3.11.8/lib/python3.11/threading.py", line 1045, in _bootstrap_inner
    self.run()
  File "/Users/upforcetech/Desktop/Frappe/frappe-bench/env/lib/python3.11/site-packages/redis/client.py", line 1799, in run
    pubsub.get_message(ignore_subscribe_messages=True, timeout=sleep_time)
  File "/Users/upforcetech/Desktop/Frappe/frappe-bench/env/lib/python3.11/site-packages/redis/client.py", line 1690, in get_message
    response = self.parse_response(block=(timeout is None), timeout=timeout)
               ^^^^^^^^^^^^^^^^^^^^^^^^^^^^^^^^^^^^^^^^^^^^^^^^^^^^^^^^^^^^^
  File "/Users/upforcetech/Desktop/Frappe/frappe-bench/env/lib/python3.11/site-packages/redis/client.py", line 1542, in parse_response
    response = self._execute(conn, try_read)
               ^^^^^^^^^^^^^^^^^^^^^^^^^^^^^
  File "/Users/upforcetech/Desktop/Frappe/frappe-bench/env/lib/python3.11/site-packages/redis/client.py", line 1518, in _execute
    return conn.retry.call_with_retry(
           ^^^^^^^^^^^^^^^^^^^^^^^^^^^
  File "/Users/upforcetech/Desktop/Frappe/frappe-bench/env/lib/python3.11/site-packages/redis/retry.py", line 49, in call_with_retry
    fail(error)
  File "/Users/upforcetech/Desktop/Frappe/frappe-bench/env/lib/python3.11/site-packages/redis/client.py", line 1520, in <lambda>
    lambda error: self._disconnect_raise_connect(conn, error),
                  ^^^^^^^^^^^^^^^^^^^^^^^^^^^^^^^^^^^^^^^^^^^
  File "/Users/upforcetech/Desktop/Frappe/frappe-bench/env/lib/python3.11/site-packages/redis/client.py", line 1507, in _disconnect_raise_connect
    raise error
  File "/Users/upforcetech/Desktop/Frappe/frappe-bench/env/lib/python3.11/site-packages/redis/retry.py", line 46, in call_with_retry
    return do()
           ^^^^
  File "/Users/upforcetech/Desktop/Frappe/frappe-bench/env/lib/python3.11/site-packages/redis/client.py", line 1519, in <lambda>
    lambda: command(*args, **kwargs),
            ^^^^^^^^^^^^^^^^^^^^^^^^
  File "/Users/upforcetech/Desktop/Frappe/frappe-bench/env/lib/python3.11/site-packages/redis/client.py", line 1536, in try_read
    if not conn.can_read(timeout=timeout):
           ^^^^^^^^^^^^^^^^^^^^^^^^^^^^^^
  File "/Users/upforcetech/Desktop/Frappe/frappe-bench/env/lib/python3.11/site-packages/redis/connection.py", line 861, in can_read
    return self._parser.can_read(timeout)
           ^^^^^^^^^^^^^^^^^^^^^^^^^^^^^^
  File "/Users/upforcetech/Desktop/Frappe/frappe-bench/env/lib/python3.11/site-packages/redis/connection.py", line 444, in can_read
    return self.read_from_socket(timeout=timeout, raise_on_timeout=False)
           ^^^^^^^^^^^^^^^^^^^^^^^^^^^^^^^^^^^^^^^^^^^^^^^^^^^^^^^^^^^^^^
  File "/Users/upforcetech/Desktop/Frappe/frappe-bench/env/lib/python3.11/site-packages/redis/connection.py", line 455, in read_from_socket
    raise ConnectionError(SERVER_CLOSED_CONNECTION_ERROR)
redis.exceptions.ConnectionError: Connection closed by server.
Traceback (most recent call last):
  File "/Users/upforcetech/Desktop/Frappe/frappe-bench/env/lib/python3.11/site-packages/redis/connection.py", line 699, in connect
    sock = self.retry.call_with_retry(
           ^^^^^^^^^^^^^^^^^^^^^^^^^^^
  File "/Users/upforcetech/Desktop/Frappe/frappe-bench/env/lib/python3.11/site-packages/redis/retry.py", line 46, in call_with_retry
    return do()
           ^^^^
  File "/Users/upforcetech/Desktop/Frappe/frappe-bench/env/lib/python3.11/site-packages/redis/connection.py", line 700, in <lambda>
    lambda: self._connect(), lambda error: self.disconnect(error)
            ^^^^^^^^^^^^^^^
  File "/Users/upforcetech/Desktop/Frappe/frappe-bench/env/lib/python3.11/site-packages/redis/connection.py", line 1002, in _connect
    raise err
  File "/Users/upforcetech/Desktop/Frappe/frappe-bench/env/lib/python3.11/site-packages/redis/connection.py", line 990, in _connect
    sock.connect(socket_address)
ConnectionRefusedError: [Errno 61] Connection refused

During handling of the above exception, another exception occurred:

Traceback (most recent call last):
  File "<frozen runpy>", line 198, in _run_module_as_main
  File "<frozen runpy>", line 88, in _run_code
  File "/Users/upforcetech/Desktop/Frappe/frappe-bench/apps/frappe/frappe/utils/bench_helper.py", line 114, in <module>
    main()
  File "/Users/upforcetech/Desktop/Frappe/frappe-bench/apps/frappe/frappe/utils/bench_helper.py", line 20, in main
    click.Group(commands=commands)(prog_name="bench")
  File "/Users/upforcetech/Desktop/Frappe/frappe-bench/env/lib/python3.11/site-packages/click/core.py", line 1161, in __call__
    return self.main(*args, **kwargs)
           ^^^^^^^^^^^^^^^^^^^^^^^^^^
  File "/Users/upforcetech/Desktop/Frappe/frappe-bench/env/lib/python3.11/site-packages/click/core.py", line 1082, in main
    rv = self.invoke(ctx)
         ^^^^^^^^^^^^^^^^
  File "/Users/upforcetech/Desktop/Frappe/frappe-bench/env/lib/python3.11/site-packages/click/core.py", line 1697, in invoke
    return _process_result(sub_ctx.command.invoke(sub_ctx))
                           ^^^^^^^^^^^^^^^^^^^^^^^^^^^^^^^
  File "/Users/upforcetech/Desktop/Frappe/frappe-bench/env/lib/python3.11/site-packages/click/core.py", line 1697, in invoke
    return _process_result(sub_ctx.command.invoke(sub_ctx))
                           ^^^^^^^^^^^^^^^^^^^^^^^^^^^^^^^
  File "/Users/upforcetech/Desktop/Frappe/frappe-bench/env/lib/python3.11/site-packages/click/core.py", line 1443, in invoke
    return ctx.invoke(self.callback, **ctx.params)
           ^^^^^^^^^^^^^^^^^^^^^^^^^^^^^^^^^^^^^^^
  File "/Users/upforcetech/Desktop/Frappe/frappe-bench/env/lib/python3.11/site-packages/click/core.py", line 788, in invoke
    return __callback(*args, **kwargs)
           ^^^^^^^^^^^^^^^^^^^^^^^^^^^
  File "/Users/upforcetech/Desktop/Frappe/frappe-bench/apps/frappe/frappe/commands/scheduler.py", line 205, in start_worker
    start_worker(
  File "/Users/upforcetech/Desktop/Frappe/frappe-bench/apps/frappe/frappe/utils/background_jobs.py", line 318, in start_worker
    worker.work(
  File "/Users/upforcetech/Desktop/Frappe/frappe-bench/env/lib/python3.11/site-packages/rq/worker.py", line 456, in work
    self.teardown()
  File "/Users/upforcetech/Desktop/Frappe/frappe-bench/env/lib/python3.11/site-packages/rq/worker.py", line 1047, in teardown
    self.unsubscribe()
  File "/Users/upforcetech/Desktop/Frappe/frappe-bench/env/lib/python3.11/site-packages/rq/worker.py", line 624, in unsubscribe
    self.pubsub.unsubscribe()
  File "/Users/upforcetech/Desktop/Frappe/frappe-bench/env/lib/python3.11/site-packages/redis/client.py", line 1659, in unsubscribe
    return self.execute_command("UNSUBSCRIBE", *args)
           ^^^^^^^^^^^^^^^^^^^^^^^^^^^^^^^^^^^^^^^^^^
  File "/Users/upforcetech/Desktop/Frappe/frappe-bench/env/lib/python3.11/site-packages/redis/client.py", line 1479, in execute_command
    self._execute(connection, connection.send_command, *args, **kwargs)
  File "/Users/upforcetech/Desktop/Frappe/frappe-bench/env/lib/python3.11/site-packages/redis/client.py", line 1518, in _execute
    return conn.retry.call_with_retry(
           ^^^^^^^^^^^^^^^^^^^^^^^^^^^
  File "/Users/upforcetech/Desktop/Frappe/frappe-bench/env/lib/python3.11/site-packages/redis/retry.py", line 49, in call_with_retry
    fail(error)
  File "/Users/upforcetech/Desktop/Frappe/frappe-bench/env/lib/python3.11/site-packages/redis/client.py", line 1520, in <lambda>
    lambda error: self._disconnect_raise_connect(conn, error),
                  ^^^^^^^^^^^^^^^^^^^^^^^^^^^^^^^^^^^^^^^^^^^
  File "/Users/upforcetech/Desktop/Frappe/frappe-bench/env/lib/python3.11/site-packages/redis/client.py", line 1507, in _disconnect_raise_connect
    raise error
  File "/Users/upforcetech/Desktop/Frappe/frappe-bench/env/lib/python3.11/site-packages/redis/retry.py", line 46, in call_with_retry
    return do()
           ^^^^
  File "/Users/upforcetech/Desktop/Frappe/frappe-bench/env/lib/python3.11/site-packages/redis/client.py", line 1519, in <lambda>
    lambda: command(*args, **kwargs),
            ^^^^^^^^^^^^^^^^^^^^^^^^
  File "/Users/upforcetech/Desktop/Frappe/frappe-bench/env/lib/python3.11/site-packages/redis/connection.py", line 847, in send_command
    self.send_packed_command(
  File "/Users/upforcetech/Desktop/Frappe/frappe-bench/env/lib/python3.11/site-packages/redis/connection.py", line 817, in send_packed_command
    self.connect()
  File "/Users/upforcetech/Desktop/Frappe/frappe-bench/env/lib/python3.11/site-packages/redis/connection.py", line 705, in connect
    raise ConnectionError(self._error_message(e))
redis.exceptions.ConnectionError: Error 61 connecting to 127.0.0.1:11010. Connection refused.
Exception in thread Thread-1:
Traceback (most recent call last):
  File "/Users/upforcetech/.pyenv/versions/3.11.8/lib/python3.11/threading.py", line 1045, in _bootstrap_inner
    self.run()
  File "/Users/upforcetech/Desktop/Frappe/frappe-bench/env/lib/python3.11/site-packages/redis/client.py", line 1799, in run
    pubsub.get_message(ignore_subscribe_messages=True, timeout=sleep_time)
  File "/Users/upforcetech/Desktop/Frappe/frappe-bench/env/lib/python3.11/site-packages/redis/client.py", line 1690, in get_message
    response = self.parse_response(block=(timeout is None), timeout=timeout)
               ^^^^^^^^^^^^^^^^^^^^^^^^^^^^^^^^^^^^^^^^^^^^^^^^^^^^^^^^^^^^^
  File "/Users/upforcetech/Desktop/Frappe/frappe-bench/env/lib/python3.11/site-packages/redis/client.py", line 1542, in parse_response
    response = self._execute(conn, try_read)
               ^^^^^^^^^^^^^^^^^^^^^^^^^^^^^
  File "/Users/upforcetech/Desktop/Frappe/frappe-bench/env/lib/python3.11/site-packages/redis/client.py", line 1518, in _execute
    return conn.retry.call_with_retry(
           ^^^^^^^^^^^^^^^^^^^^^^^^^^^
  File "/Users/upforcetech/Desktop/Frappe/frappe-bench/env/lib/python3.11/site-packages/redis/retry.py", line 49, in call_with_retry
    fail(error)
  File "/Users/upforcetech/Desktop/Frappe/frappe-bench/env/lib/python3.11/site-packages/redis/client.py", line 1520, in <lambda>
    lambda error: self._disconnect_raise_connect(conn, error),
                  ^^^^^^^^^^^^^^^^^^^^^^^^^^^^^^^^^^^^^^^^^^^
  File "/Users/upforcetech/Desktop/Frappe/frappe-bench/env/lib/python3.11/site-packages/redis/client.py", line 1507, in _disconnect_raise_connect
    raise error
  File "/Users/upforcetech/Desktop/Frappe/frappe-bench/env/lib/python3.11/site-packages/redis/retry.py", line 46, in call_with_retry
    return do()
           ^^^^
  File "/Users/upforcetech/Desktop/Frappe/frappe-bench/env/lib/python3.11/site-packages/redis/client.py", line 1519, in <lambda>
    lambda: command(*args, **kwargs),
            ^^^^^^^^^^^^^^^^^^^^^^^^
  File "/Users/upforcetech/Desktop/Frappe/frappe-bench/env/lib/python3.11/site-packages/redis/client.py", line 1536, in try_read
    if not conn.can_read(timeout=timeout):
           ^^^^^^^^^^^^^^^^^^^^^^^^^^^^^^
  File "/Users/upforcetech/Desktop/Frappe/frappe-bench/env/lib/python3.11/site-packages/redis/connection.py", line 861, in can_read
    return self._parser.can_read(timeout)
           ^^^^^^^^^^^^^^^^^^^^^^^^^^^^^^
  File "/Users/upforcetech/Desktop/Frappe/frappe-bench/env/lib/python3.11/site-packages/redis/connection.py", line 444, in can_read
    return self.read_from_socket(timeout=timeout, raise_on_timeout=False)
           ^^^^^^^^^^^^^^^^^^^^^^^^^^^^^^^^^^^^^^^^^^^^^^^^^^^^^^^^^^^^^^
  File "/Users/upforcetech/Desktop/Frappe/frappe-bench/env/lib/python3.11/site-packages/redis/connection.py", line 455, in read_from_socket
    raise ConnectionError(SERVER_CLOSED_CONNECTION_ERROR)
redis.exceptions.ConnectionError: Connection closed by server.
Traceback (most recent call last):
  File "/Users/upforcetech/Desktop/Frappe/frappe-bench/env/lib/python3.11/site-packages/redis/connection.py", line 699, in connect
    sock = self.retry.call_with_retry(
           ^^^^^^^^^^^^^^^^^^^^^^^^^^^
  File "/Users/upforcetech/Desktop/Frappe/frappe-bench/env/lib/python3.11/site-packages/redis/retry.py", line 46, in call_with_retry
    return do()
           ^^^^
  File "/Users/upforcetech/Desktop/Frappe/frappe-bench/env/lib/python3.11/site-packages/redis/connection.py", line 700, in <lambda>
    lambda: self._connect(), lambda error: self.disconnect(error)
            ^^^^^^^^^^^^^^^
  File "/Users/upforcetech/Desktop/Frappe/frappe-bench/env/lib/python3.11/site-packages/redis/connection.py", line 1002, in _connect
    raise err
  File "/Users/upforcetech/Desktop/Frappe/frappe-bench/env/lib/python3.11/site-packages/redis/connection.py", line 990, in _connect
    sock.connect(socket_address)
ConnectionRefusedError: [Errno 61] Connection refused

During handling of the above exception, another exception occurred:

Traceback (most recent call last):
  File "<frozen runpy>", line 198, in _run_module_as_main
  File "<frozen runpy>", line 88, in _run_code
  File "/Users/upforcetech/Desktop/Frappe/frappe-bench/apps/frappe/frappe/utils/bench_helper.py", line 114, in <module>
    main()
  File "/Users/upforcetech/Desktop/Frappe/frappe-bench/apps/frappe/frappe/utils/bench_helper.py", line 20, in main
    click.Group(commands=commands)(prog_name="bench")
  File "/Users/upforcetech/Desktop/Frappe/frappe-bench/env/lib/python3.11/site-packages/click/core.py", line 1161, in __call__
    return self.main(*args, **kwargs)
           ^^^^^^^^^^^^^^^^^^^^^^^^^^
  File "/Users/upforcetech/Desktop/Frappe/frappe-bench/env/lib/python3.11/site-packages/click/core.py", line 1082, in main
    rv = self.invoke(ctx)
         ^^^^^^^^^^^^^^^^
  File "/Users/upforcetech/Desktop/Frappe/frappe-bench/env/lib/python3.11/site-packages/click/core.py", line 1697, in invoke
    return _process_result(sub_ctx.command.invoke(sub_ctx))
                           ^^^^^^^^^^^^^^^^^^^^^^^^^^^^^^^
  File "/Users/upforcetech/Desktop/Frappe/frappe-bench/env/lib/python3.11/site-packages/click/core.py", line 1697, in invoke
    return _process_result(sub_ctx.command.invoke(sub_ctx))
                           ^^^^^^^^^^^^^^^^^^^^^^^^^^^^^^^
  File "/Users/upforcetech/Desktop/Frappe/frappe-bench/env/lib/python3.11/site-packages/click/core.py", line 1443, in invoke
    return ctx.invoke(self.callback, **ctx.params)
           ^^^^^^^^^^^^^^^^^^^^^^^^^^^^^^^^^^^^^^^
  File "/Users/upforcetech/Desktop/Frappe/frappe-bench/env/lib/python3.11/site-packages/click/core.py", line 788, in invoke
    return __callback(*args, **kwargs)
           ^^^^^^^^^^^^^^^^^^^^^^^^^^^
  File "/Users/upforcetech/Desktop/Frappe/frappe-bench/apps/frappe/frappe/commands/scheduler.py", line 205, in start_worker
    start_worker(
  File "/Users/upforcetech/Desktop/Frappe/frappe-bench/apps/frappe/frappe/utils/background_jobs.py", line 318, in start_worker
    worker.work(
  File "/Users/upforcetech/Desktop/Frappe/frappe-bench/env/lib/python3.11/site-packages/rq/worker.py", line 456, in work
    self.teardown()
  File "/Users/upforcetech/Desktop/Frappe/frappe-bench/env/lib/python3.11/site-packages/rq/worker.py", line 1047, in teardown
    self.unsubscribe()
  File "/Users/upforcetech/Desktop/Frappe/frappe-bench/env/lib/python3.11/site-packages/rq/worker.py", line 624, in unsubscribe
    self.pubsub.unsubscribe()
  File "/Users/upforcetech/Desktop/Frappe/frappe-bench/env/lib/python3.11/site-packages/redis/client.py", line 1659, in unsubscribe
    return self.execute_command("UNSUBSCRIBE", *args)
           ^^^^^^^^^^^^^^^^^^^^^^^^^^^^^^^^^^^^^^^^^^
  File "/Users/upforcetech/Desktop/Frappe/frappe-bench/env/lib/python3.11/site-packages/redis/client.py", line 1479, in execute_command
    self._execute(connection, connection.send_command, *args, **kwargs)
  File "/Users/upforcetech/Desktop/Frappe/frappe-bench/env/lib/python3.11/site-packages/redis/client.py", line 1518, in _execute
    return conn.retry.call_with_retry(
           ^^^^^^^^^^^^^^^^^^^^^^^^^^^
  File "/Users/upforcetech/Desktop/Frappe/frappe-bench/env/lib/python3.11/site-packages/redis/retry.py", line 49, in call_with_retry
    fail(error)
  File "/Users/upforcetech/Desktop/Frappe/frappe-bench/env/lib/python3.11/site-packages/redis/client.py", line 1520, in <lambda>
    lambda error: self._disconnect_raise_connect(conn, error),
                  ^^^^^^^^^^^^^^^^^^^^^^^^^^^^^^^^^^^^^^^^^^^
  File "/Users/upforcetech/Desktop/Frappe/frappe-bench/env/lib/python3.11/site-packages/redis/client.py", line 1507, in _disconnect_raise_connect
    raise error
  File "/Users/upforcetech/Desktop/Frappe/frappe-bench/env/lib/python3.11/site-packages/redis/retry.py", line 46, in call_with_retry
    return do()
           ^^^^
  File "/Users/upforcetech/Desktop/Frappe/frappe-bench/env/lib/python3.11/site-packages/redis/client.py", line 1519, in <lambda>
    lambda: command(*args, **kwargs),
            ^^^^^^^^^^^^^^^^^^^^^^^^
  File "/Users/upforcetech/Desktop/Frappe/frappe-bench/env/lib/python3.11/site-packages/redis/connection.py", line 847, in send_command
    self.send_packed_command(
  File "/Users/upforcetech/Desktop/Frappe/frappe-bench/env/lib/python3.11/site-packages/redis/connection.py", line 817, in send_packed_command
    self.connect()
  File "/Users/upforcetech/Desktop/Frappe/frappe-bench/env/lib/python3.11/site-packages/redis/connection.py", line 705, in connect
    raise ConnectionError(self._error_message(e))
redis.exceptions.ConnectionError: Error 61 connecting to 127.0.0.1:11010. Connection refused.
Exception in thread Thread-1:
Traceback (most recent call last):
  File "/Users/upforcetech/.pyenv/versions/3.11.8/lib/python3.11/threading.py", line 1045, in _bootstrap_inner
    self.run()
  File "/Users/upforcetech/Desktop/Frappe/frappe-bench/env/lib/python3.11/site-packages/redis/client.py", line 1799, in run
    pubsub.get_message(ignore_subscribe_messages=True, timeout=sleep_time)
  File "/Users/upforcetech/Desktop/Frappe/frappe-bench/env/lib/python3.11/site-packages/redis/client.py", line 1690, in get_message
    response = self.parse_response(block=(timeout is None), timeout=timeout)
               ^^^^^^^^^^^^^^^^^^^^^^^^^^^^^^^^^^^^^^^^^^^^^^^^^^^^^^^^^^^^^
  File "/Users/upforcetech/Desktop/Frappe/frappe-bench/env/lib/python3.11/site-packages/redis/client.py", line 1542, in parse_response
    response = self._execute(conn, try_read)
               ^^^^^^^^^^^^^^^^^^^^^^^^^^^^^
  File "/Users/upforcetech/Desktop/Frappe/frappe-bench/env/lib/python3.11/site-packages/redis/client.py", line 1518, in _execute
    return conn.retry.call_with_retry(
           ^^^^^^^^^^^^^^^^^^^^^^^^^^^
  File "/Users/upforcetech/Desktop/Frappe/frappe-bench/env/lib/python3.11/site-packages/redis/retry.py", line 49, in call_with_retry
    fail(error)
  File "/Users/upforcetech/Desktop/Frappe/frappe-bench/env/lib/python3.11/site-packages/redis/client.py", line 1520, in <lambda>
    lambda error: self._disconnect_raise_connect(conn, error),
                  ^^^^^^^^^^^^^^^^^^^^^^^^^^^^^^^^^^^^^^^^^^^
  File "/Users/upforcetech/Desktop/Frappe/frappe-bench/env/lib/python3.11/site-packages/redis/client.py", line 1507, in _disconnect_raise_connect
    raise error
  File "/Users/upforcetech/Desktop/Frappe/frappe-bench/env/lib/python3.11/site-packages/redis/retry.py", line 46, in call_with_retry
    return do()
           ^^^^
  File "/Users/upforcetech/Desktop/Frappe/frappe-bench/env/lib/python3.11/site-packages/redis/client.py", line 1519, in <lambda>
    lambda: command(*args, **kwargs),
            ^^^^^^^^^^^^^^^^^^^^^^^^
  File "/Users/upforcetech/Desktop/Frappe/frappe-bench/env/lib/python3.11/site-packages/redis/client.py", line 1536, in try_read
    if not conn.can_read(timeout=timeout):
           ^^^^^^^^^^^^^^^^^^^^^^^^^^^^^^
  File "/Users/upforcetech/Desktop/Frappe/frappe-bench/env/lib/python3.11/site-packages/redis/connection.py", line 861, in can_read
    return self._parser.can_read(timeout)
           ^^^^^^^^^^^^^^^^^^^^^^^^^^^^^^
  File "/Users/upforcetech/Desktop/Frappe/frappe-bench/env/lib/python3.11/site-packages/redis/connection.py", line 444, in can_read
    return self.read_from_socket(timeout=timeout, raise_on_timeout=False)
           ^^^^^^^^^^^^^^^^^^^^^^^^^^^^^^^^^^^^^^^^^^^^^^^^^^^^^^^^^^^^^^
  File "/Users/upforcetech/Desktop/Frappe/frappe-bench/env/lib/python3.11/site-packages/redis/connection.py", line 455, in read_from_socket
    raise ConnectionError(SERVER_CLOSED_CONNECTION_ERROR)
redis.exceptions.ConnectionError: Connection closed by server.
Traceback (most recent call last):
  File "/Users/upforcetech/Desktop/Frappe/frappe-bench/env/lib/python3.11/site-packages/redis/connection.py", line 699, in connect
    sock = self.retry.call_with_retry(
           ^^^^^^^^^^^^^^^^^^^^^^^^^^^
  File "/Users/upforcetech/Desktop/Frappe/frappe-bench/env/lib/python3.11/site-packages/redis/retry.py", line 46, in call_with_retry
    return do()
           ^^^^
  File "/Users/upforcetech/Desktop/Frappe/frappe-bench/env/lib/python3.11/site-packages/redis/connection.py", line 700, in <lambda>
    lambda: self._connect(), lambda error: self.disconnect(error)
            ^^^^^^^^^^^^^^^
  File "/Users/upforcetech/Desktop/Frappe/frappe-bench/env/lib/python3.11/site-packages/redis/connection.py", line 1002, in _connect
    raise err
  File "/Users/upforcetech/Desktop/Frappe/frappe-bench/env/lib/python3.11/site-packages/redis/connection.py", line 990, in _connect
    sock.connect(socket_address)
ConnectionRefusedError: [Errno 61] Connection refused

During handling of the above exception, another exception occurred:

Traceback (most recent call last):
  File "<frozen runpy>", line 198, in _run_module_as_main
  File "<frozen runpy>", line 88, in _run_code
  File "/Users/upforcetech/Desktop/Frappe/frappe-bench/apps/frappe/frappe/utils/bench_helper.py", line 114, in <module>
    main()
  File "/Users/upforcetech/Desktop/Frappe/frappe-bench/apps/frappe/frappe/utils/bench_helper.py", line 20, in main
    click.Group(commands=commands)(prog_name="bench")
  File "/Users/upforcetech/Desktop/Frappe/frappe-bench/env/lib/python3.11/site-packages/click/core.py", line 1161, in __call__
    return self.main(*args, **kwargs)
           ^^^^^^^^^^^^^^^^^^^^^^^^^^
  File "/Users/upforcetech/Desktop/Frappe/frappe-bench/env/lib/python3.11/site-packages/click/core.py", line 1082, in main
    rv = self.invoke(ctx)
         ^^^^^^^^^^^^^^^^
  File "/Users/upforcetech/Desktop/Frappe/frappe-bench/env/lib/python3.11/site-packages/click/core.py", line 1697, in invoke
    return _process_result(sub_ctx.command.invoke(sub_ctx))
                           ^^^^^^^^^^^^^^^^^^^^^^^^^^^^^^^
  File "/Users/upforcetech/Desktop/Frappe/frappe-bench/env/lib/python3.11/site-packages/click/core.py", line 1697, in invoke
    return _process_result(sub_ctx.command.invoke(sub_ctx))
                           ^^^^^^^^^^^^^^^^^^^^^^^^^^^^^^^
  File "/Users/upforcetech/Desktop/Frappe/frappe-bench/env/lib/python3.11/site-packages/click/core.py", line 1443, in invoke
    return ctx.invoke(self.callback, **ctx.params)
           ^^^^^^^^^^^^^^^^^^^^^^^^^^^^^^^^^^^^^^^
  File "/Users/upforcetech/Desktop/Frappe/frappe-bench/env/lib/python3.11/site-packages/click/core.py", line 788, in invoke
    return __callback(*args, **kwargs)
           ^^^^^^^^^^^^^^^^^^^^^^^^^^^
  File "/Users/upforcetech/Desktop/Frappe/frappe-bench/apps/frappe/frappe/commands/scheduler.py", line 205, in start_worker
    start_worker(
  File "/Users/upforcetech/Desktop/Frappe/frappe-bench/apps/frappe/frappe/utils/background_jobs.py", line 318, in start_worker
    worker.work(
  File "/Users/upforcetech/Desktop/Frappe/frappe-bench/env/lib/python3.11/site-packages/rq/worker.py", line 456, in work
    self.teardown()
  File "/Users/upforcetech/Desktop/Frappe/frappe-bench/env/lib/python3.11/site-packages/rq/worker.py", line 1047, in teardown
    self.unsubscribe()
  File "/Users/upforcetech/Desktop/Frappe/frappe-bench/env/lib/python3.11/site-packages/rq/worker.py", line 624, in unsubscribe
    self.pubsub.unsubscribe()
  File "/Users/upforcetech/Desktop/Frappe/frappe-bench/env/lib/python3.11/site-packages/redis/client.py", line 1659, in unsubscribe
    return self.execute_command("UNSUBSCRIBE", *args)
           ^^^^^^^^^^^^^^^^^^^^^^^^^^^^^^^^^^^^^^^^^^
  File "/Users/upforcetech/Desktop/Frappe/frappe-bench/env/lib/python3.11/site-packages/redis/client.py", line 1479, in execute_command
    self._execute(connection, connection.send_command, *args, **kwargs)
  File "/Users/upforcetech/Desktop/Frappe/frappe-bench/env/lib/python3.11/site-packages/redis/client.py", line 1518, in _execute
    return conn.retry.call_with_retry(
           ^^^^^^^^^^^^^^^^^^^^^^^^^^^
  File "/Users/upforcetech/Desktop/Frappe/frappe-bench/env/lib/python3.11/site-packages/redis/retry.py", line 49, in call_with_retry
    fail(error)
  File "/Users/upforcetech/Desktop/Frappe/frappe-bench/env/lib/python3.11/site-packages/redis/client.py", line 1520, in <lambda>
    lambda error: self._disconnect_raise_connect(conn, error),
                  ^^^^^^^^^^^^^^^^^^^^^^^^^^^^^^^^^^^^^^^^^^^
  File "/Users/upforcetech/Desktop/Frappe/frappe-bench/env/lib/python3.11/site-packages/redis/client.py", line 1507, in _disconnect_raise_connect
    raise error
  File "/Users/upforcetech/Desktop/Frappe/frappe-bench/env/lib/python3.11/site-packages/redis/retry.py", line 46, in call_with_retry
    return do()
           ^^^^
  File "/Users/upforcetech/Desktop/Frappe/frappe-bench/env/lib/python3.11/site-packages/redis/client.py", line 1519, in <lambda>
    lambda: command(*args, **kwargs),
            ^^^^^^^^^^^^^^^^^^^^^^^^
  File "/Users/upforcetech/Desktop/Frappe/frappe-bench/env/lib/python3.11/site-packages/redis/connection.py", line 847, in send_command
    self.send_packed_command(
  File "/Users/upforcetech/Desktop/Frappe/frappe-bench/env/lib/python3.11/site-packages/redis/connection.py", line 817, in send_packed_command
    self.connect()
  File "/Users/upforcetech/Desktop/Frappe/frappe-bench/env/lib/python3.11/site-packages/redis/connection.py", line 705, in connect
    raise ConnectionError(self._error_message(e))
redis.exceptions.ConnectionError: Error 61 connecting to 127.0.0.1:11010. Connection refused.
Exception in thread Thread-1:
Traceback (most recent call last):
  File "/Users/upforcetech/.pyenv/versions/3.11.8/lib/python3.11/threading.py", line 1045, in _bootstrap_inner
    self.run()
  File "/Users/upforcetech/Desktop/Frappe/frappe-bench/env/lib/python3.11/site-packages/redis/client.py", line 1799, in run
    pubsub.get_message(ignore_subscribe_messages=True, timeout=sleep_time)
  File "/Users/upforcetech/Desktop/Frappe/frappe-bench/env/lib/python3.11/site-packages/redis/client.py", line 1690, in get_message
    response = self.parse_response(block=(timeout is None), timeout=timeout)
               ^^^^^^^^^^^^^^^^^^^^^^^^^^^^^^^^^^^^^^^^^^^^^^^^^^^^^^^^^^^^^
  File "/Users/upforcetech/Desktop/Frappe/frappe-bench/env/lib/python3.11/site-packages/redis/client.py", line 1542, in parse_response
    response = self._execute(conn, try_read)
               ^^^^^^^^^^^^^^^^^^^^^^^^^^^^^
  File "/Users/upforcetech/Desktop/Frappe/frappe-bench/env/lib/python3.11/site-packages/redis/client.py", line 1518, in _execute
    return conn.retry.call_with_retry(
           ^^^^^^^^^^^^^^^^^^^^^^^^^^^
  File "/Users/upforcetech/Desktop/Frappe/frappe-bench/env/lib/python3.11/site-packages/redis/retry.py", line 49, in call_with_retry
    fail(error)
  File "/Users/upforcetech/Desktop/Frappe/frappe-bench/env/lib/python3.11/site-packages/redis/client.py", line 1520, in <lambda>
    lambda error: self._disconnect_raise_connect(conn, error),
                  ^^^^^^^^^^^^^^^^^^^^^^^^^^^^^^^^^^^^^^^^^^^
  File "/Users/upforcetech/Desktop/Frappe/frappe-bench/env/lib/python3.11/site-packages/redis/client.py", line 1507, in _disconnect_raise_connect
    raise error
  File "/Users/upforcetech/Desktop/Frappe/frappe-bench/env/lib/python3.11/site-packages/redis/retry.py", line 46, in call_with_retry
    return do()
           ^^^^
  File "/Users/upforcetech/Desktop/Frappe/frappe-bench/env/lib/python3.11/site-packages/redis/client.py", line 1519, in <lambda>
    lambda: command(*args, **kwargs),
            ^^^^^^^^^^^^^^^^^^^^^^^^
  File "/Users/upforcetech/Desktop/Frappe/frappe-bench/env/lib/python3.11/site-packages/redis/client.py", line 1536, in try_read
    if not conn.can_read(timeout=timeout):
           ^^^^^^^^^^^^^^^^^^^^^^^^^^^^^^
  File "/Users/upforcetech/Desktop/Frappe/frappe-bench/env/lib/python3.11/site-packages/redis/connection.py", line 861, in can_read
    return self._parser.can_read(timeout)
           ^^^^^^^^^^^^^^^^^^^^^^^^^^^^^^
  File "/Users/upforcetech/Desktop/Frappe/frappe-bench/env/lib/python3.11/site-packages/redis/connection.py", line 444, in can_read
    return self.read_from_socket(timeout=timeout, raise_on_timeout=False)
           ^^^^^^^^^^^^^^^^^^^^^^^^^^^^^^^^^^^^^^^^^^^^^^^^^^^^^^^^^^^^^^
  File "/Users/upforcetech/Desktop/Frappe/frappe-bench/env/lib/python3.11/site-packages/redis/connection.py", line 455, in read_from_socket
    raise ConnectionError(SERVER_CLOSED_CONNECTION_ERROR)
redis.exceptions.ConnectionError: Connection closed by server.
Traceback (most recent call last):
  File "/Users/upforcetech/Desktop/Frappe/frappe-bench/env/lib/python3.11/site-packages/redis/connection.py", line 699, in connect
    sock = self.retry.call_with_retry(
           ^^^^^^^^^^^^^^^^^^^^^^^^^^^
  File "/Users/upforcetech/Desktop/Frappe/frappe-bench/env/lib/python3.11/site-packages/redis/retry.py", line 46, in call_with_retry
    return do()
           ^^^^
  File "/Users/upforcetech/Desktop/Frappe/frappe-bench/env/lib/python3.11/site-packages/redis/connection.py", line 700, in <lambda>
    lambda: self._connect(), lambda error: self.disconnect(error)
            ^^^^^^^^^^^^^^^
  File "/Users/upforcetech/Desktop/Frappe/frappe-bench/env/lib/python3.11/site-packages/redis/connection.py", line 1002, in _connect
    raise err
  File "/Users/upforcetech/Desktop/Frappe/frappe-bench/env/lib/python3.11/site-packages/redis/connection.py", line 990, in _connect
    sock.connect(socket_address)
ConnectionRefusedError: [Errno 61] Connection refused

During handling of the above exception, another exception occurred:

Traceback (most recent call last):
  File "<frozen runpy>", line 198, in _run_module_as_main
  File "<frozen runpy>", line 88, in _run_code
  File "/Users/upforcetech/Desktop/Frappe/frappe-bench/apps/frappe/frappe/utils/bench_helper.py", line 114, in <module>
    main()
  File "/Users/upforcetech/Desktop/Frappe/frappe-bench/apps/frappe/frappe/utils/bench_helper.py", line 20, in main
    click.Group(commands=commands)(prog_name="bench")
  File "/Users/upforcetech/Desktop/Frappe/frappe-bench/env/lib/python3.11/site-packages/click/core.py", line 1161, in __call__
    return self.main(*args, **kwargs)
           ^^^^^^^^^^^^^^^^^^^^^^^^^^
  File "/Users/upforcetech/Desktop/Frappe/frappe-bench/env/lib/python3.11/site-packages/click/core.py", line 1082, in main
    rv = self.invoke(ctx)
         ^^^^^^^^^^^^^^^^
  File "/Users/upforcetech/Desktop/Frappe/frappe-bench/env/lib/python3.11/site-packages/click/core.py", line 1697, in invoke
    return _process_result(sub_ctx.command.invoke(sub_ctx))
                           ^^^^^^^^^^^^^^^^^^^^^^^^^^^^^^^
  File "/Users/upforcetech/Desktop/Frappe/frappe-bench/env/lib/python3.11/site-packages/click/core.py", line 1697, in invoke
    return _process_result(sub_ctx.command.invoke(sub_ctx))
                           ^^^^^^^^^^^^^^^^^^^^^^^^^^^^^^^
  File "/Users/upforcetech/Desktop/Frappe/frappe-bench/env/lib/python3.11/site-packages/click/core.py", line 1443, in invoke
    return ctx.invoke(self.callback, **ctx.params)
           ^^^^^^^^^^^^^^^^^^^^^^^^^^^^^^^^^^^^^^^
  File "/Users/upforcetech/Desktop/Frappe/frappe-bench/env/lib/python3.11/site-packages/click/core.py", line 788, in invoke
    return __callback(*args, **kwargs)
           ^^^^^^^^^^^^^^^^^^^^^^^^^^^
  File "/Users/upforcetech/Desktop/Frappe/frappe-bench/apps/frappe/frappe/commands/scheduler.py", line 205, in start_worker
    start_worker(
  File "/Users/upforcetech/Desktop/Frappe/frappe-bench/apps/frappe/frappe/utils/background_jobs.py", line 318, in start_worker
    worker.work(
  File "/Users/upforcetech/Desktop/Frappe/frappe-bench/env/lib/python3.11/site-packages/rq/worker.py", line 456, in work
    self.teardown()
  File "/Users/upforcetech/Desktop/Frappe/frappe-bench/env/lib/python3.11/site-packages/rq/worker.py", line 1047, in teardown
    self.unsubscribe()
  File "/Users/upforcetech/Desktop/Frappe/frappe-bench/env/lib/python3.11/site-packages/rq/worker.py", line 624, in unsubscribe
    self.pubsub.unsubscribe()
  File "/Users/upforcetech/Desktop/Frappe/frappe-bench/env/lib/python3.11/site-packages/redis/client.py", line 1659, in unsubscribe
    return self.execute_command("UNSUBSCRIBE", *args)
           ^^^^^^^^^^^^^^^^^^^^^^^^^^^^^^^^^^^^^^^^^^
  File "/Users/upforcetech/Desktop/Frappe/frappe-bench/env/lib/python3.11/site-packages/redis/client.py", line 1479, in execute_command
    self._execute(connection, connection.send_command, *args, **kwargs)
  File "/Users/upforcetech/Desktop/Frappe/frappe-bench/env/lib/python3.11/site-packages/redis/client.py", line 1518, in _execute
    return conn.retry.call_with_retry(
           ^^^^^^^^^^^^^^^^^^^^^^^^^^^
  File "/Users/upforcetech/Desktop/Frappe/frappe-bench/env/lib/python3.11/site-packages/redis/retry.py", line 49, in call_with_retry
    fail(error)
  File "/Users/upforcetech/Desktop/Frappe/frappe-bench/env/lib/python3.11/site-packages/redis/client.py", line 1520, in <lambda>
    lambda error: self._disconnect_raise_connect(conn, error),
                  ^^^^^^^^^^^^^^^^^^^^^^^^^^^^^^^^^^^^^^^^^^^
  File "/Users/upforcetech/Desktop/Frappe/frappe-bench/env/lib/python3.11/site-packages/redis/client.py", line 1507, in _disconnect_raise_connect
    raise error
  File "/Users/upforcetech/Desktop/Frappe/frappe-bench/env/lib/python3.11/site-packages/redis/retry.py", line 46, in call_with_retry
    return do()
           ^^^^
  File "/Users/upforcetech/Desktop/Frappe/frappe-bench/env/lib/python3.11/site-packages/redis/client.py", line 1519, in <lambda>
    lambda: command(*args, **kwargs),
            ^^^^^^^^^^^^^^^^^^^^^^^^
  File "/Users/upforcetech/Desktop/Frappe/frappe-bench/env/lib/python3.11/site-packages/redis/connection.py", line 847, in send_command
    self.send_packed_command(
  File "/Users/upforcetech/Desktop/Frappe/frappe-bench/env/lib/python3.11/site-packages/redis/connection.py", line 817, in send_packed_command
    self.connect()
  File "/Users/upforcetech/Desktop/Frappe/frappe-bench/env/lib/python3.11/site-packages/redis/connection.py", line 705, in connect
    raise ConnectionError(self._error_message(e))
redis.exceptions.ConnectionError: Error 61 connecting to 127.0.0.1:11010. Connection refused.
Traceback (most recent call last):
  File "/Users/upforcetech/Desktop/Frappe/frappe-bench/env/lib/python3.11/site-packages/redis/connection.py", line 874, in read_response
Exception in thread Thread-1:
Traceback (most recent call last):
  File "/Users/upforcetech/.pyenv/versions/3.11.8/lib/python3.11/threading.py", line 1045, in _bootstrap_inner
    response = self._parser.read_response(disable_decoding=disable_decoding)
               ^^^^^^^^^^^^^^^^^^^^^^^^^^^^^^^^^^^^^^^^^^^^^^^^^^^^^^^^^^^^^
  File "/Users/upforcetech/Desktop/Frappe/frappe-bench/env/lib/python3.11/site-packages/redis/connection.py", line 493, in read_response
    self.read_from_socket()
  File "/Users/upforcetech/Desktop/Frappe/frappe-bench/env/lib/python3.11/site-packages/redis/connection.py", line 453, in read_from_socket
    bufflen = self._sock.recv_into(self._buffer)
              ^^^^^^^^^^^^^^^^^^^^^^^^^^^^^^^^^^
ConnectionResetError: [Errno 54] Connection reset by peer

During handling of the above exception, another exception occurred:

Traceback (most recent call last):
  File "<frozen runpy>", line 198, in _run_module_as_main
  File "<frozen runpy>", line 88, in _run_code
  File "/Users/upforcetech/Desktop/Frappe/frappe-bench/apps/frappe/frappe/utils/bench_helper.py", line 114, in <module>
    main()
  File "/Users/upforcetech/Desktop/Frappe/frappe-bench/apps/frappe/frappe/utils/bench_helper.py", line 20, in main
    click.Group(commands=commands)(prog_name="bench")
  File "/Users/upforcetech/Desktop/Frappe/frappe-bench/env/lib/python3.11/site-packages/click/core.py", line 1161, in __call__
    return self.main(*args, **kwargs)
           ^^^^^^^^^^^^^^^^^^^^^^^^^^
  File "/Users/upforcetech/Desktop/Frappe/frappe-bench/env/lib/python3.11/site-packages/click/core.py", line 1082, in main
    rv = self.invoke(ctx)
          self.run()
  File "/Users/upforcetech/Desktop/Frappe/frappe-bench/env/lib/python3.11/site-packages/redis/client.py", line 1799, in run
   ^^^^^^^^^^^^^    pubsub.get_message(ignore_subscribe_messages=True, timeout=sleep_time)
  File "/Users/upforcetech/Desktop/Frappe/frappe-bench/env/lib/python3.11/site-packages/redis/client.py", line 1690, in get_message
    response = self.parse_response(block=(timeout is None), timeout=timeout)
               ^^^^^^^^^^^^^^^^^^^^^^^^^^^^^^^^^^^^^^^^^^^^^^^^^^^^^^^^^^^^^
  File "/Users/upforcetech/Desktop/Frappe/frappe-bench/env/lib/python3.11/site-packages/redis/client.py", line 1542, in parse_response
    response = self._execute(conn, try_read)
               ^^^^^^^^^^^^^^^^^^^^^^^^^^^^^
  File "/Users/upforcetech/Desktop/Frappe/frappe-bench/env/lib/python3.11/site-packages/redis/client.py", line 1518, in _execute
    return conn.retry.call_with_retry(
           ^^^^^^^^^^^^^^^^^^^^^^^^^^^
  File "/Users/upforcetech/Desktop/Frappe/frappe-bench/env/lib/python3.11/site-packages/redis/retry.py", line 49, in call_with_retry
    fail(error)
  File "/Users/upforcetech/Desktop/Frappe/frappe-bench/env/lib/python3.11/site-packages/redis/client.py", line 1520, in <lambda>
^^^
  File "/Users/upforcetech/Desktop/Frappe/frappe-bench/env/lib/python3.11/site-packages/click/core.py", line 1697, in invoke
    return _process_result(sub_ctx.command.invoke(sub_ctx))
                           ^^^^^^^^^^^^^^^^^^^^^^^^^^^^^^^
  File "/Users/upforcetech/Desktop/Frappe/frappe-bench/env/lib/python3.11/site-packages/click/core.py", line 1697, in invoke
        return _process_result(sub_ctx.command.invoke(sub_ctx))
                           ^^^^^^^^^^^^^^^^^^^^lambda error: self._disconnect_raise_connect(conn, error),
                  ^^^^^^^^^^^^^^^^^^^^^^^^^^^^^^^^^^^^^^^^^^^
  File "/Users/upforcetech/Desktop/Frappe/frappe-bench/env/lib/python3.11/site-packages/redis/client.py", line 1507, in _disconnect_raise_connect
^    raise error
  File "/Users/upforcetech/Desktop/Frappe/frappe-bench/env/lib/python3.11/site-packages/redis/retry.py", line 46, in call_with_retry
    return do()
           ^^^^
  File "/Users/upforcetech/Desktop/Frappe/frappe-bench/env/lib/python3.11/site-packages/redis/client.py", line 1519, in <lambda>
    lambda: command(*args, **kwargs),
            ^^^^^^^^^^^^^^^^^^^^^^^^
  File "/Users/upforcetech/Desktop/Frappe/frappe-bench/env/lib/python3.11/site-packages/redis/client.py", line 1536, in try_read
    if not conn.can_read(timeout=timeout):
           ^^^^^^^^^^^^^^^^^^^^^^^^^^^^^^
  File "/Users/upforcetech/Desktop/Frappe/frappe-bench/env/lib/python3.11/site-packages/redis/connection.py", line 861, in can_read
    return self._parser.can_read(timeout)
           ^^^^^^^^^^^^^^^^^^^^^^^^^^^^^^
  File "/Users/upforcetech/Desktop/Frappe/frappe-bench/env/lib/python3.11/site-packages/redis/connection.py", line 444, in can_read
    return self.read_from_socket(timeout=timeout, raise_on_timeout=False)
           ^^^^^^^^^^^^^^
  File "/Users/upforcetech/Desktop/Frappe/frappe-bench/env/lib/python3.11/site-packages/click/core.py", line 1443, in invoke
    return ctx.invoke(self.callback, **ctx.params)
           ^^^^^^^^^^^^^^^^^^^^^^^^^^^^^^^^^^^^^^^^^^^^^^^^^^^^^^^^^^^^^^^^^^^^^^^^^^^^^^^^^^^
  File "/Users/upforcetech/Desktop/Frappe/frappe-bench/env/lib/python3.11/site-packages/click/core.py", line 788, in invoke
^    ^return __callback(*args, **kwargs)^
^   ^ ^ ^ ^^^^^^^     ^^^^^^^^^^
^^^  File "/Users/upforcetech/Desktop/Frappe/frappe-bench/env/lib/python3.11/site-packages/redis/connection.py", line 455, in read_from_socket
^^^^^^^^    raise ConnectionError(SERVER_CLOSED_CONNECTION_ERROR)
redis.exceptions.ConnectionError: Connection closed by server.
^^^^^^
  File "/Users/upforcetech/Desktop/Frappe/frappe-bench/apps/frappe/frappe/commands/scheduler.py", line 205, in start_worker
    start_worker(
  File "/Users/upforcetech/Desktop/Frappe/frappe-bench/apps/frappe/frappe/utils/background_jobs.py", line 318, in start_worker
    worker.work(
  File "/Users/upforcetech/Desktop/Frappe/frappe-bench/env/lib/python3.11/site-packages/rq/worker.py", line 456, in work
    self.teardown()
  File "/Users/upforcetech/Desktop/Frappe/frappe-bench/env/lib/python3.11/site-packages/rq/worker.py", line 1046, in teardown
    self.register_death()
  File "/Users/upforcetech/Desktop/Frappe/frappe-bench/env/lib/python3.11/site-packages/rq/worker.py", line 832, in register_death
    p.execute()
  File "/Users/upforcetech/Desktop/Frappe/frappe-bench/env/lib/python3.11/site-packages/redis/client.py", line 2120, in execute
    return conn.retry.call_with_retry(
           ^^^^^^^^^^^^^^^^^^^^^^^^^^^
  File "/Users/upforcetech/Desktop/Frappe/frappe-bench/env/lib/python3.11/site-packages/redis/retry.py", line 49, in call_with_retry
    fail(error)
  File "/Users/upforcetech/Desktop/Frappe/frappe-bench/env/lib/python3.11/site-packages/redis/client.py", line 2122, in <lambda>
    lambda error: self._disconnect_raise_reset(conn, error),
                  ^^^^^^^^^^^^^^^^^^^^^^^^^^^^^^^^^^^^^^^^^
  File "/Users/upforcetech/Desktop/Frappe/frappe-bench/env/lib/python3.11/site-packages/redis/retry.py", line 46, in call_with_retry
    return do()
           ^^^^
  File "/Users/upforcetech/Desktop/Frappe/frappe-bench/env/lib/python3.11/site-packages/redis/client.py", line 2121, in <lambda>
    lambda: execute(conn, stack, raise_on_error),
            ^^^^^^^^^^^^^^^^^^^^^^^^^^^^^^^^^^^^
  File "/Users/upforcetech/Desktop/Frappe/frappe-bench/env/lib/python3.11/site-packages/redis/client.py", line 1975, in _execute_transaction
    self.parse_response(connection, "_")
  File "/Users/upforcetech/Desktop/Frappe/frappe-bench/env/lib/python3.11/site-packages/redis/client.py", line 2060, in parse_response
    result = Redis.parse_response(self, connection, command_name, **options)
             ^^^^^^^^^^^^^^^^^^^^^^^^^^^^^^^^^^^^^^^^^^^^^^^^^^^^^^^^^^^^^^^
  File "/Users/upforcetech/Desktop/Frappe/frappe-bench/env/lib/python3.11/site-packages/redis/client.py", line 1286, in parse_response
    response = connection.read_response()
               ^^^^^^^^^^^^^^^^^^^^^^^^^^
  File "/Users/upforcetech/Desktop/Frappe/frappe-bench/env/lib/python3.11/site-packages/redis/connection.py", line 882, in read_response
    raise ConnectionError(
redis.exceptions.ConnectionError: Error while reading from 127.0.0.1:11010 : (54, 'Connection reset by peer')
Exception in thread Thread-1:
Traceback (most recent call last):
  File "/Users/upforcetech/.pyenv/versions/3.11.8/lib/python3.11/threading.py", line 1045, in _bootstrap_inner
Traceback (most recent call last):
  File "/Users/upforcetech/Desktop/Frappe/frappe-bench/env/lib/python3.11/site-packages/redis/connection.py", line 699, in connect
    self.run()
  File "/Users/upforcetech/Desktop/Frappe/frappe-bench/env/lib/python3.11/site-packages/redis/client.py", line 1799, in run
    pubsub.get_message(ignore_subscribe_messages=True, timeout=sleep_time)    sock = self.retry.call_with_retry(
           ^^^^^^^^^^^^^^^^^^^^^^^^^^^
  File "/Users/upforcetech/Desktop/Frappe/frappe-bench/env/lib/python3.11/site-packages/redis/retry.py", line 46, in call_with_retry

  File "/Users/upforcetech/Desktop/Frappe/frappe-bench/env/lib/python3.11/site-packages/redis/client.py", line 1690, in get_message
    response = self.parse_response(block=(timeout is None), timeout=timeout)
           return do()
           ^  ^^^
  File "/Users/upforcetech/Desktop/Frappe/frappe-bench/env/lib/python3.11/site-packages/redis/connection.py", line 700, in <lambda>
    lambda: self._connect(), lambda error: self.disconnect(error)
            ^^^^^^^^^^^^^^^
   File "/Users/upforcetech/Desktop/Frappe/frappe-bench/env/lib/python3.11/site-packages/redis/connection.py", line 1002, in _connect
     ^^^^^^^^^^^^^^^^^^^^^^^^^^^^^^^^^^^^^^^^^^^^^^^^^    raise err
  File "/Users/upforcetech/Desktop/Frappe/frappe-bench/env/lib/python3.11/site-packages/redis/connection.py", line 990, in _connect
    sock.connect(socket_address)
ConnectionRefusedError: [Errno 61] Connection refused

During handling of the above exception, another exception occurred:

Traceback (most recent call last):
  File "<frozen runpy>", line 198, in _run_module_as_main
  File "<frozen runpy>", line 88, in _run_code
  File "/Users/upforcetech/Desktop/Frappe/frappe-bench/apps/frappe/frappe/utils/bench_helper.py", line 114, in <module>
    ^^^^^^^^^^^^main()
  File "/Users/upforcetech/Desktop/Frappe/frappe-bench/apps/frappe/frappe/utils/bench_helper.py", line 20, in main
    click.Group(commands=commands)(prog_name="bench")
  File "/Users/upforcetech/Desktop/Frappe/frappe-bench/env/lib/python3.11/site-packages/click/core.py", line 1161, in __call__
    return self.main(*args, **kwargs)
           ^^^^^^^^^^
  File "/Users/upforcetech/Desktop/Frappe/frappe-bench/env/lib/python3.11/site-packages/redis/client.py", line 1542, in parse_response
    response = self._execute(conn, try_read)
               ^^^^^^^^^^^^^^^^^^^^^^^^^^^
  File "/Users/upforcetech/Desktop/Frappe/frappe-bench/env/lib/python3.11/site-packages/click/core.py", line 1082, in main
    rv = self.invoke(ctx)
         ^^^^^^^^^^^^^^^^
  File "/Users/upforcetech/Desktop/Frappe/frappe-bench/env/lib/python3.11/site-packages/click/core.py", line 1697, in invoke
^^^^^^^^^^^^^    return _process_result(sub_ctx.command.invoke(sub_ctx))
                           ^^^^^^^^^^^^^^^^^^^^^^^^^^^^^^^
  File "/Users/upforcetech/Desktop/Frappe/frappe-bench/env/lib/python3.11/site-packages/click/core.py", line 1697, in invoke
    return _process_result(sub_ctx.command.invoke(sub_ctx))
                           ^^^^^^^^^^^^^^^^^^^^^^^^^^^^^^^
  File "/Users/upforcetech/Desktop/Frappe/frappe-bench/env/lib/python3.11/site-packages/click/core.py", line 1443, in invoke
    return ctx.invoke(self.callback, **ctx.params)
           ^^^^^^^^^^^^^^^^^^^^^^^^^^^^^^^^^^^^^^^
  File "/Users/upforcetech/Desktop/Frappe/frappe-bench/env/lib/python3.11/site-packages/click/core.py", line 788, in invoke
    return __callback(*args, **kwargs)
           ^^^^^^^^^^^^^^^^^^^^^^^^^^^
  File "/Users/upforcetech/Desktop/Frappe/frappe-bench/apps/frappe/frappe/commands/scheduler.py", line 205, in start_worker
    start_worker(
  File "/Users/upforcetech/Desktop/Frappe/frappe-bench/apps/frappe/frappe/utils/background_jobs.py", line 318, in start_worker
    worker.work(
  File "/Users/upforcetech/Desktop/Frappe/frappe-bench/env/lib/python3.11/site-packages/rq/worker.py", line 456, in work
    self.teardown()
  File "/Users/upforcetech/Desktop/Frappe/frappe-bench/env/lib/python3.11/site-packages/rq/worker.py", line 1046, in teardown
^    self.register_death()
  File "/Users/upforcetech/Desktop/Frappe/frappe-bench/env/lib/python3.11/site-packages/rq/worker.py", line 832, in register_death
    p.execute()
  File "/Users/upforcetech/Desktop/Frappe/frappe-bench/env/lib/python3.11/site-packages/redis/client.py", line 2114, in execute
    conn = self.connection_pool.get_connection("MULTI", self.shard_hint)
           ^^^^^^^^^^^^^^^^^^^^^^^^^^^^^^^^^^^^^^^^^^^^^^^^^^^^^^^^^^^^^
  File "/Users/upforcetech/Desktop/Frappe/frappe-bench/env/lib/python3.11/site-packages/redis/connection.py", line 1457, in get_connection
    connection.connect()
  File "/Users/upforcetech/Desktop/Frappe/frappe-bench/env/lib/python3.11/site-packages/redis/connection.py", line 705, in connect
    raise ConnectionError(self._error_message(e))
redis.exceptions.ConnectionError: Error 61 connecting to 127.0.0.1:11010. Connection refused.
Exception in thread Thread-1:
Traceback (most recent call last):
  File "/Users/upforcetech/.pyenv/versions/3.11.8/lib/python3.11/threading.py", line 1045, in _bootstrap_inner
    self.run()
  File "/Users/upforcetech/Desktop/Frappe/frappe-bench/env/lib/python3.11/site-packages/redis/client.py", line 1799, in run
    pubsub.get_message(ignore_subscribe_messages=True, timeout=sleep_time)
  File "/Users/upforcetech/Desktop/Frappe/frappe-bench/env/lib/python3.11/site-packages/redis/client.py", line 1690, in get_message
    response = self.parse_response(block=(timeout is None), timeout=timeout)
               ^^^^^^^^^^^^^^^^^^^^^^^^^^^^^^^^^^^^^^^^^^^^^^^^^^^^^^^^^^^^^
  File "/Users/upforcetech/Desktop/Frappe/frappe-bench/env/lib/python3.11/site-packages/redis/client.py", line 1542, in parse_response
    response = self._execute(conn, try_read)
               ^^^^^^^^^^^^^^^^^^^^^^^^^^^^^
  File "/Users/upforcetech/Desktop/Frappe/frappe-bench/env/lib/python3.11/site-packages/redis/client.py", line 1518, in _execute
    return conn.retry.call_with_retry(
           ^^^^^^^^^^^^^^^^^^^^^^^^^^^
  File "/Users/upforcetech/Desktop/Frappe/frappe-bench/env/lib/python3.11/site-packages/redis/retry.py", line 49, in call_with_retry
    fail(error)
  File "/Users/upforcetech/Desktop/Frappe/frappe-bench/env/lib/python3.11/site-packages/redis/client.py", line 1520, in <lambda>
    lambda error: self._disconnect_raise_connect(conn, error),
                  ^^^^^^^^^^^^^^^^^^^^^^^^^^^^^^^^^^^^^^^^^^^
  File "/Users/upforcetech/Desktop/Frappe/frappe-bench/env/lib/python3.11/site-packages/redis/client.py", line 1507, in _disconnect_raise_connect
    raise error
  File "/Users/upforcetech/Desktop/Frappe/frappe-bench/env/lib/python3.11/site-packages/redis/retry.py", line 46, in call_with_retry
    return do()
           ^^^^
  File "/Users/upforcetech/Desktop/Frappe/frappe-bench/env/lib/python3.11/site-packages/redis/client.py", line 1519, in <lambda>
    lambda: command(*args, **kwargs),
            ^^^^^^^^^^^^^^^^^^^^^^^^
  File "/Users/upforcetech/Desktop/Frappe/frappe-bench/env/lib/python3.11/site-packages/redis/client.py", line 1536, in try_read
    if not conn.can_read(timeout=timeout):
           ^^^^^^^^^^^^^^^^^^^^^^^^^^^^^^
  File "/Users/upforcetech/Desktop/Frappe/frappe-bench/env/lib/python3.11/site-packages/redis/connection.py", line 861, in can_read
    return self._parser.can_read(timeout)
           ^^^^^^^^^^^^^^^^^^^^^^^^^^^^^^
  File "/Users/upforcetech/Desktop/Frappe/frappe-bench/env/lib/python3.11/site-packages/redis/connection.py", line 444, in can_read
    return self.read_from_socket(timeout=timeout, raise_on_timeout=False)
           ^^^^^^^^^^^^^^^^^^^^^^^^^^^^^^^^^^^^^^^^^^^^^^^^^^^^^^^^^^^^^^
  File "/Users/upforcetech/Desktop/Frappe/frappe-bench/env/lib/python3.11/site-packages/redis/connection.py", line 455, in read_from_socket
    raise ConnectionError(SERVER_CLOSED_CONNECTION_ERROR)
redis.exceptions.ConnectionError: Connection closed by server.
Traceback (most recent call last):
  File "/Users/upforcetech/Desktop/Frappe/frappe-bench/env/lib/python3.11/site-packages/redis/connection.py", line 699, in connect
    sock = self.retry.call_with_retry(
           ^^^^^^^^^^^^^^^^^^^^^^^^^^^
  File "/Users/upforcetech/Desktop/Frappe/frappe-bench/env/lib/python3.11/site-packages/redis/retry.py", line 46, in call_with_retry
    return do()
           ^^^^
  File "/Users/upforcetech/Desktop/Frappe/frappe-bench/env/lib/python3.11/site-packages/redis/connection.py", line 700, in <lambda>
    lambda: self._connect(), lambda error: self.disconnect(error)
            ^^^^^^^^^^^^^^^
  File "/Users/upforcetech/Desktop/Frappe/frappe-bench/env/lib/python3.11/site-packages/redis/connection.py", line 1002, in _connect
    raise err
  File "/Users/upforcetech/Desktop/Frappe/frappe-bench/env/lib/python3.11/site-packages/redis/connection.py", line 990, in _connect
    sock.connect(socket_address)
ConnectionRefusedError: [Errno 61] Connection refused

During handling of the above exception, another exception occurred:

Traceback (most recent call last):
  File "<frozen runpy>", line 198, in _run_module_as_main
  File "<frozen runpy>", line 88, in _run_code
  File "/Users/upforcetech/Desktop/Frappe/frappe-bench/apps/frappe/frappe/utils/bench_helper.py", line 114, in <module>
    main()
  File "/Users/upforcetech/Desktop/Frappe/frappe-bench/apps/frappe/frappe/utils/bench_helper.py", line 20, in main
    click.Group(commands=commands)(prog_name="bench")
  File "/Users/upforcetech/Desktop/Frappe/frappe-bench/env/lib/python3.11/site-packages/click/core.py", line 1161, in __call__
    return self.main(*args, **kwargs)
           ^^^^^^^^^^^^^^^^^^^^^^^^^^
  File "/Users/upforcetech/Desktop/Frappe/frappe-bench/env/lib/python3.11/site-packages/click/core.py", line 1082, in main
    rv = self.invoke(ctx)
         ^^^^^^^^^^^^^^^^
  File "/Users/upforcetech/Desktop/Frappe/frappe-bench/env/lib/python3.11/site-packages/click/core.py", line 1697, in invoke
    return _process_result(sub_ctx.command.invoke(sub_ctx))
                           ^^^^^^^^^^^^^^^^^^^^^^^^^^^^^^^
  File "/Users/upforcetech/Desktop/Frappe/frappe-bench/env/lib/python3.11/site-packages/click/core.py", line 1697, in invoke
    return _process_result(sub_ctx.command.invoke(sub_ctx))
                           ^^^^^^^^^^^^^^^^^^^^^^^^^^^^^^^
  File "/Users/upforcetech/Desktop/Frappe/frappe-bench/env/lib/python3.11/site-packages/click/core.py", line 1443, in invoke
    return ctx.invoke(self.callback, **ctx.params)
           ^^^^^^^^^^^^^^^^^^^^^^^^^^^^^^^^^^^^^^^
  File "/Users/upforcetech/Desktop/Frappe/frappe-bench/env/lib/python3.11/site-packages/click/core.py", line 788, in invoke
    return __callback(*args, **kwargs)
           ^^^^^^^^^^^^^^^^^^^^^^^^^^^
  File "/Users/upforcetech/Desktop/Frappe/frappe-bench/apps/frappe/frappe/commands/scheduler.py", line 205, in start_worker
    start_worker(
  File "/Users/upforcetech/Desktop/Frappe/frappe-bench/apps/frappe/frappe/utils/background_jobs.py", line 318, in start_worker
    worker.work(
  File "/Users/upforcetech/Desktop/Frappe/frappe-bench/env/lib/python3.11/site-packages/rq/worker.py", line 456, in work
    self.teardown()
  File "/Users/upforcetech/Desktop/Frappe/frappe-bench/env/lib/python3.11/site-packages/rq/worker.py", line 1047, in teardown
    self.unsubscribe()
  File "/Users/upforcetech/Desktop/Frappe/frappe-bench/env/lib/python3.11/site-packages/rq/worker.py", line 624, in unsubscribe
    self.pubsub.unsubscribe()
  File "/Users/upforcetech/Desktop/Frappe/frappe-bench/env/lib/python3.11/site-packages/redis/client.py", line 1659, in unsubscribe
    return self.execute_command("UNSUBSCRIBE", *args)
           ^^^^^^^^^^^^^^^^^^^^^^^^^^^^^^^^^^^^^^^^^^
  File "/Users/upforcetech/Desktop/Frappe/frappe-bench/env/lib/python3.11/site-packages/redis/client.py", line 1479, in execute_command
    self._execute(connection, connection.send_command, *args, **kwargs)
  File "/Users/upforcetech/Desktop/Frappe/frappe-bench/env/lib/python3.11/site-packages/redis/client.py", line 1518, in _execute
    return conn.retry.call_with_retry(
           ^^^^^^^^^^^^^^^^^^^^^^^^^^^
  File "/Users/upforcetech/Desktop/Frappe/frappe-bench/env/lib/python3.11/site-packages/redis/retry.py", line 49, in call_with_retry
    fail(error)
  File "/Users/upforcetech/Desktop/Frappe/frappe-bench/env/lib/python3.11/site-packages/redis/client.py", line 1520, in <lambda>
    lambda error: self._disconnect_raise_connect(conn, error),
                  ^^^^^^^^^^^^^^^^^^^^^^^^^^^^^^^^^^^^^^^^^^^
  File "/Users/upforcetech/Desktop/Frappe/frappe-bench/env/lib/python3.11/site-packages/redis/client.py", line 1507, in _disconnect_raise_connect
    raise error
  File "/Users/upforcetech/Desktop/Frappe/frappe-bench/env/lib/python3.11/site-packages/redis/retry.py", line 46, in call_with_retry
    return do()
           ^^^^
  File "/Users/upforcetech/Desktop/Frappe/frappe-bench/env/lib/python3.11/site-packages/redis/client.py", line 1519, in <lambda>
    lambda: command(*args, **kwargs),
            ^^^^^^^^^^^^^^^^^^^^^^^^
  File "/Users/upforcetech/Desktop/Frappe/frappe-bench/env/lib/python3.11/site-packages/redis/connection.py", line 847, in send_command
    self.send_packed_command(
  File "/Users/upforcetech/Desktop/Frappe/frappe-bench/env/lib/python3.11/site-packages/redis/connection.py", line 817, in send_packed_command
    self.connect()
  File "/Users/upforcetech/Desktop/Frappe/frappe-bench/env/lib/python3.11/site-packages/redis/connection.py", line 705, in connect
    raise ConnectionError(self._error_message(e))
redis.exceptions.ConnectionError: Error 61 connecting to 127.0.0.1:11010. Connection refused.
